package com.hypeirochus.scmc.worldgen.structure;

import java.util.Random;

import com.hypeirochus.scmc.handlers.BlockHandler;

import net.minecraft.block.Block;
import net.minecraft.block.material.Material;
import net.minecraft.init.Blocks;
import net.minecraft.util.math.BlockPos;
import net.minecraft.world.World;

public class StructureZergHydraliskDenTemplate extends SCWorldGenerator {

	@Override
	public boolean generate(World world, Random rand, int offsetX, int offsetY, int offsetZ, BlockPos pos, boolean flag) {
		generate_r0(world, rand, offsetX, offsetY, offsetZ, pos, flag);
		return true;
	}

	public boolean generate_r0(World world, Random rand, int offsetX, int offsetY, int offsetZ, BlockPos pos, boolean flag) {
		if (flag) {
			if (!LocationIsValidSpawn(world, pos) || !LocationIsValidSpawn(world, pos.add(24, 0, 0)) || !LocationIsValidSpawn(world, pos.add(24, 0, 24)) || !LocationIsValidSpawn(world, pos.add(0, 0, 24))) {
				return false;
			}
		}
		int x = offsetX;
		int y = offsetY;
		int z = offsetZ;
		world.setBlockState(pos.add(x + 4, y + 0, z + 1), BlockHandler.ZERG_FLESH.getDefaultState(), 2);
		world.setBlockState(pos.add(x + 5, y + 0, z + 1), BlockHandler.ZERG_FLESH.getDefaultState(), 2);
		world.setBlockState(pos.add(x + 6, y + 0, z + 1), BlockHandler.ZERG_FLESH.getDefaultState(), 2);
		world.setBlockState(pos.add(x + 3, y + 0, z + 2), BlockHandler.ZERG_FLESH.getDefaultState(), 2);
		world.setBlockState(pos.add(x + 4, y + 0, z + 2), BlockHandler.ZERG_FLESH.getDefaultState(), 2);
		world.setBlockState(pos.add(x + 5, y + 0, z + 2), BlockHandler.ZERG_FLESH.getDefaultState(), 2);
		world.setBlockState(pos.add(x + 6, y + 0, z + 2), BlockHandler.ZERG_FLESH.getDefaultState(), 2);
		world.setBlockState(pos.add(x + 7, y + 0, z + 2), BlockHandler.ZERG_FLESH.getDefaultState(), 2);
		world.setBlockState(pos.add(x + 8, y + 0, z + 2), BlockHandler.ZERG_FLESH.getDefaultState(), 2);
		world.setBlockState(pos.add(x + 2, y + 0, z + 3), BlockHandler.ZERG_FLESH.getDefaultState(), 2);
		world.setBlockState(pos.add(x + 3, y + 0, z + 3), BlockHandler.ZERG_FLESH.getDefaultState(), 2);
		world.setBlockState(pos.add(x + 4, y + 0, z + 3), BlockHandler.ZERG_FLESH.getDefaultState(), 2);
		world.setBlockState(pos.add(x + 5, y + 0, z + 3), BlockHandler.ZERG_FLESH.getDefaultState(), 2);
		world.setBlockState(pos.add(x + 6, y + 0, z + 3), BlockHandler.ZERG_FLESH.getDefaultState(), 2);
		world.setBlockState(pos.add(x + 7, y + 0, z + 3), BlockHandler.ZERG_FLESH.getDefaultState(), 2);
		world.setBlockState(pos.add(x + 8, y + 0, z + 3), BlockHandler.ZERG_FLESH.getDefaultState(), 2);
		world.setBlockState(pos.add(x + 9, y + 0, z + 3), BlockHandler.ZERG_FLESH.getDefaultState(), 2);
		world.setBlockState(pos.add(x + 2, y + 0, z + 4), BlockHandler.ZERG_FLESH.getDefaultState(), 2);
		world.setBlockState(pos.add(x + 3, y + 0, z + 4), BlockHandler.ZERG_FLESH.getDefaultState(), 2);
		world.setBlockState(pos.add(x + 4, y + 0, z + 4), BlockHandler.ZERG_FLESH.getDefaultState(), 2);
		world.setBlockState(pos.add(x + 5, y + 0, z + 4), BlockHandler.ZERG_FLESH.getDefaultState(), 2);
		world.setBlockState(pos.add(x + 6, y + 0, z + 4), BlockHandler.ZERG_FLESH.getDefaultState(), 2);
		world.setBlockState(pos.add(x + 7, y + 0, z + 4), BlockHandler.ZERG_FLESH.getDefaultState(), 2);
		world.setBlockState(pos.add(x + 8, y + 0, z + 4), BlockHandler.ZERG_FLESH.getDefaultState(), 2);
		world.setBlockState(pos.add(x + 9, y + 0, z + 4), BlockHandler.ZERG_FLESH.getDefaultState(), 2);
		world.setBlockState(pos.add(x + 10, y + 0, z + 4), BlockHandler.ZERG_FLESH.getDefaultState(), 2);
		world.setBlockState(pos.add(x + 1, y + 0, z + 5), BlockHandler.ZERG_FLESH.getDefaultState(), 2);
		world.setBlockState(pos.add(x + 2, y + 0, z + 5), BlockHandler.ZERG_FLESH.getDefaultState(), 2);
		world.setBlockState(pos.add(x + 3, y + 0, z + 5), BlockHandler.ZERG_FLESH.getDefaultState(), 2);
		world.setBlockState(pos.add(x + 4, y + 0, z + 5), BlockHandler.ZERG_FLESH.getDefaultState(), 2);
		world.setBlockState(pos.add(x + 5, y + 0, z + 5), BlockHandler.ZERG_FLESH.getDefaultState(), 2);
		world.setBlockState(pos.add(x + 6, y + 0, z + 5), BlockHandler.ZERG_FLESH.getDefaultState(), 2);
		world.setBlockState(pos.add(x + 7, y + 0, z + 5), BlockHandler.ZERG_FLESH.getDefaultState(), 2);
		world.setBlockState(pos.add(x + 8, y + 0, z + 5), BlockHandler.ZERG_FLESH.getDefaultState(), 2);
		world.setBlockState(pos.add(x + 9, y + 0, z + 5), BlockHandler.ZERG_FLESH.getDefaultState(), 2);
		world.setBlockState(pos.add(x + 10, y + 0, z + 5), BlockHandler.ZERG_FLESH.getDefaultState(), 2);
		world.setBlockState(pos.add(x + 11, y + 0, z + 5), BlockHandler.ZERG_FLESH.getDefaultState(), 2);
		world.setBlockState(pos.add(x + 1, y + 0, z + 6), BlockHandler.ZERG_FLESH.getDefaultState(), 2);
		world.setBlockState(pos.add(x + 2, y + 0, z + 6), BlockHandler.ZERG_FLESH.getDefaultState(), 2);
		world.setBlockState(pos.add(x + 3, y + 0, z + 6), BlockHandler.ZERG_FLESH.getDefaultState(), 2);
		world.setBlockState(pos.add(x + 4, y + 0, z + 6), BlockHandler.ZERG_FLESH.getDefaultState(), 2);
		world.setBlockState(pos.add(x + 5, y + 0, z + 6), BlockHandler.ZERG_FLESH.getDefaultState(), 2);
		world.setBlockState(pos.add(x + 6, y + 0, z + 6), BlockHandler.ZERG_FLESH.getDefaultState(), 2);
		world.setBlockState(pos.add(x + 7, y + 0, z + 6), BlockHandler.ZERG_FLESH.getDefaultState(), 2);
		world.setBlockState(pos.add(x + 8, y + 0, z + 6), BlockHandler.ZERG_FLESH.getDefaultState(), 2);
		world.setBlockState(pos.add(x + 9, y + 0, z + 6), BlockHandler.ZERG_FLESH.getDefaultState(), 2);
		world.setBlockState(pos.add(x + 10, y + 0, z + 6), BlockHandler.ZERG_FLESH.getDefaultState(), 2);
		world.setBlockState(pos.add(x + 11, y + 0, z + 6), BlockHandler.ZERG_FLESH.getDefaultState(), 2);
		world.setBlockState(pos.add(x + 12, y + 0, z + 6), BlockHandler.ZERG_FLESH.getDefaultState(), 2);
		world.setBlockState(pos.add(x + 15, y + 0, z + 6), BlockHandler.ZERG_FLESH.getDefaultState(), 2);
		world.setBlockState(pos.add(x + 1, y + 0, z + 7), BlockHandler.ZERG_FLESH.getDefaultState(), 2);
		world.setBlockState(pos.add(x + 2, y + 0, z + 7), BlockHandler.ZERG_FLESH.getDefaultState(), 2);
		world.setBlockState(pos.add(x + 3, y + 0, z + 7), BlockHandler.ZERG_FLESH.getDefaultState(), 2);
		world.setBlockState(pos.add(x + 4, y + 0, z + 7), BlockHandler.ZERG_FLESH.getDefaultState(), 2);
		world.setBlockState(pos.add(x + 5, y + 0, z + 7), BlockHandler.ZERG_FLESH.getDefaultState(), 2);
		world.setBlockState(pos.add(x + 6, y + 0, z + 7), BlockHandler.ZERG_FLESH.getDefaultState(), 2);
		world.setBlockState(pos.add(x + 7, y + 0, z + 7), BlockHandler.ZERG_FLESH.getDefaultState(), 2);
		world.setBlockState(pos.add(x + 8, y + 0, z + 7), BlockHandler.ZERG_FLESH.getDefaultState(), 2);
		world.setBlockState(pos.add(x + 9, y + 0, z + 7), BlockHandler.ZERG_FLESH.getDefaultState(), 2);
		world.setBlockState(pos.add(x + 10, y + 0, z + 7), BlockHandler.ZERG_FLESH.getDefaultState(), 2);
		world.setBlockState(pos.add(x + 11, y + 0, z + 7), BlockHandler.ZERG_FLESH.getDefaultState(), 2);
		world.setBlockState(pos.add(x + 12, y + 0, z + 7), BlockHandler.ZERG_FLESH.getDefaultState(), 2);
		world.setBlockState(pos.add(x + 13, y + 0, z + 7), BlockHandler.ZERG_FLESH.getDefaultState(), 2);
		world.setBlockState(pos.add(x + 14, y + 0, z + 7), BlockHandler.ZERG_FLESH.getDefaultState(), 2);
		world.setBlockState(pos.add(x + 15, y + 0, z + 7), BlockHandler.ZERG_FLESH.getDefaultState(), 2);
		world.setBlockState(pos.add(x + 16, y + 0, z + 7), BlockHandler.ZERG_FLESH.getDefaultState(), 2);
		world.setBlockState(pos.add(x + 1, y + 0, z + 8), BlockHandler.ZERG_FLESH.getDefaultState(), 2);

		world.setBlockState(pos.add(x + 2, y + 0, z + 8), BlockHandler.ZERG_FLESH.getDefaultState(), 2);

		world.setBlockState(pos.add(x + 3, y + 0, z + 8), BlockHandler.ZERG_FLESH.getDefaultState(), 2);

		world.setBlockState(pos.add(x + 4, y + 0, z + 8), BlockHandler.ZERG_FLESH.getDefaultState(), 2);

		world.setBlockState(pos.add(x + 5, y + 0, z + 8), BlockHandler.ZERG_FLESH.getDefaultState(), 2);

		world.setBlockState(pos.add(x + 6, y + 0, z + 8), BlockHandler.ZERG_FLESH.getDefaultState(), 2);

		world.setBlockState(pos.add(x + 7, y + 0, z + 8), BlockHandler.ZERG_FLESH.getDefaultState(), 2);

		world.setBlockState(pos.add(x + 8, y + 0, z + 8), BlockHandler.ZERG_FLESH.getDefaultState(), 2);

		world.setBlockState(pos.add(x + 9, y + 0, z + 8), BlockHandler.ZERG_FLESH.getDefaultState(), 2);

		world.setBlockState(pos.add(x + 10, y + 0, z + 8), BlockHandler.ZERG_FLESH.getDefaultState(), 2);

		world.setBlockState(pos.add(x + 11, y + 0, z + 8), BlockHandler.ZERG_FLESH.getDefaultState(), 2);

		world.setBlockState(pos.add(x + 12, y + 0, z + 8), BlockHandler.ZERG_FLESH.getDefaultState(), 2);

		world.setBlockState(pos.add(x + 13, y + 0, z + 8), BlockHandler.ZERG_FLESH.getDefaultState(), 2);

		world.setBlockState(pos.add(x + 14, y + 0, z + 8), BlockHandler.ZERG_FLESH.getDefaultState(), 2);

		world.setBlockState(pos.add(x + 15, y + 0, z + 8), BlockHandler.ZERG_FLESH.getDefaultState(), 2);

		world.setBlockState(pos.add(x + 16, y + 0, z + 8), BlockHandler.ZERG_FLESH.getDefaultState(), 2);

		world.setBlockState(pos.add(x + 17, y + 0, z + 8), BlockHandler.ZERG_FLESH.getDefaultState(), 2);
		world.setBlockState(pos.add(x + 1, y + 0, z + 9), BlockHandler.ZERG_FLESH.getDefaultState(), 2);

		world.setBlockState(pos.add(x + 2, y + 0, z + 9), BlockHandler.ZERG_FLESH.getDefaultState(), 2);

		world.setBlockState(pos.add(x + 3, y + 0, z + 9), BlockHandler.ZERG_FLESH.getDefaultState(), 2);

		world.setBlockState(pos.add(x + 4, y + 0, z + 9), BlockHandler.ZERG_FLESH.getDefaultState(), 2);

		world.setBlockState(pos.add(x + 5, y + 0, z + 9), BlockHandler.ZERG_FLESH.getDefaultState(), 2);

		world.setBlockState(pos.add(x + 6, y + 0, z + 9), BlockHandler.ZERG_FLESH.getDefaultState(), 2);

		world.setBlockState(pos.add(x + 7, y + 0, z + 9), BlockHandler.ZERG_FLESH.getDefaultState(), 2);

		world.setBlockState(pos.add(x + 8, y + 0, z + 9), BlockHandler.ZERG_FLESH.getDefaultState(), 2);

		world.setBlockState(pos.add(x + 9, y + 0, z + 9), BlockHandler.ZERG_FLESH.getDefaultState(), 2);

		world.setBlockState(pos.add(x + 10, y + 0, z + 9), BlockHandler.ZERG_FLESH.getDefaultState(), 2);

		world.setBlockState(pos.add(x + 11, y + 0, z + 9), BlockHandler.ZERG_FLESH.getDefaultState(), 2);

		world.setBlockState(pos.add(x + 12, y + 0, z + 9), BlockHandler.ZERG_FLESH.getDefaultState(), 2);

		world.setBlockState(pos.add(x + 13, y + 0, z + 9), BlockHandler.ZERG_FLESH.getDefaultState(), 2);

		world.setBlockState(pos.add(x + 14, y + 0, z + 9), BlockHandler.ZERG_FLESH.getDefaultState(), 2);

		world.setBlockState(pos.add(x + 15, y + 0, z + 9), BlockHandler.ZERG_FLESH.getDefaultState(), 2);

		world.setBlockState(pos.add(x + 16, y + 0, z + 9), BlockHandler.ZERG_FLESH.getDefaultState(), 2);

		world.setBlockState(pos.add(x + 17, y + 0, z + 9), BlockHandler.ZERG_FLESH.getDefaultState(), 2);

		world.setBlockState(pos.add(x + 18, y + 0, z + 9), BlockHandler.ZERG_FLESH.getDefaultState(), 2);
		world.setBlockState(pos.add(x + 1, y + 0, z + 10), BlockHandler.ZERG_FLESH.getDefaultState(), 2);

		world.setBlockState(pos.add(x + 2, y + 0, z + 10), BlockHandler.ZERG_FLESH.getDefaultState(), 2);

		world.setBlockState(pos.add(x + 3, y + 0, z + 10), BlockHandler.ZERG_FLESH.getDefaultState(), 2);

		world.setBlockState(pos.add(x + 4, y + 0, z + 10), BlockHandler.ZERG_FLESH.getDefaultState(), 2);

		world.setBlockState(pos.add(x + 5, y + 0, z + 10), BlockHandler.ZERG_FLESH.getDefaultState(), 2);

		world.setBlockState(pos.add(x + 6, y + 0, z + 10), BlockHandler.ZERG_FLESH.getDefaultState(), 2);

		world.setBlockState(pos.add(x + 7, y + 0, z + 10), BlockHandler.ZERG_FLESH.getDefaultState(), 2);

		world.setBlockState(pos.add(x + 8, y + 0, z + 10), BlockHandler.ZERG_FLESH.getDefaultState(), 2);

		world.setBlockState(pos.add(x + 9, y + 0, z + 10), BlockHandler.ZERG_FLESH.getDefaultState(), 2);

		world.setBlockState(pos.add(x + 10, y + 0, z + 10), BlockHandler.ZERG_FLESH.getDefaultState(), 2);

		world.setBlockState(pos.add(x + 11, y + 0, z + 10), BlockHandler.ZERG_FLESH.getDefaultState(), 2);

		world.setBlockState(pos.add(x + 12, y + 0, z + 10), BlockHandler.ZERG_FLESH.getDefaultState(), 2);

		world.setBlockState(pos.add(x + 13, y + 0, z + 10), BlockHandler.ZERG_FLESH.getDefaultState(), 2);

		world.setBlockState(pos.add(x + 14, y + 0, z + 10), BlockHandler.ZERG_FLESH.getDefaultState(), 2);

		world.setBlockState(pos.add(x + 15, y + 0, z + 10), BlockHandler.ZERG_FLESH.getDefaultState(), 2);

		world.setBlockState(pos.add(x + 16, y + 0, z + 10), BlockHandler.ZERG_FLESH.getDefaultState(), 2);

		world.setBlockState(pos.add(x + 17, y + 0, z + 10), BlockHandler.ZERG_FLESH.getDefaultState(), 2);
		world.setBlockState(pos.add(x + 1, y + 0, z + 11), BlockHandler.ZERG_FLESH.getDefaultState(), 2);

		world.setBlockState(pos.add(x + 2, y + 0, z + 11), BlockHandler.ZERG_FLESH.getDefaultState(), 2);

		world.setBlockState(pos.add(x + 3, y + 0, z + 11), BlockHandler.ZERG_FLESH.getDefaultState(), 2);

		world.setBlockState(pos.add(x + 4, y + 0, z + 11), BlockHandler.ZERG_FLESH.getDefaultState(), 2);

		world.setBlockState(pos.add(x + 5, y + 0, z + 11), BlockHandler.ZERG_FLESH.getDefaultState(), 2);

		world.setBlockState(pos.add(x + 6, y + 0, z + 11), BlockHandler.ZERG_FLESH.getDefaultState(), 2);

		world.setBlockState(pos.add(x + 7, y + 0, z + 11), BlockHandler.ZERG_FLESH.getDefaultState(), 2);

		world.setBlockState(pos.add(x + 8, y + 0, z + 11), BlockHandler.ZERG_FLESH.getDefaultState(), 2);

		world.setBlockState(pos.add(x + 9, y + 0, z + 11), BlockHandler.ZERG_FLESH.getDefaultState(), 2);

		world.setBlockState(pos.add(x + 10, y + 0, z + 11), BlockHandler.ZERG_FLESH.getDefaultState(), 2);

		world.setBlockState(pos.add(x + 11, y + 0, z + 11), BlockHandler.ZERG_FLESH.getDefaultState(), 2);

		world.setBlockState(pos.add(x + 12, y + 0, z + 11), BlockHandler.ZERG_FLESH.getDefaultState(), 2);

		world.setBlockState(pos.add(x + 13, y + 0, z + 11), BlockHandler.ZERG_FLESH.getDefaultState(), 2);

		world.setBlockState(pos.add(x + 14, y + 0, z + 11), BlockHandler.ZERG_FLESH.getDefaultState(), 2);

		world.setBlockState(pos.add(x + 15, y + 0, z + 11), BlockHandler.ZERG_FLESH.getDefaultState(), 2);

		world.setBlockState(pos.add(x + 16, y + 0, z + 11), BlockHandler.ZERG_FLESH.getDefaultState(), 2);

		world.setBlockState(pos.add(x + 17, y + 0, z + 11), BlockHandler.ZERG_FLESH.getDefaultState(), 2);
		world.setBlockState(pos.add(x + 1, y + 0, z + 12), BlockHandler.ZERG_FLESH.getDefaultState(), 2);

		world.setBlockState(pos.add(x + 2, y + 0, z + 12), BlockHandler.ZERG_FLESH.getDefaultState(), 2);

		world.setBlockState(pos.add(x + 3, y + 0, z + 12), BlockHandler.ZERG_FLESH.getDefaultState(), 2);

		world.setBlockState(pos.add(x + 4, y + 0, z + 12), BlockHandler.ZERG_FLESH.getDefaultState(), 2);

		world.setBlockState(pos.add(x + 5, y + 0, z + 12), BlockHandler.ZERG_FLESH.getDefaultState(), 2);

		world.setBlockState(pos.add(x + 6, y + 0, z + 12), BlockHandler.ZERG_FLESH.getDefaultState(), 2);

		world.setBlockState(pos.add(x + 7, y + 0, z + 12), BlockHandler.ZERG_FLESH.getDefaultState(), 2);

		world.setBlockState(pos.add(x + 8, y + 0, z + 12), BlockHandler.ZERG_FLESH.getDefaultState(), 2);

		world.setBlockState(pos.add(x + 9, y + 0, z + 12), BlockHandler.ZERG_FLESH.getDefaultState(), 2);

		world.setBlockState(pos.add(x + 10, y + 0, z + 12), BlockHandler.ZERG_FLESH.getDefaultState(), 2);

		world.setBlockState(pos.add(x + 11, y + 0, z + 12), BlockHandler.ZERG_FLESH.getDefaultState(), 2);

		world.setBlockState(pos.add(x + 12, y + 0, z + 12), BlockHandler.ZERG_FLESH.getDefaultState(), 2);

		world.setBlockState(pos.add(x + 13, y + 0, z + 12), BlockHandler.ZERG_FLESH.getDefaultState(), 2);

		world.setBlockState(pos.add(x + 14, y + 0, z + 12), BlockHandler.ZERG_FLESH.getDefaultState(), 2);

		world.setBlockState(pos.add(x + 15, y + 0, z + 12), BlockHandler.ZERG_FLESH.getDefaultState(), 2);

		world.setBlockState(pos.add(x + 16, y + 0, z + 12), BlockHandler.ZERG_FLESH.getDefaultState(), 2);

		world.setBlockState(pos.add(x + 17, y + 0, z + 12), BlockHandler.ZERG_FLESH.getDefaultState(), 2);

		world.setBlockState(pos.add(x + 18, y + 0, z + 12), BlockHandler.ZERG_FLESH.getDefaultState(), 2);
		world.setBlockState(pos.add(x + 1, y + 0, z + 13), BlockHandler.ZERG_FLESH.getDefaultState(), 2);

		world.setBlockState(pos.add(x + 2, y + 0, z + 13), BlockHandler.ZERG_FLESH.getDefaultState(), 2);

		world.setBlockState(pos.add(x + 3, y + 0, z + 13), BlockHandler.ZERG_FLESH.getDefaultState(), 2);

		world.setBlockState(pos.add(x + 4, y + 0, z + 13), BlockHandler.ZERG_FLESH.getDefaultState(), 2);

		world.setBlockState(pos.add(x + 5, y + 0, z + 13), BlockHandler.ZERG_FLESH.getDefaultState(), 2);

		world.setBlockState(pos.add(x + 6, y + 0, z + 13), BlockHandler.ZERG_FLESH.getDefaultState(), 2);

		world.setBlockState(pos.add(x + 7, y + 0, z + 13), BlockHandler.ZERG_FLESH.getDefaultState(), 2);

		world.setBlockState(pos.add(x + 8, y + 0, z + 13), BlockHandler.ZERG_FLESH.getDefaultState(), 2);

		world.setBlockState(pos.add(x + 9, y + 0, z + 13), BlockHandler.ZERG_FLESH.getDefaultState(), 2);

		world.setBlockState(pos.add(x + 10, y + 0, z + 13), BlockHandler.ZERG_FLESH.getDefaultState(), 2);

		world.setBlockState(pos.add(x + 11, y + 0, z + 13), BlockHandler.ZERG_FLESH.getDefaultState(), 2);

		world.setBlockState(pos.add(x + 12, y + 0, z + 13), BlockHandler.ZERG_FLESH.getDefaultState(), 2);

		world.setBlockState(pos.add(x + 13, y + 0, z + 13), BlockHandler.ZERG_FLESH.getDefaultState(), 2);

		world.setBlockState(pos.add(x + 14, y + 0, z + 13), BlockHandler.ZERG_FLESH.getDefaultState(), 2);

		world.setBlockState(pos.add(x + 15, y + 0, z + 13), BlockHandler.ZERG_FLESH.getDefaultState(), 2);

		world.setBlockState(pos.add(x + 16, y + 0, z + 13), BlockHandler.ZERG_FLESH.getDefaultState(), 2);

		world.setBlockState(pos.add(x + 17, y + 0, z + 13), BlockHandler.ZERG_FLESH.getDefaultState(), 2);

		world.setBlockState(pos.add(x + 18, y + 0, z + 13), BlockHandler.ZERG_FLESH.getDefaultState(), 2);

		world.setBlockState(pos.add(x + 19, y + 0, z + 13), BlockHandler.ZERG_FLESH.getDefaultState(), 2);
		world.setBlockState(pos.add(x + 2, y + 0, z + 14), BlockHandler.ZERG_FLESH.getDefaultState(), 2);

		world.setBlockState(pos.add(x + 3, y + 0, z + 14), BlockHandler.ZERG_FLESH.getDefaultState(), 2);

		world.setBlockState(pos.add(x + 4, y + 0, z + 14), BlockHandler.ZERG_FLESH.getDefaultState(), 2);

		world.setBlockState(pos.add(x + 5, y + 0, z + 14), BlockHandler.ZERG_FLESH.getDefaultState(), 2);

		world.setBlockState(pos.add(x + 6, y + 0, z + 14), BlockHandler.ZERG_FLESH.getDefaultState(), 2);

		world.setBlockState(pos.add(x + 7, y + 0, z + 14), BlockHandler.ZERG_FLESH.getDefaultState(), 2);

		world.setBlockState(pos.add(x + 8, y + 0, z + 14), BlockHandler.ZERG_FLESH.getDefaultState(), 2);

		world.setBlockState(pos.add(x + 9, y + 0, z + 14), BlockHandler.ZERG_FLESH.getDefaultState(), 2);

		world.setBlockState(pos.add(x + 10, y + 0, z + 14), BlockHandler.ZERG_FLESH.getDefaultState(), 2);

		world.setBlockState(pos.add(x + 11, y + 0, z + 14), BlockHandler.ZERG_FLESH.getDefaultState(), 2);

		world.setBlockState(pos.add(x + 12, y + 0, z + 14), BlockHandler.ZERG_FLESH.getDefaultState(), 2);

		world.setBlockState(pos.add(x + 13, y + 0, z + 14), BlockHandler.ZERG_FLESH.getDefaultState(), 2);

		world.setBlockState(pos.add(x + 14, y + 0, z + 14), BlockHandler.ZERG_FLESH.getDefaultState(), 2);

		world.setBlockState(pos.add(x + 15, y + 0, z + 14), BlockHandler.ZERG_FLESH.getDefaultState(), 2);

		world.setBlockState(pos.add(x + 16, y + 0, z + 14), BlockHandler.ZERG_FLESH.getDefaultState(), 2);

		world.setBlockState(pos.add(x + 17, y + 0, z + 14), BlockHandler.ZERG_FLESH.getDefaultState(), 2);

		world.setBlockState(pos.add(x + 18, y + 0, z + 14), BlockHandler.ZERG_FLESH.getDefaultState(), 2);

		world.setBlockState(pos.add(x + 19, y + 0, z + 14), BlockHandler.ZERG_FLESH.getDefaultState(), 2);

		world.setBlockState(pos.add(x + 20, y + 0, z + 14), BlockHandler.ZERG_FLESH.getDefaultState(), 2);
		world.setBlockState(pos.add(x + 2, y + 0, z + 15), BlockHandler.ZERG_FLESH.getDefaultState(), 2);

		world.setBlockState(pos.add(x + 3, y + 0, z + 15), BlockHandler.ZERG_FLESH.getDefaultState(), 2);

		world.setBlockState(pos.add(x + 4, y + 0, z + 15), BlockHandler.ZERG_FLESH.getDefaultState(), 2);

		world.setBlockState(pos.add(x + 5, y + 0, z + 15), BlockHandler.ZERG_FLESH.getDefaultState(), 2);

		world.setBlockState(pos.add(x + 6, y + 0, z + 15), BlockHandler.ZERG_FLESH.getDefaultState(), 2);

		world.setBlockState(pos.add(x + 7, y + 0, z + 15), BlockHandler.ZERG_FLESH.getDefaultState(), 2);

		world.setBlockState(pos.add(x + 8, y + 0, z + 15), BlockHandler.ZERG_FLESH.getDefaultState(), 2);

		world.setBlockState(pos.add(x + 9, y + 0, z + 15), BlockHandler.ZERG_FLESH.getDefaultState(), 2);

		world.setBlockState(pos.add(x + 10, y + 0, z + 15), BlockHandler.ZERG_FLESH.getDefaultState(), 2);

		world.setBlockState(pos.add(x + 11, y + 0, z + 15), BlockHandler.ZERG_FLESH.getDefaultState(), 2);

		world.setBlockState(pos.add(x + 12, y + 0, z + 15), BlockHandler.ZERG_FLESH.getDefaultState(), 2);

		world.setBlockState(pos.add(x + 13, y + 0, z + 15), BlockHandler.ZERG_FLESH.getDefaultState(), 2);

		world.setBlockState(pos.add(x + 14, y + 0, z + 15), BlockHandler.ZERG_FLESH.getDefaultState(), 2);

		world.setBlockState(pos.add(x + 15, y + 0, z + 15), BlockHandler.ZERG_FLESH.getDefaultState(), 2);

		world.setBlockState(pos.add(x + 16, y + 0, z + 15), BlockHandler.ZERG_FLESH.getDefaultState(), 2);

		world.setBlockState(pos.add(x + 17, y + 0, z + 15), BlockHandler.ZERG_FLESH.getDefaultState(), 2);

		world.setBlockState(pos.add(x + 18, y + 0, z + 15), BlockHandler.ZERG_FLESH.getDefaultState(), 2);

		world.setBlockState(pos.add(x + 19, y + 0, z + 15), BlockHandler.ZERG_FLESH.getDefaultState(), 2);

		world.setBlockState(pos.add(x + 20, y + 0, z + 15), BlockHandler.ZERG_FLESH.getDefaultState(), 2);

		world.setBlockState(pos.add(x + 21, y + 0, z + 15), BlockHandler.ZERG_FLESH.getDefaultState(), 2);
		world.setBlockState(pos.add(x + 2, y + 0, z + 16), BlockHandler.ZERG_FLESH.getDefaultState(), 2);

		world.setBlockState(pos.add(x + 3, y + 0, z + 16), BlockHandler.ZERG_FLESH.getDefaultState(), 2);

		world.setBlockState(pos.add(x + 4, y + 0, z + 16), BlockHandler.ZERG_FLESH.getDefaultState(), 2);

		world.setBlockState(pos.add(x + 5, y + 0, z + 16), BlockHandler.ZERG_FLESH.getDefaultState(), 2);

		world.setBlockState(pos.add(x + 6, y + 0, z + 16), BlockHandler.ZERG_FLESH.getDefaultState(), 2);

		world.setBlockState(pos.add(x + 7, y + 0, z + 16), BlockHandler.ZERG_FLESH.getDefaultState(), 2);

		world.setBlockState(pos.add(x + 8, y + 0, z + 16), BlockHandler.ZERG_FLESH.getDefaultState(), 2);

		world.setBlockState(pos.add(x + 9, y + 0, z + 16), BlockHandler.ZERG_FLESH.getDefaultState(), 2);

		world.setBlockState(pos.add(x + 10, y + 0, z + 16), BlockHandler.ZERG_FLESH.getDefaultState(), 2);

		world.setBlockState(pos.add(x + 11, y + 0, z + 16), BlockHandler.ZERG_FLESH.getDefaultState(), 2);

		world.setBlockState(pos.add(x + 12, y + 0, z + 16), BlockHandler.ZERG_FLESH.getDefaultState(), 2);

		world.setBlockState(pos.add(x + 13, y + 0, z + 16), BlockHandler.ZERG_FLESH.getDefaultState(), 2);

		world.setBlockState(pos.add(x + 14, y + 0, z + 16), BlockHandler.ZERG_FLESH.getDefaultState(), 2);

		world.setBlockState(pos.add(x + 15, y + 0, z + 16), BlockHandler.ZERG_FLESH.getDefaultState(), 2);

		world.setBlockState(pos.add(x + 16, y + 0, z + 16), BlockHandler.ZERG_FLESH.getDefaultState(), 2);

		world.setBlockState(pos.add(x + 17, y + 0, z + 16), BlockHandler.ZERG_FLESH.getDefaultState(), 2);

		world.setBlockState(pos.add(x + 18, y + 0, z + 16), BlockHandler.ZERG_FLESH.getDefaultState(), 2);

		world.setBlockState(pos.add(x + 19, y + 0, z + 16), BlockHandler.ZERG_FLESH.getDefaultState(), 2);

		world.setBlockState(pos.add(x + 20, y + 0, z + 16), BlockHandler.ZERG_FLESH.getDefaultState(), 2);

		world.setBlockState(pos.add(x + 21, y + 0, z + 16), BlockHandler.ZERG_FLESH.getDefaultState(), 2);

		world.setBlockState(pos.add(x + 22, y + 0, z + 16), BlockHandler.ZERG_FLESH.getDefaultState(), 2);
		world.setBlockState(pos.add(x + 2, y + 0, z + 17), BlockHandler.ZERG_FLESH.getDefaultState(), 2);

		world.setBlockState(pos.add(x + 3, y + 0, z + 17), BlockHandler.ZERG_FLESH.getDefaultState(), 2);

		world.setBlockState(pos.add(x + 4, y + 0, z + 17), BlockHandler.ZERG_FLESH.getDefaultState(), 2);

		world.setBlockState(pos.add(x + 5, y + 0, z + 17), BlockHandler.ZERG_FLESH.getDefaultState(), 2);

		world.setBlockState(pos.add(x + 6, y + 0, z + 17), BlockHandler.ZERG_FLESH.getDefaultState(), 2);

		world.setBlockState(pos.add(x + 7, y + 0, z + 17), BlockHandler.ZERG_FLESH.getDefaultState(), 2);

		world.setBlockState(pos.add(x + 8, y + 0, z + 17), BlockHandler.ZERG_FLESH.getDefaultState(), 2);

		world.setBlockState(pos.add(x + 9, y + 0, z + 17), BlockHandler.ZERG_FLESH.getDefaultState(), 2);

		world.setBlockState(pos.add(x + 10, y + 0, z + 17), BlockHandler.ZERG_FLESH.getDefaultState(), 2);

		world.setBlockState(pos.add(x + 11, y + 0, z + 17), BlockHandler.ZERG_FLESH.getDefaultState(), 2);

		world.setBlockState(pos.add(x + 12, y + 0, z + 17), BlockHandler.ZERG_FLESH.getDefaultState(), 2);

		world.setBlockState(pos.add(x + 13, y + 0, z + 17), BlockHandler.ZERG_FLESH.getDefaultState(), 2);

		world.setBlockState(pos.add(x + 14, y + 0, z + 17), BlockHandler.ZERG_FLESH.getDefaultState(), 2);

		world.setBlockState(pos.add(x + 15, y + 0, z + 17), BlockHandler.ZERG_FLESH.getDefaultState(), 2);

		world.setBlockState(pos.add(x + 16, y + 0, z + 17), BlockHandler.ZERG_FLESH.getDefaultState(), 2);

		world.setBlockState(pos.add(x + 17, y + 0, z + 17), BlockHandler.ZERG_FLESH.getDefaultState(), 2);

		world.setBlockState(pos.add(x + 18, y + 0, z + 17), BlockHandler.ZERG_FLESH.getDefaultState(), 2);

		world.setBlockState(pos.add(x + 19, y + 0, z + 17), BlockHandler.ZERG_FLESH.getDefaultState(), 2);

		world.setBlockState(pos.add(x + 20, y + 0, z + 17), BlockHandler.ZERG_FLESH.getDefaultState(), 2);

		world.setBlockState(pos.add(x + 21, y + 0, z + 17), BlockHandler.ZERG_FLESH.getDefaultState(), 2);

		world.setBlockState(pos.add(x + 22, y + 0, z + 17), BlockHandler.ZERG_FLESH.getDefaultState(), 2);
		world.setBlockState(pos.add(x + 2, y + 0, z + 18), BlockHandler.ZERG_FLESH.getDefaultState(), 2);

		world.setBlockState(pos.add(x + 3, y + 0, z + 18), BlockHandler.ZERG_FLESH.getDefaultState(), 2);

		world.setBlockState(pos.add(x + 4, y + 0, z + 18), BlockHandler.ZERG_FLESH.getDefaultState(), 2);

		world.setBlockState(pos.add(x + 5, y + 0, z + 18), BlockHandler.ZERG_FLESH.getDefaultState(), 2);

		world.setBlockState(pos.add(x + 6, y + 0, z + 18), BlockHandler.ZERG_FLESH.getDefaultState(), 2);

		world.setBlockState(pos.add(x + 7, y + 0, z + 18), BlockHandler.ZERG_FLESH.getDefaultState(), 2);

		world.setBlockState(pos.add(x + 8, y + 0, z + 18), BlockHandler.ZERG_FLESH.getDefaultState(), 2);

		world.setBlockState(pos.add(x + 9, y + 0, z + 18), BlockHandler.ZERG_FLESH.getDefaultState(), 2);

		world.setBlockState(pos.add(x + 10, y + 0, z + 18), BlockHandler.ZERG_FLESH.getDefaultState(), 2);

		world.setBlockState(pos.add(x + 11, y + 0, z + 18), BlockHandler.ZERG_FLESH.getDefaultState(), 2);

		world.setBlockState(pos.add(x + 12, y + 0, z + 18), BlockHandler.ZERG_FLESH.getDefaultState(), 2);

		world.setBlockState(pos.add(x + 13, y + 0, z + 18), BlockHandler.ZERG_FLESH.getDefaultState(), 2);

		world.setBlockState(pos.add(x + 14, y + 0, z + 18), BlockHandler.ZERG_FLESH.getDefaultState(), 2);

		world.setBlockState(pos.add(x + 15, y + 0, z + 18), BlockHandler.ZERG_FLESH.getDefaultState(), 2);

		world.setBlockState(pos.add(x + 16, y + 0, z + 18), BlockHandler.ZERG_FLESH.getDefaultState(), 2);

		world.setBlockState(pos.add(x + 17, y + 0, z + 18), BlockHandler.ZERG_FLESH.getDefaultState(), 2);

		world.setBlockState(pos.add(x + 18, y + 0, z + 18), BlockHandler.ZERG_FLESH.getDefaultState(), 2);

		world.setBlockState(pos.add(x + 19, y + 0, z + 18), BlockHandler.ZERG_FLESH.getDefaultState(), 2);

		world.setBlockState(pos.add(x + 20, y + 0, z + 18), BlockHandler.ZERG_FLESH.getDefaultState(), 2);

		world.setBlockState(pos.add(x + 21, y + 0, z + 18), BlockHandler.ZERG_FLESH.getDefaultState(), 2);

		world.setBlockState(pos.add(x + 22, y + 0, z + 18), BlockHandler.ZERG_FLESH.getDefaultState(), 2);

		world.setBlockState(pos.add(x + 23, y + 0, z + 18), BlockHandler.ZERG_FLESH.getDefaultState(), 2);
		world.setBlockState(pos.add(x + 3, y + 0, z + 19), BlockHandler.ZERG_FLESH.getDefaultState(), 2);

		world.setBlockState(pos.add(x + 4, y + 0, z + 19), BlockHandler.ZERG_FLESH.getDefaultState(), 2);

		world.setBlockState(pos.add(x + 5, y + 0, z + 19), BlockHandler.ZERG_FLESH.getDefaultState(), 2);

		world.setBlockState(pos.add(x + 6, y + 0, z + 19), BlockHandler.ZERG_FLESH.getDefaultState(), 2);

		world.setBlockState(pos.add(x + 7, y + 0, z + 19), BlockHandler.ZERG_FLESH.getDefaultState(), 2);

		world.setBlockState(pos.add(x + 8, y + 0, z + 19), BlockHandler.ZERG_FLESH.getDefaultState(), 2);

		world.setBlockState(pos.add(x + 9, y + 0, z + 19), BlockHandler.ZERG_FLESH.getDefaultState(), 2);

		world.setBlockState(pos.add(x + 10, y + 0, z + 19), BlockHandler.ZERG_FLESH.getDefaultState(), 2);

		world.setBlockState(pos.add(x + 11, y + 0, z + 19), BlockHandler.ZERG_FLESH.getDefaultState(), 2);

		world.setBlockState(pos.add(x + 12, y + 0, z + 19), BlockHandler.ZERG_FLESH.getDefaultState(), 2);

		world.setBlockState(pos.add(x + 13, y + 0, z + 19), BlockHandler.ZERG_FLESH.getDefaultState(), 2);

		world.setBlockState(pos.add(x + 14, y + 0, z + 19), BlockHandler.ZERG_FLESH.getDefaultState(), 2);

		world.setBlockState(pos.add(x + 15, y + 0, z + 19), BlockHandler.ZERG_FLESH.getDefaultState(), 2);

		world.setBlockState(pos.add(x + 16, y + 0, z + 19), BlockHandler.ZERG_FLESH.getDefaultState(), 2);

		world.setBlockState(pos.add(x + 17, y + 0, z + 19), BlockHandler.ZERG_FLESH.getDefaultState(), 2);

		world.setBlockState(pos.add(x + 18, y + 0, z + 19), BlockHandler.ZERG_FLESH.getDefaultState(), 2);

		world.setBlockState(pos.add(x + 19, y + 0, z + 19), BlockHandler.ZERG_FLESH.getDefaultState(), 2);

		world.setBlockState(pos.add(x + 20, y + 0, z + 19), BlockHandler.ZERG_FLESH.getDefaultState(), 2);

		world.setBlockState(pos.add(x + 21, y + 0, z + 19), BlockHandler.ZERG_FLESH.getDefaultState(), 2);

		world.setBlockState(pos.add(x + 22, y + 0, z + 19), BlockHandler.ZERG_FLESH.getDefaultState(), 2);

		world.setBlockState(pos.add(x + 23, y + 0, z + 19), BlockHandler.ZERG_FLESH.getDefaultState(), 2);
		world.setBlockState(pos.add(x + 4, y + 0, z + 20), BlockHandler.ZERG_FLESH.getDefaultState(), 2);

		world.setBlockState(pos.add(x + 5, y + 0, z + 20), BlockHandler.ZERG_FLESH.getDefaultState(), 2);

		world.setBlockState(pos.add(x + 6, y + 0, z + 20), BlockHandler.ZERG_FLESH.getDefaultState(), 2);

		world.setBlockState(pos.add(x + 7, y + 0, z + 20), BlockHandler.ZERG_FLESH.getDefaultState(), 2);

		world.setBlockState(pos.add(x + 8, y + 0, z + 20), BlockHandler.ZERG_FLESH.getDefaultState(), 2);

		world.setBlockState(pos.add(x + 9, y + 0, z + 20), BlockHandler.ZERG_FLESH.getDefaultState(), 2);

		world.setBlockState(pos.add(x + 10, y + 0, z + 20), BlockHandler.ZERG_FLESH.getDefaultState(), 2);

		world.setBlockState(pos.add(x + 11, y + 0, z + 20), BlockHandler.ZERG_FLESH.getDefaultState(), 2);

		world.setBlockState(pos.add(x + 12, y + 0, z + 20), BlockHandler.ZERG_FLESH.getDefaultState(), 2);

		world.setBlockState(pos.add(x + 13, y + 0, z + 20), BlockHandler.ZERG_FLESH.getDefaultState(), 2);

		world.setBlockState(pos.add(x + 14, y + 0, z + 20), BlockHandler.ZERG_FLESH.getDefaultState(), 2);

		world.setBlockState(pos.add(x + 15, y + 0, z + 20), BlockHandler.ZERG_FLESH.getDefaultState(), 2);

		world.setBlockState(pos.add(x + 16, y + 0, z + 20), BlockHandler.ZERG_FLESH.getDefaultState(), 2);

		world.setBlockState(pos.add(x + 17, y + 0, z + 20), BlockHandler.ZERG_FLESH.getDefaultState(), 2);

		world.setBlockState(pos.add(x + 18, y + 0, z + 20), BlockHandler.ZERG_FLESH.getDefaultState(), 2);

		world.setBlockState(pos.add(x + 19, y + 0, z + 20), BlockHandler.ZERG_FLESH.getDefaultState(), 2);

		world.setBlockState(pos.add(x + 20, y + 0, z + 20), BlockHandler.ZERG_FLESH.getDefaultState(), 2);

		world.setBlockState(pos.add(x + 21, y + 0, z + 20), BlockHandler.ZERG_FLESH.getDefaultState(), 2);

		world.setBlockState(pos.add(x + 22, y + 0, z + 20), BlockHandler.ZERG_FLESH.getDefaultState(), 2);

		world.setBlockState(pos.add(x + 23, y + 0, z + 20), BlockHandler.ZERG_FLESH.getDefaultState(), 2);
		world.setBlockState(pos.add(x + 5, y + 0, z + 21), BlockHandler.ZERG_FLESH.getDefaultState(), 2);

		world.setBlockState(pos.add(x + 6, y + 0, z + 21), BlockHandler.ZERG_FLESH.getDefaultState(), 2);

		world.setBlockState(pos.add(x + 7, y + 0, z + 21), BlockHandler.ZERG_FLESH.getDefaultState(), 2);

		world.setBlockState(pos.add(x + 8, y + 0, z + 21), BlockHandler.ZERG_FLESH.getDefaultState(), 2);

		world.setBlockState(pos.add(x + 9, y + 0, z + 21), BlockHandler.ZERG_FLESH.getDefaultState(), 2);

		world.setBlockState(pos.add(x + 10, y + 0, z + 21), BlockHandler.ZERG_FLESH.getDefaultState(), 2);

		world.setBlockState(pos.add(x + 11, y + 0, z + 21), BlockHandler.ZERG_FLESH.getDefaultState(), 2);

		world.setBlockState(pos.add(x + 12, y + 0, z + 21), BlockHandler.ZERG_FLESH.getDefaultState(), 2);

		world.setBlockState(pos.add(x + 13, y + 0, z + 21), BlockHandler.ZERG_FLESH.getDefaultState(), 2);

		world.setBlockState(pos.add(x + 14, y + 0, z + 21), BlockHandler.ZERG_FLESH.getDefaultState(), 2);

		world.setBlockState(pos.add(x + 15, y + 0, z + 21), BlockHandler.ZERG_FLESH.getDefaultState(), 2);

		world.setBlockState(pos.add(x + 16, y + 0, z + 21), BlockHandler.ZERG_FLESH.getDefaultState(), 2);

		world.setBlockState(pos.add(x + 17, y + 0, z + 21), BlockHandler.ZERG_FLESH.getDefaultState(), 2);

		world.setBlockState(pos.add(x + 18, y + 0, z + 21), BlockHandler.ZERG_FLESH.getDefaultState(), 2);

		world.setBlockState(pos.add(x + 19, y + 0, z + 21), BlockHandler.ZERG_FLESH.getDefaultState(), 2);

		world.setBlockState(pos.add(x + 20, y + 0, z + 21), BlockHandler.ZERG_FLESH.getDefaultState(), 2);

		world.setBlockState(pos.add(x + 21, y + 0, z + 21), BlockHandler.ZERG_FLESH.getDefaultState(), 2);

		world.setBlockState(pos.add(x + 22, y + 0, z + 21), BlockHandler.ZERG_FLESH.getDefaultState(), 2);
		world.setBlockState(pos.add(x + 6, y + 0, z + 22), BlockHandler.ZERG_FLESH.getDefaultState(), 2);

		world.setBlockState(pos.add(x + 7, y + 0, z + 22), BlockHandler.ZERG_FLESH.getDefaultState(), 2);

		world.setBlockState(pos.add(x + 8, y + 0, z + 22), BlockHandler.ZERG_FLESH.getDefaultState(), 2);

		world.setBlockState(pos.add(x + 9, y + 0, z + 22), BlockHandler.ZERG_FLESH.getDefaultState(), 2);

		world.setBlockState(pos.add(x + 10, y + 0, z + 22), BlockHandler.ZERG_FLESH.getDefaultState(), 2);

		world.setBlockState(pos.add(x + 11, y + 0, z + 22), BlockHandler.ZERG_FLESH.getDefaultState(), 2);

		world.setBlockState(pos.add(x + 12, y + 0, z + 22), BlockHandler.ZERG_FLESH.getDefaultState(), 2);

		world.setBlockState(pos.add(x + 13, y + 0, z + 22), BlockHandler.ZERG_FLESH.getDefaultState(), 2);

		world.setBlockState(pos.add(x + 14, y + 0, z + 22), BlockHandler.ZERG_FLESH.getDefaultState(), 2);

		world.setBlockState(pos.add(x + 15, y + 0, z + 22), BlockHandler.ZERG_FLESH.getDefaultState(), 2);

		world.setBlockState(pos.add(x + 16, y + 0, z + 22), BlockHandler.ZERG_FLESH.getDefaultState(), 2);

		world.setBlockState(pos.add(x + 17, y + 0, z + 22), BlockHandler.ZERG_FLESH.getDefaultState(), 2);

		world.setBlockState(pos.add(x + 18, y + 0, z + 22), BlockHandler.ZERG_FLESH.getDefaultState(), 2);

		world.setBlockState(pos.add(x + 19, y + 0, z + 22), BlockHandler.ZERG_FLESH.getDefaultState(), 2);

		world.setBlockState(pos.add(x + 20, y + 0, z + 22), BlockHandler.ZERG_FLESH.getDefaultState(), 2);

		world.setBlockState(pos.add(x + 21, y + 0, z + 22), BlockHandler.ZERG_FLESH.getDefaultState(), 2);
		world.setBlockState(pos.add(x + 11, y + 0, z + 23), BlockHandler.ZERG_FLESH.getDefaultState(), 2);

		world.setBlockState(pos.add(x + 12, y + 0, z + 23), BlockHandler.ZERG_FLESH.getDefaultState(), 2);

		world.setBlockState(pos.add(x + 13, y + 0, z + 23), BlockHandler.ZERG_FLESH.getDefaultState(), 2);

		world.setBlockState(pos.add(x + 14, y + 0, z + 23), BlockHandler.ZERG_FLESH.getDefaultState(), 2);

		world.setBlockState(pos.add(x + 15, y + 0, z + 23), BlockHandler.ZERG_FLESH.getDefaultState(), 2);

		world.setBlockState(pos.add(x + 16, y + 0, z + 23), BlockHandler.ZERG_FLESH.getDefaultState(), 2);

		world.setBlockState(pos.add(x + 17, y + 0, z + 23), BlockHandler.ZERG_FLESH.getDefaultState(), 2);

		world.setBlockState(pos.add(x + 18, y + 0, z + 23), BlockHandler.ZERG_FLESH.getDefaultState(), 2);

		world.setBlockState(pos.add(x + 19, y + 0, z + 23), BlockHandler.ZERG_FLESH.getDefaultState(), 2);
		world.setBlockState(pos.add(x + 4, y + 1, z + 1), BlockHandler.ZERG_FLESH.getDefaultState(), 2);

		world.setBlockState(pos.add(x + 5, y + 1, z + 1), BlockHandler.ZERG_FLESH.getDefaultState(), 2);

		world.setBlockState(pos.add(x + 6, y + 1, z + 1), BlockHandler.ZERG_FLESH.getDefaultState(), 2);

		world.setBlockState(pos.add(x + 3, y + 1, z + 2), BlockHandler.ZERG_FLESH.getDefaultState(), 2);

		world.setBlockState(pos.add(x + 4, y + 1, z + 2), BlockHandler.ZERG_FLESH.getDefaultState(), 2);

		world.setBlockState(pos.add(x + 5, y + 1, z + 2), BlockHandler.ZERG_FLESH.getDefaultState(), 2);

		world.setBlockState(pos.add(x + 6, y + 1, z + 2), BlockHandler.ZERG_FLESH.getDefaultState(), 2);

		world.setBlockState(pos.add(x + 7, y + 1, z + 2), BlockHandler.ZERG_FLESH.getDefaultState(), 2);

		world.setBlockState(pos.add(x + 8, y + 1, z + 2), BlockHandler.ZERG_FLESH.getStateFromMeta(1), 2);

		world.setBlockState(pos.add(x + 2, y + 1, z + 3), BlockHandler.ZERG_FLESH.getDefaultState(), 2);

		world.setBlockState(pos.add(x + 3, y + 1, z + 3), BlockHandler.ZERG_FLESH.getDefaultState(), 2);

		world.setBlockState(pos.add(x + 4, y + 1, z + 3), BlockHandler.ZERG_FLESH.getDefaultState(), 2);

		world.setBlockState(pos.add(x + 5, y + 1, z + 3), BlockHandler.ZERG_FLESH.getDefaultState(), 2);

		world.setBlockState(pos.add(x + 6, y + 1, z + 3), BlockHandler.ZERG_FLESH.getDefaultState(), 2);

		world.setBlockState(pos.add(x + 7, y + 1, z + 3), BlockHandler.ZERG_FLESH.getDefaultState(), 2);

		world.setBlockState(pos.add(x + 8, y + 1, z + 3), BlockHandler.ZERG_FLESH.getStateFromMeta(1), 2);

		world.setBlockState(pos.add(x + 9, y + 1, z + 3), BlockHandler.ZERG_FLESH.getStateFromMeta(1), 2);

		world.setBlockState(pos.add(x + 2, y + 1, z + 4), BlockHandler.ZERG_FLESH.getDefaultState(), 2);

		world.setBlockState(pos.add(x + 3, y + 1, z + 4), BlockHandler.ZERG_FLESH.getDefaultState(), 2);

		world.setBlockState(pos.add(x + 4, y + 1, z + 4), BlockHandler.ZERG_FLESH.getDefaultState(), 2);

		world.setBlockState(pos.add(x + 5, y + 1, z + 4), BlockHandler.ZERG_FLESH.getDefaultState(), 2);

		world.setBlockState(pos.add(x + 6, y + 1, z + 4), BlockHandler.ZERG_FLESH.getDefaultState(), 2);

		world.setBlockState(pos.add(x + 7, y + 1, z + 4), BlockHandler.ZERG_FLESH.getDefaultState(), 2);

		world.setBlockState(pos.add(x + 8, y + 1, z + 4), BlockHandler.ZERG_FLESH.getStateFromMeta(1), 2);

		world.setBlockState(pos.add(x + 9, y + 1, z + 4), BlockHandler.ZERG_FLESH.getStateFromMeta(1), 2);

		world.setBlockState(pos.add(x + 10, y + 1, z + 4), BlockHandler.ZERG_FLESH.getStateFromMeta(1), 2);

		world.setBlockState(pos.add(x + 1, y + 1, z + 5), BlockHandler.ZERG_FLESH.getDefaultState(), 2);

		world.setBlockState(pos.add(x + 2, y + 1, z + 5), BlockHandler.ZERG_FLESH.getDefaultState(), 2);

		world.setBlockState(pos.add(x + 3, y + 1, z + 5), BlockHandler.ZERG_FLESH.getDefaultState(), 2);

		world.setBlockState(pos.add(x + 4, y + 1, z + 5), BlockHandler.ZERG_FLESH.getDefaultState(), 2);

		world.setBlockState(pos.add(x + 5, y + 1, z + 5), BlockHandler.ZERG_FLESH.getDefaultState(), 2);

		world.setBlockState(pos.add(x + 6, y + 1, z + 5), BlockHandler.ZERG_FLESH.getDefaultState(), 2);

		world.setBlockState(pos.add(x + 7, y + 1, z + 5), BlockHandler.ZERG_FLESH.getDefaultState(), 2);

		world.setBlockState(pos.add(x + 8, y + 1, z + 5), BlockHandler.ZERG_FLESH.getDefaultState(), 2);

		world.setBlockState(pos.add(x + 9, y + 1, z + 5), BlockHandler.ZERG_FLESH.getDefaultState(), 2);

		world.setBlockState(pos.add(x + 10, y + 1, z + 5), BlockHandler.ZERG_FLESH.getDefaultState(), 2);

		world.setBlockState(pos.add(x + 11, y + 1, z + 5), BlockHandler.ZERG_FLESH.getDefaultState(), 2);

		world.setBlockState(pos.add(x + 1, y + 1, z + 6), BlockHandler.ZERG_FLESH.getDefaultState(), 2);

		world.setBlockState(pos.add(x + 2, y + 1, z + 6), BlockHandler.ZERG_FLESH.getDefaultState(), 2);

		world.setBlockState(pos.add(x + 3, y + 1, z + 6), BlockHandler.ZERG_FLESH.getDefaultState(), 2);

		world.setBlockState(pos.add(x + 4, y + 1, z + 6), BlockHandler.ZERG_FLESH.getDefaultState(), 2);

		world.setBlockState(pos.add(x + 5, y + 1, z + 6), BlockHandler.ZERG_FLESH.getDefaultState(), 2);

		world.setBlockState(pos.add(x + 6, y + 1, z + 6), BlockHandler.ZERG_FLESH.getDefaultState(), 2);

		world.setBlockState(pos.add(x + 7, y + 1, z + 6), BlockHandler.ZERG_FLESH.getDefaultState(), 2);

		world.setBlockState(pos.add(x + 8, y + 1, z + 6), BlockHandler.ZERG_FLESH.getDefaultState(), 2);

		world.setBlockState(pos.add(x + 9, y + 1, z + 6), BlockHandler.ZERG_FLESH.getDefaultState(), 2);

		world.setBlockState(pos.add(x + 10, y + 1, z + 6), BlockHandler.ZERG_FLESH.getDefaultState(), 2);

		world.setBlockState(pos.add(x + 11, y + 1, z + 6), BlockHandler.ZERG_FLESH.getDefaultState(), 2);

		world.setBlockState(pos.add(x + 12, y + 1, z + 6), BlockHandler.ZERG_FLESH.getDefaultState(), 2);

		world.setBlockState(pos.add(x + 15, y + 1, z + 6), BlockHandler.ZERG_FLESH.getDefaultState(), 2);

		world.setBlockState(pos.add(x + 16, y + 1, z + 6), BlockHandler.ZERG_FLESH.getDefaultState(), 2);

		world.setBlockState(pos.add(x + 1, y + 1, z + 7), BlockHandler.ZERG_FLESH.getDefaultState(), 2);

		world.setBlockState(pos.add(x + 2, y + 1, z + 7), BlockHandler.ZERG_FLESH.getDefaultState(), 2);

		world.setBlockState(pos.add(x + 3, y + 1, z + 7), BlockHandler.ZERG_FLESH.getDefaultState(), 2);

		world.setBlockState(pos.add(x + 4, y + 1, z + 7), BlockHandler.ZERG_FLESH.getDefaultState(), 2);

		world.setBlockState(pos.add(x + 5, y + 1, z + 7), BlockHandler.ZERG_FLESH.getDefaultState(), 2);

		world.setBlockState(pos.add(x + 6, y + 1, z + 7), BlockHandler.ZERG_FLESH.getDefaultState(), 2);

		world.setBlockState(pos.add(x + 7, y + 1, z + 7), BlockHandler.ZERG_FLESH.getDefaultState(), 2);

		world.setBlockState(pos.add(x + 8, y + 1, z + 7), BlockHandler.ZERG_FLESH.getDefaultState(), 2);

		world.setBlockState(pos.add(x + 9, y + 1, z + 7), BlockHandler.ZERG_FLESH.getDefaultState(), 2);

		world.setBlockState(pos.add(x + 10, y + 1, z + 7), BlockHandler.ZERG_FLESH.getDefaultState(), 2);

		world.setBlockState(pos.add(x + 11, y + 1, z + 7), BlockHandler.ZERG_FLESH.getDefaultState(), 2);

		world.setBlockState(pos.add(x + 12, y + 1, z + 7), BlockHandler.ZERG_FLESH.getDefaultState(), 2);

		world.setBlockState(pos.add(x + 13, y + 1, z + 7), BlockHandler.ZERG_FLESH.getDefaultState(), 2);

		world.setBlockState(pos.add(x + 14, y + 1, z + 7), BlockHandler.ZERG_FLESH.getDefaultState(), 2);

		world.setBlockState(pos.add(x + 15, y + 1, z + 7), BlockHandler.ZERG_FLESH.getDefaultState(), 2);

		world.setBlockState(pos.add(x + 16, y + 1, z + 7), BlockHandler.ZERG_FLESH.getDefaultState(), 2);

		world.setBlockState(pos.add(x + 17, y + 1, z + 7), BlockHandler.ZERG_FLESH.getDefaultState(), 2);

		world.setBlockState(pos.add(x + 1, y + 1, z + 8), BlockHandler.ZERG_FLESH.getDefaultState(), 2);

		world.setBlockState(pos.add(x + 2, y + 1, z + 8), BlockHandler.ZERG_FLESH.getDefaultState(), 2);

		world.setBlockState(pos.add(x + 3, y + 1, z + 8), BlockHandler.ZERG_FLESH.getDefaultState(), 2);

		world.setBlockState(pos.add(x + 4, y + 1, z + 8), BlockHandler.ZERG_FLESH.getDefaultState(), 2);

		world.setBlockState(pos.add(x + 5, y + 1, z + 8), BlockHandler.ZERG_FLESH.getDefaultState(), 2);

		world.setBlockState(pos.add(x + 6, y + 1, z + 8), BlockHandler.ZERG_FLESH.getDefaultState(), 2);

		world.setBlockState(pos.add(x + 7, y + 1, z + 8), BlockHandler.ZERG_FLESH.getDefaultState(), 2);

		world.setBlockState(pos.add(x + 8, y + 1, z + 8), BlockHandler.ZERG_FLESH.getDefaultState(), 2);

		world.setBlockState(pos.add(x + 9, y + 1, z + 8), BlockHandler.ZERG_FLESH.getDefaultState(), 2);

		world.setBlockState(pos.add(x + 10, y + 1, z + 8), BlockHandler.ZERG_FLESH.getDefaultState(), 2);

		world.setBlockState(pos.add(x + 11, y + 1, z + 8), BlockHandler.ZERG_FLESH.getDefaultState(), 2);

		world.setBlockState(pos.add(x + 12, y + 1, z + 8), BlockHandler.ZERG_FLESH.getDefaultState(), 2);

		world.setBlockState(pos.add(x + 13, y + 1, z + 8), BlockHandler.ZERG_FLESH.getDefaultState(), 2);

		world.setBlockState(pos.add(x + 14, y + 1, z + 8), BlockHandler.ZERG_FLESH.getDefaultState(), 2);

		world.setBlockState(pos.add(x + 15, y + 1, z + 8), BlockHandler.ZERG_FLESH.getDefaultState(), 2);

		world.setBlockState(pos.add(x + 16, y + 1, z + 8), BlockHandler.ZERG_FLESH.getDefaultState(), 2);

		world.setBlockState(pos.add(x + 17, y + 1, z + 8), BlockHandler.ZERG_FLESH.getDefaultState(), 2);

		world.setBlockState(pos.add(x + 18, y + 1, z + 8), BlockHandler.ZERG_FLESH.getDefaultState(), 2);

		world.setBlockState(pos.add(x + 1, y + 1, z + 9), BlockHandler.ZERG_FLESH.getDefaultState(), 2);

		world.setBlockState(pos.add(x + 2, y + 1, z + 9), BlockHandler.ZERG_FLESH.getDefaultState(), 2);

		world.setBlockState(pos.add(x + 3, y + 1, z + 9), BlockHandler.ZERG_FLESH.getDefaultState(), 2);

		world.setBlockState(pos.add(x + 4, y + 1, z + 9), BlockHandler.ZERG_FLESH.getDefaultState(), 2);

		world.setBlockState(pos.add(x + 5, y + 1, z + 9), BlockHandler.ZERG_FLESH.getDefaultState(), 2);

		world.setBlockState(pos.add(x + 6, y + 1, z + 9), BlockHandler.ZERG_FLESH.getDefaultState(), 2);

		world.setBlockState(pos.add(x + 7, y + 1, z + 9), BlockHandler.ZERG_FLESH.getDefaultState(), 2);

		world.setBlockState(pos.add(x + 8, y + 1, z + 9), BlockHandler.ZERG_FLESH.getDefaultState(), 2);

		world.setBlockState(pos.add(x + 9, y + 1, z + 9), BlockHandler.ZERG_FLESH.getDefaultState(), 2);

		world.setBlockState(pos.add(x + 10, y + 1, z + 9), BlockHandler.ZERG_FLESH.getStateFromMeta(2));
		world.setBlockState(pos.add(x + 11, y + 1, z + 9), BlockHandler.ZERG_FLESH.getStateFromMeta(2));
		world.setBlockState(pos.add(x + 12, y + 1, z + 9), BlockHandler.ZERG_FLESH.getStateFromMeta(2));
		world.setBlockState(pos.add(x + 13, y + 1, z + 9), BlockHandler.ZERG_FLESH.getDefaultState(), 2);

		world.setBlockState(pos.add(x + 14, y + 1, z + 9), BlockHandler.ZERG_FLESH.getDefaultState(), 2);

		world.setBlockState(pos.add(x + 15, y + 1, z + 9), BlockHandler.ZERG_FLESH.getDefaultState(), 2);

		world.setBlockState(pos.add(x + 16, y + 1, z + 9), BlockHandler.ZERG_FLESH.getDefaultState(), 2);

		world.setBlockState(pos.add(x + 17, y + 1, z + 9), BlockHandler.ZERG_FLESH.getDefaultState(), 2);

		world.setBlockState(pos.add(x + 18, y + 1, z + 9), BlockHandler.ZERG_FLESH.getDefaultState(), 2);

		world.setBlockState(pos.add(x + 1, y + 1, z + 10), BlockHandler.ZERG_FLESH.getDefaultState(), 2);

		world.setBlockState(pos.add(x + 2, y + 1, z + 10), BlockHandler.ZERG_FLESH.getDefaultState(), 2);

		world.setBlockState(pos.add(x + 3, y + 1, z + 10), BlockHandler.ZERG_FLESH.getDefaultState(), 2);

		world.setBlockState(pos.add(x + 4, y + 1, z + 10), BlockHandler.ZERG_FLESH.getDefaultState(), 2);

		world.setBlockState(pos.add(x + 5, y + 1, z + 10), BlockHandler.ZERG_FLESH.getDefaultState(), 2);

		world.setBlockState(pos.add(x + 6, y + 1, z + 10), BlockHandler.ZERG_FLESH.getStateFromMeta(2));
		world.setBlockState(pos.add(x + 7, y + 1, z + 10), BlockHandler.ZERG_FLESH.getStateFromMeta(2));
		world.setBlockState(pos.add(x + 8, y + 1, z + 10), BlockHandler.ZERG_FLESH.getStateFromMeta(2));
		world.setBlockState(pos.add(x + 9, y + 1, z + 10), BlockHandler.ZERG_FLESH.getStateFromMeta(2));
		world.setBlockState(pos.add(x + 10, y + 1, z + 10), BlockHandler.ZERG_FLESH.getStateFromMeta(2));
		world.setBlockState(pos.add(x + 11, y + 1, z + 10), BlockHandler.ZERG_FLESH.getStateFromMeta(2));
		world.setBlockState(pos.add(x + 12, y + 1, z + 10), BlockHandler.ZERG_FLESH.getStateFromMeta(2));
		world.setBlockState(pos.add(x + 13, y + 1, z + 10), BlockHandler.ZERG_FLESH.getStateFromMeta(2));
		world.setBlockState(pos.add(x + 14, y + 1, z + 10), BlockHandler.ZERG_FLESH.getDefaultState(), 2);

		world.setBlockState(pos.add(x + 15, y + 1, z + 10), BlockHandler.ZERG_FLESH.getDefaultState(), 2);

		world.setBlockState(pos.add(x + 16, y + 1, z + 10), BlockHandler.ZERG_FLESH.getDefaultState(), 2);

		world.setBlockState(pos.add(x + 17, y + 1, z + 10), BlockHandler.ZERG_FLESH.getDefaultState(), 2);

		world.setBlockState(pos.add(x + 1, y + 1, z + 11), BlockHandler.ZERG_FLESH.getDefaultState(), 2);

		world.setBlockState(pos.add(x + 2, y + 1, z + 11), BlockHandler.ZERG_FLESH.getDefaultState(), 2);

		world.setBlockState(pos.add(x + 3, y + 1, z + 11), BlockHandler.ZERG_FLESH.getDefaultState(), 2);

		world.setBlockState(pos.add(x + 4, y + 1, z + 11), BlockHandler.ZERG_FLESH.getDefaultState(), 2);

		world.setBlockState(pos.add(x + 5, y + 1, z + 11), BlockHandler.ZERG_FLESH.getDefaultState(), 2);

		world.setBlockState(pos.add(x + 6, y + 1, z + 11), BlockHandler.ZERG_FLESH.getStateFromMeta(2));
		world.setBlockState(pos.add(x + 7, y + 1, z + 11), BlockHandler.ZERG_FLESH.getStateFromMeta(2));
		world.setBlockState(pos.add(x + 8, y + 1, z + 11), BlockHandler.ZERG_FLESH.getStateFromMeta(2));
		world.setBlockState(pos.add(x + 9, y + 1, z + 11), BlockHandler.ZERG_FLESH.getStateFromMeta(2));
		world.setBlockState(pos.add(x + 10, y + 1, z + 11), BlockHandler.ZERG_FLESH.getStateFromMeta(2));
		world.setBlockState(pos.add(x + 11, y + 1, z + 11), BlockHandler.ZERG_FLESH.getStateFromMeta(2));
		world.setBlockState(pos.add(x + 12, y + 1, z + 11), BlockHandler.ZERG_FLESH.getStateFromMeta(2));
		world.setBlockState(pos.add(x + 13, y + 1, z + 11), BlockHandler.ZERG_FLESH.getStateFromMeta(2));
		world.setBlockState(pos.add(x + 14, y + 1, z + 11), BlockHandler.ZERG_FLESH.getStateFromMeta(2));
		world.setBlockState(pos.add(x + 15, y + 1, z + 11), BlockHandler.ZERG_FLESH.getDefaultState(), 2);

		world.setBlockState(pos.add(x + 16, y + 1, z + 11), BlockHandler.ZERG_FLESH.getDefaultState(), 2);

		world.setBlockState(pos.add(x + 17, y + 1, z + 11), BlockHandler.ZERG_FLESH.getDefaultState(), 2);

		world.setBlockState(pos.add(x + 1, y + 1, z + 12), BlockHandler.ZERG_FLESH.getDefaultState(), 2);

		world.setBlockState(pos.add(x + 2, y + 1, z + 12), BlockHandler.ZERG_FLESH.getDefaultState(), 2);

		world.setBlockState(pos.add(x + 3, y + 1, z + 12), BlockHandler.ZERG_FLESH.getDefaultState(), 2);

		world.setBlockState(pos.add(x + 4, y + 1, z + 12), BlockHandler.ZERG_FLESH.getDefaultState(), 2);

		world.setBlockState(pos.add(x + 5, y + 1, z + 12), BlockHandler.ZERG_FLESH.getDefaultState(), 2);

		world.setBlockState(pos.add(x + 6, y + 1, z + 12), BlockHandler.ZERG_FLESH.getDefaultState(), 2);

		world.setBlockState(pos.add(x + 7, y + 1, z + 12), BlockHandler.ZERG_FLESH.getStateFromMeta(2));
		world.setBlockState(pos.add(x + 8, y + 1, z + 12), BlockHandler.ZERG_FLESH.getStateFromMeta(2));
		world.setBlockState(pos.add(x + 9, y + 1, z + 12), BlockHandler.ZERG_FLESH.getStateFromMeta(2));
		world.setBlockState(pos.add(x + 10, y + 1, z + 12), BlockHandler.ZERG_FLESH.getStateFromMeta(2));
		world.setBlockState(pos.add(x + 11, y + 1, z + 12), BlockHandler.ZERG_FLESH.getStateFromMeta(2));
		world.setBlockState(pos.add(x + 12, y + 1, z + 12), BlockHandler.ZERG_FLESH.getStateFromMeta(2));
		world.setBlockState(pos.add(x + 13, y + 1, z + 12), BlockHandler.ZERG_FLESH.getStateFromMeta(2));
		world.setBlockState(pos.add(x + 14, y + 1, z + 12), BlockHandler.ZERG_FLESH.getStateFromMeta(2));
		world.setBlockState(pos.add(x + 15, y + 1, z + 12), BlockHandler.ZERG_FLESH.getStateFromMeta(2));
		world.setBlockState(pos.add(x + 16, y + 1, z + 12), BlockHandler.ZERG_FLESH.getDefaultState(), 2);

		world.setBlockState(pos.add(x + 17, y + 1, z + 12), BlockHandler.ZERG_FLESH.getDefaultState(), 2);

		world.setBlockState(pos.add(x + 18, y + 1, z + 12), BlockHandler.ZERG_FLESH.getDefaultState(), 2);

		world.setBlockState(pos.add(x + 1, y + 1, z + 13), BlockHandler.ZERG_FLESH.getDefaultState(), 2);

		world.setBlockState(pos.add(x + 2, y + 1, z + 13), BlockHandler.ZERG_FLESH.getDefaultState(), 2);

		world.setBlockState(pos.add(x + 3, y + 1, z + 13), BlockHandler.ZERG_FLESH.getDefaultState(), 2);

		world.setBlockState(pos.add(x + 4, y + 1, z + 13), BlockHandler.ZERG_FLESH.getDefaultState(), 2);

		world.setBlockState(pos.add(x + 5, y + 1, z + 13), BlockHandler.ZERG_FLESH.getDefaultState(), 2);

		world.setBlockState(pos.add(x + 6, y + 1, z + 13), BlockHandler.ZERG_FLESH.getDefaultState(), 2);

		world.setBlockState(pos.add(x + 7, y + 1, z + 13), BlockHandler.ZERG_FLESH.getDefaultState(), 2);

		world.setBlockState(pos.add(x + 8, y + 1, z + 13), BlockHandler.ZERG_FLESH.getStateFromMeta(2));
		world.setBlockState(pos.add(x + 9, y + 1, z + 13), BlockHandler.ZERG_FLESH.getStateFromMeta(2));
		world.setBlockState(pos.add(x + 10, y + 1, z + 13), BlockHandler.ZERG_FLESH.getStateFromMeta(2));
		world.setBlockState(pos.add(x + 11, y + 1, z + 13), BlockHandler.ZERG_FLESH.getStateFromMeta(2));
		world.setBlockState(pos.add(x + 12, y + 1, z + 13), BlockHandler.ZERG_FLESH.getStateFromMeta(2));
		world.setBlockState(pos.add(x + 13, y + 1, z + 13), BlockHandler.ZERG_FLESH.getStateFromMeta(2));
		world.setBlockState(pos.add(x + 14, y + 1, z + 13), BlockHandler.ZERG_FLESH.getStateFromMeta(2));
		world.setBlockState(pos.add(x + 15, y + 1, z + 13), BlockHandler.ZERG_FLESH.getStateFromMeta(2));
		world.setBlockState(pos.add(x + 16, y + 1, z + 13), BlockHandler.ZERG_FLESH.getDefaultState(), 2);

		world.setBlockState(pos.add(x + 17, y + 1, z + 13), BlockHandler.ZERG_FLESH.getDefaultState(), 2);

		world.setBlockState(pos.add(x + 18, y + 1, z + 13), BlockHandler.ZERG_FLESH.getDefaultState(), 2);

		world.setBlockState(pos.add(x + 19, y + 1, z + 13), BlockHandler.ZERG_FLESH.getDefaultState(), 2);

		world.setBlockState(pos.add(x + 2, y + 1, z + 14), BlockHandler.ZERG_FLESH.getDefaultState(), 2);

		world.setBlockState(pos.add(x + 3, y + 1, z + 14), BlockHandler.ZERG_FLESH.getDefaultState(), 2);

		world.setBlockState(pos.add(x + 4, y + 1, z + 14), BlockHandler.ZERG_FLESH.getDefaultState(), 2);

		world.setBlockState(pos.add(x + 5, y + 1, z + 14), BlockHandler.ZERG_FLESH.getDefaultState(), 2);

		world.setBlockState(pos.add(x + 6, y + 1, z + 14), BlockHandler.ZERG_FLESH.getDefaultState(), 2);

		world.setBlockState(pos.add(x + 7, y + 1, z + 14), BlockHandler.ZERG_FLESH.getDefaultState(), 2);

		world.setBlockState(pos.add(x + 8, y + 1, z + 14), BlockHandler.ZERG_FLESH.getDefaultState(), 2);

		world.setBlockState(pos.add(x + 9, y + 1, z + 14), BlockHandler.ZERG_FLESH.getStateFromMeta(2));
		world.setBlockState(pos.add(x + 10, y + 1, z + 14), BlockHandler.ZERG_FLESH.getStateFromMeta(2));
		world.setBlockState(pos.add(x + 11, y + 1, z + 14), BlockHandler.ZERG_FLESH.getStateFromMeta(2));
		world.setBlockState(pos.add(x + 12, y + 1, z + 14), BlockHandler.ZERG_FLESH.getStateFromMeta(2));
		world.setBlockState(pos.add(x + 13, y + 1, z + 14), BlockHandler.ZERG_FLESH.getStateFromMeta(2));
		world.setBlockState(pos.add(x + 14, y + 1, z + 14), BlockHandler.ZERG_FLESH.getStateFromMeta(2));
		world.setBlockState(pos.add(x + 15, y + 1, z + 14), BlockHandler.ZERG_FLESH.getStateFromMeta(2));
		world.setBlockState(pos.add(x + 16, y + 1, z + 14), BlockHandler.ZERG_FLESH.getDefaultState(), 2);

		world.setBlockState(pos.add(x + 17, y + 1, z + 14), BlockHandler.ZERG_FLESH.getDefaultState(), 2);

		world.setBlockState(pos.add(x + 18, y + 1, z + 14), BlockHandler.ZERG_FLESH.getDefaultState(), 2);

		world.setBlockState(pos.add(x + 19, y + 1, z + 14), BlockHandler.ZERG_FLESH.getDefaultState(), 2);

		world.setBlockState(pos.add(x + 20, y + 1, z + 14), BlockHandler.ZERG_FLESH.getStateFromMeta(1), 2);

		world.setBlockState(pos.add(x + 2, y + 1, z + 15), BlockHandler.ZERG_FLESH.getDefaultState(), 2);

		world.setBlockState(pos.add(x + 3, y + 1, z + 15), BlockHandler.ZERG_FLESH.getDefaultState(), 2);

		world.setBlockState(pos.add(x + 4, y + 1, z + 15), BlockHandler.ZERG_FLESH.getDefaultState(), 2);

		world.setBlockState(pos.add(x + 5, y + 1, z + 15), BlockHandler.ZERG_FLESH.getDefaultState(), 2);

		world.setBlockState(pos.add(x + 6, y + 1, z + 15), BlockHandler.ZERG_FLESH.getDefaultState(), 2);

		world.setBlockState(pos.add(x + 7, y + 1, z + 15), BlockHandler.ZERG_FLESH.getDefaultState(), 2);

		world.setBlockState(pos.add(x + 8, y + 1, z + 15), BlockHandler.ZERG_FLESH.getDefaultState(), 2);

		world.setBlockState(pos.add(x + 9, y + 1, z + 15), BlockHandler.ZERG_FLESH.getDefaultState(), 2);

		world.setBlockState(pos.add(x + 10, y + 1, z + 15), BlockHandler.ZERG_FLESH.getStateFromMeta(2));
		world.setBlockState(pos.add(x + 11, y + 1, z + 15), BlockHandler.ZERG_FLESH.getStateFromMeta(2));
		world.setBlockState(pos.add(x + 12, y + 1, z + 15), BlockHandler.ZERG_FLESH.getStateFromMeta(2));
		world.setBlockState(pos.add(x + 13, y + 1, z + 15), BlockHandler.ZERG_FLESH.getStateFromMeta(2));
		world.setBlockState(pos.add(x + 14, y + 1, z + 15), BlockHandler.ZERG_FLESH.getStateFromMeta(2));
		world.setBlockState(pos.add(x + 15, y + 1, z + 15), BlockHandler.ZERG_FLESH.getDefaultState(), 2);

		world.setBlockState(pos.add(x + 16, y + 1, z + 15), BlockHandler.ZERG_FLESH.getDefaultState(), 2);

		world.setBlockState(pos.add(x + 17, y + 1, z + 15), BlockHandler.ZERG_FLESH.getDefaultState(), 2);

		world.setBlockState(pos.add(x + 18, y + 1, z + 15), BlockHandler.ZERG_FLESH.getDefaultState(), 2);

		world.setBlockState(pos.add(x + 19, y + 1, z + 15), BlockHandler.ZERG_FLESH.getDefaultState(), 2);

		world.setBlockState(pos.add(x + 20, y + 1, z + 15), BlockHandler.ZERG_FLESH.getStateFromMeta(1), 2);

		world.setBlockState(pos.add(x + 21, y + 1, z + 15), BlockHandler.ZERG_FLESH.getStateFromMeta(1), 2);

		world.setBlockState(pos.add(x + 2, y + 1, z + 16), BlockHandler.ZERG_FLESH.getDefaultState(), 2);

		world.setBlockState(pos.add(x + 3, y + 1, z + 16), BlockHandler.ZERG_FLESH.getDefaultState(), 2);

		world.setBlockState(pos.add(x + 4, y + 1, z + 16), BlockHandler.ZERG_FLESH.getDefaultState(), 2);

		world.setBlockState(pos.add(x + 5, y + 1, z + 16), BlockHandler.ZERG_FLESH.getDefaultState(), 2);

		world.setBlockState(pos.add(x + 6, y + 1, z + 16), BlockHandler.ZERG_FLESH.getDefaultState(), 2);

		world.setBlockState(pos.add(x + 7, y + 1, z + 16), BlockHandler.ZERG_FLESH.getDefaultState(), 2);

		world.setBlockState(pos.add(x + 8, y + 1, z + 16), BlockHandler.ZERG_FLESH.getDefaultState(), 2);

		world.setBlockState(pos.add(x + 9, y + 1, z + 16), BlockHandler.ZERG_FLESH.getDefaultState(), 2);

		world.setBlockState(pos.add(x + 10, y + 1, z + 16), BlockHandler.ZERG_FLESH.getDefaultState(), 2);

		world.setBlockState(pos.add(x + 11, y + 1, z + 16), BlockHandler.ZERG_FLESH.getStateFromMeta(2));
		world.setBlockState(pos.add(x + 12, y + 1, z + 16), BlockHandler.ZERG_FLESH.getStateFromMeta(2));
		world.setBlockState(pos.add(x + 13, y + 1, z + 16), BlockHandler.ZERG_FLESH.getStateFromMeta(2));
		world.setBlockState(pos.add(x + 14, y + 1, z + 16), BlockHandler.ZERG_FLESH.getStateFromMeta(2));
		world.setBlockState(pos.add(x + 15, y + 1, z + 16), BlockHandler.ZERG_FLESH.getDefaultState(), 2);

		world.setBlockState(pos.add(x + 16, y + 1, z + 16), BlockHandler.ZERG_FLESH.getDefaultState(), 2);

		world.setBlockState(pos.add(x + 17, y + 1, z + 16), BlockHandler.ZERG_FLESH.getDefaultState(), 2);

		world.setBlockState(pos.add(x + 18, y + 1, z + 16), BlockHandler.ZERG_FLESH.getDefaultState(), 2);

		world.setBlockState(pos.add(x + 19, y + 1, z + 16), BlockHandler.ZERG_FLESH.getDefaultState(), 2);

		world.setBlockState(pos.add(x + 20, y + 1, z + 16), BlockHandler.ZERG_FLESH.getStateFromMeta(1), 2);

		world.setBlockState(pos.add(x + 21, y + 1, z + 16), BlockHandler.ZERG_FLESH.getStateFromMeta(1), 2);

		world.setBlockState(pos.add(x + 22, y + 1, z + 16), BlockHandler.ZERG_FLESH.getStateFromMeta(1), 2);

		world.setBlockState(pos.add(x + 2, y + 1, z + 17), BlockHandler.ZERG_FLESH.getDefaultState(), 2);

		world.setBlockState(pos.add(x + 3, y + 1, z + 17), BlockHandler.ZERG_FLESH.getDefaultState(), 2);

		world.setBlockState(pos.add(x + 4, y + 1, z + 17), BlockHandler.ZERG_FLESH.getDefaultState(), 2);

		world.setBlockState(pos.add(x + 5, y + 1, z + 17), BlockHandler.ZERG_FLESH.getDefaultState(), 2);

		world.setBlockState(pos.add(x + 6, y + 1, z + 17), BlockHandler.ZERG_FLESH.getDefaultState(), 2);

		world.setBlockState(pos.add(x + 7, y + 1, z + 17), BlockHandler.ZERG_FLESH.getDefaultState(), 2);

		world.setBlockState(pos.add(x + 8, y + 1, z + 17), BlockHandler.ZERG_FLESH.getDefaultState(), 2);

		world.setBlockState(pos.add(x + 9, y + 1, z + 17), BlockHandler.ZERG_FLESH.getDefaultState(), 2);

		world.setBlockState(pos.add(x + 10, y + 1, z + 17), BlockHandler.ZERG_FLESH.getDefaultState(), 2);

		world.setBlockState(pos.add(x + 11, y + 1, z + 17), BlockHandler.ZERG_FLESH.getDefaultState(), 2);

		world.setBlockState(pos.add(x + 12, y + 1, z + 17), BlockHandler.ZERG_FLESH.getStateFromMeta(2));
		world.setBlockState(pos.add(x + 13, y + 1, z + 17), BlockHandler.ZERG_FLESH.getStateFromMeta(2));
		world.setBlockState(pos.add(x + 14, y + 1, z + 17), BlockHandler.ZERG_FLESH.getStateFromMeta(2));
		world.setBlockState(pos.add(x + 15, y + 1, z + 17), BlockHandler.ZERG_FLESH.getDefaultState(), 2);

		world.setBlockState(pos.add(x + 16, y + 1, z + 17), BlockHandler.ZERG_FLESH.getDefaultState(), 2);

		world.setBlockState(pos.add(x + 17, y + 1, z + 17), BlockHandler.ZERG_FLESH.getDefaultState(), 2);

		world.setBlockState(pos.add(x + 18, y + 1, z + 17), BlockHandler.ZERG_FLESH.getDefaultState(), 2);

		world.setBlockState(pos.add(x + 19, y + 1, z + 17), BlockHandler.ZERG_FLESH.getDefaultState(), 2);

		world.setBlockState(pos.add(x + 20, y + 1, z + 17), BlockHandler.ZERG_FLESH.getDefaultState(), 2);

		world.setBlockState(pos.add(x + 21, y + 1, z + 17), BlockHandler.ZERG_FLESH.getDefaultState(), 2);

		world.setBlockState(pos.add(x + 22, y + 1, z + 17), BlockHandler.ZERG_FLESH.getDefaultState(), 2);

		world.setBlockState(pos.add(x + 2, y + 1, z + 18), BlockHandler.ZERG_FLESH.getDefaultState(), 2);

		world.setBlockState(pos.add(x + 3, y + 1, z + 18), BlockHandler.ZERG_FLESH.getDefaultState(), 2);

		world.setBlockState(pos.add(x + 4, y + 1, z + 18), BlockHandler.ZERG_FLESH.getDefaultState(), 2);

		world.setBlockState(pos.add(x + 5, y + 1, z + 18), BlockHandler.ZERG_FLESH.getDefaultState(), 2);

		world.setBlockState(pos.add(x + 6, y + 1, z + 18), BlockHandler.ZERG_FLESH.getDefaultState(), 2);

		world.setBlockState(pos.add(x + 7, y + 1, z + 18), BlockHandler.ZERG_FLESH.getDefaultState(), 2);

		world.setBlockState(pos.add(x + 8, y + 1, z + 18), BlockHandler.ZERG_FLESH.getDefaultState(), 2);

		world.setBlockState(pos.add(x + 9, y + 1, z + 18), BlockHandler.ZERG_FLESH.getDefaultState(), 2);

		world.setBlockState(pos.add(x + 10, y + 1, z + 18), BlockHandler.ZERG_FLESH.getDefaultState(), 2);

		world.setBlockState(pos.add(x + 11, y + 1, z + 18), BlockHandler.ZERG_FLESH.getDefaultState(), 2);

		world.setBlockState(pos.add(x + 12, y + 1, z + 18), BlockHandler.ZERG_FLESH.getDefaultState(), 2);

		world.setBlockState(pos.add(x + 13, y + 1, z + 18), BlockHandler.ZERG_FLESH.getStateFromMeta(2));
		world.setBlockState(pos.add(x + 14, y + 1, z + 18), BlockHandler.ZERG_FLESH.getStateFromMeta(2));
		world.setBlockState(pos.add(x + 15, y + 1, z + 18), BlockHandler.ZERG_FLESH.getDefaultState(), 2);

		world.setBlockState(pos.add(x + 16, y + 1, z + 18), BlockHandler.ZERG_FLESH.getDefaultState(), 2);

		world.setBlockState(pos.add(x + 17, y + 1, z + 18), BlockHandler.ZERG_FLESH.getDefaultState(), 2);

		world.setBlockState(pos.add(x + 18, y + 1, z + 18), BlockHandler.ZERG_FLESH.getDefaultState(), 2);

		world.setBlockState(pos.add(x + 19, y + 1, z + 18), BlockHandler.ZERG_FLESH.getDefaultState(), 2);

		world.setBlockState(pos.add(x + 20, y + 1, z + 18), BlockHandler.ZERG_FLESH.getDefaultState(), 2);

		world.setBlockState(pos.add(x + 21, y + 1, z + 18), BlockHandler.ZERG_FLESH.getDefaultState(), 2);

		world.setBlockState(pos.add(x + 22, y + 1, z + 18), BlockHandler.ZERG_FLESH.getDefaultState(), 2);

		world.setBlockState(pos.add(x + 23, y + 1, z + 18), BlockHandler.ZERG_FLESH.getDefaultState(), 2);

		world.setBlockState(pos.add(x + 3, y + 1, z + 19), BlockHandler.ZERG_FLESH.getDefaultState(), 2);

		world.setBlockState(pos.add(x + 4, y + 1, z + 19), BlockHandler.ZERG_FLESH.getDefaultState(), 2);

		world.setBlockState(pos.add(x + 5, y + 1, z + 19), BlockHandler.ZERG_FLESH.getDefaultState(), 2);

		world.setBlockState(pos.add(x + 6, y + 1, z + 19), BlockHandler.ZERG_FLESH.getDefaultState(), 2);

		world.setBlockState(pos.add(x + 7, y + 1, z + 19), BlockHandler.ZERG_FLESH.getDefaultState(), 2);

		world.setBlockState(pos.add(x + 8, y + 1, z + 19), BlockHandler.ZERG_FLESH.getDefaultState(), 2);

		world.setBlockState(pos.add(x + 9, y + 1, z + 19), BlockHandler.ZERG_FLESH.getDefaultState(), 2);

		world.setBlockState(pos.add(x + 10, y + 1, z + 19), BlockHandler.ZERG_FLESH.getDefaultState(), 2);

		world.setBlockState(pos.add(x + 11, y + 1, z + 19), BlockHandler.ZERG_FLESH.getDefaultState(), 2);

		world.setBlockState(pos.add(x + 12, y + 1, z + 19), BlockHandler.ZERG_FLESH.getDefaultState(), 2);

		world.setBlockState(pos.add(x + 13, y + 1, z + 19), BlockHandler.ZERG_FLESH.getDefaultState(), 2);

		world.setBlockState(pos.add(x + 14, y + 1, z + 19), BlockHandler.ZERG_FLESH.getStateFromMeta(2));
		world.setBlockState(pos.add(x + 15, y + 1, z + 19), BlockHandler.ZERG_FLESH.getDefaultState(), 2);

		world.setBlockState(pos.add(x + 16, y + 1, z + 19), BlockHandler.ZERG_FLESH.getDefaultState(), 2);

		world.setBlockState(pos.add(x + 17, y + 1, z + 19), BlockHandler.ZERG_FLESH.getDefaultState(), 2);

		world.setBlockState(pos.add(x + 18, y + 1, z + 19), BlockHandler.ZERG_FLESH.getDefaultState(), 2);

		world.setBlockState(pos.add(x + 19, y + 1, z + 19), BlockHandler.ZERG_FLESH.getDefaultState(), 2);

		world.setBlockState(pos.add(x + 20, y + 1, z + 19), BlockHandler.ZERG_FLESH.getDefaultState(), 2);

		world.setBlockState(pos.add(x + 21, y + 1, z + 19), BlockHandler.ZERG_FLESH.getDefaultState(), 2);

		world.setBlockState(pos.add(x + 22, y + 1, z + 19), BlockHandler.ZERG_FLESH.getDefaultState(), 2);

		world.setBlockState(pos.add(x + 23, y + 1, z + 19), BlockHandler.ZERG_FLESH.getDefaultState(), 2);

		world.setBlockState(pos.add(x + 4, y + 1, z + 20), BlockHandler.ZERG_FLESH.getDefaultState(), 2);

		world.setBlockState(pos.add(x + 5, y + 1, z + 20), BlockHandler.ZERG_FLESH.getDefaultState(), 2);

		world.setBlockState(pos.add(x + 6, y + 1, z + 20), BlockHandler.ZERG_FLESH.getDefaultState(), 2);

		world.setBlockState(pos.add(x + 7, y + 1, z + 20), BlockHandler.ZERG_FLESH.getDefaultState(), 2);

		world.setBlockState(pos.add(x + 8, y + 1, z + 20), BlockHandler.ZERG_FLESH.getDefaultState(), 2);

		world.setBlockState(pos.add(x + 9, y + 1, z + 20), BlockHandler.ZERG_FLESH.getDefaultState(), 2);

		world.setBlockState(pos.add(x + 10, y + 1, z + 20), BlockHandler.ZERG_FLESH.getDefaultState(), 2);

		world.setBlockState(pos.add(x + 11, y + 1, z + 20), BlockHandler.ZERG_FLESH.getDefaultState(), 2);

		world.setBlockState(pos.add(x + 12, y + 1, z + 20), BlockHandler.ZERG_FLESH.getDefaultState(), 2);

		world.setBlockState(pos.add(x + 13, y + 1, z + 20), BlockHandler.ZERG_FLESH.getDefaultState(), 2);

		world.setBlockState(pos.add(x + 14, y + 1, z + 20), BlockHandler.ZERG_FLESH.getDefaultState(), 2);

		world.setBlockState(pos.add(x + 15, y + 1, z + 20), BlockHandler.ZERG_FLESH.getDefaultState(), 2);

		world.setBlockState(pos.add(x + 16, y + 1, z + 20), BlockHandler.ZERG_FLESH.getDefaultState(), 2);

		world.setBlockState(pos.add(x + 17, y + 1, z + 20), BlockHandler.ZERG_FLESH.getDefaultState(), 2);

		world.setBlockState(pos.add(x + 18, y + 1, z + 20), BlockHandler.ZERG_FLESH.getDefaultState(), 2);

		world.setBlockState(pos.add(x + 19, y + 1, z + 20), BlockHandler.ZERG_FLESH.getDefaultState(), 2);

		world.setBlockState(pos.add(x + 20, y + 1, z + 20), BlockHandler.ZERG_FLESH.getDefaultState(), 2);

		world.setBlockState(pos.add(x + 21, y + 1, z + 20), BlockHandler.ZERG_FLESH.getDefaultState(), 2);

		world.setBlockState(pos.add(x + 22, y + 1, z + 20), BlockHandler.ZERG_FLESH.getDefaultState(), 2);

		world.setBlockState(pos.add(x + 23, y + 1, z + 20), BlockHandler.ZERG_FLESH.getDefaultState(), 2);

		world.setBlockState(pos.add(x + 5, y + 1, z + 21), BlockHandler.ZERG_FLESH.getDefaultState(), 2);

		world.setBlockState(pos.add(x + 6, y + 1, z + 21), BlockHandler.ZERG_FLESH.getDefaultState(), 2);

		world.setBlockState(pos.add(x + 7, y + 1, z + 21), BlockHandler.ZERG_FLESH.getDefaultState(), 2);

		world.setBlockState(pos.add(x + 8, y + 1, z + 21), BlockHandler.ZERG_FLESH.getDefaultState(), 2);

		world.setBlockState(pos.add(x + 9, y + 1, z + 21), BlockHandler.ZERG_FLESH.getDefaultState(), 2);

		world.setBlockState(pos.add(x + 10, y + 1, z + 21), BlockHandler.ZERG_FLESH.getDefaultState(), 2);

		world.setBlockState(pos.add(x + 11, y + 1, z + 21), BlockHandler.ZERG_FLESH.getDefaultState(), 2);

		world.setBlockState(pos.add(x + 12, y + 1, z + 21), BlockHandler.ZERG_FLESH.getDefaultState(), 2);

		world.setBlockState(pos.add(x + 13, y + 1, z + 21), BlockHandler.ZERG_FLESH.getDefaultState(), 2);

		world.setBlockState(pos.add(x + 14, y + 1, z + 21), BlockHandler.ZERG_FLESH.getDefaultState(), 2);

		world.setBlockState(pos.add(x + 15, y + 1, z + 21), BlockHandler.ZERG_FLESH.getDefaultState(), 2);

		world.setBlockState(pos.add(x + 16, y + 1, z + 21), BlockHandler.ZERG_FLESH.getDefaultState(), 2);

		world.setBlockState(pos.add(x + 17, y + 1, z + 21), BlockHandler.ZERG_FLESH.getDefaultState(), 2);

		world.setBlockState(pos.add(x + 18, y + 1, z + 21), BlockHandler.ZERG_FLESH.getDefaultState(), 2);

		world.setBlockState(pos.add(x + 19, y + 1, z + 21), BlockHandler.ZERG_FLESH.getDefaultState(), 2);

		world.setBlockState(pos.add(x + 20, y + 1, z + 21), BlockHandler.ZERG_FLESH.getDefaultState(), 2);

		world.setBlockState(pos.add(x + 21, y + 1, z + 21), BlockHandler.ZERG_FLESH.getDefaultState(), 2);

		world.setBlockState(pos.add(x + 22, y + 1, z + 21), BlockHandler.ZERG_FLESH.getDefaultState(), 2);

		world.setBlockState(pos.add(x + 6, y + 1, z + 22), BlockHandler.ZERG_FLESH.getDefaultState(), 2);

		world.setBlockState(pos.add(x + 7, y + 1, z + 22), BlockHandler.ZERG_FLESH.getDefaultState(), 2);

		world.setBlockState(pos.add(x + 8, y + 1, z + 22), BlockHandler.ZERG_FLESH.getDefaultState(), 2);

		world.setBlockState(pos.add(x + 9, y + 1, z + 22), BlockHandler.ZERG_FLESH.getDefaultState(), 2);

		world.setBlockState(pos.add(x + 10, y + 1, z + 22), BlockHandler.ZERG_FLESH.getDefaultState(), 2);

		world.setBlockState(pos.add(x + 11, y + 1, z + 22), BlockHandler.ZERG_FLESH.getDefaultState(), 2);

		world.setBlockState(pos.add(x + 12, y + 1, z + 22), BlockHandler.ZERG_FLESH.getDefaultState(), 2);

		world.setBlockState(pos.add(x + 13, y + 1, z + 22), BlockHandler.ZERG_FLESH.getDefaultState(), 2);

		world.setBlockState(pos.add(x + 14, y + 1, z + 22), BlockHandler.ZERG_FLESH.getDefaultState(), 2);

		world.setBlockState(pos.add(x + 15, y + 1, z + 22), BlockHandler.ZERG_FLESH.getDefaultState(), 2);

		world.setBlockState(pos.add(x + 16, y + 1, z + 22), BlockHandler.ZERG_FLESH.getDefaultState(), 2);

		world.setBlockState(pos.add(x + 17, y + 1, z + 22), BlockHandler.ZERG_FLESH.getDefaultState(), 2);

		world.setBlockState(pos.add(x + 18, y + 1, z + 22), BlockHandler.ZERG_FLESH.getDefaultState(), 2);

		world.setBlockState(pos.add(x + 19, y + 1, z + 22), BlockHandler.ZERG_FLESH.getDefaultState(), 2);

		world.setBlockState(pos.add(x + 20, y + 1, z + 22), BlockHandler.ZERG_FLESH.getDefaultState(), 2);

		world.setBlockState(pos.add(x + 21, y + 1, z + 22), BlockHandler.ZERG_FLESH.getDefaultState(), 2);

		world.setBlockState(pos.add(x + 11, y + 1, z + 23), BlockHandler.ZERG_FLESH.getDefaultState(), 2);

		world.setBlockState(pos.add(x + 12, y + 1, z + 23), BlockHandler.ZERG_FLESH.getDefaultState(), 2);

		world.setBlockState(pos.add(x + 13, y + 1, z + 23), BlockHandler.ZERG_FLESH.getDefaultState(), 2);

		world.setBlockState(pos.add(x + 14, y + 1, z + 23), BlockHandler.ZERG_FLESH.getDefaultState(), 2);

		world.setBlockState(pos.add(x + 15, y + 1, z + 23), BlockHandler.ZERG_FLESH.getDefaultState(), 2);

		world.setBlockState(pos.add(x + 16, y + 1, z + 23), BlockHandler.ZERG_FLESH.getDefaultState(), 2);

		world.setBlockState(pos.add(x + 17, y + 1, z + 23), BlockHandler.ZERG_FLESH.getDefaultState(), 2);

		world.setBlockState(pos.add(x + 18, y + 1, z + 23), BlockHandler.ZERG_FLESH.getDefaultState(), 2);

		world.setBlockState(pos.add(x + 19, y + 1, z + 23), BlockHandler.ZERG_FLESH.getDefaultState(), 2);

		world.setBlockState(pos.add(x + 3, y + 2, z + 1), BlockHandler.ZERG_FLESH.getDefaultState(), 2);

		world.setBlockState(pos.add(x + 4, y + 2, z + 1), BlockHandler.ZERG_FLESH.getDefaultState(), 2);

		world.setBlockState(pos.add(x + 5, y + 2, z + 1), BlockHandler.ZERG_FLESH.getDefaultState(), 2);

		world.setBlockState(pos.add(x + 6, y + 2, z + 1), BlockHandler.ZERG_FLESH.getDefaultState(), 2);

		world.setBlockState(pos.add(x + 2, y + 2, z + 2), BlockHandler.ZERG_FLESH.getDefaultState(), 2);

		world.setBlockState(pos.add(x + 3, y + 2, z + 2), BlockHandler.ZERG_FLESH.getDefaultState(), 2);

		world.setBlockState(pos.add(x + 4, y + 2, z + 2), BlockHandler.ZERG_FLESH.getDefaultState(), 2);

		world.setBlockState(pos.add(x + 5, y + 2, z + 2), BlockHandler.ZERG_FLESH.getDefaultState(), 2);

		world.setBlockState(pos.add(x + 6, y + 2, z + 2), BlockHandler.ZERG_FLESH.getDefaultState(), 2);

		world.setBlockState(pos.add(x + 7, y + 2, z + 2), BlockHandler.ZERG_FLESH.getDefaultState(), 2);

		world.setBlockState(pos.add(x + 8, y + 2, z + 2), BlockHandler.ZERG_FLESH.getStateFromMeta(1), 2);

		world.setBlockState(pos.add(x + 2, y + 2, z + 3), BlockHandler.ZERG_FLESH.getDefaultState(), 2);

		world.setBlockState(pos.add(x + 3, y + 2, z + 3), BlockHandler.ZERG_FLESH.getDefaultState(), 2);

		world.setBlockState(pos.add(x + 4, y + 2, z + 3), BlockHandler.ZERG_FLESH.getStateFromMeta(2));
		world.setBlockState(pos.add(x + 5, y + 2, z + 3), BlockHandler.ZERG_FLESH.getStateFromMeta(2));
		world.setBlockState(pos.add(x + 6, y + 2, z + 3), BlockHandler.ZERG_FLESH.getDefaultState(), 2);

		world.setBlockState(pos.add(x + 7, y + 2, z + 3), BlockHandler.ZERG_FLESH.getStateFromMeta(1), 2);

		world.setBlockState(pos.add(x + 1, y + 2, z + 4), BlockHandler.ZERG_FLESH.getDefaultState(), 2);

		world.setBlockState(pos.add(x + 2, y + 2, z + 4), BlockHandler.ZERG_FLESH.getDefaultState(), 2);

		world.setBlockState(pos.add(x + 3, y + 2, z + 4), BlockHandler.ZERG_FLESH.getStateFromMeta(2));
		world.setBlockState(pos.add(x + 4, y + 2, z + 4), BlockHandler.ZERG_FLESH.getStateFromMeta(2));
		world.setBlockState(pos.add(x + 5, y + 2, z + 4), BlockHandler.ZERG_FLESH.getStateFromMeta(2));
		world.setBlockState(pos.add(x + 6, y + 2, z + 4), BlockHandler.ZERG_FLESH.getDefaultState(), 2);

		world.setBlockState(pos.add(x + 7, y + 2, z + 4), BlockHandler.ZERG_FLESH.getStateFromMeta(1), 2);

		world.setBlockState(pos.add(x + 10, y + 2, z + 4), BlockHandler.ZERG_FLESH.getStateFromMeta(1), 2);

		world.setBlockState(pos.add(x + 0, y + 2, z + 5), BlockHandler.ZERG_FLESH.getDefaultState(), 2);

		world.setBlockState(pos.add(x + 1, y + 2, z + 5), BlockHandler.ZERG_FLESH.getDefaultState(), 2);

		world.setBlockState(pos.add(x + 2, y + 2, z + 5), BlockHandler.ZERG_FLESH.getDefaultState(), 2);

		world.setBlockState(pos.add(x + 3, y + 2, z + 5), BlockHandler.ZERG_FLESH.getStateFromMeta(2));
		world.setBlockState(pos.add(x + 4, y + 2, z + 5), BlockHandler.ZERG_FLESH.getStateFromMeta(2));
		world.setBlockState(pos.add(x + 5, y + 2, z + 5), BlockHandler.ZERG_FLESH.getStateFromMeta(2));
		world.setBlockState(pos.add(x + 6, y + 2, z + 5), BlockHandler.ZERG_FLESH.getStateFromMeta(2));
		world.setBlockState(pos.add(x + 7, y + 2, z + 5), BlockHandler.ZERG_FLESH.getDefaultState(), 2);

		world.setBlockState(pos.add(x + 8, y + 2, z + 5), BlockHandler.ZERG_FLESH.getStateFromMeta(1), 2);

		world.setBlockState(pos.add(x + 9, y + 2, z + 5), BlockHandler.ZERG_FLESH.getStateFromMeta(1), 2);

		world.setBlockState(pos.add(x + 10, y + 2, z + 5), BlockHandler.ZERG_FLESH.getDefaultState(), 2);

		world.setBlockState(pos.add(x + 11, y + 2, z + 5), BlockHandler.ZERG_FLESH.getDefaultState(), 2);

		world.setBlockState(pos.add(x + 15, y + 2, z + 5), BlockHandler.ZERG_FLESH.getDefaultState(), 2);

		world.setBlockState(pos.add(x + 0, y + 2, z + 6), BlockHandler.ZERG_FLESH.getDefaultState(), 2);

		world.setBlockState(pos.add(x + 1, y + 2, z + 6), BlockHandler.ZERG_FLESH.getDefaultState(), 2);

		world.setBlockState(pos.add(x + 2, y + 2, z + 6), BlockHandler.ZERG_FLESH.getDefaultState(), 2);

		world.setBlockState(pos.add(x + 3, y + 2, z + 6), BlockHandler.ZERG_FLESH.getStateFromMeta(2));
		world.setBlockState(pos.add(x + 4, y + 2, z + 6), BlockHandler.ZERG_FLESH.getStateFromMeta(2));
		world.setBlockState(pos.add(x + 5, y + 2, z + 6), BlockHandler.ZERG_FLESH.getStateFromMeta(2));
		world.setBlockState(pos.add(x + 6, y + 2, z + 6), BlockHandler.ZERG_FLESH.getStateFromMeta(2));
		world.setBlockState(pos.add(x + 7, y + 2, z + 6), BlockHandler.ZERG_FLESH.getDefaultState(), 2);

		world.setBlockState(pos.add(x + 8, y + 2, z + 6), BlockHandler.ZERG_FLESH.getDefaultState(), 2);

		world.setBlockState(pos.add(x + 9, y + 2, z + 6), BlockHandler.ZERG_FLESH.getDefaultState(), 2);

		world.setBlockState(pos.add(x + 10, y + 2, z + 6), BlockHandler.ZERG_FLESH.getStateFromMeta(2));
		world.setBlockState(pos.add(x + 11, y + 2, z + 6), BlockHandler.ZERG_FLESH.getDefaultState(), 2);

		world.setBlockState(pos.add(x + 12, y + 2, z + 6), BlockHandler.ZERG_FLESH.getDefaultState(), 2);

		world.setBlockState(pos.add(x + 14, y + 2, z + 6), BlockHandler.ZERG_FLESH.getDefaultState(), 2);

		world.setBlockState(pos.add(x + 15, y + 2, z + 6), BlockHandler.KERATIN_CHUNK.getDefaultState(), 2);
		world.setBlockState(pos.add(x + 0, y + 2, z + 7), BlockHandler.ZERG_FLESH.getDefaultState(), 2);

		world.setBlockState(pos.add(x + 1, y + 2, z + 7), BlockHandler.ZERG_FLESH.getDefaultState(), 2);

		world.setBlockState(pos.add(x + 2, y + 2, z + 7), BlockHandler.ZERG_FLESH.getDefaultState(), 2);

		world.setBlockState(pos.add(x + 3, y + 2, z + 7), BlockHandler.ZERG_FLESH.getStateFromMeta(2));
		world.setBlockState(pos.add(x + 4, y + 2, z + 7), BlockHandler.ZERG_FLESH.getStateFromMeta(2));
		world.setBlockState(pos.add(x + 5, y + 2, z + 7), BlockHandler.ZERG_FLESH.getStateFromMeta(2));
		world.setBlockState(pos.add(x + 6, y + 2, z + 7), BlockHandler.ZERG_FLESH.getStateFromMeta(2));
		world.setBlockState(pos.add(x + 7, y + 2, z + 7), BlockHandler.ZERG_FLESH.getDefaultState(), 2);

		world.setBlockState(pos.add(x + 8, y + 2, z + 7), BlockHandler.ZERG_FLESH.getStateFromMeta(2));
		world.setBlockState(pos.add(x + 9, y + 2, z + 7), BlockHandler.ZERG_FLESH.getStateFromMeta(2));
		world.setBlockState(pos.add(x + 10, y + 2, z + 7), BlockHandler.ZERG_FLESH.getStateFromMeta(2));
		world.setBlockState(pos.add(x + 11, y + 2, z + 7), BlockHandler.ZERG_FLESH.getStateFromMeta(2));
		world.setBlockState(pos.add(x + 12, y + 2, z + 7), BlockHandler.ZERG_FLESH.getDefaultState(), 2);

		world.setBlockState(pos.add(x + 13, y + 2, z + 7), BlockHandler.ZERG_FLESH.getDefaultState(), 2);

		world.setBlockState(pos.add(x + 17, y + 2, z + 7), BlockHandler.KERATIN_CHUNK.getDefaultState(), 2);
		world.setBlockState(pos.add(x + 0, y + 2, z + 8), BlockHandler.ZERG_FLESH.getDefaultState(), 2);

		world.setBlockState(pos.add(x + 1, y + 2, z + 8), BlockHandler.ZERG_FLESH.getDefaultState(), 2);

		world.setBlockState(pos.add(x + 2, y + 2, z + 8), BlockHandler.ZERG_FLESH.getStateFromMeta(2));
		world.setBlockState(pos.add(x + 3, y + 2, z + 8), BlockHandler.ZERG_FLESH.getStateFromMeta(2));
		world.setBlockState(pos.add(x + 4, y + 2, z + 8), BlockHandler.ZERG_FLESH.getStateFromMeta(2));
		world.setBlockState(pos.add(x + 5, y + 2, z + 8), BlockHandler.ZERG_FLESH.getStateFromMeta(2));
		world.setBlockState(pos.add(x + 6, y + 2, z + 8), BlockHandler.ZERG_FLESH.getStateFromMeta(2));
		world.setBlockState(pos.add(x + 7, y + 2, z + 8), BlockHandler.ZERG_FLESH.getStateFromMeta(2));
		world.setBlockState(pos.add(x + 8, y + 2, z + 8), BlockHandler.ZERG_FLESH.getStateFromMeta(2));
		world.setBlockState(pos.add(x + 9, y + 2, z + 8), BlockHandler.ZERG_FLESH.getStateFromMeta(2));
		world.setBlockState(pos.add(x + 10, y + 2, z + 8), BlockHandler.ZERG_FLESH.getStateFromMeta(2));
		world.setBlockState(pos.add(x + 11, y + 2, z + 8), BlockHandler.ZERG_FLESH.getStateFromMeta(2));
		world.setBlockState(pos.add(x + 12, y + 2, z + 8), BlockHandler.ZERG_FLESH.getDefaultState(), 2);

		world.setBlockState(pos.add(x + 0, y + 2, z + 9), BlockHandler.ZERG_FLESH.getDefaultState(), 2);

		world.setBlockState(pos.add(x + 1, y + 2, z + 9), BlockHandler.ZERG_FLESH.getDefaultState(), 2);

		world.setBlockState(pos.add(x + 2, y + 2, z + 9), BlockHandler.ZERG_FLESH.getStateFromMeta(2));
		world.setBlockState(pos.add(x + 3, y + 2, z + 9), BlockHandler.ZERG_FLESH.getStateFromMeta(2));
		world.setBlockState(pos.add(x + 4, y + 2, z + 9), BlockHandler.ZERG_FLESH.getStateFromMeta(2));
		world.setBlockState(pos.add(x + 5, y + 2, z + 9), BlockHandler.ZERG_FLESH.getStateFromMeta(2));
		world.setBlockState(pos.add(x + 6, y + 2, z + 9), BlockHandler.ZERG_FLESH.getStateFromMeta(2));
		world.setBlockState(pos.add(x + 7, y + 2, z + 9), BlockHandler.ZERG_FLESH.getStateFromMeta(2));
		world.setBlockState(pos.add(x + 8, y + 2, z + 9), BlockHandler.ZERG_FLESH.getStateFromMeta(2));
		world.setBlockState(pos.add(x + 9, y + 2, z + 9), BlockHandler.ZERG_FLESH.getStateFromMeta(2));
		world.setBlockState(pos.add(x + 18, y + 2, z + 9), BlockHandler.KERATIN_CHUNK.getDefaultState(), 2);
		world.setBlockState(pos.add(x + 19, y + 2, z + 9), BlockHandler.ZERG_FLESH.getDefaultState(), 2);

		world.setBlockState(pos.add(x + 0, y + 2, z + 10), BlockHandler.ZERG_FLESH.getDefaultState(), 2);

		world.setBlockState(pos.add(x + 1, y + 2, z + 10), BlockHandler.ZERG_FLESH.getDefaultState(), 2);

		world.setBlockState(pos.add(x + 2, y + 2, z + 10), BlockHandler.ZERG_FLESH.getStateFromMeta(2));
		world.setBlockState(pos.add(x + 3, y + 2, z + 10), BlockHandler.ZERG_FLESH.getStateFromMeta(2));
		world.setBlockState(pos.add(x + 4, y + 2, z + 10), BlockHandler.ZERG_FLESH.getStateFromMeta(2));
		world.setBlockState(pos.add(x + 5, y + 2, z + 10), BlockHandler.ZERG_FLESH.getStateFromMeta(2));
		world.setBlockState(pos.add(x + 18, y + 2, z + 10), BlockHandler.ZERG_FLESH.getDefaultState(), 2);

		world.setBlockState(pos.add(x + 0, y + 2, z + 11), BlockHandler.ZERG_FLESH.getDefaultState(), 2);

		world.setBlockState(pos.add(x + 1, y + 2, z + 11), BlockHandler.ZERG_FLESH.getDefaultState(), 2);

		world.setBlockState(pos.add(x + 2, y + 2, z + 11), BlockHandler.ZERG_FLESH.getStateFromMeta(2));
		world.setBlockState(pos.add(x + 3, y + 2, z + 11), BlockHandler.ZERG_FLESH.getStateFromMeta(2));
		world.setBlockState(pos.add(x + 4, y + 2, z + 11), BlockHandler.ZERG_FLESH.getStateFromMeta(2));
		world.setBlockState(pos.add(x + 5, y + 2, z + 11), BlockHandler.ZERG_FLESH.getStateFromMeta(2));
		world.setBlockState(pos.add(x + 17, y + 2, z + 11), BlockHandler.ZERG_FLESH.getDefaultState(), 2);

		world.setBlockState(pos.add(x + 0, y + 2, z + 12), BlockHandler.ZERG_FLESH.getDefaultState(), 2);

		world.setBlockState(pos.add(x + 1, y + 2, z + 12), BlockHandler.ZERG_FLESH.getDefaultState(), 2);

		world.setBlockState(pos.add(x + 2, y + 2, z + 12), BlockHandler.ZERG_FLESH.getStateFromMeta(2));
		world.setBlockState(pos.add(x + 3, y + 2, z + 12), BlockHandler.ZERG_FLESH.getStateFromMeta(2));
		world.setBlockState(pos.add(x + 4, y + 2, z + 12), BlockHandler.ZERG_FLESH.getStateFromMeta(2));
		world.setBlockState(pos.add(x + 5, y + 2, z + 12), BlockHandler.ZERG_FLESH.getStateFromMeta(2));
		world.setBlockState(pos.add(x + 6, y + 2, z + 12), BlockHandler.ZERG_FLESH.getStateFromMeta(2));
		world.setBlockState(pos.add(x + 16, y + 2, z + 12), BlockHandler.ZERG_FLESH.getDefaultState(), 2);

		world.setBlockState(pos.add(x + 17, y + 2, z + 12), BlockHandler.ZERG_FLESH.getDefaultState(), 2);

		world.setBlockState(pos.add(x + 18, y + 2, z + 12), BlockHandler.ZERG_FLESH.getDefaultState(), 2);

		world.setBlockState(pos.add(x + 0, y + 2, z + 13), BlockHandler.ZERG_FLESH.getDefaultState(), 2);

		world.setBlockState(pos.add(x + 1, y + 2, z + 13), BlockHandler.ZERG_FLESH.getDefaultState(), 2);

		world.setBlockState(pos.add(x + 2, y + 2, z + 13), BlockHandler.ZERG_FLESH.getStateFromMeta(2));
		world.setBlockState(pos.add(x + 3, y + 2, z + 13), BlockHandler.ZERG_FLESH.getStateFromMeta(2));
		world.setBlockState(pos.add(x + 4, y + 2, z + 13), BlockHandler.ZERG_FLESH.getStateFromMeta(2));
		world.setBlockState(pos.add(x + 5, y + 2, z + 13), BlockHandler.ZERG_FLESH.getStateFromMeta(2));
		world.setBlockState(pos.add(x + 6, y + 2, z + 13), BlockHandler.ZERG_FLESH.getStateFromMeta(2));
		world.setBlockState(pos.add(x + 7, y + 2, z + 13), BlockHandler.ZERG_FLESH.getStateFromMeta(2));
		world.setBlockState(pos.add(x + 8, y + 2, z + 13), BlockHandler.ZERG_FLESH.getStateFromMeta(2));
		world.setBlockState(pos.add(x + 9, y + 2, z + 13), BlockHandler.ZERG_FLESH.getStateFromMeta(2));
		world.setBlockState(pos.add(x + 10, y + 2, z + 13), BlockHandler.ZERG_FLESH.getStateFromMeta(2));
		world.setBlockState(pos.add(x + 16, y + 2, z + 13), BlockHandler.ZERG_FLESH.getStateFromMeta(2));
		world.setBlockState(pos.add(x + 17, y + 2, z + 13), BlockHandler.ZERG_FLESH.getStateFromMeta(2));
		world.setBlockState(pos.add(x + 18, y + 2, z + 13), BlockHandler.ZERG_FLESH.getDefaultState(), 2);

		world.setBlockState(pos.add(x + 19, y + 2, z + 13), BlockHandler.ZERG_FLESH.getDefaultState(), 2);

		spawn1(world, rand, offsetX, offsetY, offsetZ, pos);
		return true;
	}

	protected Block[] GetValidSpawnBlocks() {
		return new Block[] { BlockHandler.ZERG_CREEP };
	}

	public boolean LocationIsValidSpawn(World world, BlockPos pos) {

		Block checkBlock = world.getBlockState(pos).getBlock();
		Material m = checkBlock.getDefaultState().getMaterial();
		Block blockAbove = world.getBlockState(pos.up()).getBlock();
		Block blockBelow = world.getBlockState(pos.down()).getBlock();

		for (Block i : GetValidSpawnBlocks()) {
			if (blockAbove != Blocks.AIR) {
				return false;
			}
			if (checkBlock == i) {
				return true;
			} else if (m == Material.PLANTS && blockBelow == i) {
				return true;
			}
		}
		return false;
	}

	public boolean spawn1(World world, Random rand, int offsetX, int offsetY, int offsetZ, BlockPos pos) {
		int x = offsetX;
		int y = offsetY;
		int z = offsetZ;
		world.setBlockState(pos.add(x + 1, y + 2, z + 14), BlockHandler.ZERG_FLESH.getDefaultState(), 2);

		world.setBlockState(pos.add(x + 2, y + 2, z + 14), BlockHandler.ZERG_FLESH.getDefaultState(), 2);

		world.setBlockState(pos.add(x + 3, y + 2, z + 14), BlockHandler.ZERG_FLESH.getStateFromMeta(2));
		world.setBlockState(pos.add(x + 4, y + 2, z + 14), BlockHandler.ZERG_FLESH.getStateFromMeta(2));
		world.setBlockState(pos.add(x + 5, y + 2, z + 14), BlockHandler.ZERG_FLESH.getStateFromMeta(2));
		world.setBlockState(pos.add(x + 6, y + 2, z + 14), BlockHandler.ZERG_FLESH.getStateFromMeta(2));
		world.setBlockState(pos.add(x + 7, y + 2, z + 14), BlockHandler.ZERG_FLESH.getStateFromMeta(2));
		world.setBlockState(pos.add(x + 8, y + 2, z + 14), BlockHandler.ZERG_FLESH.getStateFromMeta(2));
		world.setBlockState(pos.add(x + 9, y + 2, z + 14), BlockHandler.ZERG_FLESH.getStateFromMeta(2));
		world.setBlockState(pos.add(x + 10, y + 2, z + 14), BlockHandler.ZERG_FLESH.getStateFromMeta(2));
		world.setBlockState(pos.add(x + 11, y + 2, z + 14), BlockHandler.ZERG_FLESH.getStateFromMeta(2));
		world.setBlockState(pos.add(x + 16, y + 2, z + 14), BlockHandler.ZERG_FLESH.getStateFromMeta(2));
		world.setBlockState(pos.add(x + 17, y + 2, z + 14), BlockHandler.ZERG_FLESH.getStateFromMeta(2));
		world.setBlockState(pos.add(x + 18, y + 2, z + 14), BlockHandler.ZERG_FLESH.getStateFromMeta(2));
		world.setBlockState(pos.add(x + 19, y + 2, z + 14), BlockHandler.ZERG_FLESH.getDefaultState(), 2);

		world.setBlockState(pos.add(x + 20, y + 2, z + 14), BlockHandler.ZERG_FLESH.getStateFromMeta(1), 2);

		world.setBlockState(pos.add(x + 1, y + 2, z + 15), BlockHandler.ZERG_FLESH.getDefaultState(), 2);

		world.setBlockState(pos.add(x + 2, y + 2, z + 15), BlockHandler.ZERG_FLESH.getDefaultState(), 2);

		world.setBlockState(pos.add(x + 3, y + 2, z + 15), BlockHandler.ZERG_FLESH.getStateFromMeta(2));
		world.setBlockState(pos.add(x + 4, y + 2, z + 15), BlockHandler.ZERG_FLESH.getStateFromMeta(2));
		world.setBlockState(pos.add(x + 5, y + 2, z + 15), BlockHandler.ZERG_FLESH.getStateFromMeta(2));
		world.setBlockState(pos.add(x + 6, y + 2, z + 15), BlockHandler.ZERG_FLESH.getStateFromMeta(2));
		world.setBlockState(pos.add(x + 7, y + 2, z + 15), BlockHandler.ZERG_FLESH.getStateFromMeta(2));
		world.setBlockState(pos.add(x + 8, y + 2, z + 15), BlockHandler.ZERG_FLESH.getStateFromMeta(2));
		world.setBlockState(pos.add(x + 9, y + 2, z + 15), BlockHandler.ZERG_FLESH.getStateFromMeta(2));
		world.setBlockState(pos.add(x + 10, y + 2, z + 15), BlockHandler.ZERG_FLESH.getStateFromMeta(2));
		world.setBlockState(pos.add(x + 11, y + 2, z + 15), BlockHandler.ZERG_FLESH.getStateFromMeta(2));
		world.setBlockState(pos.add(x + 15, y + 2, z + 15), BlockHandler.ZERG_FLESH.getStateFromMeta(2));
		world.setBlockState(pos.add(x + 16, y + 2, z + 15), BlockHandler.ZERG_FLESH.getStateFromMeta(2));
		world.setBlockState(pos.add(x + 17, y + 2, z + 15), BlockHandler.ZERG_FLESH.getStateFromMeta(2));
		world.setBlockState(pos.add(x + 18, y + 2, z + 15), BlockHandler.ZERG_FLESH.getDefaultState(), 2);

		world.setBlockState(pos.add(x + 19, y + 2, z + 15), BlockHandler.ZERG_FLESH.getStateFromMeta(1), 2);

		world.setBlockState(pos.add(x + 1, y + 2, z + 16), BlockHandler.ZERG_FLESH.getDefaultState(), 2);

		world.setBlockState(pos.add(x + 2, y + 2, z + 16), BlockHandler.ZERG_FLESH.getDefaultState(), 2);

		world.setBlockState(pos.add(x + 3, y + 2, z + 16), BlockHandler.ZERG_FLESH.getStateFromMeta(2));
		world.setBlockState(pos.add(x + 4, y + 2, z + 16), BlockHandler.ZERG_FLESH.getStateFromMeta(2));
		world.setBlockState(pos.add(x + 5, y + 2, z + 16), BlockHandler.ZERG_FLESH.getStateFromMeta(2));
		world.setBlockState(pos.add(x + 6, y + 2, z + 16), BlockHandler.ZERG_FLESH.getStateFromMeta(2));
		world.setBlockState(pos.add(x + 7, y + 2, z + 16), BlockHandler.ZERG_FLESH.getStateFromMeta(2));
		world.setBlockState(pos.add(x + 8, y + 2, z + 16), BlockHandler.ZERG_FLESH.getStateFromMeta(2));
		world.setBlockState(pos.add(x + 9, y + 2, z + 16), BlockHandler.ZERG_FLESH.getStateFromMeta(2));
		world.setBlockState(pos.add(x + 10, y + 2, z + 16), BlockHandler.ZERG_FLESH.getStateFromMeta(2));
		world.setBlockState(pos.add(x + 11, y + 2, z + 16), BlockHandler.ZERG_FLESH.getStateFromMeta(2));
		world.setBlockState(pos.add(x + 15, y + 2, z + 16), BlockHandler.ZERG_FLESH.getStateFromMeta(2));
		world.setBlockState(pos.add(x + 16, y + 2, z + 16), BlockHandler.ZERG_FLESH.getStateFromMeta(2));
		world.setBlockState(pos.add(x + 17, y + 2, z + 16), BlockHandler.ZERG_FLESH.getStateFromMeta(2));
		world.setBlockState(pos.add(x + 18, y + 2, z + 16), BlockHandler.ZERG_FLESH.getDefaultState(), 2);

		world.setBlockState(pos.add(x + 19, y + 2, z + 16), BlockHandler.ZERG_FLESH.getStateFromMeta(1), 2);

		world.setBlockState(pos.add(x + 22, y + 2, z + 16), BlockHandler.ZERG_FLESH.getStateFromMeta(1), 2);

		world.setBlockState(pos.add(x + 1, y + 2, z + 17), BlockHandler.ZERG_FLESH.getDefaultState(), 2);

		world.setBlockState(pos.add(x + 2, y + 2, z + 17), BlockHandler.ZERG_FLESH.getDefaultState(), 2);

		world.setBlockState(pos.add(x + 3, y + 2, z + 17), BlockHandler.ZERG_FLESH.getStateFromMeta(2));
		world.setBlockState(pos.add(x + 4, y + 2, z + 17), BlockHandler.ZERG_FLESH.getStateFromMeta(2));
		world.setBlockState(pos.add(x + 5, y + 2, z + 17), BlockHandler.ZERG_FLESH.getStateFromMeta(2));
		world.setBlockState(pos.add(x + 6, y + 2, z + 17), BlockHandler.ZERG_FLESH.getStateFromMeta(2));
		world.setBlockState(pos.add(x + 7, y + 2, z + 17), BlockHandler.ZERG_FLESH.getStateFromMeta(2));
		world.setBlockState(pos.add(x + 8, y + 2, z + 17), BlockHandler.ZERG_FLESH.getStateFromMeta(2));
		world.setBlockState(pos.add(x + 9, y + 2, z + 17), BlockHandler.ZERG_FLESH.getStateFromMeta(2));
		world.setBlockState(pos.add(x + 10, y + 2, z + 17), BlockHandler.ZERG_FLESH.getStateFromMeta(2));
		world.setBlockState(pos.add(x + 11, y + 2, z + 17), BlockHandler.ZERG_FLESH.getStateFromMeta(2));
		world.setBlockState(pos.add(x + 15, y + 2, z + 17), BlockHandler.ZERG_FLESH.getStateFromMeta(2));
		world.setBlockState(pos.add(x + 16, y + 2, z + 17), BlockHandler.ZERG_FLESH.getStateFromMeta(2));
		world.setBlockState(pos.add(x + 17, y + 2, z + 17), BlockHandler.ZERG_FLESH.getDefaultState(), 2);

		world.setBlockState(pos.add(x + 18, y + 2, z + 17), BlockHandler.ZERG_FLESH.getDefaultState(), 2);

		world.setBlockState(pos.add(x + 19, y + 2, z + 17), BlockHandler.ZERG_FLESH.getDefaultState(), 2);

		world.setBlockState(pos.add(x + 20, y + 2, z + 17), BlockHandler.ZERG_FLESH.getStateFromMeta(1), 2);

		world.setBlockState(pos.add(x + 21, y + 2, z + 17), BlockHandler.ZERG_FLESH.getStateFromMeta(1), 2);

		world.setBlockState(pos.add(x + 22, y + 2, z + 17), BlockHandler.ZERG_FLESH.getDefaultState(), 2);

		world.setBlockState(pos.add(x + 2, y + 2, z + 18), BlockHandler.ZERG_FLESH.getDefaultState(), 2);

		world.setBlockState(pos.add(x + 3, y + 2, z + 18), BlockHandler.ZERG_FLESH.getStateFromMeta(2));
		world.setBlockState(pos.add(x + 4, y + 2, z + 18), BlockHandler.ZERG_FLESH.getStateFromMeta(2));
		world.setBlockState(pos.add(x + 5, y + 2, z + 18), BlockHandler.ZERG_FLESH.getStateFromMeta(2));
		world.setBlockState(pos.add(x + 6, y + 2, z + 18), BlockHandler.ZERG_FLESH.getStateFromMeta(2));
		world.setBlockState(pos.add(x + 7, y + 2, z + 18), BlockHandler.ZERG_FLESH.getStateFromMeta(2));
		world.setBlockState(pos.add(x + 8, y + 2, z + 18), BlockHandler.ZERG_FLESH.getStateFromMeta(2));
		world.setBlockState(pos.add(x + 9, y + 2, z + 18), BlockHandler.ZERG_FLESH.getStateFromMeta(2));
		world.setBlockState(pos.add(x + 10, y + 2, z + 18), BlockHandler.ZERG_FLESH.getStateFromMeta(2));
		world.setBlockState(pos.add(x + 11, y + 2, z + 18), BlockHandler.ZERG_FLESH.getStateFromMeta(2));
		world.setBlockState(pos.add(x + 12, y + 2, z + 18), BlockHandler.ZERG_FLESH.getStateFromMeta(2));
		world.setBlockState(pos.add(x + 15, y + 2, z + 18), BlockHandler.ZERG_FLESH.getStateFromMeta(2));
		world.setBlockState(pos.add(x + 16, y + 2, z + 18), BlockHandler.ZERG_FLESH.getStateFromMeta(2));
		world.setBlockState(pos.add(x + 17, y + 2, z + 18), BlockHandler.ZERG_FLESH.getStateFromMeta(2));
		world.setBlockState(pos.add(x + 18, y + 2, z + 18), BlockHandler.ZERG_FLESH.getStateFromMeta(2));
		world.setBlockState(pos.add(x + 19, y + 2, z + 18), BlockHandler.ZERG_FLESH.getStateFromMeta(2));
		world.setBlockState(pos.add(x + 20, y + 2, z + 18), BlockHandler.ZERG_FLESH.getDefaultState(), 2);

		world.setBlockState(pos.add(x + 21, y + 2, z + 18), BlockHandler.ZERG_FLESH.getDefaultState(), 2);

		world.setBlockState(pos.add(x + 22, y + 2, z + 18), BlockHandler.ZERG_FLESH.getDefaultState(), 2);

		world.setBlockState(pos.add(x + 23, y + 2, z + 18), BlockHandler.ZERG_FLESH.getDefaultState(), 2);

		world.setBlockState(pos.add(x + 3, y + 2, z + 19), BlockHandler.ZERG_FLESH.getDefaultState(), 2);

		world.setBlockState(pos.add(x + 4, y + 2, z + 19), BlockHandler.ZERG_FLESH.getStateFromMeta(2));
		world.setBlockState(pos.add(x + 5, y + 2, z + 19), BlockHandler.ZERG_FLESH.getStateFromMeta(2));
		world.setBlockState(pos.add(x + 6, y + 2, z + 19), BlockHandler.ZERG_FLESH.getStateFromMeta(2));
		world.setBlockState(pos.add(x + 7, y + 2, z + 19), BlockHandler.ZERG_FLESH.getStateFromMeta(2));
		world.setBlockState(pos.add(x + 8, y + 2, z + 19), BlockHandler.ZERG_FLESH.getStateFromMeta(2));
		world.setBlockState(pos.add(x + 9, y + 2, z + 19), BlockHandler.ZERG_FLESH.getStateFromMeta(2));
		world.setBlockState(pos.add(x + 10, y + 2, z + 19), BlockHandler.ZERG_FLESH.getStateFromMeta(2));
		world.setBlockState(pos.add(x + 11, y + 2, z + 19), BlockHandler.ZERG_FLESH.getStateFromMeta(2));
		world.setBlockState(pos.add(x + 12, y + 2, z + 19), BlockHandler.ZERG_FLESH.getStateFromMeta(2));
		world.setBlockState(pos.add(x + 13, y + 2, z + 19), BlockHandler.ZERG_FLESH.getStateFromMeta(2));
		world.setBlockState(pos.add(x + 15, y + 2, z + 19), BlockHandler.ZERG_FLESH.getStateFromMeta(2));
		world.setBlockState(pos.add(x + 16, y + 2, z + 19), BlockHandler.ZERG_FLESH.getStateFromMeta(2));
		world.setBlockState(pos.add(x + 17, y + 2, z + 19), BlockHandler.ZERG_FLESH.getStateFromMeta(2));
		world.setBlockState(pos.add(x + 18, y + 2, z + 19), BlockHandler.ZERG_FLESH.getStateFromMeta(2));
		world.setBlockState(pos.add(x + 19, y + 2, z + 19), BlockHandler.ZERG_FLESH.getStateFromMeta(2));
		world.setBlockState(pos.add(x + 20, y + 2, z + 19), BlockHandler.ZERG_FLESH.getStateFromMeta(2));
		world.setBlockState(pos.add(x + 21, y + 2, z + 19), BlockHandler.ZERG_FLESH.getStateFromMeta(2));
		world.setBlockState(pos.add(x + 22, y + 2, z + 19), BlockHandler.ZERG_FLESH.getDefaultState(), 2);

		world.setBlockState(pos.add(x + 23, y + 2, z + 19), BlockHandler.ZERG_FLESH.getDefaultState(), 2);

		world.setBlockState(pos.add(x + 4, y + 2, z + 20), BlockHandler.ZERG_FLESH.getDefaultState(), 2);

		world.setBlockState(pos.add(x + 5, y + 2, z + 20), BlockHandler.ZERG_FLESH.getStateFromMeta(2));
		world.setBlockState(pos.add(x + 6, y + 2, z + 20), BlockHandler.ZERG_FLESH.getStateFromMeta(2));
		world.setBlockState(pos.add(x + 7, y + 2, z + 20), BlockHandler.ZERG_FLESH.getStateFromMeta(2));
		world.setBlockState(pos.add(x + 8, y + 2, z + 20), BlockHandler.ZERG_FLESH.getStateFromMeta(2));
		world.setBlockState(pos.add(x + 9, y + 2, z + 20), BlockHandler.ZERG_FLESH.getStateFromMeta(2));
		world.setBlockState(pos.add(x + 10, y + 2, z + 20), BlockHandler.ZERG_FLESH.getStateFromMeta(2));
		world.setBlockState(pos.add(x + 11, y + 2, z + 20), BlockHandler.ZERG_FLESH.getStateFromMeta(2));
		world.setBlockState(pos.add(x + 12, y + 2, z + 20), BlockHandler.ZERG_FLESH.getStateFromMeta(2));
		world.setBlockState(pos.add(x + 13, y + 2, z + 20), BlockHandler.ZERG_FLESH.getStateFromMeta(2));
		world.setBlockState(pos.add(x + 14, y + 2, z + 20), BlockHandler.ZERG_FLESH.getStateFromMeta(2));
		world.setBlockState(pos.add(x + 15, y + 2, z + 20), BlockHandler.ZERG_FLESH.getStateFromMeta(2));
