package com.hypeirochus.scmc.worldgen.structure;

import java.util.Random;

import com.hypeirochus.scmc.handlers.BlockHandler;
import com.hypeirochus.scmc.handlers.BlockHandler;

import net.minecraft.block.Block;
import net.minecraft.block.BlockStainedGlass;
import net.minecraft.block.BlockStairs;
import net.minecraft.block.material.Material;
import net.minecraft.block.state.IBlockState;
import net.minecraft.init.Blocks;
import net.minecraft.item.EnumDyeColor;
import net.minecraft.util.EnumFacing;
import net.minecraft.util.math.BlockPos;
import net.minecraft.world.World;

/**
 * @author SoggyMustache's Structure Converter
 *         (http://soggymustache.net/tools.html)
 */
public class StructureTerranCommandCenterTemplate extends SCWorldGenerator {

	@Override
	public boolean generate(World world, Random rand, int offsetX, int offsetY, int offsetZ, BlockPos pos, boolean flag) {
		generate(world, pos, flag);
		return true;
	}

	public boolean generate(World worldIn, BlockPos bp, boolean flag) {
		if (flag) {
			if (!LocationIsValidSpawn(worldIn, bp) || !LocationIsValidSpawn(worldIn, bp.add(26, 0, 0)) || !LocationIsValidSpawn(worldIn, bp.add(26, 0, 27)) || !LocationIsValidSpawn(worldIn, bp.add(0, 0, 27))) {
				return false;
			}
		}
		int k = 0;
		int i = 0;
		int j = 0;
		worldIn.setBlockState(bp.add(i + 0, j + 1, k + 3), BlockHandler.PARISTEEL_METAL.getStateFromMeta(5));
		worldIn.setBlockState(bp.add(i + 0, j + 1, k + 4), BlockHandler.PARISTEEL_METAL.getStateFromMeta(5));
		worldIn.setBlockState(bp.add(i + 0, j + 1, k + 5), BlockHandler.PARISTEEL_METAL.getStateFromMeta(5));
		worldIn.setBlockState(bp.add(i + 0, j + 1, k + 23), BlockHandler.PARISTEEL_METAL.getStateFromMeta(5));
		worldIn.setBlockState(bp.add(i + 0, j + 1, k + 24), BlockHandler.PARISTEEL_METAL.getStateFromMeta(5));
		worldIn.setBlockState(bp.add(i + 0, j + 1, k + 25), BlockHandler.PARISTEEL_METAL.getStateFromMeta(5));
		worldIn.setBlockState(bp.add(i + 0, j + 3, k + 12), BlockHandler.PARISTEEL_METAL.getStateFromMeta(15));
		worldIn.setBlockState(bp.add(i + 0, j + 3, k + 13), BlockHandler.PARISTEEL_METAL.getStateFromMeta(15));
		worldIn.setBlockState(bp.add(i + 0, j + 3, k + 14), BlockHandler.PARISTEEL_METAL.getStateFromMeta(15));
		worldIn.setBlockState(bp.add(i + 0, j + 3, k + 15), BlockHandler.PARISTEEL_METAL.getStateFromMeta(15));
		worldIn.setBlockState(bp.add(i + 0, j + 3, k + 16), BlockHandler.PARISTEEL_METAL.getStateFromMeta(15));
		worldIn.setBlockState(bp.add(i + 0, j + 4, k + 12), BlockHandler.PARISTEEL_METAL.getStateFromMeta(15));
		worldIn.setBlockState(bp.add(i + 0, j + 4, k + 13), BlockHandler.PARISTEEL_METAL.getStateFromMeta(15));
		worldIn.setBlockState(bp.add(i + 0, j + 4, k + 14), BlockHandler.PARISTEEL_METAL.getStateFromMeta(15));
		worldIn.setBlockState(bp.add(i + 0, j + 4, k + 15), BlockHandler.PARISTEEL_METAL.getStateFromMeta(15));
		worldIn.setBlockState(bp.add(i + 0, j + 4, k + 16), BlockHandler.PARISTEEL_METAL.getStateFromMeta(15));
		worldIn.setBlockState(bp.add(i + 0, j + 5, k + 12), BlockHandler.PARISTEEL_METAL.getStateFromMeta(15));
		worldIn.setBlockState(bp.add(i + 0, j + 5, k + 13), BlockHandler.PARISTEEL_METAL.getStateFromMeta(15));
		worldIn.setBlockState(bp.add(i + 0, j + 5, k + 14), BlockHandler.PARISTEEL_METAL.getStateFromMeta(15));
		worldIn.setBlockState(bp.add(i + 0, j + 5, k + 15), BlockHandler.PARISTEEL_METAL.getStateFromMeta(15));
		worldIn.setBlockState(bp.add(i + 0, j + 5, k + 16), BlockHandler.PARISTEEL_METAL.getStateFromMeta(15));
		worldIn.setBlockState(bp.add(i + 0, j + 6, k + 12), BlockHandler.PARISTEEL_METAL.getStateFromMeta(15));
		worldIn.setBlockState(bp.add(i + 0, j + 6, k + 13), BlockHandler.PARISTEEL_METAL.getStateFromMeta(15));
		worldIn.setBlockState(bp.add(i + 0, j + 6, k + 14), BlockHandler.PARISTEEL_METAL.getStateFromMeta(15));
		worldIn.setBlockState(bp.add(i + 0, j + 6, k + 15), BlockHandler.PARISTEEL_METAL.getStateFromMeta(15));
		worldIn.setBlockState(bp.add(i + 0, j + 6, k + 16), BlockHandler.PARISTEEL_METAL.getStateFromMeta(15));
		worldIn.setBlockState(bp.add(i + 0, j + 7, k + 12), BlockHandler.PARISTEEL_METAL.getStateFromMeta(15));
		worldIn.setBlockState(bp.add(i + 0, j + 7, k + 13), BlockHandler.PARISTEEL_METAL.getStateFromMeta(15));
		worldIn.setBlockState(bp.add(i + 0, j + 7, k + 14), BlockHandler.PARISTEEL_METAL.getStateFromMeta(15));
		worldIn.setBlockState(bp.add(i + 0, j + 7, k + 15), BlockHandler.PARISTEEL_METAL.getStateFromMeta(15));
		worldIn.setBlockState(bp.add(i + 0, j + 7, k + 16), BlockHandler.PARISTEEL_METAL.getStateFromMeta(15));
		worldIn.setBlockState(bp.add(i + 1, j + 1, k + 3), BlockHandler.PARISTEEL_METAL.getStateFromMeta(5));
		worldIn.setBlockState(bp.add(i + 1, j + 1, k + 4), BlockHandler.PARISTEEL_METAL.getStateFromMeta(5));
		worldIn.setBlockState(bp.add(i + 1, j + 1, k + 5), BlockHandler.PARISTEEL_METAL.getStateFromMeta(5));
		worldIn.setBlockState(bp.add(i + 1, j + 1, k + 23), BlockHandler.PARISTEEL_METAL.getStateFromMeta(5));
		worldIn.setBlockState(bp.add(i + 1, j + 1, k + 24), BlockHandler.PARISTEEL_METAL.getStateFromMeta(5));
		worldIn.setBlockState(bp.add(i + 1, j + 1, k + 25), BlockHandler.PARISTEEL_METAL.getStateFromMeta(5));
		worldIn.setBlockState(bp.add(i + 1, j + 2, k + 3), BlockHandler.PARISTEEL_METAL.getStateFromMeta(5));
		worldIn.setBlockState(bp.add(i + 1, j + 2, k + 4), BlockHandler.PARISTEEL_METAL.getStateFromMeta(5));
		worldIn.setBlockState(bp.add(i + 1, j + 2, k + 5), BlockHandler.PARISTEEL_METAL.getStateFromMeta(5));
		worldIn.setBlockState(bp.add(i + 1, j + 2, k + 12), BlockHandler.PARISTEEL_METAL.getStateFromMeta(5));
		worldIn.setBlockState(bp.add(i + 1, j + 2, k + 13), BlockHandler.PARISTEEL_METAL.getStateFromMeta(5));
		worldIn.setBlockState(bp.add(i + 1, j + 2, k + 14), BlockHandler.PARISTEEL_METAL.getStateFromMeta(5));
		worldIn.setBlockState(bp.add(i + 1, j + 2, k + 15), BlockHandler.PARISTEEL_METAL.getStateFromMeta(5));
		worldIn.setBlockState(bp.add(i + 1, j + 2, k + 16), BlockHandler.PARISTEEL_METAL.getStateFromMeta(5));
		worldIn.setBlockState(bp.add(i + 1, j + 2, k + 23), BlockHandler.PARISTEEL_METAL.getStateFromMeta(5));
		worldIn.setBlockState(bp.add(i + 1, j + 2, k + 24), BlockHandler.PARISTEEL_METAL.getStateFromMeta(5));
		worldIn.setBlockState(bp.add(i + 1, j + 2, k + 25), BlockHandler.PARISTEEL_METAL.getStateFromMeta(5));
		worldIn.setBlockState(bp.add(i + 1, j + 3, k + 10), BlockHandler.PARISTEEL_METAL.getStateFromMeta(5));
		worldIn.setBlockState(bp.add(i + 1, j + 3, k + 11), BlockHandler.PARISTEEL_METAL.getStateFromMeta(5));
		worldIn.setBlockState(bp.add(i + 1, j + 3, k + 12), BlockHandler.PARISTEEL_METAL.getStateFromMeta(5));
		worldIn.setBlockState(bp.add(i + 1, j + 3, k + 13), BlockHandler.PARISTEEL_METAL.getStateFromMeta(5));
		worldIn.setBlockState(bp.add(i + 1, j + 3, k + 14), BlockHandler.PARISTEEL_METAL.getStateFromMeta(5));
		worldIn.setBlockState(bp.add(i + 1, j + 3, k + 15), BlockHandler.PARISTEEL_METAL.getStateFromMeta(5));
		worldIn.setBlockState(bp.add(i + 1, j + 3, k + 16), BlockHandler.PARISTEEL_METAL.getStateFromMeta(5));
		worldIn.setBlockState(bp.add(i + 1, j + 3, k + 17), BlockHandler.PARISTEEL_METAL.getStateFromMeta(5));
		worldIn.setBlockState(bp.add(i + 1, j + 3, k + 18), BlockHandler.PARISTEEL_METAL.getStateFromMeta(5));
		worldIn.setBlockState(bp.add(i + 1, j + 4, k + 10), BlockHandler.PARISTEEL_METAL.getStateFromMeta(5));
		worldIn.setBlockState(bp.add(i + 1, j + 4, k + 11), BlockHandler.PARISTEEL_METAL.getStateFromMeta(5));
		worldIn.setBlockState(bp.add(i + 1, j + 4, k + 12), BlockHandler.PARISTEEL_METAL.getStateFromMeta(5));
		worldIn.setBlockState(bp.add(i + 1, j + 4, k + 13), BlockHandler.PARISTEEL_METAL.getStateFromMeta(5));
		worldIn.setBlockState(bp.add(i + 1, j + 4, k + 14), BlockHandler.PARISTEEL_METAL.getStateFromMeta(5));
		worldIn.setBlockState(bp.add(i + 1, j + 4, k + 15), BlockHandler.PARISTEEL_METAL.getStateFromMeta(5));
		worldIn.setBlockState(bp.add(i + 1, j + 4, k + 16), BlockHandler.PARISTEEL_METAL.getStateFromMeta(5));
		worldIn.setBlockState(bp.add(i + 1, j + 4, k + 17), BlockHandler.PARISTEEL_METAL.getStateFromMeta(5));
		worldIn.setBlockState(bp.add(i + 1, j + 4, k + 18), BlockHandler.PARISTEEL_METAL.getStateFromMeta(5));
		worldIn.setBlockState(bp.add(i + 1, j + 5, k + 10), BlockHandler.PARISTEEL_METAL.getStateFromMeta(5));
		worldIn.setBlockState(bp.add(i + 1, j + 5, k + 11), BlockHandler.PARISTEEL_METAL.getStateFromMeta(5));
		worldIn.setBlockState(bp.add(i + 1, j + 5, k + 12), BlockHandler.PARISTEEL_METAL.getStateFromMeta(5));
		worldIn.setBlockState(bp.add(i + 1, j + 5, k + 13), BlockHandler.PARISTEEL_METAL.getStateFromMeta(5));
		worldIn.setBlockState(bp.add(i + 1, j + 5, k + 14), BlockHandler.PARISTEEL_METAL.getStateFromMeta(5));
		worldIn.setBlockState(bp.add(i + 1, j + 5, k + 15), BlockHandler.PARISTEEL_METAL.getStateFromMeta(5));
		worldIn.setBlockState(bp.add(i + 1, j + 5, k + 16), BlockHandler.PARISTEEL_METAL.getStateFromMeta(5));
		worldIn.setBlockState(bp.add(i + 1, j + 5, k + 17), BlockHandler.PARISTEEL_METAL.getStateFromMeta(5));
		worldIn.setBlockState(bp.add(i + 1, j + 5, k + 18), BlockHandler.PARISTEEL_METAL.getStateFromMeta(5));
		worldIn.setBlockState(bp.add(i + 1, j + 6, k + 10), BlockHandler.PARISTEEL_METAL.getStateFromMeta(5));
		worldIn.setBlockState(bp.add(i + 1, j + 6, k + 11), BlockHandler.PARISTEEL_METAL.getStateFromMeta(5));
		worldIn.setBlockState(bp.add(i + 1, j + 6, k + 12), BlockHandler.PARISTEEL_METAL.getStateFromMeta(5));
		worldIn.setBlockState(bp.add(i + 1, j + 6, k + 13), BlockHandler.PARISTEEL_METAL.getStateFromMeta(5));
		worldIn.setBlockState(bp.add(i + 1, j + 6, k + 14), BlockHandler.PARISTEEL_METAL.getStateFromMeta(5));
		worldIn.setBlockState(bp.add(i + 1, j + 6, k + 15), BlockHandler.PARISTEEL_METAL.getStateFromMeta(5));
		worldIn.setBlockState(bp.add(i + 1, j + 6, k + 16), BlockHandler.PARISTEEL_METAL.getStateFromMeta(5));
		worldIn.setBlockState(bp.add(i + 1, j + 6, k + 17), BlockHandler.PARISTEEL_METAL.getStateFromMeta(5));
		worldIn.setBlockState(bp.add(i + 1, j + 6, k + 18), BlockHandler.PARISTEEL_METAL.getStateFromMeta(5));
		worldIn.setBlockState(bp.add(i + 1, j + 7, k + 12), BlockHandler.PARISTEEL_METAL.getStateFromMeta(5));
		worldIn.setBlockState(bp.add(i + 1, j + 7, k + 13), BlockHandler.PARISTEEL_METAL.getStateFromMeta(5));
		worldIn.setBlockState(bp.add(i + 1, j + 7, k + 14), BlockHandler.PARISTEEL_METAL.getStateFromMeta(5));
		worldIn.setBlockState(bp.add(i + 1, j + 7, k + 15), BlockHandler.PARISTEEL_METAL.getStateFromMeta(5));
		worldIn.setBlockState(bp.add(i + 1, j + 7, k + 16), BlockHandler.PARISTEEL_METAL.getStateFromMeta(5));
		worldIn.setBlockState(bp.add(i + 1, j + 8, k + 12), BlockHandler.PARISTEEL_METAL.getStateFromMeta(15));
		worldIn.setBlockState(bp.add(i + 1, j + 8, k + 13), BlockHandler.PARISTEEL_METAL.getStateFromMeta(5));
		worldIn.setBlockState(bp.add(i + 1, j + 8, k + 14), BlockHandler.PARISTEEL_METAL.getStateFromMeta(5));
		worldIn.setBlockState(bp.add(i + 1, j + 8, k + 15), BlockHandler.PARISTEEL_METAL.getStateFromMeta(5));
		worldIn.setBlockState(bp.add(i + 1, j + 8, k + 16), BlockHandler.PARISTEEL_METAL.getStateFromMeta(15));
		worldIn.setBlockState(bp.add(i + 1, j + 9, k + 12), BlockHandler.PARISTEEL_METAL.getStateFromMeta(15));
		worldIn.setBlockState(bp.add(i + 1, j + 9, k + 13), BlockHandler.PARISTEEL_METAL.getStateFromMeta(5));
		worldIn.setBlockState(bp.add(i + 1, j + 9, k + 14), BlockHandler.PARISTEEL_METAL.getStateFromMeta(5));
		worldIn.setBlockState(bp.add(i + 1, j + 9, k + 15), BlockHandler.PARISTEEL_METAL.getStateFromMeta(5));
		worldIn.setBlockState(bp.add(i + 1, j + 9, k + 16), BlockHandler.PARISTEEL_METAL.getStateFromMeta(15));
		worldIn.setBlockState(bp.add(i + 2, j + 1, k + 1), BlockHandler.PARISTEEL_METAL.getStateFromMeta(5));
		worldIn.setBlockState(bp.add(i + 2, j + 1, k + 2), BlockHandler.PARISTEEL_METAL.getStateFromMeta(5));
		worldIn.setBlockState(bp.add(i + 2, j + 1, k + 3), BlockHandler.PARISTEEL_METAL.getStateFromMeta(5));
		worldIn.setBlockState(bp.add(i + 2, j + 1, k + 4), BlockHandler.PARISTEEL_METAL.getStateFromMeta(5));
		worldIn.setBlockState(bp.add(i + 2, j + 1, k + 5), BlockHandler.PARISTEEL_METAL.getStateFromMeta(5));
		worldIn.setBlockState(bp.add(i + 2, j + 1, k + 6), BlockHandler.PARISTEEL_METAL.getStateFromMeta(5));
		worldIn.setBlockState(bp.add(i + 2, j + 1, k + 7), BlockHandler.PARISTEEL_METAL.getStateFromMeta(5));
		worldIn.setBlockState(bp.add(i + 2, j + 1, k + 12), BlockHandler.PARISTEEL_METAL.getStateFromMeta(5));
		worldIn.setBlockState(bp.add(i + 2, j + 1, k + 13), BlockHandler.PARISTEEL_METAL.getStateFromMeta(5));
		worldIn.setBlockState(bp.add(i + 2, j + 1, k + 14), BlockHandler.PARISTEEL_METAL.getStateFromMeta(5));
		worldIn.setBlockState(bp.add(i + 2, j + 1, k + 15), BlockHandler.PARISTEEL_METAL.getStateFromMeta(5));
		worldIn.setBlockState(bp.add(i + 2, j + 1, k + 16), BlockHandler.PARISTEEL_METAL.getStateFromMeta(5));
		worldIn.setBlockState(bp.add(i + 2, j + 1, k + 21), BlockHandler.PARISTEEL_METAL.getStateFromMeta(5));
		worldIn.setBlockState(bp.add(i + 2, j + 1, k + 22), BlockHandler.PARISTEEL_METAL.getStateFromMeta(5));
		worldIn.setBlockState(bp.add(i + 2, j + 1, k + 23), BlockHandler.PARISTEEL_METAL.getStateFromMeta(5));
		worldIn.setBlockState(bp.add(i + 2, j + 1, k + 24), BlockHandler.PARISTEEL_METAL.getStateFromMeta(5));
		worldIn.setBlockState(bp.add(i + 2, j + 1, k + 25), BlockHandler.PARISTEEL_METAL.getStateFromMeta(5));
		worldIn.setBlockState(bp.add(i + 2, j + 1, k + 26), BlockHandler.PARISTEEL_METAL.getStateFromMeta(5));
		worldIn.setBlockState(bp.add(i + 2, j + 1, k + 27), BlockHandler.PARISTEEL_METAL.getStateFromMeta(5));
		worldIn.setBlockState(bp.add(i + 2, j + 2, k + 2), BlockHandler.PARISTEEL_METAL.getStateFromMeta(5));
		worldIn.setBlockState(bp.add(i + 2, j + 2, k + 3), BlockHandler.PARISTEEL_METAL.getStateFromMeta(5));
		worldIn.setBlockState(bp.add(i + 2, j + 2, k + 4), BlockHandler.PARISTEEL_METAL.getStateFromMeta(5));
		worldIn.setBlockState(bp.add(i + 2, j + 2, k + 5), BlockHandler.PARISTEEL_METAL.getStateFromMeta(5));
		worldIn.setBlockState(bp.add(i + 2, j + 2, k + 6), BlockHandler.PARISTEEL_METAL.getStateFromMeta(5));
		worldIn.setBlockState(bp.add(i + 2, j + 2, k + 10), BlockHandler.PARISTEEL_METAL.getStateFromMeta(5));
		worldIn.setBlockState(bp.add(i + 2, j + 2, k + 11), BlockHandler.PARISTEEL_METAL.getStateFromMeta(5));
		worldIn.setBlockState(bp.add(i + 2, j + 2, k + 12), BlockHandler.PARISTEEL_METAL.getStateFromMeta(5));
		worldIn.setBlockState(bp.add(i + 2, j + 2, k + 13), BlockHandler.PARISTEEL_METAL.getStateFromMeta(5));
		worldIn.setBlockState(bp.add(i + 2, j + 2, k + 14), BlockHandler.PARISTEEL_METAL.getStateFromMeta(5));
		worldIn.setBlockState(bp.add(i + 2, j + 2, k + 15), BlockHandler.PARISTEEL_METAL.getStateFromMeta(5));
		worldIn.setBlockState(bp.add(i + 2, j + 2, k + 16), BlockHandler.PARISTEEL_METAL.getStateFromMeta(5));
		worldIn.setBlockState(bp.add(i + 2, j + 2, k + 17), BlockHandler.PARISTEEL_METAL.getStateFromMeta(5));
		worldIn.setBlockState(bp.add(i + 2, j + 2, k + 18), BlockHandler.PARISTEEL_METAL.getStateFromMeta(5));
		worldIn.setBlockState(bp.add(i + 2, j + 2, k + 22), BlockHandler.PARISTEEL_METAL.getStateFromMeta(5));
		worldIn.setBlockState(bp.add(i + 2, j + 2, k + 23), BlockHandler.PARISTEEL_METAL.getStateFromMeta(5));
		worldIn.setBlockState(bp.add(i + 2, j + 2, k + 24), BlockHandler.PARISTEEL_METAL.getStateFromMeta(5));
		worldIn.setBlockState(bp.add(i + 2, j + 2, k + 25), BlockHandler.PARISTEEL_METAL.getStateFromMeta(5));
		worldIn.setBlockState(bp.add(i + 2, j + 2, k + 26), BlockHandler.PARISTEEL_METAL.getStateFromMeta(5));
		worldIn.setBlockState(bp.add(i + 2, j + 3, k + 3), BlockHandler.PARISTEEL_METAL.getStateFromMeta(15));
		worldIn.setBlockState(bp.add(i + 2, j + 3, k + 4), BlockHandler.PARISTEEL_METAL.getStateFromMeta(15));
		worldIn.setBlockState(bp.add(i + 2, j + 3, k + 5), BlockHandler.PARISTEEL_METAL.getStateFromMeta(15));
		worldIn.setBlockState(bp.add(i + 2, j + 3, k + 9), BlockHandler.PARISTEEL_METAL.getStateFromMeta(5));
		worldIn.setBlockState(bp.add(i + 2, j + 3, k + 10), BlockHandler.PARISTEEL_METAL.getStateFromMeta(5));
		worldIn.setBlockState(bp.add(i + 2, j + 3, k + 11), BlockHandler.PARISTEEL_METAL.getStateFromMeta(5));
		worldIn.setBlockState(bp.add(i + 2, j + 3, k + 12), BlockHandler.NEOSTEEL_METAL.getStateFromMeta(1));
		worldIn.setBlockState(bp.add(i + 2, j + 3, k + 13), BlockHandler.NEOSTEEL_METAL.getStateFromMeta(1));
		worldIn.setBlockState(bp.add(i + 2, j + 3, k + 14), BlockHandler.NEOSTEEL_METAL.getStateFromMeta(1));
		worldIn.setBlockState(bp.add(i + 2, j + 3, k + 15), BlockHandler.NEOSTEEL_METAL.getStateFromMeta(1));
		worldIn.setBlockState(bp.add(i + 2, j + 3, k + 16), BlockHandler.NEOSTEEL_METAL.getStateFromMeta(1));
		worldIn.setBlockState(bp.add(i + 2, j + 3, k + 17), BlockHandler.PARISTEEL_METAL.getStateFromMeta(5));
		worldIn.setBlockState(bp.add(i + 2, j + 3, k + 18), BlockHandler.PARISTEEL_METAL.getStateFromMeta(5));
		worldIn.setBlockState(bp.add(i + 2, j + 3, k + 19), BlockHandler.PARISTEEL_METAL.getStateFromMeta(5));
		worldIn.setBlockState(bp.add(i + 2, j + 3, k + 23), BlockHandler.PARISTEEL_METAL.getStateFromMeta(15));
		worldIn.setBlockState(bp.add(i + 2, j + 3, k + 24), BlockHandler.PARISTEEL_METAL.getStateFromMeta(15));
		worldIn.setBlockState(bp.add(i + 2, j + 3, k + 25), BlockHandler.PARISTEEL_METAL.getStateFromMeta(15));
		worldIn.setBlockState(bp.add(i + 2, j + 4, k + 5), BlockHandler.PARISTEEL_METAL.getStateFromMeta(15));
		worldIn.setBlockState(bp.add(i + 2, j + 4, k + 9), BlockHandler.PARISTEEL_METAL.getStateFromMeta(5));
		worldIn.setBlockState(bp.add(i + 2, j + 4, k + 10), BlockHandler.PARISTEEL_METAL.getStateFromMeta(5));
		worldIn.setBlockState(bp.add(i + 2, j + 4, k + 11), BlockHandler.PARISTEEL_METAL.getStateFromMeta(5));
		worldIn.setBlockState(bp.add(i + 2, j + 4, k + 17), BlockHandler.PARISTEEL_METAL.getStateFromMeta(5));
		worldIn.setBlockState(bp.add(i + 2, j + 4, k + 18), BlockHandler.PARISTEEL_METAL.getStateFromMeta(5));
		worldIn.setBlockState(bp.add(i + 2, j + 4, k + 19), BlockHandler.PARISTEEL_METAL.getStateFromMeta(5));
		worldIn.setBlockState(bp.add(i + 2, j + 4, k + 23), BlockHandler.PARISTEEL_METAL.getStateFromMeta(15));
		worldIn.setBlockState(bp.add(i + 2, j + 5, k + 9), BlockHandler.PARISTEEL_METAL.getStateFromMeta(5));
		worldIn.setBlockState(bp.add(i + 2, j + 5, k + 10), BlockHandler.PARISTEEL_METAL.getStateFromMeta(5));
		worldIn.setBlockState(bp.add(i + 2, j + 5, k + 11), BlockHandler.PARISTEEL_METAL.getStateFromMeta(5));
		worldIn.setBlockState(bp.add(i + 2, j + 5, k + 17), BlockHandler.PARISTEEL_METAL.getStateFromMeta(5));
		worldIn.setBlockState(bp.add(i + 2, j + 5, k + 18), BlockHandler.PARISTEEL_METAL.getStateFromMeta(5));
		worldIn.setBlockState(bp.add(i + 2, j + 5, k + 19), BlockHandler.PARISTEEL_METAL.getStateFromMeta(5));
		worldIn.setBlockState(bp.add(i + 2, j + 6, k + 9), BlockHandler.PARISTEEL_METAL.getStateFromMeta(5));
		worldIn.setBlockState(bp.add(i + 2, j + 6, k + 10), BlockHandler.PARISTEEL_METAL.getStateFromMeta(5));
		worldIn.setBlockState(bp.add(i + 2, j + 6, k + 11), BlockHandler.PARISTEEL_METAL.getStateFromMeta(5));
		worldIn.setBlockState(bp.add(i + 2, j + 6, k + 17), BlockHandler.PARISTEEL_METAL.getStateFromMeta(5));
		worldIn.setBlockState(bp.add(i + 2, j + 6, k + 18), BlockHandler.PARISTEEL_METAL.getStateFromMeta(5));
		worldIn.setBlockState(bp.add(i + 2, j + 6, k + 19), BlockHandler.PARISTEEL_METAL.getStateFromMeta(5));
		worldIn.setBlockState(bp.add(i + 2, j + 7, k + 10), BlockHandler.PARISTEEL_METAL.getStateFromMeta(5));
		worldIn.setBlockState(bp.add(i + 2, j + 7, k + 11), BlockHandler.PARISTEEL_METAL.getStateFromMeta(5));
		worldIn.setBlockState(bp.add(i + 2, j + 7, k + 12), BlockHandler.PARISTEEL_METAL.getStateFromMeta(5));
		worldIn.setBlockState(bp.add(i + 2, j + 7, k + 13), BlockHandler.PARISTEEL_METAL.getStateFromMeta(5));
		worldIn.setBlockState(bp.add(i + 2, j + 7, k + 14), Blocks.SEA_LANTERN.getDefaultState());
		worldIn.setBlockState(bp.add(i + 2, j + 7, k + 15), BlockHandler.PARISTEEL_METAL.getStateFromMeta(5));
		worldIn.setBlockState(bp.add(i + 2, j + 7, k + 16), BlockHandler.PARISTEEL_METAL.getStateFromMeta(5));
		worldIn.setBlockState(bp.add(i + 2, j + 7, k + 17), BlockHandler.PARISTEEL_METAL.getStateFromMeta(5));
		worldIn.setBlockState(bp.add(i + 2, j + 7, k + 18), BlockHandler.PARISTEEL_METAL.getStateFromMeta(5));
		worldIn.setBlockState(bp.add(i + 2, j + 8, k + 12), BlockHandler.PARISTEEL_METAL.getStateFromMeta(5));
		worldIn.setBlockState(bp.add(i + 2, j + 8, k + 13), BlockHandler.PARISTEEL_METAL.getStateFromMeta(5));
		worldIn.setBlockState(bp.add(i + 2, j + 8, k + 14), BlockHandler.PARISTEEL_METAL.getStateFromMeta(5));
		worldIn.setBlockState(bp.add(i + 2, j + 8, k + 15), BlockHandler.PARISTEEL_METAL.getStateFromMeta(5));
		worldIn.setBlockState(bp.add(i + 2, j + 8, k + 16), BlockHandler.PARISTEEL_METAL.getStateFromMeta(5));
		worldIn.setBlockState(bp.add(i + 2, j + 9, k + 12), BlockHandler.PARISTEEL_METAL.getStateFromMeta(5));
		worldIn.setBlockState(bp.add(i + 2, j + 9, k + 13), BlockHandler.PARISTEEL_METAL.getStateFromMeta(5));
		worldIn.setBlockState(bp.add(i + 2, j + 9, k + 14), BlockHandler.PARISTEEL_METAL.getStateFromMeta(5));
		worldIn.setBlockState(bp.add(i + 2, j + 9, k + 15), BlockHandler.PARISTEEL_METAL.getStateFromMeta(5));
		worldIn.setBlockState(bp.add(i + 2, j + 9, k + 16), BlockHandler.PARISTEEL_METAL.getStateFromMeta(5));
		worldIn.setBlockState(bp.add(i + 2, j + 10, k + 13), BlockHandler.PARISTEEL_METAL.getStateFromMeta(15));
		worldIn.setBlockState(bp.add(i + 2, j + 10, k + 14), BlockHandler.PARISTEEL_METAL.getStateFromMeta(15));
		worldIn.setBlockState(bp.add(i + 2, j + 10, k + 15), BlockHandler.PARISTEEL_METAL.getStateFromMeta(15));
		worldIn.setBlockState(bp.add(i + 3, j + 1, k + 1), BlockHandler.PARISTEEL_METAL.getStateFromMeta(5));
		worldIn.setBlockState(bp.add(i + 3, j + 1, k + 2), BlockHandler.PARISTEEL_METAL.getStateFromMeta(5));
		worldIn.setBlockState(bp.add(i + 3, j + 1, k + 3), BlockHandler.PARISTEEL_METAL.getStateFromMeta(5));
		worldIn.setBlockState(bp.add(i + 3, j + 1, k + 4), BlockHandler.PARISTEEL_METAL.getStateFromMeta(5));
		worldIn.setBlockState(bp.add(i + 3, j + 1, k + 5), BlockHandler.PARISTEEL_METAL.getStateFromMeta(5));
		worldIn.setBlockState(bp.add(i + 3, j + 1, k + 6), BlockHandler.PARISTEEL_METAL.getStateFromMeta(5));
		worldIn.setBlockState(bp.add(i + 3, j + 1, k + 7), BlockHandler.PARISTEEL_METAL.getStateFromMeta(5));
		worldIn.setBlockState(bp.add(i + 3, j + 1, k + 10), BlockHandler.PARISTEEL_METAL.getStateFromMeta(5));
		worldIn.setBlockState(bp.add(i + 3, j + 1, k + 11), BlockHandler.PARISTEEL_METAL.getStateFromMeta(5));
		worldIn.setBlockState(bp.add(i + 3, j + 1, k + 12), BlockHandler.PARISTEEL_METAL.getStateFromMeta(5));
		worldIn.setBlockState(bp.add(i + 3, j + 1, k + 13), BlockHandler.PARISTEEL_METAL.getStateFromMeta(5));
		worldIn.setBlockState(bp.add(i + 3, j + 1, k + 14), BlockHandler.PARISTEEL_METAL.getStateFromMeta(5));
		worldIn.setBlockState(bp.add(i + 3, j + 1, k + 15), BlockHandler.PARISTEEL_METAL.getStateFromMeta(5));
		worldIn.setBlockState(bp.add(i + 3, j + 1, k + 16), BlockHandler.PARISTEEL_METAL.getStateFromMeta(5));
		worldIn.setBlockState(bp.add(i + 3, j + 1, k + 17), BlockHandler.PARISTEEL_METAL.getStateFromMeta(5));
		worldIn.setBlockState(bp.add(i + 3, j + 1, k + 18), BlockHandler.PARISTEEL_METAL.getStateFromMeta(5));
		worldIn.setBlockState(bp.add(i + 3, j + 1, k + 21), BlockHandler.PARISTEEL_METAL.getStateFromMeta(5));
		worldIn.setBlockState(bp.add(i + 3, j + 1, k + 22), BlockHandler.PARISTEEL_METAL.getStateFromMeta(5));
		worldIn.setBlockState(bp.add(i + 3, j + 1, k + 23), BlockHandler.PARISTEEL_METAL.getStateFromMeta(5));
		worldIn.setBlockState(bp.add(i + 3, j + 1, k + 24), BlockHandler.PARISTEEL_METAL.getStateFromMeta(5));
		worldIn.setBlockState(bp.add(i + 3, j + 1, k + 25), BlockHandler.PARISTEEL_METAL.getStateFromMeta(5));
		worldIn.setBlockState(bp.add(i + 3, j + 1, k + 26), BlockHandler.PARISTEEL_METAL.getStateFromMeta(5));
		worldIn.setBlockState(bp.add(i + 3, j + 1, k + 27), BlockHandler.PARISTEEL_METAL.getStateFromMeta(5));
		worldIn.setBlockState(bp.add(i + 3, j + 2, k + 2), BlockHandler.PARISTEEL_METAL.getStateFromMeta(5));
		worldIn.setBlockState(bp.add(i + 3, j + 2, k + 3), BlockHandler.PARISTEEL_METAL.getStateFromMeta(5));
		worldIn.setBlockState(bp.add(i + 3, j + 2, k + 4), BlockHandler.PARISTEEL_METAL.getStateFromMeta(5));
		worldIn.setBlockState(bp.add(i + 3, j + 2, k + 5), BlockHandler.PARISTEEL_METAL.getStateFromMeta(5));
		worldIn.setBlockState(bp.add(i + 3, j + 2, k + 6), BlockHandler.PARISTEEL_METAL.getStateFromMeta(5));
		worldIn.setBlockState(bp.add(i + 3, j + 2, k + 9), BlockHandler.PARISTEEL_METAL.getStateFromMeta(5));
		worldIn.setBlockState(bp.add(i + 3, j + 2, k + 10), BlockHandler.PARISTEEL_METAL.getStateFromMeta(5));
		worldIn.setBlockState(bp.add(i + 3, j + 2, k + 11), BlockHandler.PARISTEEL_METAL.getStateFromMeta(5));
		worldIn.setBlockState(bp.add(i + 3, j + 2, k + 12), BlockHandler.PARISTEEL_METAL.getStateFromMeta(5));
		worldIn.setBlockState(bp.add(i + 3, j + 2, k + 13), BlockHandler.PARISTEEL_METAL.getStateFromMeta(5));
		worldIn.setBlockState(bp.add(i + 3, j + 2, k + 14), BlockHandler.PARISTEEL_METAL.getStateFromMeta(5));
		worldIn.setBlockState(bp.add(i + 3, j + 2, k + 15), BlockHandler.PARISTEEL_METAL.getStateFromMeta(5));
		worldIn.setBlockState(bp.add(i + 3, j + 2, k + 16), BlockHandler.PARISTEEL_METAL.getStateFromMeta(5));
		worldIn.setBlockState(bp.add(i + 3, j + 2, k + 17), BlockHandler.PARISTEEL_METAL.getStateFromMeta(5));
		worldIn.setBlockState(bp.add(i + 3, j + 2, k + 18), BlockHandler.PARISTEEL_METAL.getStateFromMeta(5));
		worldIn.setBlockState(bp.add(i + 3, j + 2, k + 19), BlockHandler.PARISTEEL_METAL.getStateFromMeta(5));
		worldIn.setBlockState(bp.add(i + 3, j + 2, k + 22), BlockHandler.PARISTEEL_METAL.getStateFromMeta(5));
		worldIn.setBlockState(bp.add(i + 3, j + 2, k + 23), BlockHandler.PARISTEEL_METAL.getStateFromMeta(5));
		worldIn.setBlockState(bp.add(i + 3, j + 2, k + 24), BlockHandler.PARISTEEL_METAL.getStateFromMeta(5));
		worldIn.setBlockState(bp.add(i + 3, j + 2, k + 25), BlockHandler.PARISTEEL_METAL.getStateFromMeta(5));
		worldIn.setBlockState(bp.add(i + 3, j + 2, k + 26), BlockHandler.PARISTEEL_METAL.getStateFromMeta(5));
		worldIn.setBlockState(bp.add(i + 3, j + 3, k + 3), BlockHandler.PARISTEEL_METAL.getStateFromMeta(15));
		worldIn.setBlockState(bp.add(i + 3, j + 3, k + 4), BlockHandler.PARISTEEL_METAL.getStateFromMeta(5));
		worldIn.setBlockState(bp.add(i + 3, j + 3, k + 5), BlockHandler.PARISTEEL_METAL.getStateFromMeta(5));
		worldIn.setBlockState(bp.add(i + 3, j + 3, k + 8), BlockHandler.PARISTEEL_METAL.getStateFromMeta(15));
		worldIn.setBlockState(bp.add(i + 3, j + 3, k + 9), BlockHandler.PARISTEEL_METAL.getStateFromMeta(5));
		worldIn.setBlockState(bp.add(i + 3, j + 3, k + 10), BlockHandler.NEOSTEEL_METAL.getStateFromMeta(1));
		worldIn.setBlockState(bp.add(i + 3, j + 3, k + 11), BlockHandler.NEOSTEEL_METAL.getStateFromMeta(1));
		worldIn.setBlockState(bp.add(i + 3, j + 3, k + 12), BlockHandler.NEOSTEEL_METAL.getStateFromMeta(1));
		worldIn.setBlockState(bp.add(i + 3, j + 3, k + 13), BlockHandler.NEOSTEEL_METAL.getStateFromMeta(1));
		worldIn.setBlockState(bp.add(i + 3, j + 3, k + 14), BlockHandler.NEOSTEEL_METAL.getStateFromMeta(1));
		worldIn.setBlockState(bp.add(i + 3, j + 3, k + 15), BlockHandler.NEOSTEEL_METAL.getStateFromMeta(1));
		worldIn.setBlockState(bp.add(i + 3, j + 3, k + 16), BlockHandler.NEOSTEEL_METAL.getStateFromMeta(1));
		worldIn.setBlockState(bp.add(i + 3, j + 3, k + 17), BlockHandler.NEOSTEEL_METAL.getStateFromMeta(1));
		worldIn.setBlockState(bp.add(i + 3, j + 3, k + 18), BlockHandler.NEOSTEEL_METAL.getStateFromMeta(1));
		worldIn.setBlockState(bp.add(i + 3, j + 3, k + 19), BlockHandler.PARISTEEL_METAL.getStateFromMeta(5));
		worldIn.setBlockState(bp.add(i + 3, j + 3, k + 20), BlockHandler.PARISTEEL_METAL.getStateFromMeta(15));
		worldIn.setBlockState(bp.add(i + 3, j + 3, k + 23), BlockHandler.PARISTEEL_METAL.getStateFromMeta(5));
		worldIn.setBlockState(bp.add(i + 3, j + 3, k + 24), BlockHandler.PARISTEEL_METAL.getStateFromMeta(5));
		worldIn.setBlockState(bp.add(i + 3, j + 3, k + 25), BlockHandler.PARISTEEL_METAL.getStateFromMeta(15));
		worldIn.setBlockState(bp.add(i + 3, j + 4, k + 4), BlockHandler.PARISTEEL_METAL.getStateFromMeta(15));
		worldIn.setBlockState(bp.add(i + 3, j + 4, k + 5), BlockHandler.PARISTEEL_METAL.getStateFromMeta(5));
		worldIn.setBlockState(bp.add(i + 3, j + 4, k + 6), BlockHandler.PARISTEEL_METAL.getStateFromMeta(5));
		worldIn.setBlockState(bp.add(i + 3, j + 4, k + 8), BlockHandler.PARISTEEL_METAL.getStateFromMeta(15));
		worldIn.setBlockState(bp.add(i + 3, j + 4, k + 9), BlockHandler.PARISTEEL_METAL.getStateFromMeta(5));
		worldIn.setBlockState(bp.add(i + 3, j + 4, k + 19), BlockHandler.PARISTEEL_METAL.getStateFromMeta(5));
		worldIn.setBlockState(bp.add(i + 3, j + 4, k + 20), BlockHandler.PARISTEEL_METAL.getStateFromMeta(15));
		worldIn.setBlockState(bp.add(i + 3, j + 4, k + 22), BlockHandler.PARISTEEL_METAL.getStateFromMeta(5));
		worldIn.setBlockState(bp.add(i + 3, j + 4, k + 23), BlockHandler.PARISTEEL_METAL.getStateFromMeta(5));
		worldIn.setBlockState(bp.add(i + 3, j + 4, k + 24), BlockHandler.PARISTEEL_METAL.getStateFromMeta(15));
		worldIn.setBlockState(bp.add(i + 3, j + 5, k + 5), BlockHandler.PARISTEEL_METAL.getStateFromMeta(5));
		worldIn.setBlockState(bp.add(i + 3, j + 5, k + 6), BlockHandler.PARISTEEL_METAL.getStateFromMeta(5));
		worldIn.setBlockState(bp.add(i + 3, j + 5, k + 8), BlockHandler.PARISTEEL_METAL.getStateFromMeta(15));
		worldIn.setBlockState(bp.add(i + 3, j + 5, k + 9), BlockHandler.PARISTEEL_METAL.getStateFromMeta(5));
		worldIn.setBlockState(bp.add(i + 3, j + 5, k + 19), BlockHandler.PARISTEEL_METAL.getStateFromMeta(5));
		worldIn.setBlockState(bp.add(i + 3, j + 5, k + 20), BlockHandler.PARISTEEL_METAL.getStateFromMeta(15));
		worldIn.setBlockState(bp.add(i + 3, j + 5, k + 22), BlockHandler.PARISTEEL_METAL.getStateFromMeta(5));
		worldIn.setBlockState(bp.add(i + 3, j + 5, k + 23), BlockHandler.PARISTEEL_METAL.getStateFromMeta(5));
		worldIn.setBlockState(bp.add(i + 3, j + 6, k + 8), BlockHandler.PARISTEEL_METAL.getStateFromMeta(15));
		worldIn.setBlockState(bp.add(i + 3, j + 6, k + 9), BlockHandler.PARISTEEL_METAL.getStateFromMeta(5));
		worldIn.setBlockState(bp.add(i + 3, j + 6, k + 19), BlockHandler.PARISTEEL_METAL.getStateFromMeta(5));
		worldIn.setBlockState(bp.add(i + 3, j + 6, k + 20), BlockHandler.PARISTEEL_METAL.getStateFromMeta(15));
		worldIn.setBlockState(bp.add(i + 3, j + 7, k + 9), BlockHandler.PARISTEEL_METAL.getStateFromMeta(15));
		worldIn.setBlockState(bp.add(i + 3, j + 7, k + 10), BlockHandler.PARISTEEL_METAL.getStateFromMeta(5));
		worldIn.setBlockState(bp.add(i + 3, j + 7, k + 11), BlockHandler.PARISTEEL_METAL.getStateFromMeta(5));
		worldIn.setBlockState(bp.add(i + 3, j + 7, k + 12), BlockHandler.PARISTEEL_METAL.getStateFromMeta(5));
		worldIn.setBlockState(bp.add(i + 3, j + 7, k + 13), BlockHandler.PARISTEEL_METAL.getStateFromMeta(5));
		worldIn.setBlockState(bp.add(i + 3, j + 7, k + 14), Blocks.SEA_LANTERN.getDefaultState());
		worldIn.setBlockState(bp.add(i + 3, j + 7, k + 15), BlockHandler.PARISTEEL_METAL.getStateFromMeta(5));
		worldIn.setBlockState(bp.add(i + 3, j + 7, k + 16), BlockHandler.PARISTEEL_METAL.getStateFromMeta(5));
		worldIn.setBlockState(bp.add(i + 3, j + 7, k + 17), BlockHandler.PARISTEEL_METAL.getStateFromMeta(5));
		worldIn.setBlockState(bp.add(i + 3, j + 7, k + 18), BlockHandler.PARISTEEL_METAL.getStateFromMeta(5));
		worldIn.setBlockState(bp.add(i + 3, j + 7, k + 19), BlockHandler.PARISTEEL_METAL.getStateFromMeta(15));
		worldIn.setBlockState(bp.add(i + 3, j + 8, k + 10), BlockHandler.PARISTEEL_METAL.getStateFromMeta(5));
		worldIn.setBlockState(bp.add(i + 3, j + 8, k + 11), BlockHandler.PARISTEEL_METAL.getStateFromMeta(5));
		worldIn.setBlockState(bp.add(i + 3, j + 8, k + 12), BlockHandler.PARISTEEL_METAL.getStateFromMeta(5));
		worldIn.setBlockState(bp.add(i + 3, j + 8, k + 13), BlockHandler.PARISTEEL_METAL.getStateFromMeta(5));
		worldIn.setBlockState(bp.add(i + 3, j + 8, k + 14), BlockHandler.PARISTEEL_METAL.getStateFromMeta(5));
		worldIn.setBlockState(bp.add(i + 3, j + 8, k + 15), BlockHandler.PARISTEEL_METAL.getStateFromMeta(5));
		worldIn.setBlockState(bp.add(i + 3, j + 8, k + 16), BlockHandler.PARISTEEL_METAL.getStateFromMeta(5));
		worldIn.setBlockState(bp.add(i + 3, j + 8, k + 17), BlockHandler.PARISTEEL_METAL.getStateFromMeta(5));
		worldIn.setBlockState(bp.add(i + 3, j + 8, k + 18), BlockHandler.PARISTEEL_METAL.getStateFromMeta(5));
		worldIn.setBlockState(bp.add(i + 3, j + 9, k + 10), BlockHandler.PARISTEEL_METAL.getStateFromMeta(5));
		worldIn.setBlockState(bp.add(i + 3, j + 9, k + 11), BlockHandler.PARISTEEL_METAL.getStateFromMeta(5));
		worldIn.setBlockState(bp.add(i + 3, j + 9, k + 12), BlockHandler.PARISTEEL_METAL.getStateFromMeta(5));
		worldIn.setBlockState(bp.add(i + 3, j + 9, k + 13), BlockHandler.PARISTEEL_METAL.getStateFromMeta(5));
		worldIn.setBlockState(bp.add(i + 3, j + 9, k + 14), BlockHandler.PARISTEEL_METAL.getStateFromMeta(5));
		worldIn.setBlockState(bp.add(i + 3, j + 9, k + 15), BlockHandler.PARISTEEL_METAL.getStateFromMeta(5));
		worldIn.setBlockState(bp.add(i + 3, j + 9, k + 16), BlockHandler.PARISTEEL_METAL.getStateFromMeta(5));
		worldIn.setBlockState(bp.add(i + 3, j + 9, k + 17), BlockHandler.PARISTEEL_METAL.getStateFromMeta(5));
		worldIn.setBlockState(bp.add(i + 3, j + 9, k + 18), BlockHandler.PARISTEEL_METAL.getStateFromMeta(5));
		worldIn.setBlockState(bp.add(i + 3, j + 10, k + 12), BlockHandler.PARISTEEL_METAL.getStateFromMeta(5));
		worldIn.setBlockState(bp.add(i + 3, j + 10, k + 13), BlockHandler.PARISTEEL_METAL.getStateFromMeta(5));
		worldIn.setBlockState(bp.add(i + 3, j + 10, k + 14), BlockHandler.PARISTEEL_METAL.getStateFromMeta(5));
		worldIn.setBlockState(bp.add(i + 3, j + 10, k + 15), BlockHandler.PARISTEEL_METAL.getStateFromMeta(5));
		worldIn.setBlockState(bp.add(i + 3, j + 10, k + 16), BlockHandler.PARISTEEL_METAL.getStateFromMeta(5));
		worldIn.setBlockState(bp.add(i + 4, j + 1, k + 1), BlockHandler.PARISTEEL_METAL.getStateFromMeta(5));
		worldIn.setBlockState(bp.add(i + 4, j + 1, k + 2), BlockHandler.PARISTEEL_METAL.getStateFromMeta(5));
		worldIn.setBlockState(bp.add(i + 4, j + 1, k + 3), BlockHandler.PARISTEEL_METAL.getStateFromMeta(5));
		worldIn.setBlockState(bp.add(i + 4, j + 1, k + 4), BlockHandler.PARISTEEL_METAL.getStateFromMeta(5));
		worldIn.setBlockState(bp.add(i + 4, j + 1, k + 5), BlockHandler.PARISTEEL_METAL.getStateFromMeta(5));
		worldIn.setBlockState(bp.add(i + 4, j + 1, k + 6), BlockHandler.PARISTEEL_METAL.getStateFromMeta(5));
		worldIn.setBlockState(bp.add(i + 4, j + 1, k + 7), BlockHandler.PARISTEEL_METAL.getStateFromMeta(5));
		worldIn.setBlockState(bp.add(i + 4, j + 1, k + 9), BlockHandler.PARISTEEL_METAL.getStateFromMeta(5));
		worldIn.setBlockState(bp.add(i + 4, j + 1, k + 10), BlockHandler.PARISTEEL_METAL.getStateFromMeta(5));
		worldIn.setBlockState(bp.add(i + 4, j + 1, k + 11), BlockHandler.PARISTEEL_METAL.getStateFromMeta(5));
		worldIn.setBlockState(bp.add(i + 4, j + 1, k + 12), BlockHandler.PARISTEEL_METAL.getStateFromMeta(5));
		worldIn.setBlockState(bp.add(i + 4, j + 1, k + 13), BlockHandler.PARISTEEL_METAL.getStateFromMeta(5));
		worldIn.setBlockState(bp.add(i + 4, j + 1, k + 14), BlockHandler.PARISTEEL_METAL.getStateFromMeta(5));
		worldIn.setBlockState(bp.add(i + 4, j + 1, k + 15), BlockHandler.PARISTEEL_METAL.getStateFromMeta(5));
		worldIn.setBlockState(bp.add(i + 4, j + 1, k + 16), BlockHandler.PARISTEEL_METAL.getStateFromMeta(5));
		worldIn.setBlockState(bp.add(i + 4, j + 1, k + 17), BlockHandler.PARISTEEL_METAL.getStateFromMeta(5));
		worldIn.setBlockState(bp.add(i + 4, j + 1, k + 18), BlockHandler.PARISTEEL_METAL.getStateFromMeta(5));
		worldIn.setBlockState(bp.add(i + 4, j + 1, k + 19), BlockHandler.PARISTEEL_METAL.getStateFromMeta(5));
		worldIn.setBlockState(bp.add(i + 4, j + 1, k + 21), BlockHandler.PARISTEEL_METAL.getStateFromMeta(5));
		worldIn.setBlockState(bp.add(i + 4, j + 1, k + 22), BlockHandler.PARISTEEL_METAL.getStateFromMeta(5));
		worldIn.setBlockState(bp.add(i + 4, j + 1, k + 23), BlockHandler.PARISTEEL_METAL.getStateFromMeta(5));
		worldIn.setBlockState(bp.add(i + 4, j + 1, k + 24), BlockHandler.PARISTEEL_METAL.getStateFromMeta(5));
		worldIn.setBlockState(bp.add(i + 4, j + 1, k + 25), BlockHandler.PARISTEEL_METAL.getStateFromMeta(5));
		worldIn.setBlockState(bp.add(i + 4, j + 1, k + 26), BlockHandler.PARISTEEL_METAL.getStateFromMeta(5));
		worldIn.setBlockState(bp.add(i + 4, j + 1, k + 27), BlockHandler.PARISTEEL_METAL.getStateFromMeta(5));
		worldIn.setBlockState(bp.add(i + 4, j + 2, k + 2), BlockHandler.PARISTEEL_METAL.getStateFromMeta(5));
		worldIn.setBlockState(bp.add(i + 4, j + 2, k + 3), BlockHandler.PARISTEEL_METAL.getStateFromMeta(5));
		worldIn.setBlockState(bp.add(i + 4, j + 2, k + 4), BlockHandler.PARISTEEL_METAL.getStateFromMeta(5));
		worldIn.setBlockState(bp.add(i + 4, j + 2, k + 5), BlockHandler.PARISTEEL_METAL.getStateFromMeta(5));
		worldIn.setBlockState(bp.add(i + 4, j + 2, k + 6), BlockHandler.PARISTEEL_METAL.getStateFromMeta(5));
		worldIn.setBlockState(bp.add(i + 4, j + 2, k + 8), BlockHandler.PARISTEEL_METAL.getStateFromMeta(5));
		worldIn.setBlockState(bp.add(i + 4, j + 2, k + 9), BlockHandler.PARISTEEL_METAL.getStateFromMeta(5));
		worldIn.setBlockState(bp.add(i + 4, j + 2, k + 10), BlockHandler.PARISTEEL_METAL.getStateFromMeta(5));
		worldIn.setBlockState(bp.add(i + 4, j + 2, k + 11), BlockHandler.PARISTEEL_METAL.getStateFromMeta(5));
		worldIn.setBlockState(bp.add(i + 4, j + 2, k + 12), BlockHandler.PARISTEEL_METAL.getStateFromMeta(5));
		worldIn.setBlockState(bp.add(i + 4, j + 2, k + 13), BlockHandler.PARISTEEL_METAL.getStateFromMeta(5));
		worldIn.setBlockState(bp.add(i + 4, j + 2, k + 14), BlockHandler.PARISTEEL_METAL.getStateFromMeta(5));
		worldIn.setBlockState(bp.add(i + 4, j + 2, k + 15), BlockHandler.PARISTEEL_METAL.getStateFromMeta(5));
		worldIn.setBlockState(bp.add(i + 4, j + 2, k + 16), BlockHandler.PARISTEEL_METAL.getStateFromMeta(5));
		worldIn.setBlockState(bp.add(i + 4, j + 2, k + 17), BlockHandler.PARISTEEL_METAL.getStateFromMeta(5));
		worldIn.setBlockState(bp.add(i + 4, j + 2, k + 18), BlockHandler.PARISTEEL_METAL.getStateFromMeta(5));
		worldIn.setBlockState(bp.add(i + 4, j + 2, k + 19), BlockHandler.PARISTEEL_METAL.getStateFromMeta(5));
		worldIn.setBlockState(bp.add(i + 4, j + 2, k + 20), BlockHandler.PARISTEEL_METAL.getStateFromMeta(5));
		worldIn.setBlockState(bp.add(i + 4, j + 2, k + 22), BlockHandler.PARISTEEL_METAL.getStateFromMeta(5));
		worldIn.setBlockState(bp.add(i + 4, j + 2, k + 23), BlockHandler.PARISTEEL_METAL.getStateFromMeta(5));
		worldIn.setBlockState(bp.add(i + 4, j + 2, k + 24), BlockHandler.PARISTEEL_METAL.getStateFromMeta(5));
		worldIn.setBlockState(bp.add(i + 4, j + 2, k + 25), BlockHandler.PARISTEEL_METAL.getStateFromMeta(5));
		worldIn.setBlockState(bp.add(i + 4, j + 2, k + 26), BlockHandler.PARISTEEL_METAL.getStateFromMeta(5));
		worldIn.setBlockState(bp.add(i + 4, j + 3, k + 3), BlockHandler.PARISTEEL_METAL.getStateFromMeta(15));
		worldIn.setBlockState(bp.add(i + 4, j + 3, k + 4), BlockHandler.PARISTEEL_METAL.getStateFromMeta(5));
		worldIn.setBlockState(bp.add(i + 4, j + 3, k + 5), BlockHandler.PARISTEEL_METAL.getStateFromMeta(5));
		worldIn.setBlockState(bp.add(i + 4, j + 3, k + 6), BlockHandler.PARISTEEL_METAL.getStateFromMeta(5));
		worldIn.setBlockState(bp.add(i + 4, j + 3, k + 7), BlockHandler.PARISTEEL_METAL.getStateFromMeta(5));
		worldIn.setBlockState(bp.add(i + 4, j + 3, k + 8), BlockHandler.PARISTEEL_METAL.getStateFromMeta(5));
		worldIn.setBlockState(bp.add(i + 4, j + 3, k + 9), BlockHandler.NEOSTEEL_METAL.getStateFromMeta(1));
		worldIn.setBlockState(bp.add(i + 4, j + 3, k + 10), BlockHandler.NEOSTEEL_METAL.getStateFromMeta(1));
		worldIn.setBlockState(bp.add(i + 4, j + 3, k + 11), BlockHandler.NEOSTEEL_METAL.getStateFromMeta(1));
		worldIn.setBlockState(bp.add(i + 4, j + 3, k + 12), BlockHandler.NEOSTEEL_METAL.getStateFromMeta(1));
		worldIn.setBlockState(bp.add(i + 4, j + 3, k + 13), BlockHandler.NEOSTEEL_METAL.getStateFromMeta(1));
		worldIn.setBlockState(bp.add(i + 4, j + 3, k + 14), BlockHandler.NEOSTEEL_METAL.getStateFromMeta(1));
		worldIn.setBlockState(bp.add(i + 4, j + 3, k + 15), BlockHandler.NEOSTEEL_METAL.getStateFromMeta(1));
		worldIn.setBlockState(bp.add(i + 4, j + 3, k + 16), BlockHandler.NEOSTEEL_METAL.getStateFromMeta(1));
		worldIn.setBlockState(bp.add(i + 4, j + 3, k + 17), BlockHandler.NEOSTEEL_METAL.getStateFromMeta(1));
		worldIn.setBlockState(bp.add(i + 4, j + 3, k + 18), BlockHandler.NEOSTEEL_METAL.getStateFromMeta(1));
		worldIn.setBlockState(bp.add(i + 4, j + 3, k + 19), BlockHandler.PARISTEEL_METAL.getStateFromMeta(5));
		worldIn.setBlockState(bp.add(i + 4, j + 3, k + 20), BlockHandler.PARISTEEL_METAL.getStateFromMeta(5));
		worldIn.setBlockState(bp.add(i + 4, j + 3, k + 21), BlockHandler.PARISTEEL_METAL.getStateFromMeta(5));
		worldIn.setBlockState(bp.add(i + 4, j + 3, k + 22), BlockHandler.PARISTEEL_METAL.getStateFromMeta(5));
		worldIn.setBlockState(bp.add(i + 4, j + 3, k + 23), BlockHandler.PARISTEEL_METAL.getStateFromMeta(5));
		worldIn.setBlockState(bp.add(i + 4, j + 3, k + 24), BlockHandler.PARISTEEL_METAL.getStateFromMeta(5));
		worldIn.setBlockState(bp.add(i + 4, j + 3, k + 25), BlockHandler.PARISTEEL_METAL.getStateFromMeta(15));
		worldIn.setBlockState(bp.add(i + 4, j + 4, k + 3), BlockHandler.PARISTEEL_METAL.getStateFromMeta(15));
		worldIn.setBlockState(bp.add(i + 4, j + 4, k + 4), BlockHandler.PARISTEEL_METAL.getStateFromMeta(5));
		worldIn.setBlockState(bp.add(i + 4, j + 4, k + 5), BlockHandler.PARISTEEL_METAL.getStateFromMeta(5));
		worldIn.setBlockState(bp.add(i + 4, j + 4, k + 6), BlockHandler.PARISTEEL_METAL.getStateFromMeta(5));
		worldIn.setBlockState(bp.add(i + 4, j + 4, k + 7), BlockHandler.PARISTEEL_METAL.getStateFromMeta(5));
		worldIn.setBlockState(bp.add(i + 4, j + 4, k + 8), BlockHandler.PARISTEEL_METAL.getStateFromMeta(5));
		worldIn.setBlockState(bp.add(i + 4, j + 4, k + 19), BlockHandler.PARISTEEL_METAL.getStateFromMeta(5));
		worldIn.setBlockState(bp.add(i + 4, j + 4, k + 20), BlockHandler.PARISTEEL_METAL.getStateFromMeta(5));
		worldIn.setBlockState(bp.add(i + 4, j + 4, k + 21), BlockHandler.PARISTEEL_METAL.getStateFromMeta(5));
		worldIn.setBlockState(bp.add(i + 4, j + 4, k + 22), BlockHandler.PARISTEEL_METAL.getStateFromMeta(5));
		worldIn.setBlockState(bp.add(i + 4, j + 4, k + 23), BlockHandler.PARISTEEL_METAL.getStateFromMeta(5));
		worldIn.setBlockState(bp.add(i + 4, j + 4, k + 24), BlockHandler.PARISTEEL_METAL.getStateFromMeta(5));
		worldIn.setBlockState(bp.add(i + 4, j + 4, k + 25), BlockHandler.PARISTEEL_METAL.getStateFromMeta(15));
		worldIn.setBlockState(bp.add(i + 4, j + 5, k + 4), BlockHandler.PARISTEEL_METAL.getStateFromMeta(5));
		worldIn.setBlockState(bp.add(i + 4, j + 5, k + 5), BlockHandler.PARISTEEL_METAL.getStateFromMeta(3));
		worldIn.setBlockState(bp.add(i + 4, j + 5, k + 6), BlockHandler.PARISTEEL_METAL.getStateFromMeta(3));
		worldIn.setBlockState(bp.add(i + 4, j + 5, k + 7), BlockHandler.PARISTEEL_METAL.getStateFromMeta(5));
		worldIn.setBlockState(bp.add(i + 4, j + 5, k + 8), BlockHandler.PARISTEEL_METAL.getStateFromMeta(5));
		worldIn.setBlockState(bp.add(i + 4, j + 5, k + 19), BlockHandler.PARISTEEL_METAL.getStateFromMeta(5));
		worldIn.setBlockState(bp.add(i + 4, j + 5, k + 20), BlockHandler.PARISTEEL_METAL.getStateFromMeta(5));
		worldIn.setBlockState(bp.add(i + 4, j + 5, k + 21), BlockHandler.PARISTEEL_METAL.getStateFromMeta(5));
		worldIn.setBlockState(bp.add(i + 4, j + 5, k + 22), BlockHandler.PARISTEEL_METAL.getStateFromMeta(3));
		worldIn.setBlockState(bp.add(i + 4, j + 5, k + 23), BlockHandler.PARISTEEL_METAL.getStateFromMeta(3));
		worldIn.setBlockState(bp.add(i + 4, j + 5, k + 24), BlockHandler.PARISTEEL_METAL.getStateFromMeta(5));
		worldIn.setBlockState(bp.add(i + 4, j + 6, k + 8), BlockHandler.PARISTEEL_METAL.getStateFromMeta(3));
		worldIn.setBlockState(bp.add(i + 4, j + 6, k + 9), BlockHandler.PARISTEEL_METAL.getStateFromMeta(5));
		worldIn.setBlockState(bp.add(i + 4, j + 6, k + 19), BlockHandler.PARISTEEL_METAL.getStateFromMeta(5));
		worldIn.setBlockState(bp.add(i + 4, j + 6, k + 20), BlockHandler.PARISTEEL_METAL.getStateFromMeta(3));
		worldIn.setBlockState(bp.add(i + 4, j + 7, k + 8), (IBlockState) Blocks.STAINED_GLASS.getDefaultState().withProperty(BlockStainedGlass.COLOR, EnumDyeColor.YELLOW));
		worldIn.setBlockState(bp.add(i + 4, j + 7, k + 9), BlockHandler.PARISTEEL_METAL.getStateFromMeta(5));
		worldIn.setBlockState(bp.add(i + 4, j + 7, k + 13), BlockHandler.PARISTEEL_METAL.getStateFromMeta(5));
		worldIn.setBlockState(bp.add(i + 4, j + 7, k + 14), Blocks.SEA_LANTERN.getDefaultState());
		worldIn.setBlockState(bp.add(i + 4, j + 7, k + 15), BlockHandler.PARISTEEL_METAL.getStateFromMeta(5));
		worldIn.setBlockState(bp.add(i + 4, j + 7, k + 19), BlockHandler.PARISTEEL_METAL.getStateFromMeta(5));
		worldIn.setBlockState(bp.add(i + 4, j + 7, k + 20), (IBlockState) Blocks.STAINED_GLASS.getDefaultState().withProperty(BlockStainedGlass.COLOR, EnumDyeColor.YELLOW));
		worldIn.setBlockState(bp.add(i + 4, j + 8, k + 9), BlockHandler.PARISTEEL_METAL.getStateFromMeta(15));
		worldIn.setBlockState(bp.add(i + 4, j + 8, k + 10), BlockHandler.PARISTEEL_METAL.getStateFromMeta(5));
		worldIn.setBlockState(bp.add(i + 4, j + 8, k + 11), BlockHandler.PARISTEEL_METAL.getStateFromMeta(5));
		worldIn.setBlockState(bp.add(i + 4, j + 8, k + 12), BlockHandler.PARISTEEL_METAL.getStateFromMeta(5));
		worldIn.setBlockState(bp.add(i + 4, j + 8, k + 13), BlockHandler.PARISTEEL_METAL.getStateFromMeta(5));
		worldIn.setBlockState(bp.add(i + 4, j + 8, k + 14), BlockHandler.PARISTEEL_METAL.getStateFromMeta(5));
		worldIn.setBlockState(bp.add(i + 4, j + 8, k + 15), BlockHandler.PARISTEEL_METAL.getStateFromMeta(5));
		worldIn.setBlockState(bp.add(i + 4, j + 8, k + 16), BlockHandler.PARISTEEL_METAL.getStateFromMeta(5));
		worldIn.setBlockState(bp.add(i + 4, j + 8, k + 17), BlockHandler.PARISTEEL_METAL.getStateFromMeta(5));
		worldIn.setBlockState(bp.add(i + 4, j + 8, k + 18), BlockHandler.PARISTEEL_METAL.getStateFromMeta(5));
		worldIn.setBlockState(bp.add(i + 4, j + 8, k + 19), BlockHandler.PARISTEEL_METAL.getStateFromMeta(15));
		worldIn.setBlockState(bp.add(i + 4, j + 9, k + 9), BlockHandler.PARISTEEL_METAL.getStateFromMeta(3));
		worldIn.setBlockState(bp.add(i + 4, j + 9, k + 10), BlockHandler.PARISTEEL_METAL.getStateFromMeta(5));
		worldIn.setBlockState(bp.add(i + 4, j + 9, k + 11), BlockHandler.PARISTEEL_METAL.getStateFromMeta(5));
		worldIn.setBlockState(bp.add(i + 4, j + 9, k + 12), BlockHandler.PARISTEEL_METAL.getStateFromMeta(5));
		worldIn.setBlockState(bp.add(i + 4, j + 9, k + 13), BlockHandler.PARISTEEL_METAL.getStateFromMeta(5));
		worldIn.setBlockState(bp.add(i + 4, j + 9, k + 14), BlockHandler.PARISTEEL_METAL.getStateFromMeta(5));
		worldIn.setBlockState(bp.add(i + 4, j + 9, k + 15), BlockHandler.PARISTEEL_METAL.getStateFromMeta(5));
		worldIn.setBlockState(bp.add(i + 4, j + 9, k + 16), BlockHandler.PARISTEEL_METAL.getStateFromMeta(5));
		worldIn.setBlockState(bp.add(i + 4, j + 9, k + 17), BlockHandler.PARISTEEL_METAL.getStateFromMeta(5));
		worldIn.setBlockState(bp.add(i + 4, j + 9, k + 18), BlockHandler.PARISTEEL_METAL.getStateFromMeta(5));
		worldIn.setBlockState(bp.add(i + 4, j + 9, k + 19), BlockHandler.PARISTEEL_METAL.getStateFromMeta(5));
		worldIn.setBlockState(bp.add(i + 4, j + 10, k + 10), BlockHandler.PARISTEEL_METAL.getStateFromMeta(5));
		worldIn.setBlockState(bp.add(i + 4, j + 10, k + 11), BlockHandler.PARISTEEL_METAL.getStateFromMeta(5));
		worldIn.setBlockState(bp.add(i + 4, j + 10, k + 12), BlockHandler.PARISTEEL_METAL.getStateFromMeta(5));
		worldIn.setBlockState(bp.add(i + 4, j + 10, k + 13), BlockHandler.PARISTEEL_METAL.getStateFromMeta(5));
		worldIn.setBlockState(bp.add(i + 4, j + 10, k + 14), BlockHandler.PARISTEEL_METAL.getStateFromMeta(5));
		worldIn.setBlockState(bp.add(i + 4, j + 10, k + 15), BlockHandler.PARISTEEL_METAL.getStateFromMeta(5));
		worldIn.setBlockState(bp.add(i + 4, j + 10, k + 16), BlockHandler.PARISTEEL_METAL.getStateFromMeta(5));
		worldIn.setBlockState(bp.add(i + 4, j + 10, k + 17), BlockHandler.PARISTEEL_METAL.getStateFromMeta(5));
		worldIn.setBlockState(bp.add(i + 4, j + 10, k + 18), BlockHandler.PARISTEEL_METAL.getStateFromMeta(5));
		worldIn.setBlockState(bp.add(i + 4, j + 11, k + 12), BlockHandler.PARISTEEL_METAL.getStateFromMeta(3));
		worldIn.setBlockState(bp.add(i + 4, j + 11, k + 13), (IBlockState) Blocks.STAINED_GLASS.getDefaultState().withProperty(BlockStainedGlass.COLOR, EnumDyeColor.GREEN));
		worldIn.setBlockState(bp.add(i + 4, j + 11, k + 14), (IBlockState) Blocks.STAINED_GLASS.getDefaultState().withProperty(BlockStainedGlass.COLOR, EnumDyeColor.GREEN));
		worldIn.setBlockState(bp.add(i + 4, j + 11, k + 15), (IBlockState) Blocks.STAINED_GLASS.getDefaultState().withProperty(BlockStainedGlass.COLOR, EnumDyeColor.GREEN));
		worldIn.setBlockState(bp.add(i + 4, j + 11, k + 16), BlockHandler.PARISTEEL_METAL.getStateFromMeta(3));
		worldIn.setBlockState(bp.add(i + 5, j + 1, k + 3), BlockHandler.PARISTEEL_METAL.getStateFromMeta(5));
		worldIn.setBlockState(bp.add(i + 5, j + 1, k + 4), BlockHandler.PARISTEEL_METAL.getStateFromMeta(5));
		worldIn.setBlockState(bp.add(i + 5, j + 1, k + 5), BlockHandler.PARISTEEL_METAL.getStateFromMeta(5));
		worldIn.setBlockState(bp.add(i + 5, j + 1, k + 6), BlockHandler.PARISTEEL_METAL.getStateFromMeta(5));
		worldIn.setBlockState(bp.add(i + 5, j + 1, k + 7), BlockHandler.PARISTEEL_METAL.getStateFromMeta(5));
		worldIn.setBlockState(bp.add(i + 5, j + 1, k + 8), BlockHandler.PARISTEEL_METAL.getStateFromMeta(5));
		worldIn.setBlockState(bp.add(i + 5, j + 1, k + 9), BlockHandler.PARISTEEL_METAL.getStateFromMeta(5));
		worldIn.setBlockState(bp.add(i + 5, j + 1, k + 10), BlockHandler.PARISTEEL_METAL.getStateFromMeta(5));
		worldIn.setBlockState(bp.add(i + 5, j + 1, k + 11), BlockHandler.PARISTEEL_METAL.getStateFromMeta(5));
		worldIn.setBlockState(bp.add(i + 5, j + 1, k + 12), BlockHandler.PARISTEEL_METAL.getStateFromMeta(5));
		worldIn.setBlockState(bp.add(i + 5, j + 1, k + 13), BlockHandler.PARISTEEL_METAL.getStateFromMeta(5));
		worldIn.setBlockState(bp.add(i + 5, j + 1, k + 14), BlockHandler.PARISTEEL_METAL.getStateFromMeta(5));
		worldIn.setBlockState(bp.add(i + 5, j + 1, k + 15), BlockHandler.PARISTEEL_METAL.getStateFromMeta(5));
		worldIn.setBlockState(bp.add(i + 5, j + 1, k + 16), BlockHandler.PARISTEEL_METAL.getStateFromMeta(5));
		worldIn.setBlockState(bp.add(i + 5, j + 1, k + 17), BlockHandler.PARISTEEL_METAL.getStateFromMeta(5));
		worldIn.setBlockState(bp.add(i + 5, j + 1, k + 18), BlockHandler.PARISTEEL_METAL.getStateFromMeta(5));
		worldIn.setBlockState(bp.add(i + 5, j + 1, k + 19), BlockHandler.PARISTEEL_METAL.getStateFromMeta(5));
		worldIn.setBlockState(bp.add(i + 5, j + 1, k + 20), BlockHandler.PARISTEEL_METAL.getStateFromMeta(5));
		worldIn.setBlockState(bp.add(i + 5, j + 1, k + 21), BlockHandler.PARISTEEL_METAL.getStateFromMeta(5));
		worldIn.setBlockState(bp.add(i + 5, j + 1, k + 22), BlockHandler.PARISTEEL_METAL.getStateFromMeta(5));
		worldIn.setBlockState(bp.add(i + 5, j + 1, k + 23), BlockHandler.PARISTEEL_METAL.getStateFromMeta(5));
		worldIn.setBlockState(bp.add(i + 5, j + 1, k + 24), BlockHandler.PARISTEEL_METAL.getStateFromMeta(5));
		worldIn.setBlockState(bp.add(i + 5, j + 1, k + 25), BlockHandler.PARISTEEL_METAL.getStateFromMeta(5));
		worldIn.setBlockState(bp.add(i + 5, j + 2, k + 3), BlockHandler.PARISTEEL_METAL.getStateFromMeta(5));
		worldIn.setBlockState(bp.add(i + 5, j + 2, k + 4), BlockHandler.PARISTEEL_METAL.getStateFromMeta(5));
		worldIn.setBlockState(bp.add(i + 5, j + 2, k + 5), BlockHandler.PARISTEEL_METAL.getStateFromMeta(5));
		worldIn.setBlockState(bp.add(i + 5, j + 2, k + 6), BlockHandler.PARISTEEL_METAL.getStateFromMeta(5));
		worldIn.setBlockState(bp.add(i + 5, j + 2, k + 7), BlockHandler.PARISTEEL_METAL.getStateFromMeta(5));
		worldIn.setBlockState(bp.add(i + 5, j + 2, k + 8), BlockHandler.PARISTEEL_METAL.getStateFromMeta(5));
		worldIn.setBlockState(bp.add(i + 5, j + 2, k + 9), BlockHandler.PARISTEEL_METAL.getStateFromMeta(5));
		worldIn.setBlockState(bp.add(i + 5, j + 2, k + 10), BlockHandler.PARISTEEL_METAL.getStateFromMeta(5));
		worldIn.setBlockState(bp.add(i + 5, j + 2, k + 11), BlockHandler.PARISTEEL_METAL.getStateFromMeta(5));
		worldIn.setBlockState(bp.add(i + 5, j + 2, k + 12), BlockHandler.PARISTEEL_METAL.getStateFromMeta(5));
		worldIn.setBlockState(bp.add(i + 5, j + 2, k + 13), BlockHandler.PARISTEEL_METAL.getStateFromMeta(5));
		worldIn.setBlockState(bp.add(i + 5, j + 2, k + 14), BlockHandler.PARISTEEL_METAL.getStateFromMeta(5));
		worldIn.setBlockState(bp.add(i + 5, j + 2, k + 15), BlockHandler.PARISTEEL_METAL.getStateFromMeta(5));
		worldIn.setBlockState(bp.add(i + 5, j + 2, k + 16), BlockHandler.PARISTEEL_METAL.getStateFromMeta(5));
		worldIn.setBlockState(bp.add(i + 5, j + 2, k + 17), BlockHandler.PARISTEEL_METAL.getStateFromMeta(5));
		worldIn.setBlockState(bp.add(i + 5, j + 2, k + 18), BlockHandler.PARISTEEL_METAL.getStateFromMeta(5));
		worldIn.setBlockState(bp.add(i + 5, j + 2, k + 19), BlockHandler.PARISTEEL_METAL.getStateFromMeta(5));
		worldIn.setBlockState(bp.add(i + 5, j + 2, k + 20), BlockHandler.PARISTEEL_METAL.getStateFromMeta(5));
		worldIn.setBlockState(bp.add(i + 5, j + 2, k + 21), BlockHandler.PARISTEEL_METAL.getStateFromMeta(5));
		worldIn.setBlockState(bp.add(i + 5, j + 2, k + 22), BlockHandler.PARISTEEL_METAL.getStateFromMeta(5));
		worldIn.setBlockState(bp.add(i + 5, j + 2, k + 23), BlockHandler.PARISTEEL_METAL.getStateFromMeta(5));
		worldIn.setBlockState(bp.add(i + 5, j + 2, k + 24), BlockHandler.PARISTEEL_METAL.getStateFromMeta(5));
		worldIn.setBlockState(bp.add(i + 5, j + 2, k + 25), BlockHandler.PARISTEEL_METAL.getStateFromMeta(5));
		worldIn.setBlockState(bp.add(i + 5, j + 3, k + 5), BlockHandler.PARISTEEL_METAL.getStateFromMeta(5));
		worldIn.setBlockState(bp.add(i + 5, j + 3, k + 6), BlockHandler.PARISTEEL_METAL.getStateFromMeta(5));
		worldIn.setBlockState(bp.add(i + 5, j + 3, k + 7), BlockHandler.PARISTEEL_METAL.getStateFromMeta(5));
		worldIn.setBlockState(bp.add(i + 5, j + 3, k + 8), BlockHandler.PARISTEEL_METAL.getStateFromMeta(5));
		worldIn.setBlockState(bp.add(i + 5, j + 3, k + 9), BlockHandler.NEOSTEEL_METAL.getStateFromMeta(1));
		worldIn.setBlockState(bp.add(i + 5, j + 3, k + 10), BlockHandler.NEOSTEEL_METAL.getStateFromMeta(1));
		worldIn.setBlockState(bp.add(i + 5, j + 3, k + 11), BlockHandler.NEOSTEEL_METAL.getStateFromMeta(1));
		worldIn.setBlockState(bp.add(i + 5, j + 3, k + 12), BlockHandler.NEOSTEEL_METAL.getStateFromMeta(1));
		worldIn.setBlockState(bp.add(i + 5, j + 3, k + 13), BlockHandler.NEOSTEEL_METAL.getStateFromMeta(1));
		worldIn.setBlockState(bp.add(i + 5, j + 3, k + 14), BlockHandler.NEOSTEEL_METAL.getStateFromMeta(1));
		worldIn.setBlockState(bp.add(i + 5, j + 3, k + 15), BlockHandler.NEOSTEEL_METAL.getStateFromMeta(1));
		worldIn.setBlockState(bp.add(i + 5, j + 3, k + 16), BlockHandler.NEOSTEEL_METAL.getStateFromMeta(1));
		worldIn.setBlockState(bp.add(i + 5, j + 3, k + 17), BlockHandler.NEOSTEEL_METAL.getStateFromMeta(1));
		worldIn.setBlockState(bp.add(i + 5, j + 3, k + 18), BlockHandler.NEOSTEEL_METAL.getStateFromMeta(1));
		worldIn.setBlockState(bp.add(i + 5, j + 3, k + 19), BlockHandler.NEOSTEEL_METAL.getStateFromMeta(1));
		worldIn.setBlockState(bp.add(i + 5, j + 3, k + 20), BlockHandler.PARISTEEL_METAL.getStateFromMeta(5));
		worldIn.setBlockState(bp.add(i + 5, j + 3, k + 21), BlockHandler.PARISTEEL_METAL.getStateFromMeta(5));
		worldIn.setBlockState(bp.add(i + 5, j + 3, k + 22), BlockHandler.PARISTEEL_METAL.getStateFromMeta(5));
		worldIn.setBlockState(bp.add(i + 5, j + 3, k + 23), BlockHandler.PARISTEEL_METAL.getStateFromMeta(5));
		worldIn.setBlockState(bp.add(i + 5, j + 4, k + 4), BlockHandler.PARISTEEL_METAL.getStateFromMeta(5));
		worldIn.setBlockState(bp.add(i + 5, j + 4, k + 5), BlockHandler.PARISTEEL_METAL.getStateFromMeta(5));
		worldIn.setBlockState(bp.add(i + 5, j + 4, k + 6), BlockHandler.PARISTEEL_METAL.getStateFromMeta(5));
		worldIn.setBlockState(bp.add(i + 5, j + 4, k + 7), BlockHandler.PARISTEEL_METAL.getStateFromMeta(5));
		worldIn.setBlockState(bp.add(i + 5, j + 4, k + 8), BlockHandler.PARISTEEL_METAL.getStateFromMeta(5));
		worldIn.setBlockState(bp.add(i + 5, j + 4, k + 20), BlockHandler.PARISTEEL_METAL.getStateFromMeta(5));
		worldIn.setBlockState(bp.add(i + 5, j + 4, k + 21), BlockHandler.PARISTEEL_METAL.getStateFromMeta(5));
		worldIn.setBlockState(bp.add(i + 5, j + 4, k + 22), BlockHandler.PARISTEEL_METAL.getStateFromMeta(5));
		worldIn.setBlockState(bp.add(i + 5, j + 4, k + 23), BlockHandler.PARISTEEL_METAL.getStateFromMeta(5));
		worldIn.setBlockState(bp.add(i + 5, j + 4, k + 24), BlockHandler.PARISTEEL_METAL.getStateFromMeta(5));
		worldIn.setBlockState(bp.add(i + 5, j + 5, k + 4), BlockHandler.PARISTEEL_METAL.getStateFromMeta(5));
		worldIn.setBlockState(bp.add(i + 5, j + 5, k + 5), BlockHandler.PARISTEEL_METAL.getStateFromMeta(3));
		worldIn.setBlockState(bp.add(i + 5, j + 5, k + 6), BlockHandler.PARISTEEL_METAL.getStateFromMeta(3));
		worldIn.setBlockState(bp.add(i + 5, j + 5, k + 7), BlockHandler.PARISTEEL_METAL.getStateFromMeta(5));
		worldIn.setBlockState(bp.add(i + 5, j + 5, k + 8), BlockHandler.PARISTEEL_METAL.getStateFromMeta(5));
		worldIn.setBlockState(bp.add(i + 5, j + 5, k + 20), BlockHandler.PARISTEEL_METAL.getStateFromMeta(5));
		worldIn.setBlockState(bp.add(i + 5, j + 5, k + 21), BlockHandler.PARISTEEL_METAL.getStateFromMeta(5));
		worldIn.setBlockState(bp.add(i + 5, j + 5, k + 22), BlockHandler.PARISTEEL_METAL.getStateFromMeta(3));
		worldIn.setBlockState(bp.add(i + 5, j + 5, k + 23), BlockHandler.PARISTEEL_METAL.getStateFromMeta(3));
		worldIn.setBlockState(bp.add(i + 5, j + 5, k + 24), BlockHandler.PARISTEEL_METAL.getStateFromMeta(5));
		worldIn.setBlockState(bp.add(i + 5, j + 6, k + 7), BlockHandler.PARISTEEL_METAL.getStateFromMeta(3));
		worldIn.setBlockState(bp.add(i + 5, j + 6, k + 8), BlockHandler.PARISTEEL_METAL.getStateFromMeta(5));
		worldIn.setBlockState(bp.add(i + 5, j + 6, k + 20), BlockHandler.PARISTEEL_METAL.getStateFromMeta(5));
		worldIn.setBlockState(bp.add(i + 5, j + 6, k + 21), BlockHandler.PARISTEEL_METAL.getStateFromMeta(3));
		worldIn.setBlockState(bp.add(i + 5, j + 7, k + 7), (IBlockState) Blocks.STAINED_GLASS.getDefaultState().withProperty(BlockStainedGlass.COLOR, EnumDyeColor.YELLOW));
		worldIn.setBlockState(bp.add(i + 5, j + 7, k + 13), BlockHandler.PARISTEEL_METAL.getStateFromMeta(5));
		worldIn.setBlockState(bp.add(i + 5, j + 7, k + 14), Blocks.SEA_LANTERN.getDefaultState());
		worldIn.setBlockState(bp.add(i + 5, j + 7, k + 15), BlockHandler.PARISTEEL_METAL.getStateFromMeta(5));
		worldIn.setBlockState(bp.add(i + 5, j + 7, k + 21), (IBlockState) Blocks.STAINED_GLASS.getDefaultState().withProperty(BlockStainedGlass.COLOR, EnumDyeColor.YELLOW));
		worldIn.setBlockState(bp.add(i + 5, j + 8, k + 8), BlockHandler.PARISTEEL_METAL.getStateFromMeta(15));
		worldIn.setBlockState(bp.add(i + 5, j + 8, k + 9), BlockHandler.PARISTEEL_METAL.getStateFromMeta(5));
		worldIn.setBlockState(bp.add(i + 5, j + 8, k + 10), BlockHandler.PARISTEEL_METAL.getStateFromMeta(5));
		worldIn.setBlockState(bp.add(i + 5, j + 8, k + 11), BlockHandler.PARISTEEL_METAL.getStateFromMeta(5));
		worldIn.setBlockState(bp.add(i + 5, j + 8, k + 12), BlockHandler.PARISTEEL_METAL.getStateFromMeta(5));
		worldIn.setBlockState(bp.add(i + 5, j + 8, k + 13), BlockHandler.PARISTEEL_METAL.getStateFromMeta(5));
		worldIn.setBlockState(bp.add(i + 5, j + 8, k + 14), BlockHandler.PARISTEEL_METAL.getStateFromMeta(5));
		worldIn.setBlockState(bp.add(i + 5, j + 8, k + 15), BlockHandler.PARISTEEL_METAL.getStateFromMeta(5));
		worldIn.setBlockState(bp.add(i + 5, j + 8, k + 16), BlockHandler.PARISTEEL_METAL.getStateFromMeta(5));
		worldIn.setBlockState(bp.add(i + 5, j + 8, k + 17), BlockHandler.PARISTEEL_METAL.getStateFromMeta(5));
		worldIn.setBlockState(bp.add(i + 5, j + 8, k + 18), BlockHandler.PARISTEEL_METAL.getStateFromMeta(5));
		worldIn.setBlockState(bp.add(i + 5, j + 8, k + 19), BlockHandler.PARISTEEL_METAL.getStateFromMeta(5));
		worldIn.setBlockState(bp.add(i + 5, j + 8, k + 20), BlockHandler.PARISTEEL_METAL.getStateFromMeta(15));
		worldIn.setBlockState(bp.add(i + 5, j + 9, k + 8), BlockHandler.PARISTEEL_METAL.getStateFromMeta(3));
		worldIn.setBlockState(bp.add(i + 5, j + 9, k + 9), BlockHandler.PARISTEEL_METAL.getStateFromMeta(5));
		worldIn.setBlockState(bp.add(i + 5, j + 9, k + 10), BlockHandler.PARISTEEL_METAL.getStateFromMeta(5));
		worldIn.setBlockState(bp.add(i + 5, j + 9, k + 11), BlockHandler.PARISTEEL_METAL.getStateFromMeta(5));
		worldIn.setBlockState(bp.add(i + 5, j + 9, k + 12), BlockHandler.PARISTEEL_METAL.getStateFromMeta(5));
		worldIn.setBlockState(bp.add(i + 5, j + 9, k + 13), BlockHandler.PARISTEEL_METAL.getStateFromMeta(5));
		worldIn.setBlockState(bp.add(i + 5, j + 9, k + 14), BlockHandler.PARISTEEL_METAL.getStateFromMeta(5));
		worldIn.setBlockState(bp.add(i + 5, j + 9, k + 15), BlockHandler.PARISTEEL_METAL.getStateFromMeta(5));
		worldIn.setBlockState(bp.add(i + 5, j + 9, k + 16), BlockHandler.PARISTEEL_METAL.getStateFromMeta(5));
		worldIn.setBlockState(bp.add(i + 5, j + 9, k + 17), BlockHandler.PARISTEEL_METAL.getStateFromMeta(5));
		worldIn.setBlockState(bp.add(i + 5, j + 9, k + 18), BlockHandler.PARISTEEL_METAL.getStateFromMeta(5));
		worldIn.setBlockState(bp.add(i + 5, j + 9, k + 19), BlockHandler.PARISTEEL_METAL.getStateFromMeta(5));
		worldIn.setBlockState(bp.add(i + 5, j + 9, k + 20), BlockHandler.PARISTEEL_METAL.getStateFromMeta(5));
		worldIn.setBlockState(bp.add(i + 5, j + 10, k + 9), BlockHandler.PARISTEEL_METAL.getStateFromMeta(5));
		worldIn.setBlockState(bp.add(i + 5, j + 10, k + 10), BlockHandler.PARISTEEL_METAL.getStateFromMeta(5));
		worldIn.setBlockState(bp.add(i + 5, j + 10, k + 11), BlockHandler.PARISTEEL_METAL.getStateFromMeta(5));
		worldIn.setBlockState(bp.add(i + 5, j + 10, k + 12), BlockHandler.PARISTEEL_METAL.getStateFromMeta(5));
		worldIn.setBlockState(bp.add(i + 5, j + 10, k + 13), BlockHandler.PARISTEEL_METAL.getStateFromMeta(5));
		worldIn.setBlockState(bp.add(i + 5, j + 10, k + 14), BlockHandler.PARISTEEL_METAL.getStateFromMeta(5));
		worldIn.setBlockState(bp.add(i + 5, j + 10, k + 15), BlockHandler.PARISTEEL_METAL.getStateFromMeta(5));
		worldIn.setBlockState(bp.add(i + 5, j + 10, k + 16), BlockHandler.PARISTEEL_METAL.getStateFromMeta(5));
		worldIn.setBlockState(bp.add(i + 5, j + 10, k + 17), BlockHandler.PARISTEEL_METAL.getStateFromMeta(5));
		worldIn.setBlockState(bp.add(i + 5, j + 10, k + 18), BlockHandler.PARISTEEL_METAL.getStateFromMeta(5));
		worldIn.setBlockState(bp.add(i + 5, j + 10, k + 19), BlockHandler.PARISTEEL_METAL.getStateFromMeta(5));
		worldIn.setBlockState(bp.add(i + 5, j + 11, k + 10), BlockHandler.PARISTEEL_METAL.getStateFromMeta(5));
		worldIn.setBlockState(bp.add(i + 5, j + 11, k + 11), BlockHandler.PARISTEEL_METAL.getStateFromMeta(5));
		worldIn.setBlockState(bp.add(i + 5, j + 11, k + 12), BlockHandler.PARISTEEL_METAL.getStateFromMeta(5));
		worldIn.setBlockState(bp.add(i + 5, j + 11, k + 16), BlockHandler.PARISTEEL_METAL.getStateFromMeta(5));
		worldIn.setBlockState(bp.add(i + 5, j + 11, k + 17), BlockHandler.PARISTEEL_METAL.getStateFromMeta(5));
		worldIn.setBlockState(bp.add(i + 5, j + 11, k + 18), BlockHandler.PARISTEEL_METAL.getStateFromMeta(5));
		worldIn.setBlockState(bp.add(i + 5, j + 12, k + 12), BlockHandler.PARISTEEL_METAL.getStateFromMeta(3));
		worldIn.setBlockState(bp.add(i + 5, j + 12, k + 13), BlockHandler.PARISTEEL_METAL.getStateFromMeta(3));
		worldIn.setBlockState(bp.add(i + 5, j + 12, k + 14), BlockHandler.PARISTEEL_METAL.getStateFromMeta(3));
		worldIn.setBlockState(bp.add(i + 5, j + 12, k + 15), BlockHandler.PARISTEEL_METAL.getStateFromMeta(3));
		worldIn.setBlockState(bp.add(i + 5, j + 12, k + 16), BlockHandler.PARISTEEL_METAL.getStateFromMeta(3));
		worldIn.setBlockState(bp.add(i + 6, j + 1, k + 3), BlockHandler.PARISTEEL_METAL.getStateFromMeta(5));
		worldIn.setBlockState(bp.add(i + 6, j + 1, k + 4), BlockHandler.PARISTEEL_METAL.getStateFromMeta(5));
		worldIn.setBlockState(bp.add(i + 6, j + 1, k + 5), BlockHandler.PARISTEEL_METAL.getStateFromMeta(5));
		worldIn.setBlockState(bp.add(i + 6, j + 1, k + 6), BlockHandler.PARISTEEL_METAL.getStateFromMeta(5));
		worldIn.setBlockState(bp.add(i + 6, j + 1, k + 7), BlockHandler.PARISTEEL_METAL.getStateFromMeta(5));
		worldIn.setBlockState(bp.add(i + 6, j + 1, k + 8), BlockHandler.PARISTEEL_METAL.getStateFromMeta(5));
		worldIn.setBlockState(bp.add(i + 6, j + 1, k + 9), BlockHandler.PARISTEEL_METAL.getStateFromMeta(5));
		worldIn.setBlockState(bp.add(i + 6, j + 1, k + 10), BlockHandler.PARISTEEL_METAL.getStateFromMeta(5));
		worldIn.setBlockState(bp.add(i + 6, j + 1, k + 11), BlockHandler.PARISTEEL_METAL.getStateFromMeta(5));
		worldIn.setBlockState(bp.add(i + 6, j + 1, k + 12), BlockHandler.PARISTEEL_METAL.getStateFromMeta(5));
		worldIn.setBlockState(bp.add(i + 6, j + 1, k + 13), BlockHandler.PARISTEEL_METAL.getStateFromMeta(5));
		worldIn.setBlockState(bp.add(i + 6, j + 1, k + 14), BlockHandler.PARISTEEL_METAL.getStateFromMeta(5));
		worldIn.setBlockState(bp.add(i + 6, j + 1, k + 15), BlockHandler.PARISTEEL_METAL.getStateFromMeta(5));
		worldIn.setBlockState(bp.add(i + 6, j + 1, k + 16), BlockHandler.PARISTEEL_METAL.getStateFromMeta(5));
		worldIn.setBlockState(bp.add(i + 6, j + 1, k + 17), BlockHandler.PARISTEEL_METAL.getStateFromMeta(5));
		worldIn.setBlockState(bp.add(i + 6, j + 1, k + 18), BlockHandler.PARISTEEL_METAL.getStateFromMeta(5));
		worldIn.setBlockState(bp.add(i + 6, j + 1, k + 19), BlockHandler.PARISTEEL_METAL.getStateFromMeta(5));
		worldIn.setBlockState(bp.add(i + 6, j + 1, k + 20), BlockHandler.PARISTEEL_METAL.getStateFromMeta(5));
		worldIn.setBlockState(bp.add(i + 6, j + 1, k + 21), BlockHandler.PARISTEEL_METAL.getStateFromMeta(5));
		worldIn.setBlockState(bp.add(i + 6, j + 1, k + 22), BlockHandler.PARISTEEL_METAL.getStateFromMeta(5));
		worldIn.setBlockState(bp.add(i + 6, j + 1, k + 23), BlockHandler.PARISTEEL_METAL.getStateFromMeta(5));
		worldIn.setBlockState(bp.add(i + 6, j + 1, k + 24), BlockHandler.PARISTEEL_METAL.getStateFromMeta(5));
		worldIn.setBlockState(bp.add(i + 6, j + 1, k + 25), BlockHandler.PARISTEEL_METAL.getStateFromMeta(5));
		worldIn.setBlockState(bp.add(i + 6, j + 2, k + 6), BlockHandler.PARISTEEL_METAL.getStateFromMeta(5));
		worldIn.setBlockState(bp.add(i + 6, j + 2, k + 7), BlockHandler.PARISTEEL_METAL.getStateFromMeta(5));
		worldIn.setBlockState(bp.add(i + 6, j + 2, k + 8), BlockHandler.PARISTEEL_METAL.getStateFromMeta(5));
		worldIn.setBlockState(bp.add(i + 6, j + 2, k + 9), BlockHandler.PARISTEEL_METAL.getStateFromMeta(5));
		worldIn.setBlockState(bp.add(i + 6, j + 2, k + 10), BlockHandler.PARISTEEL_METAL.getStateFromMeta(5));
		worldIn.setBlockState(bp.add(i + 6, j + 2, k + 11), BlockHandler.PARISTEEL_METAL.getStateFromMeta(5));
		worldIn.setBlockState(bp.add(i + 6, j + 2, k + 12), BlockHandler.PARISTEEL_METAL.getStateFromMeta(5));
		worldIn.setBlockState(bp.add(i + 6, j + 2, k + 13), BlockHandler.PARISTEEL_METAL.getStateFromMeta(5));
		worldIn.setBlockState(bp.add(i + 6, j + 2, k + 14), BlockHandler.PARISTEEL_METAL.getStateFromMeta(5));
		worldIn.setBlockState(bp.add(i + 6, j + 2, k + 15), BlockHandler.PARISTEEL_METAL.getStateFromMeta(5));
		worldIn.setBlockState(bp.add(i + 6, j + 2, k + 16), BlockHandler.PARISTEEL_METAL.getStateFromMeta(5));
		worldIn.setBlockState(bp.add(i + 6, j + 2, k + 17), BlockHandler.PARISTEEL_METAL.getStateFromMeta(5));
		worldIn.setBlockState(bp.add(i + 6, j + 2, k + 18), BlockHandler.PARISTEEL_METAL.getStateFromMeta(5));
		worldIn.setBlockState(bp.add(i + 6, j + 2, k + 19), BlockHandler.PARISTEEL_METAL.getStateFromMeta(5));
		worldIn.setBlockState(bp.add(i + 6, j + 2, k + 20), BlockHandler.PARISTEEL_METAL.getStateFromMeta(5));
		worldIn.setBlockState(bp.add(i + 6, j + 2, k + 21), BlockHandler.PARISTEEL_METAL.getStateFromMeta(5));
		worldIn.setBlockState(bp.add(i + 6, j + 2, k + 22), BlockHandler.PARISTEEL_METAL.getStateFromMeta(5));
		worldIn.setBlockState(bp.add(i + 6, j + 3, k + 5), BlockHandler.PARISTEEL_METAL.getStateFromMeta(5));
		worldIn.setBlockState(bp.add(i + 6, j + 3, k + 6), BlockHandler.PARISTEEL_METAL.getStateFromMeta(5));
		worldIn.setBlockState(bp.add(i + 6, j + 3, k + 7), BlockHandler.PARISTEEL_METAL.getStateFromMeta(5));
		worldIn.setBlockState(bp.add(i + 6, j + 3, k + 8), BlockHandler.NEOSTEEL_METAL.getStateFromMeta(1));
		worldIn.setBlockState(bp.add(i + 6, j + 3, k + 9), BlockHandler.NEOSTEEL_METAL.getStateFromMeta(1));
		worldIn.setBlockState(bp.add(i + 6, j + 3, k + 10), BlockHandler.NEOSTEEL_METAL.getStateFromMeta(1));
		worldIn.setBlockState(bp.add(i + 6, j + 3, k + 11), BlockHandler.NEOSTEEL_METAL.getStateFromMeta(1));
		worldIn.setBlockState(bp.add(i + 6, j + 3, k + 12), BlockHandler.NEOSTEEL_METAL.getStateFromMeta(1));
		worldIn.setBlockState(bp.add(i + 6, j + 3, k + 13), BlockHandler.NEOSTEEL_METAL.getStateFromMeta(1));
		worldIn.setBlockState(bp.add(i + 6, j + 3, k + 14), BlockHandler.NEOSTEEL_METAL.getStateFromMeta(1));
		worldIn.setBlockState(bp.add(i + 6, j + 3, k + 15), BlockHandler.NEOSTEEL_METAL.getStateFromMeta(1));
		worldIn.setBlockState(bp.add(i + 6, j + 3, k + 16), BlockHandler.NEOSTEEL_METAL.getStateFromMeta(1));
		worldIn.setBlockState(bp.add(i + 6, j + 3, k + 17), BlockHandler.NEOSTEEL_METAL.getStateFromMeta(1));
		worldIn.setBlockState(bp.add(i + 6, j + 3, k + 18), BlockHandler.NEOSTEEL_METAL.getStateFromMeta(1));
		worldIn.setBlockState(bp.add(i + 6, j + 3, k + 19), BlockHandler.NEOSTEEL_METAL.getStateFromMeta(1));
		worldIn.setBlockState(bp.add(i + 6, j + 3, k + 20), BlockHandler.NEOSTEEL_METAL.getStateFromMeta(1));
		worldIn.setBlockState(bp.add(i + 6, j + 3, k + 21), BlockHandler.PARISTEEL_METAL.getStateFromMeta(5));
		worldIn.setBlockState(bp.add(i + 6, j + 3, k + 22), BlockHandler.PARISTEEL_METAL.getStateFromMeta(5));
		worldIn.setBlockState(bp.add(i + 6, j + 3, k + 23), BlockHandler.PARISTEEL_METAL.getStateFromMeta(5));
		worldIn.setBlockState(bp.add(i + 6, j + 4, k + 5), BlockHandler.PARISTEEL_METAL.getStateFromMeta(5));
		worldIn.setBlockState(bp.add(i + 6, j + 4, k + 6), BlockHandler.PARISTEEL_METAL.getStateFromMeta(5));
		worldIn.setBlockState(bp.add(i + 6, j + 4, k + 7), BlockHandler.PARISTEEL_METAL.getStateFromMeta(5));
		worldIn.setBlockState(bp.add(i + 6, j + 4, k + 21), BlockHandler.PARISTEEL_METAL.getStateFromMeta(5));
		worldIn.setBlockState(bp.add(i + 6, j + 4, k + 22), BlockHandler.PARISTEEL_METAL.getStateFromMeta(5));
		worldIn.setBlockState(bp.add(i + 6, j + 4, k + 23), BlockHandler.PARISTEEL_METAL.getStateFromMeta(5));
		worldIn.setBlockState(bp.add(i + 6, j + 5, k + 5), BlockHandler.PARISTEEL_METAL.getStateFromMeta(5));
		worldIn.setBlockState(bp.add(i + 6, j + 5, k + 6), BlockHandler.PARISTEEL_METAL.getStateFromMeta(5));
		worldIn.setBlockState(bp.add(i + 6, j + 5, k + 7), BlockHandler.PARISTEEL_METAL.getStateFromMeta(5));
		worldIn.setBlockState(bp.add(i + 6, j + 5, k + 21), BlockHandler.PARISTEEL_METAL.getStateFromMeta(5));
		worldIn.setBlockState(bp.add(i + 6, j + 5, k + 22), BlockHandler.PARISTEEL_METAL.getStateFromMeta(5));
		worldIn.setBlockState(bp.add(i + 6, j + 5, k + 23), BlockHandler.PARISTEEL_METAL.getStateFromMeta(5));
		worldIn.setBlockState(bp.add(i + 6, j + 6, k + 6), BlockHandler.PARISTEEL_METAL.getStateFromMeta(3));
		worldIn.setBlockState(bp.add(i + 6, j + 6, k + 7), BlockHandler.PARISTEEL_METAL.getStateFromMeta(5));
		worldIn.setBlockState(bp.add(i + 6, j + 6, k + 21), BlockHandler.PARISTEEL_METAL.getStateFromMeta(5));
		worldIn.setBlockState(bp.add(i + 6, j + 6, k + 22), BlockHandler.PARISTEEL_METAL.getStateFromMeta(3));
		worldIn.setBlockState(bp.add(i + 6, j + 7, k + 6), (IBlockState) Blocks.STAINED_GLASS.getDefaultState().withProperty(BlockStainedGlass.COLOR, EnumDyeColor.YELLOW));
		worldIn.setBlockState(bp.add(i + 6, j + 7, k + 13), BlockHandler.PARISTEEL_METAL.getStateFromMeta(5));
		worldIn.setBlockState(bp.add(i + 6, j + 7, k + 14), Blocks.SEA_LANTERN.getDefaultState());
		worldIn.setBlockState(bp.add(i + 6, j + 7, k + 15), BlockHandler.PARISTEEL_METAL.getStateFromMeta(5));
		worldIn.setBlockState(bp.add(i + 6, j + 7, k + 22), (IBlockState) Blocks.STAINED_GLASS.getDefaultState().withProperty(BlockStainedGlass.COLOR, EnumDyeColor.YELLOW));
		worldIn.setBlockState(bp.add(i + 6, j + 8, k + 7), BlockHandler.PARISTEEL_METAL.getStateFromMeta(15));
		worldIn.setBlockState(bp.add(i + 6, j + 8, k + 8), BlockHandler.PARISTEEL_METAL.getStateFromMeta(5));
		worldIn.setBlockState(bp.add(i + 6, j + 8, k + 9), BlockHandler.PARISTEEL_METAL.getStateFromMeta(5));
		worldIn.setBlockState(bp.add(i + 6, j + 8, k + 10), BlockHandler.PARISTEEL_METAL.getStateFromMeta(5));
		worldIn.setBlockState(bp.add(i + 6, j + 8, k + 11), BlockHandler.PARISTEEL_METAL.getStateFromMeta(5));
		worldIn.setBlockState(bp.add(i + 6, j + 8, k + 12), BlockHandler.PARISTEEL_METAL.getStateFromMeta(5));
		worldIn.setBlockState(bp.add(i + 6, j + 8, k + 13), BlockHandler.PARISTEEL_METAL.getStateFromMeta(5));
		worldIn.setBlockState(bp.add(i + 6, j + 8, k + 14), BlockHandler.PARISTEEL_METAL.getStateFromMeta(5));
		worldIn.setBlockState(bp.add(i + 6, j + 8, k + 15), BlockHandler.PARISTEEL_METAL.getStateFromMeta(5));
		worldIn.setBlockState(bp.add(i + 6, j + 8, k + 16), BlockHandler.PARISTEEL_METAL.getStateFromMeta(5));
		worldIn.setBlockState(bp.add(i + 6, j + 8, k + 17), BlockHandler.PARISTEEL_METAL.getStateFromMeta(5));
		worldIn.setBlockState(bp.add(i + 6, j + 8, k + 18), BlockHandler.PARISTEEL_METAL.getStateFromMeta(5));
		worldIn.setBlockState(bp.add(i + 6, j + 8, k + 19), BlockHandler.PARISTEEL_METAL.getStateFromMeta(5));
		worldIn.setBlockState(bp.add(i + 6, j + 8, k + 20), BlockHandler.PARISTEEL_METAL.getStateFromMeta(5));
		worldIn.setBlockState(bp.add(i + 6, j + 8, k + 21), BlockHandler.PARISTEEL_METAL.getStateFromMeta(15));
		worldIn.setBlockState(bp.add(i + 6, j + 9, k + 7), BlockHandler.PARISTEEL_METAL.getStateFromMeta(3));
		worldIn.setBlockState(bp.add(i + 6, j + 9, k + 8), BlockHandler.PARISTEEL_METAL.getStateFromMeta(5));
		worldIn.setBlockState(bp.add(i + 6, j + 9, k + 9), BlockHandler.PARISTEEL_METAL.getStateFromMeta(5));
		worldIn.setBlockState(bp.add(i + 6, j + 9, k + 10), BlockHandler.NEOSTEEL_METAL.getStateFromMeta(1));
		worldIn.setBlockState(bp.add(i + 6, j + 9, k + 11), BlockHandler.NEOSTEEL_METAL.getStateFromMeta(1));
		worldIn.setBlockState(bp.add(i + 6, j + 9, k + 12), BlockHandler.NEOSTEEL_METAL.getStateFromMeta(1));
		worldIn.setBlockState(bp.add(i + 6, j + 9, k + 13), BlockHandler.NEOSTEEL_METAL.getStateFromMeta(1));
		worldIn.setBlockState(bp.add(i + 6, j + 9, k + 14), BlockHandler.NEOSTEEL_METAL.getStateFromMeta(1));
		worldIn.setBlockState(bp.add(i + 6, j + 9, k + 15), BlockHandler.NEOSTEEL_METAL.getStateFromMeta(1));
		worldIn.setBlockState(bp.add(i + 6, j + 9, k + 16), BlockHandler.NEOSTEEL_METAL.getStateFromMeta(1));
		worldIn.setBlockState(bp.add(i + 6, j + 9, k + 17), BlockHandler.NEOSTEEL_METAL.getStateFromMeta(1));
		worldIn.setBlockState(bp.add(i + 6, j + 9, k + 18), BlockHandler.NEOSTEEL_METAL.getStateFromMeta(1));
		worldIn.setBlockState(bp.add(i + 6, j + 9, k + 19), BlockHandler.PARISTEEL_METAL.getStateFromMeta(5));
		worldIn.setBlockState(bp.add(i + 6, j + 9, k + 20), BlockHandler.PARISTEEL_METAL.getStateFromMeta(5));
		worldIn.setBlockState(bp.add(i + 6, j + 9, k + 21), BlockHandler.PARISTEEL_METAL.getStateFromMeta(5));
		worldIn.setBlockState(bp.add(i + 6, j + 10, k + 8), BlockHandler.PARISTEEL_METAL.getStateFromMeta(5));
		worldIn.setBlockState(bp.add(i + 6, j + 10, k + 9), BlockHandler.PARISTEEL_METAL.getStateFromMeta(5));
		worldIn.setBlockState(bp.add(i + 6, j + 10, k + 19), BlockHandler.PARISTEEL_METAL.getStateFromMeta(5));
		worldIn.setBlockState(bp.add(i + 6, j + 10, k + 20), BlockHandler.PARISTEEL_METAL.getStateFromMeta(5));
		worldIn.setBlockState(bp.add(i + 6, j + 11, k + 9), BlockHandler.PARISTEEL_METAL.getStateFromMeta(5));
		worldIn.setBlockState(bp.add(i + 6, j + 11, k + 19), BlockHandler.PARISTEEL_METAL.getStateFromMeta(5));
		worldIn.setBlockState(bp.add(i + 6, j + 12, k + 10), BlockHandler.PARISTEEL_METAL.getStateFromMeta(5));
		worldIn.setBlockState(bp.add(i + 6, j + 12, k + 11), BlockHandler.PARISTEEL_METAL.getStateFromMeta(5));
		worldIn.setBlockState(bp.add(i + 6, j + 12, k + 12), BlockHandler.PARISTEEL_METAL.getStateFromMeta(5));
		worldIn.setBlockState(bp.add(i + 6, j + 12, k + 13), BlockHandler.PARISTEEL_METAL.getStateFromMeta(5));
		worldIn.setBlockState(bp.add(i + 6, j + 12, k + 14), BlockHandler.PARISTEEL_METAL.getStateFromMeta(5));
		worldIn.setBlockState(bp.add(i + 6, j + 12, k + 15), BlockHandler.PARISTEEL_METAL.getStateFromMeta(5));
		worldIn.setBlockState(bp.add(i + 6, j + 12, k + 16), BlockHandler.PARISTEEL_METAL.getStateFromMeta(5));
		worldIn.setBlockState(bp.add(i + 6, j + 12, k + 17), BlockHandler.PARISTEEL_METAL.getStateFromMeta(5));
		worldIn.setBlockState(bp.add(i + 6, j + 12, k + 18), BlockHandler.PARISTEEL_METAL.getStateFromMeta(5));
		worldIn.setBlockState(bp.add(i + 6, j + 13, k + 12), BlockHandler.PARISTEEL_METAL.getStateFromMeta(3));
		worldIn.setBlockState(bp.add(i + 6, j + 13, k + 13), BlockHandler.PARISTEEL_METAL.getStateFromMeta(3));
		worldIn.setBlockState(bp.add(i + 6, j + 13, k + 14), BlockHandler.PARISTEEL_METAL.getStateFromMeta(3));
		worldIn.setBlockState(bp.add(i + 6, j + 13, k + 15), BlockHandler.PARISTEEL_METAL.getStateFromMeta(3));
		worldIn.setBlockState(bp.add(i + 6, j + 13, k + 16), BlockHandler.PARISTEEL_METAL.getStateFromMeta(3));
		worldIn.setBlockState(bp.add(i + 6, j + 14, k + 14), BlockHandler.PARISTEEL_METAL.getStateFromMeta(15));
		worldIn.setBlockState(bp.add(i + 6, j + 15, k + 14), BlockHandler.PARISTEEL_METAL.getStateFromMeta(15));
		worldIn.setBlockState(bp.add(i + 6, j + 16, k + 14), BlockHandler.PARISTEEL_METAL.getStateFromMeta(15));
		worldIn.setBlockState(bp.add(i + 6, j + 17, k + 14), BlockHandler.PARISTEEL_METAL.getStateFromMeta(15));
		worldIn.setBlockState(bp.add(i + 6, j + 18, k + 14), BlockHandler.PARISTEEL_METAL.getStateFromMeta(15));
		worldIn.setBlockState(bp.add(i + 7, j + 1, k + 5), BlockHandler.PARISTEEL_METAL.getStateFromMeta(5));
		worldIn.setBlockState(bp.add(i + 7, j + 1, k + 6), BlockHandler.PARISTEEL_METAL.getStateFromMeta(5));
		worldIn.setBlockState(bp.add(i + 7, j + 1, k + 7), BlockHandler.PARISTEEL_METAL.getStateFromMeta(5));
		worldIn.setBlockState(bp.add(i + 7, j + 1, k + 8), BlockHandler.PARISTEEL_METAL.getStateFromMeta(5));
		worldIn.setBlockState(bp.add(i + 7, j + 1, k + 9), BlockHandler.PARISTEEL_METAL.getStateFromMeta(5));
		worldIn.setBlockState(bp.add(i + 7, j + 1, k + 10), BlockHandler.PARISTEEL_METAL.getStateFromMeta(5));
		worldIn.setBlockState(bp.add(i + 7, j + 1, k + 11), BlockHandler.PARISTEEL_METAL.getStateFromMeta(5));
		worldIn.setBlockState(bp.add(i + 7, j + 1, k + 12), BlockHandler.PARISTEEL_METAL.getStateFromMeta(5));
		worldIn.setBlockState(bp.add(i + 7, j + 1, k + 13), BlockHandler.PARISTEEL_METAL.getStateFromMeta(5));
		worldIn.setBlockState(bp.add(i + 7, j + 1, k + 14), BlockHandler.PARISTEEL_METAL.getStateFromMeta(5));
		worldIn.setBlockState(bp.add(i + 7, j + 1, k + 15), BlockHandler.PARISTEEL_METAL.getStateFromMeta(5));
		worldIn.setBlockState(bp.add(i + 7, j + 1, k + 16), BlockHandler.PARISTEEL_METAL.getStateFromMeta(5));
		worldIn.setBlockState(bp.add(i + 7, j + 1, k + 17), BlockHandler.PARISTEEL_METAL.getStateFromMeta(5));
		worldIn.setBlockState(bp.add(i + 7, j + 1, k + 18), BlockHandler.PARISTEEL_METAL.getStateFromMeta(5));
		worldIn.setBlockState(bp.add(i + 7, j + 1, k + 19), BlockHandler.PARISTEEL_METAL.getStateFromMeta(5));
		worldIn.setBlockState(bp.add(i + 7, j + 1, k + 20), BlockHandler.PARISTEEL_METAL.getStateFromMeta(5));
		worldIn.setBlockState(bp.add(i + 7, j + 1, k + 21), BlockHandler.PARISTEEL_METAL.getStateFromMeta(5));
		worldIn.setBlockState(bp.add(i + 7, j + 1, k + 22), BlockHandler.PARISTEEL_METAL.getStateFromMeta(5));
		worldIn.setBlockState(bp.add(i + 7, j + 2, k + 5), BlockHandler.PARISTEEL_METAL.getStateFromMeta(5));
		worldIn.setBlockState(bp.add(i + 7, j + 2, k + 6), BlockHandler.PARISTEEL_METAL.getStateFromMeta(5));
		worldIn.setBlockState(bp.add(i + 7, j + 2, k + 7), BlockHandler.PARISTEEL_METAL.getStateFromMeta(5));
		worldIn.setBlockState(bp.add(i + 7, j + 2, k + 8), BlockHandler.PARISTEEL_METAL.getStateFromMeta(5));
		worldIn.setBlockState(bp.add(i + 7, j + 2, k + 9), BlockHandler.PARISTEEL_METAL.getStateFromMeta(5));
		worldIn.setBlockState(bp.add(i + 7, j + 2, k + 10), BlockHandler.PARISTEEL_METAL.getStateFromMeta(5));
		worldIn.setBlockState(bp.add(i + 7, j + 2, k + 11), BlockHandler.PARISTEEL_METAL.getStateFromMeta(5));
		worldIn.setBlockState(bp.add(i + 7, j + 2, k + 12), BlockHandler.PARISTEEL_METAL.getStateFromMeta(5));
		worldIn.setBlockState(bp.add(i + 7, j + 2, k + 13), BlockHandler.PARISTEEL_METAL.getStateFromMeta(5));
		worldIn.setBlockState(bp.add(i + 7, j + 2, k + 14), BlockHandler.PARISTEEL_METAL.getStateFromMeta(5));
		worldIn.setBlockState(bp.add(i + 7, j + 2, k + 15), BlockHandler.PARISTEEL_METAL.getStateFromMeta(5));
		worldIn.setBlockState(bp.add(i + 7, j + 2, k + 16), BlockHandler.PARISTEEL_METAL.getStateFromMeta(5));
		worldIn.setBlockState(bp.add(i + 7, j + 2, k + 17), BlockHandler.PARISTEEL_METAL.getStateFromMeta(5));
		worldIn.setBlockState(bp.add(i + 7, j + 2, k + 18), BlockHandler.PARISTEEL_METAL.getStateFromMeta(5));
		worldIn.setBlockState(bp.add(i + 7, j + 2, k + 19), BlockHandler.PARISTEEL_METAL.getStateFromMeta(5));
		worldIn.setBlockState(bp.add(i + 7, j + 2, k + 20), BlockHandler.PARISTEEL_METAL.getStateFromMeta(5));
		worldIn.setBlockState(bp.add(i + 7, j + 2, k + 21), BlockHandler.PARISTEEL_METAL.getStateFromMeta(5));
		worldIn.setBlockState(bp.add(i + 7, j + 2, k + 22), BlockHandler.PARISTEEL_METAL.getStateFromMeta(5));
		worldIn.setBlockState(bp.add(i + 7, j + 2, k + 23), BlockHandler.PARISTEEL_METAL.getStateFromMeta(5));
		worldIn.setBlockState(bp.add(i + 7, j + 3, k + 4), BlockHandler.PARISTEEL_METAL.getStateFromMeta(15));
		worldIn.setBlockState(bp.add(i + 7, j + 3, k + 5), BlockHandler.PARISTEEL_METAL.getStateFromMeta(5));
		worldIn.setBlockState(bp.add(i + 7, j + 3, k + 6), BlockHandler.PARISTEEL_METAL.getStateFromMeta(5));
		worldIn.setBlockState(bp.add(i + 7, j + 3, k + 7), BlockHandler.NEOSTEEL_METAL.getStateFromMeta(1));
		worldIn.setBlockState(bp.add(i + 7, j + 3, k + 8), BlockHandler.NEOSTEEL_METAL.getStateFromMeta(1));
		worldIn.setBlockState(bp.add(i + 7, j + 3, k + 9), BlockHandler.NEOSTEEL_METAL.getStateFromMeta(1));
		worldIn.setBlockState(bp.add(i + 7, j + 3, k + 10), BlockHandler.NEOSTEEL_METAL.getStateFromMeta(1));
		worldIn.setBlockState(bp.add(i + 7, j + 3, k + 11), BlockHandler.NEOSTEEL_METAL.getStateFromMeta(1));
		worldIn.setBlockState(bp.add(i + 7, j + 3, k + 12), BlockHandler.NEOSTEEL_METAL.getStateFromMeta(1));
		worldIn.setBlockState(bp.add(i + 7, j + 3, k + 13), BlockHandler.NEOSTEEL_METAL.getStateFromMeta(1));
		worldIn.setBlockState(bp.add(i + 7, j + 3, k + 14), BlockHandler.NEOSTEEL_METAL.getStateFromMeta(1));
		worldIn.setBlockState(bp.add(i + 7, j + 3, k + 15), BlockHandler.NEOSTEEL_METAL.getStateFromMeta(1));
		worldIn.setBlockState(bp.add(i + 7, j + 3, k + 16), BlockHandler.NEOSTEEL_METAL.getStateFromMeta(1));
		worldIn.setBlockState(bp.add(i + 7, j + 3, k + 17), BlockHandler.NEOSTEEL_METAL.getStateFromMeta(1));
		worldIn.setBlockState(bp.add(i + 7, j + 3, k + 18), BlockHandler.NEOSTEEL_METAL.getStateFromMeta(1));
		worldIn.setBlockState(bp.add(i + 7, j + 3, k + 19), BlockHandler.NEOSTEEL_METAL.getStateFromMeta(1));
		worldIn.setBlockState(bp.add(i + 7, j + 3, k + 20), BlockHandler.NEOSTEEL_METAL.getStateFromMeta(1));
		worldIn.setBlockState(bp.add(i + 7, j + 3, k + 21), BlockHandler.NEOSTEEL_METAL.getStateFromMeta(1));
		worldIn.setBlockState(bp.add(i + 7, j + 3, k + 22), BlockHandler.PARISTEEL_METAL.getStateFromMeta(5));
		worldIn.setBlockState(bp.add(i + 7, j + 3, k + 23), BlockHandler.PARISTEEL_METAL.getStateFromMeta(5));
		worldIn.setBlockState(bp.add(i + 7, j + 3, k + 24), BlockHandler.PARISTEEL_METAL.getStateFromMeta(15));
		worldIn.setBlockState(bp.add(i + 7, j + 4, k + 4), BlockHandler.PARISTEEL_METAL.getStateFromMeta(15));
		worldIn.setBlockState(bp.add(i + 7, j + 4, k + 5), BlockHandler.PARISTEEL_METAL.getStateFromMeta(5));
		worldIn.setBlockState(bp.add(i + 7, j + 4, k + 6), BlockHandler.PARISTEEL_METAL.getStateFromMeta(5));
		worldIn.setBlockState(bp.add(i + 7, j + 4, k + 22), BlockHandler.PARISTEEL_METAL.getStateFromMeta(5));
		worldIn.setBlockState(bp.add(i + 7, j + 4, k + 23), BlockHandler.PARISTEEL_METAL.getStateFromMeta(5));
		worldIn.setBlockState(bp.add(i + 7, j + 4, k + 24), BlockHandler.PARISTEEL_METAL.getStateFromMeta(15));
		worldIn.setBlockState(bp.add(i + 7, j + 5, k + 4), BlockHandler.PARISTEEL_METAL.getStateFromMeta(15));
		worldIn.setBlockState(bp.add(i + 7, j + 5, k + 5), BlockHandler.PARISTEEL_METAL.getStateFromMeta(5));
		worldIn.setBlockState(bp.add(i + 7, j + 5, k + 6), BlockHandler.PARISTEEL_METAL.getStateFromMeta(5));
		worldIn.setBlockState(bp.add(i + 7, j + 5, k + 22), BlockHandler.PARISTEEL_METAL.getStateFromMeta(5));
		worldIn.setBlockState(bp.add(i + 7, j + 5, k + 23), BlockHandler.PARISTEEL_METAL.getStateFromMeta(5));
		worldIn.setBlockState(bp.add(i + 7, j + 5, k + 24), BlockHandler.PARISTEEL_METAL.getStateFromMeta(15));
		worldIn.setBlockState(bp.add(i + 7, j + 6, k + 2), BlockHandler.PARISTEEL_METAL.getStateFromMeta(5));
		worldIn.setBlockState(bp.add(i + 7, j + 6, k + 4), BlockHandler.PARISTEEL_METAL.getStateFromMeta(15));
		worldIn.setBlockState(bp.add(i + 7, j + 6, k + 5), BlockHandler.PARISTEEL_METAL.getStateFromMeta(3));
		worldIn.setBlockState(bp.add(i + 7, j + 6, k + 6), BlockHandler.PARISTEEL_METAL.getStateFromMeta(5));
		worldIn.setBlockState(bp.add(i + 7, j + 6, k + 22), BlockHandler.PARISTEEL_METAL.getStateFromMeta(5));
		worldIn.setBlockState(bp.add(i + 7, j + 6, k + 23), BlockHandler.PARISTEEL_METAL.getStateFromMeta(3));
		worldIn.setBlockState(bp.add(i + 7, j + 6, k + 24), BlockHandler.PARISTEEL_METAL.getStateFromMeta(15));
		worldIn.setBlockState(bp.add(i + 7, j + 7, k + 2), BlockHandler.PARISTEEL_METAL.getStateFromMeta(5));
		worldIn.setBlockState(bp.add(i + 7, j + 7, k + 5), (IBlockState) Blocks.STAINED_GLASS.getDefaultState().withProperty(BlockStainedGlass.COLOR, EnumDyeColor.YELLOW));
		worldIn.setBlockState(bp.add(i + 7, j + 7, k + 13), BlockHandler.PARISTEEL_METAL.getStateFromMeta(5));
		worldIn.setBlockState(bp.add(i + 7, j + 7, k + 14), Blocks.SEA_LANTERN.getDefaultState());
		worldIn.setBlockState(bp.add(i + 7, j + 7, k + 15), BlockHandler.PARISTEEL_METAL.getStateFromMeta(5));
		worldIn.setBlockState(bp.add(i + 7, j + 7, k + 23), (IBlockState) Blocks.STAINED_GLASS.getDefaultState().withProperty(BlockStainedGlass.COLOR, EnumDyeColor.YELLOW));
		worldIn.setBlockState(bp.add(i + 7, j + 8, k + 6), BlockHandler.PARISTEEL_METAL.getStateFromMeta(15));
		worldIn.setBlockState(bp.add(i + 7, j + 8, k + 7), BlockHandler.PARISTEEL_METAL.getStateFromMeta(5));
		worldIn.setBlockState(bp.add(i + 7, j + 8, k + 8), BlockHandler.PARISTEEL_METAL.getStateFromMeta(5));
		worldIn.setBlockState(bp.add(i + 7, j + 8, k + 9), BlockHandler.PARISTEEL_METAL.getStateFromMeta(5));
		worldIn.setBlockState(bp.add(i + 7, j + 8, k + 10), BlockHandler.PARISTEEL_METAL.getStateFromMeta(5));
		worldIn.setBlockState(bp.add(i + 7, j + 8, k + 11), BlockHandler.PARISTEEL_METAL.getStateFromMeta(5));
		worldIn.setBlockState(bp.add(i + 7, j + 8, k + 12), BlockHandler.PARISTEEL_METAL.getStateFromMeta(5));
		worldIn.setBlockState(bp.add(i + 7, j + 8, k + 13), BlockHandler.PARISTEEL_METAL.getStateFromMeta(5));
		worldIn.setBlockState(bp.add(i + 7, j + 8, k + 14), BlockHandler.PARISTEEL_METAL.getStateFromMeta(5));
		worldIn.setBlockState(bp.add(i + 7, j + 8, k + 15), BlockHandler.PARISTEEL_METAL.getStateFromMeta(5));
		worldIn.setBlockState(bp.add(i + 7, j + 8, k + 16), BlockHandler.PARISTEEL_METAL.getStateFromMeta(5));
		worldIn.setBlockState(bp.add(i + 7, j + 8, k + 17), BlockHandler.PARISTEEL_METAL.getStateFromMeta(5));
		worldIn.setBlockState(bp.add(i + 7, j + 8, k + 18), BlockHandler.PARISTEEL_METAL.getStateFromMeta(5));
		worldIn.setBlockState(bp.add(i + 7, j + 8, k + 19), BlockHandler.PARISTEEL_METAL.getStateFromMeta(5));
		worldIn.setBlockState(bp.add(i + 7, j + 8, k + 20), BlockHandler.PARISTEEL_METAL.getStateFromMeta(5));
		worldIn.setBlockState(bp.add(i + 7, j + 8, k + 21), BlockHandler.PARISTEEL_METAL.getStateFromMeta(5));
		worldIn.setBlockState(bp.add(i + 7, j + 8, k + 22), BlockHandler.PARISTEEL_METAL.getStateFromMeta(15));
		worldIn.setBlockState(bp.add(i + 7, j + 9, k + 6), BlockHandler.PARISTEEL_METAL.getStateFromMeta(3));
		worldIn.setBlockState(bp.add(i + 7, j + 9, k + 7), BlockHandler.PARISTEEL_METAL.getStateFromMeta(5));
		worldIn.setBlockState(bp.add(i + 7, j + 9, k + 8), BlockHandler.PARISTEEL_METAL.getStateFromMeta(5));
		worldIn.setBlockState(bp.add(i + 7, j + 9, k + 9), BlockHandler.PARISTEEL_METAL.getStateFromMeta(5));
		worldIn.setBlockState(bp.add(i + 7, j + 9, k + 10), BlockHandler.NEOSTEEL_METAL.getStateFromMeta(1));
		worldIn.setBlockState(bp.add(i + 7, j + 9, k + 11), BlockHandler.NEOSTEEL_METAL.getStateFromMeta(1));
		worldIn.setBlockState(bp.add(i + 7, j + 9, k + 12), BlockHandler.NEOSTEEL_METAL.getStateFromMeta(1));
		worldIn.setBlockState(bp.add(i + 7, j + 9, k + 13), BlockHandler.NEOSTEEL_METAL.getStateFromMeta(1));
		worldIn.setBlockState(bp.add(i + 7, j + 9, k + 14), BlockHandler.NEOSTEEL_METAL.getStateFromMeta(1));
		worldIn.setBlockState(bp.add(i + 7, j + 9, k + 15), BlockHandler.NEOSTEEL_METAL.getStateFromMeta(1));
		worldIn.setBlockState(bp.add(i + 7, j + 9, k + 16), BlockHandler.NEOSTEEL_METAL.getStateFromMeta(1));
		worldIn.setBlockState(bp.add(i + 7, j + 9, k + 17), BlockHandler.NEOSTEEL_METAL.getStateFromMeta(1));
		worldIn.setBlockState(bp.add(i + 7, j + 9, k + 18), BlockHandler.NEOSTEEL_METAL.getStateFromMeta(1));
		worldIn.setBlockState(bp.add(i + 7, j + 9, k + 19), BlockHandler.NEOSTEEL_METAL.getStateFromMeta(1));
		worldIn.setBlockState(bp.add(i + 7, j + 9, k + 20), BlockHandler.PARISTEEL_METAL.getStateFromMeta(5));
		worldIn.setBlockState(bp.add(i + 7, j + 9, k + 21), BlockHandler.PARISTEEL_METAL.getStateFromMeta(5));
		worldIn.setBlockState(bp.add(i + 7, j + 9, k + 22), BlockHandler.PARISTEEL_METAL.getStateFromMeta(5));
		worldIn.setBlockState(bp.add(i + 7, j + 10, k + 7), BlockHandler.PARISTEEL_METAL.getStateFromMeta(5));
		worldIn.setBlockState(bp.add(i + 7, j + 10, k + 8), BlockHandler.PARISTEEL_METAL.getStateFromMeta(5));
		worldIn.setBlockState(bp.add(i + 7, j + 10, k + 9), BlockHandler.PARISTEEL_METAL.getStateFromMeta(5));
		worldIn.setBlockState(bp.add(i + 7, j + 10, k + 19), Blocks.SEA_LANTERN.getDefaultState());
		worldIn.setBlockState(bp.add(i + 7, j + 10, k + 20), BlockHandler.PARISTEEL_METAL.getStateFromMeta(5));
		worldIn.setBlockState(bp.add(i + 7, j + 10, k + 21), BlockHandler.PARISTEEL_METAL.getStateFromMeta(5));
		worldIn.setBlockState(bp.add(i + 7, j + 11, k + 8), BlockHandler.PARISTEEL_METAL.getStateFromMeta(15));
		worldIn.setBlockState(bp.add(i + 7, j + 11, k + 9), BlockHandler.PARISTEEL_METAL.getStateFromMeta(5));
		worldIn.setBlockState(bp.add(i + 7, j + 11, k + 19), Blocks.SEA_LANTERN.getDefaultState());
		worldIn.setBlockState(bp.add(i + 7, j + 11, k + 20), BlockHandler.PARISTEEL_METAL.getStateFromMeta(5));
		worldIn.setBlockState(bp.add(i + 7, j + 12, k + 9), BlockHandler.PARISTEEL_METAL.getStateFromMeta(15));
		worldIn.setBlockState(bp.add(i + 7, j + 12, k + 10), BlockHandler.PARISTEEL_METAL.getStateFromMeta(5));
		worldIn.setBlockState(bp.add(i + 7, j + 12, k + 11), BlockHandler.PARISTEEL_METAL.getStateFromMeta(5));
		worldIn.setBlockState(bp.add(i + 7, j + 12, k + 12), BlockHandler.PARISTEEL_METAL.getStateFromMeta(5));
		worldIn.setBlockState(bp.add(i + 7, j + 12, k + 13), BlockHandler.PARISTEEL_METAL.getStateFromMeta(5));
		worldIn.setBlockState(bp.add(i + 7, j + 12, k + 14), BlockHandler.PARISTEEL_METAL.getStateFromMeta(5));
		worldIn.setBlockState(bp.add(i + 7, j + 12, k + 15), BlockHandler.PARISTEEL_METAL.getStateFromMeta(5));
		worldIn.setBlockState(bp.add(i + 7, j + 12, k + 16), BlockHandler.PARISTEEL_METAL.getStateFromMeta(5));
		worldIn.setBlockState(bp.add(i + 7, j + 12, k + 17), BlockHandler.PARISTEEL_METAL.getStateFromMeta(5));
		worldIn.setBlockState(bp.add(i + 7, j + 12, k + 18), BlockHandler.PARISTEEL_METAL.getStateFromMeta(5));
		worldIn.setBlockState(bp.add(i + 7, j + 12, k + 19), BlockHandler.PARISTEEL_METAL.getStateFromMeta(5));
		worldIn.setBlockState(bp.add(i + 7, j + 13, k + 10), BlockHandler.PARISTEEL_METAL.getStateFromMeta(15));
		worldIn.setBlockState(bp.add(i + 7, j + 13, k + 11), BlockHandler.PARISTEEL_METAL.getStateFromMeta(15));
		worldIn.setBlockState(bp.add(i + 7, j + 13, k + 12), BlockHandler.PARISTEEL_METAL.getStateFromMeta(15));
		worldIn.setBlockState(bp.add(i + 7, j + 13, k + 13), BlockHandler.PARISTEEL_METAL.getStateFromMeta(15));
		worldIn.setBlockState(bp.add(i + 7, j + 13, k + 14), BlockHandler.PARISTEEL_METAL.getStateFromMeta(15));
		worldIn.setBlockState(bp.add(i + 7, j + 13, k + 15), BlockHandler.PARISTEEL_METAL.getStateFromMeta(15));
		worldIn.setBlockState(bp.add(i + 7, j + 13, k + 16), BlockHandler.PARISTEEL_METAL.getStateFromMeta(15));
		worldIn.setBlockState(bp.add(i + 7, j + 13, k + 17), BlockHandler.PARISTEEL_METAL.getStateFromMeta(15));
		worldIn.setBlockState(bp.add(i + 7, j + 13, k + 18), BlockHandler.PARISTEEL_METAL.getStateFromMeta(15));
		worldIn.setBlockState(bp.add(i + 8, j + 0, k + 0), BlockHandler.PARISTEEL_METAL.getStateFromMeta(5));
		worldIn.setBlockState(bp.add(i + 8, j + 1, k + 1), BlockHandler.PARISTEEL_METAL.getStateFromMeta(5));
		worldIn.setBlockState(bp.add(i + 8, j + 1, k + 2), BlockHandler.PARISTEEL_METAL.getStateFromMeta(5));
		worldIn.setBlockState(bp.add(i + 8, j + 1, k + 3), BlockHandler.PARISTEEL_METAL.getStateFromMeta(5));
		worldIn.setBlockState(bp.add(i + 8, j + 1, k + 4), BlockHandler.PARISTEEL_METAL.getStateFromMeta(5));
		worldIn.setBlockState(bp.add(i + 8, j + 1, k + 5), BlockHandler.PARISTEEL_METAL.getStateFromMeta(5));
		worldIn.setBlockState(bp.add(i + 8, j + 1, k + 6), BlockHandler.PARISTEEL_METAL.getStateFromMeta(5));
		worldIn.setBlockState(bp.add(i + 8, j + 1, k + 7), BlockHandler.PARISTEEL_METAL.getStateFromMeta(5));
		worldIn.setBlockState(bp.add(i + 8, j + 1, k + 8), BlockHandler.PARISTEEL_METAL.getStateFromMeta(5));
		worldIn.setBlockState(bp.add(i + 8, j + 1, k + 9), BlockHandler.PARISTEEL_METAL.getStateFromMeta(5));
		worldIn.setBlockState(bp.add(i + 8, j + 1, k + 10), BlockHandler.PARISTEEL_METAL.getStateFromMeta(5));
		worldIn.setBlockState(bp.add(i + 8, j + 1, k + 11), BlockHandler.PARISTEEL_METAL.getStateFromMeta(5));
		worldIn.setBlockState(bp.add(i + 8, j + 1, k + 12), BlockHandler.PARISTEEL_METAL.getStateFromMeta(5));
		worldIn.setBlockState(bp.add(i + 8, j + 1, k + 13), BlockHandler.PARISTEEL_METAL.getStateFromMeta(5));
		worldIn.setBlockState(bp.add(i + 8, j + 1, k + 14), BlockHandler.PARISTEEL_METAL.getStateFromMeta(5));
		worldIn.setBlockState(bp.add(i + 8, j + 1, k + 15), BlockHandler.PARISTEEL_METAL.getStateFromMeta(5));
		worldIn.setBlockState(bp.add(i + 8, j + 1, k + 16), BlockHandler.PARISTEEL_METAL.getStateFromMeta(5));
		worldIn.setBlockState(bp.add(i + 8, j + 1, k + 17), BlockHandler.PARISTEEL_METAL.getStateFromMeta(5));
		worldIn.setBlockState(bp.add(i + 8, j + 1, k + 18), BlockHandler.PARISTEEL_METAL.getStateFromMeta(5));
		worldIn.setBlockState(bp.add(i + 8, j + 1, k + 19), BlockHandler.PARISTEEL_METAL.getStateFromMeta(5));
		worldIn.setBlockState(bp.add(i + 8, j + 1, k + 20), BlockHandler.PARISTEEL_METAL.getStateFromMeta(5));
		worldIn.setBlockState(bp.add(i + 8, j + 1, k + 21), BlockHandler.PARISTEEL_METAL.getStateFromMeta(5));
		worldIn.setBlockState(bp.add(i + 8, j + 1, k + 22), BlockHandler.PARISTEEL_METAL.getStateFromMeta(5));
		worldIn.setBlockState(bp.add(i + 8, j + 1, k + 23), BlockHandler.PARISTEEL_METAL.getStateFromMeta(5));
		worldIn.setBlockState(bp.add(i + 8, j + 2, k + 2), BlockHandler.PARISTEEL_METAL.getStateFromMeta(5));
		worldIn.setBlockState(bp.add(i + 8, j + 2, k + 3), BlockHandler.PARISTEEL_METAL.getStateFromMeta(5));
		worldIn.setBlockState(bp.add(i + 8, j + 2, k + 4), BlockHandler.PARISTEEL_METAL.getStateFromMeta(5));
		worldIn.setBlockState(bp.add(i + 8, j + 2, k + 5), BlockHandler.PARISTEEL_METAL.getStateFromMeta(5));
		worldIn.setBlockState(bp.add(i + 8, j + 2, k + 6), BlockHandler.PARISTEEL_METAL.getStateFromMeta(5));
		worldIn.setBlockState(bp.add(i + 8, j + 2, k + 7), BlockHandler.PARISTEEL_METAL.getStateFromMeta(5));
		worldIn.setBlockState(bp.add(i + 8, j + 2, k + 8), BlockHandler.PARISTEEL_METAL.getStateFromMeta(5));
		worldIn.setBlockState(bp.add(i + 8, j + 2, k + 9), BlockHandler.PARISTEEL_METAL.getStateFromMeta(5));
		worldIn.setBlockState(bp.add(i + 8, j + 2, k + 10), BlockHandler.PARISTEEL_METAL.getStateFromMeta(5));
		worldIn.setBlockState(bp.add(i + 8, j + 2, k + 11), BlockHandler.PARISTEEL_METAL.getStateFromMeta(5));
		worldIn.setBlockState(bp.add(i + 8, j + 2, k + 12), BlockHandler.PARISTEEL_METAL.getStateFromMeta(5));
		worldIn.setBlockState(bp.add(i + 8, j + 2, k + 13), BlockHandler.PARISTEEL_METAL.getStateFromMeta(5));
		worldIn.setBlockState(bp.add(i + 8, j + 2, k + 14), BlockHandler.PARISTEEL_METAL.getStateFromMeta(5));
		worldIn.setBlockState(bp.add(i + 8, j + 2, k + 15), BlockHandler.PARISTEEL_METAL.getStateFromMeta(5));
		worldIn.setBlockState(bp.add(i + 8, j + 2, k + 16), BlockHandler.PARISTEEL_METAL.getStateFromMeta(5));
		worldIn.setBlockState(bp.add(i + 8, j + 2, k + 17), BlockHandler.PARISTEEL_METAL.getStateFromMeta(5));
		worldIn.setBlockState(bp.add(i + 8, j + 2, k + 18), BlockHandler.PARISTEEL_METAL.getStateFromMeta(5));
		worldIn.setBlockState(bp.add(i + 8, j + 2, k + 19), BlockHandler.PARISTEEL_METAL.getStateFromMeta(5));
		worldIn.setBlockState(bp.add(i + 8, j + 2, k + 20), BlockHandler.PARISTEEL_METAL.getStateFromMeta(5));
		worldIn.setBlockState(bp.add(i + 8, j + 2, k + 21), BlockHandler.PARISTEEL_METAL.getStateFromMeta(5));
		worldIn.setBlockState(bp.add(i + 8, j + 2, k + 22), BlockHandler.PARISTEEL_METAL.getStateFromMeta(5));
		worldIn.setBlockState(bp.add(i + 8, j + 2, k + 23), BlockHandler.PARISTEEL_METAL.getStateFromMeta(5));
		worldIn.setBlockState(bp.add(i + 8, j + 2, k + 24), BlockHandler.PARISTEEL_METAL.getStateFromMeta(5));
		worldIn.setBlockState(bp.add(i + 8, j + 3, k + 2), BlockHandler.PARISTEEL_METAL.getStateFromMeta(5));
		worldIn.setBlockState(bp.add(i + 8, j + 3, k + 3), BlockHandler.PARISTEEL_METAL.getStateFromMeta(5));
		worldIn.setBlockState(bp.add(i + 8, j + 3, k + 4), BlockHandler.PARISTEEL_METAL.getStateFromMeta(5));
		worldIn.setBlockState(bp.add(i + 8, j + 3, k + 5), BlockHandler.PARISTEEL_METAL.getStateFromMeta(5));
		worldIn.setBlockState(bp.add(i + 8, j + 3, k + 6), BlockHandler.NEOSTEEL_METAL.getStateFromMeta(1));
		worldIn.setBlockState(bp.add(i + 8, j + 3, k + 7), BlockHandler.NEOSTEEL_METAL.getStateFromMeta(1));
		worldIn.setBlockState(bp.add(i + 8, j + 3, k + 8), BlockHandler.NEOSTEEL_METAL.getStateFromMeta(1));
