package ga.scmc.worldgen.structure;

import java.util.Random;

import ga.scmc.handlers.BlockHandler;
import ga.scmc.handlers.ConfigurationHandler;
import ga.scmc.lib.LogHelper;
import net.minecraft.block.Block;
import net.minecraft.block.material.Material;
import net.minecraft.block.state.IBlockState;
import net.minecraft.init.Blocks;
import net.minecraft.util.math.BlockPos;
import net.minecraft.world.World;

public class StructureGeyserTemplate extends SCWorldGenerator {
	
	@Override
	public boolean generate(IBlockState state, IBlockState state2, World world, Random rand, int offsetX, int offsetY, int offsetZ, BlockPos pos, boolean flag) {
		generate_r0(state, state2, world, offsetX, offsetY, offsetZ, pos, flag);
		return true;
	}

	public boolean generate_r0(IBlockState state, IBlockState state2, World world, int offsetX, int offsetY, int offsetZ, BlockPos pos, boolean flag) {
		if(flag) {
			if(!LocationIsValidSpawn(world, pos) || !LocationIsValidSpawn(world, pos.add(16, 0, 0)) || !LocationIsValidSpawn(world, pos.add(16, 0, 16)) || !LocationIsValidSpawn(world, pos.add(0, 0, 16))) {
				return false;
			}
		}
		if(ConfigurationHandler.BOOL_DEBUG_MODE_ENABLED == true) {
			LogHelper.logger.info("A Geyser is spawning!");
		}
		int x = offsetX;
		int y = offsetY;
		int z = offsetZ;
		world.setBlockState(pos.add(x+4, y+0, z+3), state, 2);
		world.setBlockState(pos.add(x+5, y+0, z+3), state, 2);
		world.setBlockState(pos.add(x+6, y+0, z+3), state, 2);
		world.setBlockState(pos.add(x+7, y+0, z+3), state, 2);
		world.setBlockState(pos.add(x+4, y+0, z+4), state, 2);
		world.setBlockState(pos.add(x+5, y+0, z+4), state, 2);
		world.setBlockState(pos.add(x+6, y+0, z+4), state, 2);
		world.setBlockState(pos.add(x+7, y+0, z+4), state, 2);
		world.setBlockState(pos.add(x+8, y+0, z+4), state, 2);
		world.setBlockState(pos.add(x+3, y+0, z+5), state, 2);
		world.setBlockState(pos.add(x+4, y+0, z+5), state, 2);
		world.setBlockState(pos.add(x+5, y+0, z+5), state, 2);
		world.setBlockState(pos.add(x+6, y+0, z+5), state, 2);
		world.setBlockState(pos.add(x+7, y+0, z+5), state, 2);
		world.setBlockState(pos.add(x+8, y+0, z+5), state, 2);
		world.setBlockState(pos.add(x+9, y+0, z+5), state, 2);
		world.setBlockState(pos.add(x+3, y+0, z+6), state, 2);
		world.setBlockState(pos.add(x+4, y+0, z+6), state, 2);
		world.setBlockState(pos.add(x+5, y+0, z+6), state, 2);
		world.setBlockState(pos.add(x+6, y+0, z+6), state, 2);
		world.setBlockState(pos.add(x+7, y+0, z+6), state, 2);
		world.setBlockState(pos.add(x+8, y+0, z+6), state, 2);
		world.setBlockState(pos.add(x+9, y+0, z+6), state, 2);
		world.setBlockState(pos.add(x+10, y+0, z+6), state, 2);
		world.setBlockState(pos.add(x+3, y+0, z+7), state, 2);
		world.setBlockState(pos.add(x+4, y+0, z+7), state, 2);
		world.setBlockState(pos.add(x+5, y+0, z+7), state, 2);
		world.setBlockState(pos.add(x+6, y+0, z+7), state, 2);
		world.setBlockState(pos.add(x+7, y+0, z+7), state, 2);
		world.setBlockState(pos.add(x+8, y+0, z+7), state, 2);
		world.setBlockState(pos.add(x+9, y+0, z+7), state, 2);
		world.setBlockState(pos.add(x+10, y+0, z+7), state, 2);
		world.setBlockState(pos.add(x+11, y+0, z+7), state, 2);
		world.setBlockState(pos.add(x+12, y+0, z+7), state, 2);
		world.setBlockState(pos.add(x+3, y+0, z+8), state, 2);
		world.setBlockState(pos.add(x+4, y+0, z+8), state, 2);
		world.setBlockState(pos.add(x+5, y+0, z+8), state, 2);
		world.setBlockState(pos.add(x+6, y+0, z+8), state, 2);
		world.setBlockState(pos.add(x+7, y+0, z+8), state, 2);
		world.setBlockState(pos.add(x+8, y+0, z+8), state, 2);
		world.setBlockState(pos.add(x+9, y+0, z+8), state, 2);
		world.setBlockState(pos.add(x+10, y+0, z+8), state, 2);
		world.setBlockState(pos.add(x+11, y+0, z+8), state, 2);
		world.setBlockState(pos.add(x+12, y+0, z+8), state, 2);
		world.setBlockState(pos.add(x+13, y+0, z+8), state, 2);
		world.setBlockState(pos.add(x+3, y+0, z+9), state, 2);
		world.setBlockState(pos.add(x+4, y+0, z+9), state, 2);
		world.setBlockState(pos.add(x+5, y+0, z+9), state, 2);
		world.setBlockState(pos.add(x+6, y+0, z+9), state, 2);
		world.setBlockState(pos.add(x+7, y+0, z+9), state, 2);
		world.setBlockState(pos.add(x+8, y+0, z+9), state, 2);
		world.setBlockState(pos.add(x+9, y+0, z+9), state, 2);
		world.setBlockState(pos.add(x+10, y+0, z+9), state, 2);
		world.setBlockState(pos.add(x+11, y+0, z+9), state, 2);
		world.setBlockState(pos.add(x+12, y+0, z+9), state, 2);
		world.setBlockState(pos.add(x+13, y+0, z+9), state, 2);
		world.setBlockState(pos.add(x+3, y+0, z+10), state, 2);
		world.setBlockState(pos.add(x+4, y+0, z+10), state, 2);
		world.setBlockState(pos.add(x+5, y+0, z+10), state, 2);
		world.setBlockState(pos.add(x+6, y+0, z+10), state, 2);
		world.setBlockState(pos.add(x+7, y+0, z+10), state, 2);
		world.setBlockState(pos.add(x+8, y+0, z+10), state, 2);
		world.setBlockState(pos.add(x+9, y+0, z+10), state, 2);
		world.setBlockState(pos.add(x+10, y+0, z+10), state, 2);
		world.setBlockState(pos.add(x+11, y+0, z+10), state, 2);
		world.setBlockState(pos.add(x+12, y+0, z+10), state, 2);
		world.setBlockState(pos.add(x+13, y+0, z+10), state, 2);
		world.setBlockState(pos.add(x+3, y+0, z+11), state, 2);
		world.setBlockState(pos.add(x+4, y+0, z+11), state, 2);
		world.setBlockState(pos.add(x+5, y+0, z+11), state, 2);
		world.setBlockState(pos.add(x+6, y+0, z+11), state, 2);
		world.setBlockState(pos.add(x+7, y+0, z+11), state, 2);
		world.setBlockState(pos.add(x+8, y+0, z+11), state, 2);
		world.setBlockState(pos.add(x+9, y+0, z+11), state, 2);
		world.setBlockState(pos.add(x+10, y+0, z+11), state, 2);
		world.setBlockState(pos.add(x+11, y+0, z+11), state, 2);
		world.setBlockState(pos.add(x+12, y+0, z+11), state, 2);
		world.setBlockState(pos.add(x+3, y+0, z+12), state, 2);
		world.setBlockState(pos.add(x+4, y+0, z+12), state, 2);
		world.setBlockState(pos.add(x+5, y+0, z+12), state, 2);
		world.setBlockState(pos.add(x+6, y+0, z+12), state, 2);
		world.setBlockState(pos.add(x+7, y+0, z+12), state, 2);
		world.setBlockState(pos.add(x+8, y+0, z+12), state, 2);
		world.setBlockState(pos.add(x+9, y+0, z+12), state, 2);
		world.setBlockState(pos.add(x+10, y+0, z+12), state, 2);
		world.setBlockState(pos.add(x+11, y+0, z+12), state, 2);
		world.setBlockState(pos.add(x+4, y+0, z+13), state, 2);
		world.setBlockState(pos.add(x+5, y+0, z+13), state, 2);
		world.setBlockState(pos.add(x+6, y+0, z+13), state, 2);
		world.setBlockState(pos.add(x+7, y+0, z+13), state, 2);
		world.setBlockState(pos.add(x+8, y+0, z+13), state, 2);
		world.setBlockState(pos.add(x+9, y+0, z+13), state, 2);
		world.setBlockState(pos.add(x+10, y+0, z+13), state, 2);
		world.setBlockState(pos.add(x+3, y+1, z+2), state, 2);
		world.setBlockState(pos.add(x+4, y+1, z+2), state, 2);
		world.setBlockState(pos.add(x+5, y+1, z+2), state, 2);
		world.setBlockState(pos.add(x+6, y+1, z+2), state, 2);
		world.setBlockState(pos.add(x+7, y+1, z+2), state, 2);
		world.setBlockState(pos.add(x+3, y+1, z+3), state, 2);
		world.setBlockState(pos.add(x+4, y+1, z+3), state2, 2);
		world.setBlockState(pos.add(x+5, y+1, z+3), state2, 2);
		world.setBlockState(pos.add(x+6, y+1, z+3), state2, 2);
		world.setBlockState(pos.add(x+7, y+1, z+3), state2, 2);
		world.setBlockState(pos.add(x+8, y+1, z+3), state, 2);
		world.setBlockState(pos.add(x+3, y+1, z+4), state, 2);
		world.setBlockState(pos.add(x+4, y+1, z+4), state2, 2);
		world.setBlockState(pos.add(x+5, y+1, z+4), state2, 2);
		world.setBlockState(pos.add(x+6, y+1, z+4), state2, 2);
		world.setBlockState(pos.add(x+7, y+1, z+4), state2, 2);
		world.setBlockState(pos.add(x+8, y+1, z+4), state2, 2);
		world.setBlockState(pos.add(x+9, y+1, z+4), state, 2);
		world.setBlockState(pos.add(x+2, y+1, z+5), state, 2);
		world.setBlockState(pos.add(x+3, y+1, z+5), state2, 2);
		world.setBlockState(pos.add(x+4, y+1, z+5), state2, 2);
		world.setBlockState(pos.add(x+5, y+1, z+5), state2, 2);
		world.setBlockState(pos.add(x+6, y+1, z+5), state2, 2);
		world.setBlockState(pos.add(x+7, y+1, z+5), state2, 2);
		world.setBlockState(pos.add(x+8, y+1, z+5), state2, 2);
		world.setBlockState(pos.add(x+9, y+1, z+5), state2, 2);
		world.setBlockState(pos.add(x+10, y+1, z+5), state, 2);
		world.setBlockState(pos.add(x+2, y+1, z+6), state, 2);
		world.setBlockState(pos.add(x+3, y+1, z+6), state2, 2);
		world.setBlockState(pos.add(x+4, y+1, z+6), state2, 2);
		world.setBlockState(pos.add(x+5, y+1, z+6), state2, 2);
		world.setBlockState(pos.add(x+6, y+1, z+6), state2, 2);
		world.setBlockState(pos.add(x+7, y+1, z+6), state2, 2);
		world.setBlockState(pos.add(x+8, y+1, z+6), state2, 2);
		world.setBlockState(pos.add(x+9, y+1, z+6), state2, 2);
		world.setBlockState(pos.add(x+10, y+1, z+6), state2, 2);
		world.setBlockState(pos.add(x+11, y+1, z+6), state, 2);
		world.setBlockState(pos.add(x+12, y+1, z+6), state, 2);
		world.setBlockState(pos.add(x+13, y+1, z+6), state, 2);
		world.setBlockState(pos.add(x+14, y+1, z+6), state, 2);
		world.setBlockState(pos.add(x+2, y+1, z+7), state, 2);
		world.setBlockState(pos.add(x+3, y+1, z+7), state2, 2);
		world.setBlockState(pos.add(x+4, y+1, z+7), state2, 2);
		world.setBlockState(pos.add(x+5, y+1, z+7), state2, 2);
		world.setBlockState(pos.add(x+6, y+1, z+7), state2, 2);
		world.setBlockState(pos.add(x+7, y+1, z+7), state2, 2);
		world.setBlockState(pos.add(x+8, y+1, z+7), state2, 2);
		world.setBlockState(pos.add(x+9, y+1, z+7), state2, 2);
		world.setBlockState(pos.add(x+10, y+1, z+7), state2, 2);
		world.setBlockState(pos.add(x+11, y+1, z+7), state2, 2);
		world.setBlockState(pos.add(x+12, y+1, z+7), state2, 2);
		world.setBlockState(pos.add(x+13, y+1, z+7), state, 2);
		world.setBlockState(pos.add(x+14, y+1, z+7), state, 2);
		world.setBlockState(pos.add(x+2, y+1, z+8), state, 2);
		world.setBlockState(pos.add(x+3, y+1, z+8), state2, 2);
		world.setBlockState(pos.add(x+4, y+1, z+8), state2, 2);
		world.setBlockState(pos.add(x+5, y+1, z+8), state2, 2);
		world.setBlockState(pos.add(x+6, y+1, z+8), state2, 2);
		world.setBlockState(pos.add(x+7, y+1, z+8), state2, 2);
		world.setBlockState(pos.add(x+8, y+1, z+8), state2, 2);
		world.setBlockState(pos.add(x+9, y+1, z+8), state2, 2);
		world.setBlockState(pos.add(x+10, y+1, z+8), state2, 2);
		world.setBlockState(pos.add(x+11, y+1, z+8), state2, 2);
		world.setBlockState(pos.add(x+12, y+1, z+8), state2, 2);
		world.setBlockState(pos.add(x+13, y+1, z+8), state2, 2);
		world.setBlockState(pos.add(x+14, y+1, z+8), state, 2);
		world.setBlockState(pos.add(x+2, y+1, z+9), state, 2);
		world.setBlockState(pos.add(x+3, y+1, z+9), state2, 2);
		world.setBlockState(pos.add(x+4, y+1, z+9), state2, 2);
		world.setBlockState(pos.add(x+5, y+1, z+9), state2, 2);
		world.setBlockState(pos.add(x+6, y+1, z+9), state2, 2);
		world.setBlockState(pos.add(x+7, y+1, z+9), state2, 2);
		world.setBlockState(pos.add(x+8, y+1, z+9), state2, 2);
		world.setBlockState(pos.add(x+9, y+1, z+9), state2, 2);
		world.setBlockState(pos.add(x+10, y+1, z+9), state2, 2);
		world.setBlockState(pos.add(x+11, y+1, z+9), state2, 2);
		world.setBlockState(pos.add(x+12, y+1, z+9), state2, 2);
		world.setBlockState(pos.add(x+13, y+1, z+9), state2, 2);
		world.setBlockState(pos.add(x+14, y+1, z+9), state, 2);
		world.setBlockState(pos.add(x+2, y+1, z+10), state, 2);
		world.setBlockState(pos.add(x+3, y+1, z+10), state2, 2);
		world.setBlockState(pos.add(x+4, y+1, z+10), state2, 2);
		world.setBlockState(pos.add(x+5, y+1, z+10), state2, 2);
		world.setBlockState(pos.add(x+6, y+1, z+10), state2, 2);
		world.setBlockState(pos.add(x+7, y+1, z+10), state2, 2);
		world.setBlockState(pos.add(x+8, y+1, z+10), state2, 2);
		world.setBlockState(pos.add(x+9, y+1, z+10), state2, 2);
		world.setBlockState(pos.add(x+10, y+1, z+10), state2, 2);
		world.setBlockState(pos.add(x+11, y+1, z+10), state2, 2);
		world.setBlockState(pos.add(x+12, y+1, z+10), state2, 2);
		world.setBlockState(pos.add(x+13, y+1, z+10), state2, 2);
		world.setBlockState(pos.add(x+14, y+1, z+10), state, 2);
		world.setBlockState(pos.add(x+2, y+1, z+11), state, 2);
		world.setBlockState(pos.add(x+3, y+1, z+11), state2, 2);
		world.setBlockState(pos.add(x+4, y+1, z+11), state2, 2);
		world.setBlockState(pos.add(x+5, y+1, z+11), state2, 2);
		world.setBlockState(pos.add(x+6, y+1, z+11), state2, 2);
		world.setBlockState(pos.add(x+7, y+1, z+11), state2, 2);
		world.setBlockState(pos.add(x+8, y+1, z+11), state2, 2);
		world.setBlockState(pos.add(x+9, y+1, z+11), state2, 2);
		world.setBlockState(pos.add(x+10, y+1, z+11), state2, 2);
		world.setBlockState(pos.add(x+11, y+1, z+11), state2, 2);
		world.setBlockState(pos.add(x+12, y+1, z+11), state2, 2);
		world.setBlockState(pos.add(x+13, y+1, z+11), state, 2);
		world.setBlockState(pos.add(x+14, y+1, z+11), state, 2);
		world.setBlockState(pos.add(x+2, y+1, z+12), state, 2);
		world.setBlockState(pos.add(x+3, y+1, z+12), state2, 2);
		world.setBlockState(pos.add(x+4, y+1, z+12), state2, 2);
		world.setBlockState(pos.add(x+5, y+1, z+12), state2, 2);
		world.setBlockState(pos.add(x+6, y+1, z+12), state2, 2);
		world.setBlockState(pos.add(x+7, y+1, z+12), state2, 2);
		world.setBlockState(pos.add(x+8, y+1, z+12), state2, 2);
		world.setBlockState(pos.add(x+9, y+1, z+12), state2, 2);
		world.setBlockState(pos.add(x+10, y+1, z+12), state2, 2);
		world.setBlockState(pos.add(x+11, y+1, z+12), state2, 2);
		world.setBlockState(pos.add(x+12, y+1, z+12), state, 2);
		world.setBlockState(pos.add(x+2, y+1, z+13), state, 2);
		world.setBlockState(pos.add(x+3, y+1, z+13), state, 2);
		world.setBlockState(pos.add(x+4, y+1, z+13), state2, 2);
		world.setBlockState(pos.add(x+5, y+1, z+13), state2, 2);
		world.setBlockState(pos.add(x+6, y+1, z+13), state2, 2);
		world.setBlockState(pos.add(x+7, y+1, z+13), state2, 2);
		world.setBlockState(pos.add(x+8, y+1, z+13), state2, 2);
		world.setBlockState(pos.add(x+9, y+1, z+13), state2, 2);
		world.setBlockState(pos.add(x+10, y+1, z+13), state2, 2);
		world.setBlockState(pos.add(x+11, y+1, z+13), state, 2);
		world.setBlockState(pos.add(x+4, y+1, z+14), state, 2);
		world.setBlockState(pos.add(x+5, y+1, z+14), state, 2);
		world.setBlockState(pos.add(x+6, y+1, z+14), state, 2);
		world.setBlockState(pos.add(x+7, y+1, z+14), state, 2);
		world.setBlockState(pos.add(x+8, y+1, z+14), state, 2);
		world.setBlockState(pos.add(x+9, y+1, z+14), state, 2);
		world.setBlockState(pos.add(x+10, y+1, z+14), state, 2);
		world.setBlockState(pos.add(x+3, y+2, z+1), state, 2);
		world.setBlockState(pos.add(x+4, y+2, z+1), state, 2);
		world.setBlockState(pos.add(x+5, y+2, z+1), state, 2);
		world.setBlockState(pos.add(x+6, y+2, z+1), state, 2);
		world.setBlockState(pos.add(x+7, y+2, z+1), state, 2);
		world.setBlockState(pos.add(x+2, y+2, z+2), state, 2);
		world.setBlockState(pos.add(x+3, y+2, z+2), Blocks.AIR.getDefaultState(), 2);
		world.setBlockState(pos.add(x+4, y+2, z+2), Blocks.AIR.getDefaultState(), 2);
		world.setBlockState(pos.add(x+5, y+2, z+2), Blocks.AIR.getDefaultState(), 2);
		world.setBlockState(pos.add(x+6, y+2, z+2), Blocks.AIR.getDefaultState(), 2);
		world.setBlockState(pos.add(x+7, y+2, z+2), Blocks.AIR.getDefaultState(), 2);
		world.setBlockState(pos.add(x+8, y+2, z+2), state, 2);
		world.setBlockState(pos.add(x+9, y+2, z+2), state, 2);
		world.setBlockState(pos.add(x+2, y+2, z+3), state, 2);
		world.setBlockState(pos.add(x+3, y+2, z+3), Blocks.AIR.getDefaultState(), 2);
		world.setBlockState(pos.add(x+4, y+2, z+3), Blocks.AIR.getDefaultState(), 2);
		world.setBlockState(pos.add(x+5, y+2, z+3), Blocks.AIR.getDefaultState(), 2);
		world.setBlockState(pos.add(x+6, y+2, z+3), Blocks.AIR.getDefaultState(), 2);
		world.setBlockState(pos.add(x+7, y+2, z+3), Blocks.AIR.getDefaultState(), 2);
		world.setBlockState(pos.add(x+8, y+2, z+3), Blocks.AIR.getDefaultState(), 2);
		world.setBlockState(pos.add(x+9, y+2, z+3), state, 2);
		world.setBlockState(pos.add(x+2, y+2, z+4), state, 2);
		world.setBlockState(pos.add(x+3, y+2, z+4), Blocks.AIR.getDefaultState(), 2);
		world.setBlockState(pos.add(x+4, y+2, z+4), Blocks.AIR.getDefaultState(), 2);
		world.setBlockState(pos.add(x+5, y+2, z+4), Blocks.AIR.getDefaultState(), 2);
		world.setBlockState(pos.add(x+6, y+2, z+4), Blocks.AIR.getDefaultState(), 2);
		world.setBlockState(pos.add(x+7, y+2, z+4), Blocks.AIR.getDefaultState(), 2);
		world.setBlockState(pos.add(x+8, y+2, z+4), Blocks.AIR.getDefaultState(), 2);
		world.setBlockState(pos.add(x+9, y+2, z+4), Blocks.AIR.getDefaultState(), 2);
		world.setBlockState(pos.add(x+10, y+2, z+4), state, 2);
		world.setBlockState(pos.add(x+1, y+2, z+5), state, 2);
		world.setBlockState(pos.add(x+2, y+2, z+5), Blocks.AIR.getDefaultState(), 2);
		world.setBlockState(pos.add(x+3, y+2, z+5), Blocks.AIR.getDefaultState(), 2);
		world.setBlockState(pos.add(x+4, y+2, z+5), Blocks.AIR.getDefaultState(), 2);
		world.setBlockState(pos.add(x+5, y+2, z+5), Blocks.AIR.getDefaultState(), 2);
		world.setBlockState(pos.add(x+6, y+2, z+5), Blocks.AIR.getDefaultState(), 2);
		world.setBlockState(pos.add(x+7, y+2, z+5), Blocks.AIR.getDefaultState(), 2);
		world.setBlockState(pos.add(x+8, y+2, z+5), Blocks.AIR.getDefaultState(), 2);
		world.setBlockState(pos.add(x+9, y+2, z+5), Blocks.AIR.getDefaultState(), 2);
		world.setBlockState(pos.add(x+10, y+2, z+5), state, 2);
		world.setBlockState(pos.add(x+11, y+2, z+5), state, 2);
		world.setBlockState(pos.add(x+12, y+2, z+5), state, 2);
		world.setBlockState(pos.add(x+1, y+2, z+6), state, 2);
		world.setBlockState(pos.add(x+2, y+2, z+6), Blocks.AIR.getDefaultState(), 2);
		world.setBlockState(pos.add(x+3, y+2, z+6), Blocks.AIR.getDefaultState(), 2);
		world.setBlockState(pos.add(x+4, y+2, z+6), Blocks.AIR.getDefaultState(), 2);
		world.setBlockState(pos.add(x+5, y+2, z+6), Blocks.AIR.getDefaultState(), 2);
		world.setBlockState(pos.add(x+6, y+2, z+6), Blocks.AIR.getDefaultState(), 2);
		world.setBlockState(pos.add(x+7, y+2, z+6), Blocks.AIR.getDefaultState(), 2);
		world.setBlockState(pos.add(x+8, y+2, z+6), Blocks.AIR.getDefaultState(), 2);
		world.setBlockState(pos.add(x+9, y+2, z+6), Blocks.AIR.getDefaultState(), 2);
		world.setBlockState(pos.add(x+10, y+2, z+6), Blocks.AIR.getDefaultState(), 2);
		world.setBlockState(pos.add(x+11, y+2, z+6), Blocks.AIR.getDefaultState(), 2);
		world.setBlockState(pos.add(x+12, y+2, z+6), state, 2);
		world.setBlockState(pos.add(x+13, y+2, z+6), state, 2);
		world.setBlockState(pos.add(x+14, y+2, z+6), state, 2);
		world.setBlockState(pos.add(x+1, y+2, z+7), state, 2);
		world.setBlockState(pos.add(x+2, y+2, z+7), Blocks.AIR.getDefaultState(), 2);
		world.setBlockState(pos.add(x+3, y+2, z+7), Blocks.AIR.getDefaultState(), 2);
		world.setBlockState(pos.add(x+4, y+2, z+7), Blocks.AIR.getDefaultState(), 2);
		world.setBlockState(pos.add(x+5, y+2, z+7), Blocks.AIR.getDefaultState(), 2);
		world.setBlockState(pos.add(x+6, y+2, z+7), Blocks.AIR.getDefaultState(), 2);
		world.setBlockState(pos.add(x+7, y+2, z+7), Blocks.AIR.getDefaultState(), 2);
		world.setBlockState(pos.add(x+8, y+2, z+7), Blocks.AIR.getDefaultState(), 2);
		world.setBlockState(pos.add(x+9, y+2, z+7), Blocks.AIR.getDefaultState(), 2);
		world.setBlockState(pos.add(x+10, y+2, z+7), Blocks.AIR.getDefaultState(), 2);
		world.setBlockState(pos.add(x+11, y+2, z+7), Blocks.AIR.getDefaultState(), 2);
		world.setBlockState(pos.add(x+12, y+2, z+7), Blocks.AIR.getDefaultState(), 2);
		world.setBlockState(pos.add(x+13, y+2, z+7), Blocks.AIR.getDefaultState(), 2);
		world.setBlockState(pos.add(x+14, y+2, z+7), Blocks.AIR.getDefaultState(), 2);
		world.setBlockState(pos.add(x+15, y+2, z+7), state, 2);
		world.setBlockState(pos.add(x+1, y+2, z+8), state, 2);
		world.setBlockState(pos.add(x+2, y+2, z+8), Blocks.AIR.getDefaultState(), 2);
		world.setBlockState(pos.add(x+3, y+2, z+8), Blocks.AIR.getDefaultState(), 2);
		world.setBlockState(pos.add(x+4, y+2, z+8), Blocks.AIR.getDefaultState(), 2);
		world.setBlockState(pos.add(x+5, y+2, z+8), Blocks.AIR.getDefaultState(), 2);
		world.setBlockState(pos.add(x+6, y+2, z+8), Blocks.AIR.getDefaultState(), 2);
		world.setBlockState(pos.add(x+7, y+2, z+8), Blocks.AIR.getDefaultState(), 2);
		world.setBlockState(pos.add(x+8, y+2, z+8), Blocks.AIR.getDefaultState(), 2);
		world.setBlockState(pos.add(x+9, y+2, z+8), Blocks.AIR.getDefaultState(), 2);
		world.setBlockState(pos.add(x+10, y+2, z+8), Blocks.AIR.getDefaultState(), 2);
		world.setBlockState(pos.add(x+11, y+2, z+8), Blocks.AIR.getDefaultState(), 2);
		world.setBlockState(pos.add(x+12, y+2, z+8), Blocks.AIR.getDefaultState(), 2);
		world.setBlockState(pos.add(x+13, y+2, z+8), Blocks.AIR.getDefaultState(), 2);
		world.setBlockState(pos.add(x+14, y+2, z+8), Blocks.AIR.getDefaultState(), 2);
		world.setBlockState(pos.add(x+15, y+2, z+8), state, 2);
		world.setBlockState(pos.add(x+1, y+2, z+9), state, 2);
		world.setBlockState(pos.add(x+2, y+2, z+9), Blocks.AIR.getDefaultState(), 2);
		world.setBlockState(pos.add(x+3, y+2, z+9), Blocks.AIR.getDefaultState(), 2);
		world.setBlockState(pos.add(x+4, y+2, z+9), Blocks.AIR.getDefaultState(), 2);
		world.setBlockState(pos.add(x+5, y+2, z+9), Blocks.AIR.getDefaultState(), 2);
		world.setBlockState(pos.add(x+6, y+2, z+9), Blocks.AIR.getDefaultState(), 2);
		world.setBlockState(pos.add(x+7, y+2, z+9), Blocks.AIR.getDefaultState(), 2);
		world.setBlockState(pos.add(x+8, y+2, z+9), Blocks.AIR.getDefaultState(), 2);
		world.setBlockState(pos.add(x+9, y+2, z+9), Blocks.AIR.getDefaultState(), 2);
		world.setBlockState(pos.add(x+10, y+2, z+9), Blocks.AIR.getDefaultState(), 2);
		world.setBlockState(pos.add(x+11, y+2, z+9), Blocks.AIR.getDefaultState(), 2);
		world.setBlockState(pos.add(x+12, y+2, z+9), Blocks.AIR.getDefaultState(), 2);
		world.setBlockState(pos.add(x+13, y+2, z+9), Blocks.AIR.getDefaultState(), 2);
		world.setBlockState(pos.add(x+14, y+2, z+9), Blocks.AIR.getDefaultState(), 2);
		world.setBlockState(pos.add(x+15, y+2, z+9), state, 2);
		world.setBlockState(pos.add(x+1, y+2, z+10), state, 2);
		world.setBlockState(pos.add(x+2, y+2, z+10), Blocks.AIR.getDefaultState(), 2);
		world.setBlockState(pos.add(x+3, y+2, z+10), Blocks.AIR.getDefaultState(), 2);
		world.setBlockState(pos.add(x+4, y+2, z+10), Blocks.AIR.getDefaultState(), 2);
		world.setBlockState(pos.add(x+5, y+2, z+10), Blocks.AIR.getDefaultState(), 2);
		world.setBlockState(pos.add(x+6, y+2, z+10), Blocks.AIR.getDefaultState(), 2);
		world.setBlockState(pos.add(x+7, y+2, z+10), Blocks.AIR.getDefaultState(), 2);
		world.setBlockState(pos.add(x+8, y+2, z+10), Blocks.AIR.getDefaultState(), 2);
		world.setBlockState(pos.add(x+9, y+2, z+10), Blocks.AIR.getDefaultState(), 2);
		world.setBlockState(pos.add(x+10, y+2, z+10), Blocks.AIR.getDefaultState(), 2);
		world.setBlockState(pos.add(x+11, y+2, z+10), Blocks.AIR.getDefaultState(), 2);
		world.setBlockState(pos.add(x+12, y+2, z+10), Blocks.AIR.getDefaultState(), 2);
		world.setBlockState(pos.add(x+13, y+2, z+10), Blocks.AIR.getDefaultState(), 2);
		world.setBlockState(pos.add(x+14, y+2, z+10), Blocks.AIR.getDefaultState(), 2);
		world.setBlockState(pos.add(x+15, y+2, z+10), state, 2);
		world.setBlockState(pos.add(x+1, y+2, z+11), state, 2);
		world.setBlockState(pos.add(x+2, y+2, z+11), Blocks.AIR.getDefaultState(), 2);
		world.setBlockState(pos.add(x+3, y+2, z+11), Blocks.AIR.getDefaultState(), 2);
		world.setBlockState(pos.add(x+4, y+2, z+11), Blocks.AIR.getDefaultState(), 2);
		world.setBlockState(pos.add(x+5, y+2, z+11), Blocks.AIR.getDefaultState(), 2);
		world.setBlockState(pos.add(x+6, y+2, z+11), Blocks.AIR.getDefaultState(), 2);
		world.setBlockState(pos.add(x+7, y+2, z+11), Blocks.AIR.getDefaultState(), 2);
		world.setBlockState(pos.add(x+8, y+2, z+11), Blocks.AIR.getDefaultState(), 2);
		world.setBlockState(pos.add(x+9, y+2, z+11), Blocks.AIR.getDefaultState(), 2);
		world.setBlockState(pos.add(x+10, y+2, z+11), Blocks.AIR.getDefaultState(), 2);
		world.setBlockState(pos.add(x+11, y+2, z+11), Blocks.AIR.getDefaultState(), 2);
		world.setBlockState(pos.add(x+12, y+2, z+11), Blocks.AIR.getDefaultState(), 2);
		world.setBlockState(pos.add(x+13, y+2, z+11), Blocks.AIR.getDefaultState(), 2);
		world.setBlockState(pos.add(x+14, y+2, z+11), state, 2);
		world.setBlockState(pos.add(x+1, y+2, z+12), state, 2);
		world.setBlockState(pos.add(x+2, y+2, z+12), Blocks.AIR.getDefaultState(), 2);
		world.setBlockState(pos.add(x+3, y+2, z+12), Blocks.AIR.getDefaultState(), 2);
		world.setBlockState(pos.add(x+4, y+2, z+12), Blocks.AIR.getDefaultState(), 2);
		world.setBlockState(pos.add(x+5, y+2, z+12), Blocks.AIR.getDefaultState(), 2);
		world.setBlockState(pos.add(x+6, y+2, z+12), Blocks.AIR.getDefaultState(), 2);
		world.setBlockState(pos.add(x+7, y+2, z+12), Blocks.AIR.getDefaultState(), 2);
		world.setBlockState(pos.add(x+8, y+2, z+12), Blocks.AIR.getDefaultState(), 2);
		world.setBlockState(pos.add(x+9, y+2, z+12), Blocks.AIR.getDefaultState(), 2);
		world.setBlockState(pos.add(x+10, y+2, z+12), Blocks.AIR.getDefaultState(), 2);
		world.setBlockState(pos.add(x+11, y+2, z+12), Blocks.AIR.getDefaultState(), 2);
		world.setBlockState(pos.add(x+12, y+2, z+12), Blocks.AIR.getDefaultState(), 2);
		world.setBlockState(pos.add(x+13, y+2, z+12), state, 2);
		world.setBlockState(pos.add(x+2, y+2, z+13), state, 2);
		world.setBlockState(pos.add(x+3, y+2, z+13), Blocks.AIR.getDefaultState(), 2);
		world.setBlockState(pos.add(x+4, y+2, z+13), Blocks.AIR.getDefaultState(), 2);
		world.setBlockState(pos.add(x+5, y+2, z+13), Blocks.AIR.getDefaultState(), 2);
		world.setBlockState(pos.add(x+6, y+2, z+13), Blocks.AIR.getDefaultState(), 2);
		world.setBlockState(pos.add(x+7, y+2, z+13), Blocks.AIR.getDefaultState(), 2);
		world.setBlockState(pos.add(x+8, y+2, z+13), Blocks.AIR.getDefaultState(), 2);
		world.setBlockState(pos.add(x+9, y+2, z+13), Blocks.AIR.getDefaultState(), 2);
		world.setBlockState(pos.add(x+10, y+2, z+13), Blocks.AIR.getDefaultState(), 2);
		world.setBlockState(pos.add(x+11, y+2, z+13), Blocks.AIR.getDefaultState(), 2);
		world.setBlockState(pos.add(x+12, y+2, z+13), state, 2);
		world.setBlockState(pos.add(x+3, y+2, z+14), state, 2);
		world.setBlockState(pos.add(x+4, y+2, z+14), state, 2);
		world.setBlockState(pos.add(x+5, y+2, z+14), Blocks.AIR.getDefaultState(), 2);
		world.setBlockState(pos.add(x+6, y+2, z+14), Blocks.AIR.getDefaultState(), 2);
		world.setBlockState(pos.add(x+7, y+2, z+14), Blocks.AIR.getDefaultState(), 2);
		world.setBlockState(pos.add(x+8, y+2, z+14), Blocks.AIR.getDefaultState(), 2);
		world.setBlockState(pos.add(x+9, y+2, z+14), Blocks.AIR.getDefaultState(), 2);
		world.setBlockState(pos.add(x+10, y+2, z+14), Blocks.AIR.getDefaultState(), 2);
		world.setBlockState(pos.add(x+11, y+2, z+14), state, 2);
		world.setBlockState(pos.add(x+5, y+2, z+15), state, 2);
		world.setBlockState(pos.add(x+6, y+2, z+15), state, 2);
		world.setBlockState(pos.add(x+7, y+2, z+15), state, 2);
		world.setBlockState(pos.add(x+8, y+2, z+15), state, 2);
		world.setBlockState(pos.add(x+9, y+2, z+15), state, 2);
		world.setBlockState(pos.add(x+10, y+2, z+15), state, 2);
		world.setBlockState(pos.add(x+3, y+3, z+2), state, 2);
		world.setBlockState(pos.add(x+4, y+3, z+2), state, 2);
		world.setBlockState(pos.add(x+5, y+3, z+2), state, 2);
		world.setBlockState(pos.add(x+6, y+3, z+2), state, 2);
		world.setBlockState(pos.add(x+7, y+3, z+2), state, 2);
		world.setBlockState(pos.add(x+3, y+3, z+3), state, 2);
		world.setBlockState(pos.add(x+4, y+3, z+3), state, 2);
		world.setBlockState(pos.add(x+5, y+3, z+3), state, 2);
		world.setBlockState(pos.add(x+6, y+3, z+3), state, 2);
		world.setBlockState(pos.add(x+7, y+3, z+3), state, 2);
		world.setBlockState(pos.add(x+8, y+3, z+3), state, 2);
		world.setBlockState(pos.add(x+3, y+3, z+4), state, 2);
		world.setBlockState(pos.add(x+4, y+3, z+4), state, 2);
		world.setBlockState(pos.add(x+5, y+3, z+4), Blocks.AIR.getDefaultState(), 2);
		world.setBlockState(pos.add(x+6, y+3, z+4), Blocks.AIR.getDefaultState(), 2);
		world.setBlockState(pos.add(x+7, y+3, z+4), state, 2);
		world.setBlockState(pos.add(x+8, y+3, z+4), state, 2);
		world.setBlockState(pos.add(x+9, y+3, z+4), state, 2);
		world.setBlockState(pos.add(x+2, y+3, z+5), state, 2);
		world.setBlockState(pos.add(x+3, y+3, z+5), state, 2);
		world.setBlockState(pos.add(x+4, y+3, z+5), state, 2);
		world.setBlockState(pos.add(x+5, y+3, z+5), Blocks.AIR.getDefaultState(), 2);
		world.setBlockState(pos.add(x+6, y+3, z+5), Blocks.AIR.getDefaultState(), 2);
		world.setBlockState(pos.add(x+7, y+3, z+5), state, 2);
		world.setBlockState(pos.add(x+8, y+3, z+5), state, 2);
		world.setBlockState(pos.add(x+9, y+3, z+5), state, 2);
		world.setBlockState(pos.add(x+2, y+3, z+6), state, 2);
		world.setBlockState(pos.add(x+3, y+3, z+6), state, 2);
		world.setBlockState(pos.add(x+4, y+3, z+6), state, 2);
		world.setBlockState(pos.add(x+5, y+3, z+6), state, 2);
		world.setBlockState(pos.add(x+6, y+3, z+6), state, 2);
		world.setBlockState(pos.add(x+7, y+3, z+6), state, 2);
		world.setBlockState(pos.add(x+8, y+3, z+6), state, 2);
		world.setBlockState(pos.add(x+9, y+3, z+6), state, 2);
		world.setBlockState(pos.add(x+10, y+3, z+6), state, 2);
		world.setBlockState(pos.add(x+11, y+3, z+6), state, 2);
		world.setBlockState(pos.add(x+2, y+3, z+7), state, 2);
		world.setBlockState(pos.add(x+3, y+3, z+7), state, 2);
		world.setBlockState(pos.add(x+4, y+3, z+7), state, 2);
		world.setBlockState(pos.add(x+5, y+3, z+7), state, 2);
		world.setBlockState(pos.add(x+6, y+3, z+7), state, 2);
		world.setBlockState(pos.add(x+7, y+3, z+7), state, 2);
		world.setBlockState(pos.add(x+8, y+3, z+7), state, 2);
		world.setBlockState(pos.add(x+9, y+3, z+7), state, 2);
		world.setBlockState(pos.add(x+10, y+3, z+7), state, 2);
		world.setBlockState(pos.add(x+11, y+3, z+7), state, 2);
		world.setBlockState(pos.add(x+12, y+3, z+7), state, 2);
		world.setBlockState(pos.add(x+13, y+3, z+7), state, 2);
		world.setBlockState(pos.add(x+14, y+3, z+7), state, 2);
		world.setBlockState(pos.add(x+2, y+3, z+8), state, 2);
		world.setBlockState(pos.add(x+3, y+3, z+8), state, 2);
		world.setBlockState(pos.add(x+4, y+3, z+8), state, 2);
		world.setBlockState(pos.add(x+5, y+3, z+8), state, 2);
		world.setBlockState(pos.add(x+6, y+3, z+8), state, 2);
		world.setBlockState(pos.add(x+7, y+3, z+8), state, 2);
		world.setBlockState(pos.add(x+8, y+3, z+8), state, 2);
		world.setBlockState(pos.add(x+9, y+3, z+8), state, 2);
		world.setBlockState(pos.add(x+10, y+3, z+8), state, 2);
		world.setBlockState(pos.add(x+11, y+3, z+8), state, 2);
		world.setBlockState(pos.add(x+12, y+3, z+8), state, 2);
		world.setBlockState(pos.add(x+13, y+3, z+8), state, 2);
		world.setBlockState(pos.add(x+14, y+3, z+8), state, 2);
		world.setBlockState(pos.add(x+2, y+3, z+9), state, 2);
		world.setBlockState(pos.add(x+3, y+3, z+9), state, 2);
		world.setBlockState(pos.add(x+4, y+3, z+9), state, 2);
		world.setBlockState(pos.add(x+5, y+3, z+9), state, 2);
		world.setBlockState(pos.add(x+6, y+3, z+9), state, 2);
		world.setBlockState(pos.add(x+7, y+3, z+9), state, 2);
		world.setBlockState(pos.add(x+8, y+3, z+9), state, 2);
		world.setBlockState(pos.add(x+9, y+3, z+9), state, 2);
		world.setBlockState(pos.add(x+10, y+3, z+9), Blocks.AIR.getDefaultState(), 2);
		world.setBlockState(pos.add(x+11, y+3, z+9), Blocks.AIR.getDefaultState(), 2);
		world.setBlockState(pos.add(x+12, y+3, z+9), state, 2);
		world.setBlockState(pos.add(x+13, y+3, z+9), state, 2);
		world.setBlockState(pos.add(x+14, y+3, z+9), state, 2);
		world.setBlockState(pos.add(x+2, y+3, z+10), state, 2);
		world.setBlockState(pos.add(x+3, y+3, z+10), state, 2);
		world.setBlockState(pos.add(x+4, y+3, z+10), Blocks.AIR.getDefaultState(), 2);
		world.setBlockState(pos.add(x+5, y+3, z+10), Blocks.AIR.getDefaultState(), 2);
		world.setBlockState(pos.add(x+6, y+3, z+10), Blocks.AIR.getDefaultState(), 2);
		world.setBlockState(pos.add(x+7, y+3, z+10), state, 2);
		world.setBlockState(pos.add(x+8, y+3, z+10), state, 2);
		world.setBlockState(pos.add(x+9, y+3, z+10), state, 2);
		world.setBlockState(pos.add(x+10, y+3, z+10), Blocks.AIR.getDefaultState(), 2);
		world.setBlockState(pos.add(x+11, y+3, z+10), Blocks.AIR.getDefaultState(), 2);
		world.setBlockState(pos.add(x+12, y+3, z+10), state, 2);
		world.setBlockState(pos.add(x+13, y+3, z+10), state, 2);
		world.setBlockState(pos.add(x+14, y+3, z+10), state, 2);
		world.setBlockState(pos.add(x+2, y+3, z+11), state, 2);
		world.setBlockState(pos.add(x+3, y+3, z+11), state, 2);
		world.setBlockState(pos.add(x+4, y+3, z+11), Blocks.AIR.getDefaultState(), 2);
		world.setBlockState(pos.add(x+5, y+3, z+11), Blocks.AIR.getDefaultState(), 2);
		world.setBlockState(pos.add(x+6, y+3, z+11), Blocks.AIR.getDefaultState(), 2);
		world.setBlockState(pos.add(x+7, y+3, z+11), state, 2);
		world.setBlockState(pos.add(x+8, y+3, z+11), state, 2);
		world.setBlockState(pos.add(x+9, y+3, z+11), state, 2);
		world.setBlockState(pos.add(x+10, y+3, z+11), state, 2);
		world.setBlockState(pos.add(x+11, y+3, z+11), state, 2);
		world.setBlockState(pos.add(x+12, y+3, z+11), state, 2);
		world.setBlockState(pos.add(x+13, y+3, z+11), state, 2);
		world.setBlockState(pos.add(x+2, y+3, z+12), state, 2);
		world.setBlockState(pos.add(x+3, y+3, z+12), state, 2);
		world.setBlockState(pos.add(x+4, y+3, z+12), Blocks.AIR.getDefaultState(), 2);
		world.setBlockState(pos.add(x+5, y+3, z+12), Blocks.AIR.getDefaultState(), 2);
		world.setBlockState(pos.add(x+6, y+3, z+12), Blocks.AIR.getDefaultState(), 2);
		world.setBlockState(pos.add(x+7, y+3, z+12), state, 2);
		world.setBlockState(pos.add(x+8, y+3, z+12), state, 2);
		world.setBlockState(pos.add(x+9, y+3, z+12), state, 2);
		world.setBlockState(pos.add(x+10, y+3, z+12), state, 2);
		world.setBlockState(pos.add(x+11, y+3, z+12), state, 2);
		world.setBlockState(pos.add(x+12, y+3, z+12), state, 2);
		world.setBlockState(pos.add(x+3, y+3, z+13), state, 2);
		world.setBlockState(pos.add(x+4, y+3, z+13), state, 2);
		world.setBlockState(pos.add(x+5, y+3, z+13), state, 2);
		world.setBlockState(pos.add(x+6, y+3, z+13), state, 2);
		world.setBlockState(pos.add(x+7, y+3, z+13), state, 2);
		world.setBlockState(pos.add(x+8, y+3, z+13), state, 2);
		world.setBlockState(pos.add(x+9, y+3, z+13), state, 2);
		world.setBlockState(pos.add(x+10, y+3, z+13), state, 2);
		world.setBlockState(pos.add(x+11, y+3, z+13), state, 2);
		world.setBlockState(pos.add(x+5, y+3, z+14), state, 2);
		world.setBlockState(pos.add(x+6, y+3, z+14), state, 2);
		world.setBlockState(pos.add(x+7, y+3, z+14), state, 2);
		world.setBlockState(pos.add(x+8, y+3, z+14), state, 2);
		world.setBlockState(pos.add(x+9, y+3, z+14), state, 2);
		world.setBlockState(pos.add(x+10, y+3, z+14), state, 2);
		world.setBlockState(pos.add(x+5, y+4, z+3), state, 2);
		world.setBlockState(pos.add(x+6, y+4, z+3), state, 2);
		world.setBlockState(pos.add(x+4, y+4, z+4), state, 2);
		world.setBlockState(pos.add(x+5, y+4, z+4), Blocks.AIR.getDefaultState(), 2);
		world.setBlockState(pos.add(x+6, y+4, z+4), Blocks.AIR.getDefaultState(), 2);
		world.setBlockState(pos.add(x+7, y+4, z+4), state, 2);
		world.setBlockState(pos.add(x+4, y+4, z+5), state, 2);
		world.setBlockState(pos.add(x+5, y+4, z+5), Blocks.AIR.getDefaultState(), 2);
		world.setBlockState(pos.add(x+6, y+4, z+5), Blocks.AIR.getDefaultState(), 2);
		world.setBlockState(pos.add(x+7, y+4, z+5), state, 2);
		world.setBlockState(pos.add(x+5, y+4, z+6), state, 2);
		world.setBlockState(pos.add(x+6, y+4, z+6), state, 2);
		world.setBlockState(pos.add(x+10, y+4, z+8), state, 2);
		world.setBlockState(pos.add(x+11, y+4, z+8), state, 2);
		world.setBlockState(pos.add(x+4, y+4, z+9), state, 2);
		world.setBlockState(pos.add(x+5, y+4, z+9), state, 2);
		world.setBlockState(pos.add(x+6, y+4, z+9), state, 2);
		world.setBlockState(pos.add(x+9, y+4, z+9), state, 2);
		world.setBlockState(pos.add(x+10, y+4, z+9), Blocks.AIR.getDefaultState(), 2);
		world.setBlockState(pos.add(x+11, y+4, z+9), Blocks.AIR.getDefaultState(), 2);
		world.setBlockState(pos.add(x+12, y+4, z+9), state, 2);
		world.setBlockState(pos.add(x+3, y+4, z+10), state, 2);
		world.setBlockState(pos.add(x+4, y+4, z+10), Blocks.AIR.getDefaultState(), 2);
		world.setBlockState(pos.add(x+5, y+4, z+10), Blocks.AIR.getDefaultState(), 2);
		world.setBlockState(pos.add(x+6, y+4, z+10), Blocks.AIR.getDefaultState(), 2);
		world.setBlockState(pos.add(x+7, y+4, z+10), state, 2);
		world.setBlockState(pos.add(x+9, y+4, z+10), state, 2);
		world.setBlockState(pos.add(x+10, y+4, z+10), Blocks.AIR.getDefaultState(), 2);
		world.setBlockState(pos.add(x+11, y+4, z+10), Blocks.AIR.getDefaultState(), 2);
		world.setBlockState(pos.add(x+12, y+4, z+10), state, 2);
		world.setBlockState(pos.add(x+3, y+4, z+11), state, 2);
		world.setBlockState(pos.add(x+4, y+4, z+11), Blocks.AIR.getDefaultState(), 2);
		world.setBlockState(pos.add(x+5, y+4, z+11), Blocks.AIR.getDefaultState(), 2);
		world.setBlockState(pos.add(x+6, y+4, z+11), Blocks.AIR.getDefaultState(), 2);
		world.setBlockState(pos.add(x+7, y+4, z+11), state, 2);
		world.setBlockState(pos.add(x+10, y+4, z+11), state, 2);
		world.setBlockState(pos.add(x+11, y+4, z+11), state, 2);
		world.setBlockState(pos.add(x+3, y+4, z+12), state, 2);
		world.setBlockState(pos.add(x+4, y+4, z+12), Blocks.AIR.getDefaultState(), 2);
		world.setBlockState(pos.add(x+5, y+4, z+12), Blocks.AIR.getDefaultState(), 2);
		world.setBlockState(pos.add(x+6, y+4, z+12), Blocks.AIR.getDefaultState(), 2);
		world.setBlockState(pos.add(x+7, y+4, z+12), state, 2);
		world.setBlockState(pos.add(x+4, y+4, z+13), state, 2);
		world.setBlockState(pos.add(x+5, y+4, z+13), state, 2);
		world.setBlockState(pos.add(x+6, y+4, z+13), state, 2);
		world.setBlockState(pos.add(x+5, y+5, z+3), state, 2);
		world.setBlockState(pos.add(x+6, y+5, z+3), state, 2);
		world.setBlockState(pos.add(x+4, y+5, z+4), state, 2);
		world.setBlockState(pos.add(x+5, y+5, z+4), Blocks.AIR.getDefaultState(), 2);
		world.setBlockState(pos.add(x+6, y+5, z+4), Blocks.AIR.getDefaultState(), 2);
		world.setBlockState(pos.add(x+7, y+5, z+4), state, 2);
		world.setBlockState(pos.add(x+4, y+5, z+5), state, 2);
		world.setBlockState(pos.add(x+5, y+5, z+5), Blocks.AIR.getDefaultState(), 2);
		world.setBlockState(pos.add(x+6, y+5, z+5), Blocks.AIR.getDefaultState(), 2);
		world.setBlockState(pos.add(x+7, y+5, z+5), state, 2);
		world.setBlockState(pos.add(x+5, y+5, z+6), state, 2);
		world.setBlockState(pos.add(x+6, y+5, z+6), state, 2);
		world.setBlockState(pos.add(x+10, y+5, z+8), state, 2);
		world.setBlockState(pos.add(x+11, y+5, z+8), state, 2);
		world.setBlockState(pos.add(x+4, y+5, z+9), state, 2);
		world.setBlockState(pos.add(x+5, y+5, z+9), state, 2);
		world.setBlockState(pos.add(x+6, y+5, z+9), state, 2);
		world.setBlockState(pos.add(x+9, y+5, z+9), state, 2);
		world.setBlockState(pos.add(x+10, y+5, z+9), Blocks.AIR.getDefaultState(), 2);
		world.setBlockState(pos.add(x+11, y+5, z+9), Blocks.AIR.getDefaultState(), 2);
		world.setBlockState(pos.add(x+12, y+5, z+9), state, 2);
		world.setBlockState(pos.add(x+3, y+5, z+10), state, 2);
		world.setBlockState(pos.add(x+4, y+5, z+10), Blocks.AIR.getDefaultState(), 2);
		world.setBlockState(pos.add(x+5, y+5, z+10), Blocks.AIR.getDefaultState(), 2);
		world.setBlockState(pos.add(x+6, y+5, z+10), Blocks.AIR.getDefaultState(), 2);
		world.setBlockState(pos.add(x+7, y+5, z+10), state, 2);
		world.setBlockState(pos.add(x+9, y+5, z+10), state, 2);
		world.setBlockState(pos.add(x+10, y+5, z+10), Blocks.AIR.getDefaultState(), 2);
		world.setBlockState(pos.add(x+11, y+5, z+10), Blocks.AIR.getDefaultState(), 2);
		world.setBlockState(pos.add(x+12, y+5, z+10), state, 2);
		world.setBlockState(pos.add(x+3, y+5, z+11), state, 2);
		world.setBlockState(pos.add(x+4, y+5, z+11), Blocks.AIR.getDefaultState(), 2);
		world.setBlockState(pos.add(x+5, y+5, z+11), Blocks.AIR.getDefaultState(), 2);
		world.setBlockState(pos.add(x+6, y+5, z+11), Blocks.AIR.getDefaultState(), 2);
		world.setBlockState(pos.add(x+7, y+5, z+11), state, 2);
		world.setBlockState(pos.add(x+10, y+5, z+11), state, 2);
		world.setBlockState(pos.add(x+11, y+5, z+11), state, 2);
		world.setBlockState(pos.add(x+3, y+5, z+12), state, 2);
		world.setBlockState(pos.add(x+4, y+5, z+12), Blocks.AIR.getDefaultState(), 2);
		world.setBlockState(pos.add(x+5, y+5, z+12), Blocks.AIR.getDefaultState(), 2);
		world.setBlockState(pos.add(x+6, y+5, z+12), Blocks.AIR.getDefaultState(), 2);
		world.setBlockState(pos.add(x+7, y+5, z+12), state, 2);
		world.setBlockState(pos.add(x+4, y+5, z+13), state, 2);
		world.setBlockState(pos.add(x+5, y+5, z+13), state, 2);
		world.setBlockState(pos.add(x+6, y+5, z+13), state, 2);
		world.setBlockState(pos.add(x+5, y+6, z+3), state, 2);
		world.setBlockState(pos.add(x+6, y+6, z+3), state, 2);
		world.setBlockState(pos.add(x+4, y+6, z+4), state, 2);
		world.setBlockState(pos.add(x+5, y+6, z+4), Blocks.AIR.getDefaultState(), 2);
		world.setBlockState(pos.add(x+6, y+6, z+4), Blocks.AIR.getDefaultState(), 2);
		world.setBlockState(pos.add(x+7, y+6, z+4), state, 2);
		world.setBlockState(pos.add(x+4, y+6, z+5), state, 2);
		world.setBlockState(pos.add(x+5, y+6, z+5), Blocks.AIR.getDefaultState(), 2);
		world.setBlockState(pos.add(x+6, y+6, z+5), Blocks.AIR.getDefaultState(), 2);
		world.setBlockState(pos.add(x+7, y+6, z+5), state, 2);
		world.setBlockState(pos.add(x+5, y+6, z+6), state, 2);
		world.setBlockState(pos.add(x+6, y+6, z+6), state, 2);
		world.setBlockState(pos.add(x+10, y+6, z+8), state, 2);
		world.setBlockState(pos.add(x+11, y+6, z+8), state, 2);
		world.setBlockState(pos.add(x+4, y+6, z+9), state, 2);
		world.setBlockState(pos.add(x+5, y+6, z+9), state, 2);
		world.setBlockState(pos.add(x+6, y+6, z+9), state, 2);
		world.setBlockState(pos.add(x+9, y+6, z+9), state, 2);
		world.setBlockState(pos.add(x+10, y+6, z+9), Blocks.AIR.getDefaultState(), 2);
		world.setBlockState(pos.add(x+11, y+6, z+9), Blocks.AIR.getDefaultState(), 2);
		world.setBlockState(pos.add(x+12, y+6, z+9), state, 2);
		world.setBlockState(pos.add(x+3, y+6, z+10), state, 2);
		world.setBlockState(pos.add(x+4, y+6, z+10), Blocks.AIR.getDefaultState(), 2);
		world.setBlockState(pos.add(x+5, y+6, z+10), Blocks.AIR.getDefaultState(), 2);
		world.setBlockState(pos.add(x+6, y+6, z+10), Blocks.AIR.getDefaultState(), 2);
		world.setBlockState(pos.add(x+7, y+6, z+10), state, 2);
		world.setBlockState(pos.add(x+9, y+6, z+10), state, 2);
		world.setBlockState(pos.add(x+10, y+6, z+10), Blocks.AIR.getDefaultState(), 2);
		world.setBlockState(pos.add(x+11, y+6, z+10), Blocks.AIR.getDefaultState(), 2);
		world.setBlockState(pos.add(x+12, y+6, z+10), state, 2);
		world.setBlockState(pos.add(x+3, y+6, z+11), state, 2);
		world.setBlockState(pos.add(x+4, y+6, z+11), Blocks.AIR.getDefaultState(), 2);
		world.setBlockState(pos.add(x+5, y+6, z+11), Blocks.AIR.getDefaultState(), 2);
		world.setBlockState(pos.add(x+6, y+6, z+11), Blocks.AIR.getDefaultState(), 2);
		world.setBlockState(pos.add(x+7, y+6, z+11), state, 2);
		world.setBlockState(pos.add(x+10, y+6, z+11), state, 2);
		world.setBlockState(pos.add(x+11, y+6, z+11), state, 2);
		world.setBlockState(pos.add(x+3, y+6, z+12), state, 2);
		world.setBlockState(pos.add(x+4, y+6, z+12), Blocks.AIR.getDefaultState(), 2);
		world.setBlockState(pos.add(x+5, y+6, z+12), Blocks.AIR.getDefaultState(), 2);
		world.setBlockState(pos.add(x+6, y+6, z+12), Blocks.AIR.getDefaultState(), 2);
		world.setBlockState(pos.add(x+7, y+6, z+12), state, 2);
		world.setBlockState(pos.add(x+4, y+6, z+13), state, 2);
		world.setBlockState(pos.add(x+5, y+6, z+13), state, 2);
		world.setBlockState(pos.add(x+6, y+6, z+13), state, 2);
		world.setBlockState(pos.add(x+5, y+7, z+3), state, 2);
		world.setBlockState(pos.add(x+6, y+7, z+3), state, 2);
		world.setBlockState(pos.add(x+4, y+7, z+4), state, 2);
		world.setBlockState(pos.add(x+5, y+7, z+4), Blocks.AIR.getDefaultState(), 2);
		world.setBlockState(pos.add(x+6, y+7, z+4), Blocks.AIR.getDefaultState(), 2);
		world.setBlockState(pos.add(x+7, y+7, z+4), state, 2);
		world.setBlockState(pos.add(x+4, y+7, z+5), state, 2);
		world.setBlockState(pos.add(x+5, y+7, z+5), Blocks.AIR.getDefaultState(), 2);
		world.setBlockState(pos.add(x+6, y+7, z+5), Blocks.AIR.getDefaultState(), 2);
		world.setBlockState(pos.add(x+7, y+7, z+5), state, 2);
		world.setBlockState(pos.add(x+5, y+7, z+6), state, 2);
		world.setBlockState(pos.add(x+6, y+7, z+6), state, 2);
		world.setBlockState(pos.add(x+10, y+7, z+8), state, 2);
		world.setBlockState(pos.add(x+11, y+7, z+8), state, 2);
		world.setBlockState(pos.add(x+4, y+7, z+9), state, 2);
		world.setBlockState(pos.add(x+5, y+7, z+9), state, 2);
		world.setBlockState(pos.add(x+6, y+7, z+9), state, 2);
		world.setBlockState(pos.add(x+9, y+7, z+9), state, 2);
		world.setBlockState(pos.add(x+10, y+7, z+9), Blocks.AIR.getDefaultState(), 2);
		world.setBlockState(pos.add(x+11, y+7, z+9), Blocks.AIR.getDefaultState(), 2);
		world.setBlockState(pos.add(x+12, y+7, z+9), state, 2);
		world.setBlockState(pos.add(x+3, y+7, z+10), state, 2);
		world.setBlockState(pos.add(x+4, y+7, z+10), Blocks.AIR.getDefaultState(), 2);
		world.setBlockState(pos.add(x+5, y+7, z+10), Blocks.AIR.getDefaultState(), 2);
		world.setBlockState(pos.add(x+6, y+7, z+10), Blocks.AIR.getDefaultState(), 2);
		world.setBlockState(pos.add(x+7, y+7, z+10), state, 2);
		world.setBlockState(pos.add(x+9, y+7, z+10), state, 2);
		world.setBlockState(pos.add(x+10, y+7, z+10), Blocks.AIR.getDefaultState(), 2);
		world.setBlockState(pos.add(x+11, y+7, z+10), Blocks.AIR.getDefaultState(), 2);
		world.setBlockState(pos.add(x+12, y+7, z+10), state, 2);
		world.setBlockState(pos.add(x+3, y+7, z+11), state, 2);
		world.setBlockState(pos.add(x+4, y+7, z+11), Blocks.AIR.getDefaultState(), 2);
		world.setBlockState(pos.add(x+5, y+7, z+11), Blocks.AIR.getDefaultState(), 2);
		world.setBlockState(pos.add(x+6, y+7, z+11), Blocks.AIR.getDefaultState(), 2);
		world.setBlockState(pos.add(x+7, y+7, z+11), state, 2);
		world.setBlockState(pos.add(x+10, y+7, z+11), state, 2);
		world.setBlockState(pos.add(x+11, y+7, z+11), state, 2);
		world.setBlockState(pos.add(x+3, y+7, z+12), state, 2);
		world.setBlockState(pos.add(x+4, y+7, z+12), Blocks.AIR.getDefaultState(), 2);
		world.setBlockState(pos.add(x+5, y+7, z+12), Blocks.AIR.getDefaultState(), 2);
		world.setBlockState(pos.add(x+6, y+7, z+12), Blocks.AIR.getDefaultState(), 2);
		world.setBlockState(pos.add(x+7, y+7, z+12), state, 2);
		world.setBlockState(pos.add(x+4, y+7, z+13), state, 2);
		world.setBlockState(pos.add(x+5, y+7, z+13), state, 2);
		world.setBlockState(pos.add(x+6, y+7, z+13), state, 2);
		world.setBlockState(pos.add(x+5, y+8, z+3), state, 2);
		world.setBlockState(pos.add(x+6, y+8, z+3), state, 2);
		world.setBlockState(pos.add(x+4, y+8, z+4), state, 2);
		world.setBlockState(pos.add(x+5, y+8, z+4), Blocks.AIR.getDefaultState(), 2);
		world.setBlockState(pos.add(x+6, y+8, z+4), Blocks.AIR.getDefaultState(), 2);
		world.setBlockState(pos.add(x+7, y+8, z+4), state, 2);
		world.setBlockState(pos.add(x+4, y+8, z+5), state, 2);
		world.setBlockState(pos.add(x+5, y+8, z+5), Blocks.AIR.getDefaultState(), 2);
		world.setBlockState(pos.add(x+6, y+8, z+5), Blocks.AIR.getDefaultState(), 2);
		world.setBlockState(pos.add(x+7, y+8, z+5), state, 2);
		world.setBlockState(pos.add(x+5, y+8, z+6), state, 2);
		world.setBlockState(pos.add(x+6, y+8, z+6), state, 2);
		world.setBlockState(pos.add(x+10, y+8, z+8), state, 2);
		world.setBlockState(pos.add(x+11, y+8, z+8), state, 2);
		world.setBlockState(pos.add(x+4, y+8, z+9), state, 2);
		world.setBlockState(pos.add(x+5, y+8, z+9), state, 2);
		world.setBlockState(pos.add(x+6, y+8, z+9), state, 2);
		world.setBlockState(pos.add(x+9, y+8, z+9), state, 2);
		world.setBlockState(pos.add(x+10, y+8, z+9), Blocks.AIR.getDefaultState(), 2);
		world.setBlockState(pos.add(x+11, y+8, z+9), Blocks.AIR.getDefaultState(), 2);
		world.setBlockState(pos.add(x+12, y+8, z+9), state, 2);
		world.setBlockState(pos.add(x+3, y+8, z+10), state, 2);
		world.setBlockState(pos.add(x+4, y+8, z+10), Blocks.AIR.getDefaultState(), 2);
		world.setBlockState(pos.add(x+5, y+8, z+10), Blocks.AIR.getDefaultState(), 2);
		world.setBlockState(pos.add(x+6, y+8, z+10), Blocks.AIR.getDefaultState(), 2);
		world.setBlockState(pos.add(x+7, y+8, z+10), state, 2);
		world.setBlockState(pos.add(x+9, y+8, z+10), state, 2);
		world.setBlockState(pos.add(x+10, y+8, z+10), Blocks.AIR.getDefaultState(), 2);
		world.setBlockState(pos.add(x+11, y+8, z+10), Blocks.AIR.getDefaultState(), 2);
		world.setBlockState(pos.add(x+12, y+8, z+10), state, 2);
		world.setBlockState(pos.add(x+3, y+8, z+11), state, 2);
		world.setBlockState(pos.add(x+4, y+8, z+11), Blocks.AIR.getDefaultState(), 2);
		world.setBlockState(pos.add(x+5, y+8, z+11), Blocks.AIR.getDefaultState(), 2);
		world.setBlockState(pos.add(x+6, y+8, z+11), Blocks.AIR.getDefaultState(), 2);
		world.setBlockState(pos.add(x+7, y+8, z+11), state, 2);
		world.setBlockState(pos.add(x+10, y+8, z+11), state, 2);
		world.setBlockState(pos.add(x+11, y+8, z+11), state, 2);
		world.setBlockState(pos.add(x+3, y+8, z+12), state, 2);
		world.setBlockState(pos.add(x+4, y+8, z+12), Blocks.AIR.getDefaultState(), 2);
		world.setBlockState(pos.add(x+5, y+8, z+12), Blocks.AIR.getDefaultState(), 2);
		world.setBlockState(pos.add(x+6, y+8, z+12), Blocks.AIR.getDefaultState(), 2);
		world.setBlockState(pos.add(x+7, y+8, z+12), state, 2);
		world.setBlockState(pos.add(x+4, y+8, z+13), state, 2);
		world.setBlockState(pos.add(x+5, y+8, z+13), state, 2);
		world.setBlockState(pos.add(x+6, y+8, z+13), state, 2);
		world.setBlockState(pos.add(x+5, y+9, z+3), state, 2);
		world.setBlockState(pos.add(x+6, y+9, z+3), state, 2);
		world.setBlockState(pos.add(x+4, y+9, z+4), state, 2);
		world.setBlockState(pos.add(x+5, y+9, z+4), Blocks.AIR.getDefaultState(), 2);
		world.setBlockState(pos.add(x+6, y+9, z+4), Blocks.AIR.getDefaultState(), 2);
		world.setBlockState(pos.add(x+7, y+9, z+4), state, 2);
		world.setBlockState(pos.add(x+4, y+9, z+5), state, 2);
		world.setBlockState(pos.add(x+5, y+9, z+5), Blocks.AIR.getDefaultState(), 2);
		world.setBlockState(pos.add(x+6, y+9, z+5), Blocks.AIR.getDefaultState(), 2);
		world.setBlockState(pos.add(x+7, y+9, z+5), state, 2);
		world.setBlockState(pos.add(x+5, y+9, z+6), state, 2);
		world.setBlockState(pos.add(x+6, y+9, z+6), state, 2);
		world.setBlockState(pos.add(x+10, y+9, z+8), state, 2);
		world.setBlockState(pos.add(x+11, y+9, z+8), state, 2);
		world.setBlockState(pos.add(x+4, y+9, z+9), state, 2);
		world.setBlockState(pos.add(x+5, y+9, z+9), state, 2);
		world.setBlockState(pos.add(x+6, y+9, z+9), state, 2);
		world.setBlockState(pos.add(x+9, y+9, z+9), state, 2);
		world.setBlockState(pos.add(x+10, y+9, z+9), Blocks.AIR.getDefaultState(), 2);
		world.setBlockState(pos.add(x+11, y+9, z+9), Blocks.AIR.getDefaultState(), 2);
		world.setBlockState(pos.add(x+12, y+9, z+9), state, 2);
		world.setBlockState(pos.add(x+3, y+9, z+10), state, 2);
		world.setBlockState(pos.add(x+4, y+9, z+10), Blocks.AIR.getDefaultState(), 2);
		world.setBlockState(pos.add(x+5, y+9, z+10), Blocks.AIR.getDefaultState(), 2);
		world.setBlockState(pos.add(x+6, y+9, z+10), Blocks.AIR.getDefaultState(), 2);
		world.setBlockState(pos.add(x+7, y+9, z+10), state, 2);
		world.setBlockState(pos.add(x+9, y+9, z+10), state, 2);
		world.setBlockState(pos.add(x+10, y+9, z+10), Blocks.AIR.getDefaultState(), 2);
		world.setBlockState(pos.add(x+11, y+9, z+10), Blocks.AIR.getDefaultState(), 2);
		world.setBlockState(pos.add(x+12, y+9, z+10), state, 2);
		world.setBlockState(pos.add(x+3, y+9, z+11), state, 2);
		world.setBlockState(pos.add(x+4, y+9, z+11), Blocks.AIR.getDefaultState(), 2);
		world.setBlockState(pos.add(x+5, y+9, z+11), Blocks.AIR.getDefaultState(), 2);
		world.setBlockState(pos.add(x+6, y+9, z+11), Blocks.AIR.getDefaultState(), 2);
		world.setBlockState(pos.add(x+7, y+9, z+11), state, 2);
		world.setBlockState(pos.add(x+10, y+9, z+11), state, 2);
		world.setBlockState(pos.add(x+11, y+9, z+11), state, 2);
		world.setBlockState(pos.add(x+3, y+9, z+12), state, 2);
		world.setBlockState(pos.add(x+4, y+9, z+12), Blocks.AIR.getDefaultState(), 2);
		world.setBlockState(pos.add(x+5, y+9, z+12), Blocks.AIR.getDefaultState(), 2);
		world.setBlockState(pos.add(x+6, y+9, z+12), Blocks.AIR.getDefaultState(), 2);
		world.setBlockState(pos.add(x+7, y+9, z+12), state, 2);
		world.setBlockState(pos.add(x+4, y+9, z+13), state, 2);
		world.setBlockState(pos.add(x+5, y+9, z+13), state, 2);
		world.setBlockState(pos.add(x+6, y+9, z+13), state, 2);
		world.setBlockState(pos.add(x+5, y+10, z+3), state, 2);
		world.setBlockState(pos.add(x+6, y+10, z+3), state, 2);
		world.setBlockState(pos.add(x+4, y+10, z+4), state, 2);
		world.setBlockState(pos.add(x+5, y+10, z+4), Blocks.AIR.getDefaultState(), 2);
		world.setBlockState(pos.add(x+6, y+10, z+4), Blocks.AIR.getDefaultState(), 2);
		world.setBlockState(pos.add(x+7, y+10, z+4), state, 2);
		world.setBlockState(pos.add(x+4, y+10, z+5), state, 2);
		world.setBlockState(pos.add(x+5, y+10, z+5), Blocks.AIR.getDefaultState(), 2);
		world.setBlockState(pos.add(x+6, y+10, z+5), Blocks.AIR.getDefaultState(), 2);
		world.setBlockState(pos.add(x+7, y+10, z+5), state, 2);
		world.setBlockState(pos.add(x+5, y+10, z+6), state, 2);
		world.setBlockState(pos.add(x+6, y+10, z+6), state, 2);
		world.setBlockState(pos.add(x+10, y+10, z+8), state, 2);
		world.setBlockState(pos.add(x+11, y+10, z+8), state, 2);
		world.setBlockState(pos.add(x+4, y+10, z+9), state, 2);
		world.setBlockState(pos.add(x+5, y+10, z+9), state, 2);
		world.setBlockState(pos.add(x+6, y+10, z+9), state, 2);
		world.setBlockState(pos.add(x+9, y+10, z+9), state, 2);
		world.setBlockState(pos.add(x+10, y+10, z+9), Blocks.AIR.getDefaultState(), 2);
		world.setBlockState(pos.add(x+11, y+10, z+9), Blocks.AIR.getDefaultState(), 2);
		world.setBlockState(pos.add(x+12, y+10, z+9), state, 2);
		world.setBlockState(pos.add(x+3, y+10, z+10), state, 2);
		world.setBlockState(pos.add(x+4, y+10, z+10), Blocks.AIR.getDefaultState(), 2);
		world.setBlockState(pos.add(x+5, y+10, z+10), Blocks.AIR.getDefaultState(), 2);
		world.setBlockState(pos.add(x+6, y+10, z+10), Blocks.AIR.getDefaultState(), 2);
		world.setBlockState(pos.add(x+7, y+10, z+10), state, 2);
		world.setBlockState(pos.add(x+9, y+10, z+10), state, 2);
		world.setBlockState(pos.add(x+10, y+10, z+10), Blocks.AIR.getDefaultState(), 2);
		world.setBlockState(pos.add(x+11, y+10, z+10), Blocks.AIR.getDefaultState(), 2);
		world.setBlockState(pos.add(x+12, y+10, z+10), state, 2);
		world.setBlockState(pos.add(x+3, y+10, z+11), state, 2);
		world.setBlockState(pos.add(x+4, y+10, z+11), Blocks.AIR.getDefaultState(), 2);
		world.setBlockState(pos.add(x+5, y+10, z+11), Blocks.AIR.getDefaultState(), 2);
		world.setBlockState(pos.add(x+6, y+10, z+11), Blocks.AIR.getDefaultState(), 2);
		world.setBlockState(pos.add(x+7, y+10, z+11), state, 2);
		world.setBlockState(pos.add(x+10, y+10, z+11), state, 2);
		world.setBlockState(pos.add(x+11, y+10, z+11), state, 2);
		world.setBlockState(pos.add(x+3, y+10, z+12), state, 2);
		world.setBlockState(pos.add(x+4, y+10, z+12), Blocks.AIR.getDefaultState(), 2);
		world.setBlockState(pos.add(x+5, y+10, z+12), Blocks.AIR.getDefaultState(), 2);
		world.setBlockState(pos.add(x+6, y+10, z+12), Blocks.AIR.getDefaultState(), 2);
		world.setBlockState(pos.add(x+7, y+10, z+12), state, 2);
		world.setBlockState(pos.add(x+4, y+10, z+13), state, 2);
		world.setBlockState(pos.add(x+5, y+10, z+13), state, 2);
		world.setBlockState(pos.add(x+6, y+10, z+13), state, 2);
		world.setBlockState(pos.add(x+5, y+11, z+3), state, 2);
		world.setBlockState(pos.add(x+6, y+11, z+3), state, 2);
		world.setBlockState(pos.add(x+4, y+11, z+4), state, 2);
		world.setBlockState(pos.add(x+5, y+11, z+4), Blocks.AIR.getDefaultState(), 2);
		world.setBlockState(pos.add(x+6, y+11, z+4), Blocks.AIR.getDefaultState(), 2);
		world.setBlockState(pos.add(x+7, y+11, z+4), state, 2);
		world.setBlockState(pos.add(x+4, y+11, z+5), state, 2);
		world.setBlockState(pos.add(x+5, y+11, z+5), Blocks.AIR.getDefaultState(), 2);
		world.setBlockState(pos.add(x+6, y+11, z+5), Blocks.AIR.getDefaultState(), 2);
		world.setBlockState(pos.add(x+7, y+11, z+5), state, 2);
		world.setBlockState(pos.add(x+5, y+11, z+6), state, 2);
		world.setBlockState(pos.add(x+6, y+11, z+6), state, 2);
		world.setBlockState(pos.add(x+10, y+11, z+8), state, 2);
		world.setBlockState(pos.add(x+11, y+11, z+8), state, 2);
		world.setBlockState(pos.add(x+4, y+11, z+9), state, 2);
		world.setBlockState(pos.add(x+5, y+11, z+9), state, 2);
		world.setBlockState(pos.add(x+6, y+11, z+9), state, 2);
		world.setBlockState(pos.add(x+9, y+11, z+9), state, 2);
		world.setBlockState(pos.add(x+10, y+11, z+9), Blocks.AIR.getDefaultState(), 2);
		world.setBlockState(pos.add(x+11, y+11, z+9), Blocks.AIR.getDefaultState(), 2);
		world.setBlockState(pos.add(x+12, y+11, z+9), state, 2);
		world.setBlockState(pos.add(x+3, y+11, z+10), state, 2);
		world.setBlockState(pos.add(x+4, y+11, z+10), Blocks.AIR.getDefaultState(), 2);
		world.setBlockState(pos.add(x+5, y+11, z+10), Blocks.AIR.getDefaultState(), 2);
		world.setBlockState(pos.add(x+6, y+11, z+10), Blocks.AIR.getDefaultState(), 2);
		world.setBlockState(pos.add(x+7, y+11, z+10), state, 2);
		world.setBlockState(pos.add(x+9, y+11, z+10), state, 2);
		world.setBlockState(pos.add(x+10, y+11, z+10), Blocks.AIR.getDefaultState(), 2);
		world.setBlockState(pos.add(x+11, y+11, z+10), Blocks.AIR.getDefaultState(), 2);
		world.setBlockState(pos.add(x+12, y+11, z+10), state, 2);
		world.setBlockState(pos.add(x+3, y+11, z+11), state, 2);
		world.setBlockState(pos.add(x+4, y+11, z+11), Blocks.AIR.getDefaultState(), 2);
		world.setBlockState(pos.add(x+5, y+11, z+11), Blocks.AIR.getDefaultState(), 2);
		world.setBlockState(pos.add(x+6, y+11, z+11), Blocks.AIR.getDefaultState(), 2);
		world.setBlockState(pos.add(x+7, y+11, z+11), state, 2);
		world.setBlockState(pos.add(x+10, y+11, z+11), state, 2);
		world.setBlockState(pos.add(x+11, y+11, z+11), state, 2);
		world.setBlockState(pos.add(x+3, y+11, z+12), state, 2);
		world.setBlockState(pos.add(x+4, y+11, z+12), Blocks.AIR.getDefaultState(), 2);
		world.setBlockState(pos.add(x+5, y+11, z+12), Blocks.AIR.getDefaultState(), 2);
		world.setBlockState(pos.add(x+6, y+11, z+12), Blocks.AIR.getDefaultState(), 2);
		world.setBlockState(pos.add(x+7, y+11, z+12), state, 2);
		world.setBlockState(pos.add(x+4, y+11, z+13), state, 2);
		world.setBlockState(pos.add(x+5, y+11, z+13), state, 2);
		world.setBlockState(pos.add(x+6, y+11, z+13), state, 2);
		world.setBlockState(pos.add(x+5, y+12, z+3), state, 2);
		world.setBlockState(pos.add(x+6, y+12, z+3), state, 2);
		world.setBlockState(pos.add(x+4, y+12, z+4), state, 2);
		world.setBlockState(pos.add(x+5, y+12, z+4), Blocks.AIR.getDefaultState(), 2);
		world.setBlockState(pos.add(x+6, y+12, z+4), Blocks.AIR.getDefaultState(), 2);
		world.setBlockState(pos.add(x+7, y+12, z+4), state, 2);
		world.setBlockState(pos.add(x+4, y+12, z+5), state, 2);
		world.setBlockState(pos.add(x+5, y+12, z+5), Blocks.AIR.getDefaultState(), 2);
		world.setBlockState(pos.add(x+6, y+12, z+5), Blocks.AIR.getDefaultState(), 2);
		world.setBlockState(pos.add(x+7, y+12, z+5), state, 2);
		world.setBlockState(pos.add(x+5, y+12, z+6), state, 2);
		world.setBlockState(pos.add(x+6, y+12, z+6), state, 2);
		world.setBlockState(pos.add(x+10, y+12, z+8), state, 2);
		world.setBlockState(pos.add(x+11, y+12, z+8), state, 2);
		world.setBlockState(pos.add(x+4, y+12, z+9), state, 2);
		world.setBlockState(pos.add(x+5, y+12, z+9), state, 2);
		world.setBlockState(pos.add(x+6, y+12, z+9), state, 2);
		world.setBlockState(pos.add(x+9, y+12, z+9), state, 2);
		world.setBlockState(pos.add(x+10, y+12, z+9), Blocks.AIR.getDefaultState(), 2);
		world.setBlockState(pos.add(x+11, y+12, z+9), Blocks.AIR.getDefaultState(), 2);
		world.setBlockState(pos.add(x+12, y+12, z+9), state, 2);
		world.setBlockState(pos.add(x+3, y+12, z+10), state, 2);
		world.setBlockState(pos.add(x+4, y+12, z+10), Blocks.AIR.getDefaultState(), 2);
		world.setBlockState(pos.add(x+5, y+12, z+10), Blocks.AIR.getDefaultState(), 2);
		world.setBlockState(pos.add(x+6, y+12, z+10), Blocks.AIR.getDefaultState(), 2);
		world.setBlockState(pos.add(x+7, y+12, z+10), state, 2);
		world.setBlockState(pos.add(x+9, y+12, z+10), state, 2);
		world.setBlockState(pos.add(x+10, y+12, z+10), Blocks.AIR.getDefaultState(), 2);
		world.setBlockState(pos.add(x+11, y+12, z+10), Blocks.AIR.getDefaultState(), 2);
		world.setBlockState(pos.add(x+12, y+12, z+10), state, 2);
		world.setBlockState(pos.add(x+3, y+12, z+11), state, 2);
		world.setBlockState(pos.add(x+4, y+12, z+11), Blocks.AIR.getDefaultState(), 2);
		world.setBlockState(pos.add(x+5, y+12, z+11), Blocks.AIR.getDefaultState(), 2);
		world.setBlockState(pos.add(x+6, y+12, z+11), Blocks.AIR.getDefaultState(), 2);
		world.setBlockState(pos.add(x+7, y+12, z+11), state, 2);
		world.setBlockState(pos.add(x+10, y+12, z+11), state, 2);
		world.setBlockState(pos.add(x+11, y+12, z+11), state, 2);
		world.setBlockState(pos.add(x+3, y+12, z+12), state, 2);
		world.setBlockState(pos.add(x+4, y+12, z+12), Blocks.AIR.getDefaultState(), 2);
		world.setBlockState(pos.add(x+5, y+12, z+12), Blocks.AIR.getDefaultState(), 2);
		world.setBlockState(pos.add(x+6, y+12, z+12), Blocks.AIR.getDefaultState(), 2);
		world.setBlockState(pos.add(x+7, y+12, z+12), state, 2);
		world.setBlockState(pos.add(x+4, y+12, z+13), state, 2);
		world.setBlockState(pos.add(x+5, y+12, z+13), state, 2);
		world.setBlockState(pos.add(x+6, y+12, z+13), state, 2);
		world.setBlockState(pos.add(x+5, y+13, z+3), state, 2);
		world.setBlockState(pos.add(x+6, y+13, z+3), state, 2);
		world.setBlockState(pos.add(x+4, y+13, z+4), state, 2);
		world.setBlockState(pos.add(x+5, y+13, z+4), Blocks.AIR.getDefaultState(), 2);
		world.setBlockState(pos.add(x+6, y+13, z+4), Blocks.AIR.getDefaultState(), 2);
		world.setBlockState(pos.add(x+7, y+13, z+4), state, 2);
		world.setBlockState(pos.add(x+4, y+13, z+5), state, 2);
		world.setBlockState(pos.add(x+5, y+13, z+5), Blocks.AIR.getDefaultState(), 2);
		world.setBlockState(pos.add(x+6, y+13, z+5), Blocks.AIR.getDefaultState(), 2);
		world.setBlockState(pos.add(x+7, y+13, z+5), state, 2);
		world.setBlockState(pos.add(x+5, y+13, z+6), state, 2);
		world.setBlockState(pos.add(x+6, y+13, z+6), state, 2);
		world.setBlockState(pos.add(x+10, y+13, z+8), state, 2);
		world.setBlockState(pos.add(x+11, y+13, z+8), state, 2);
		world.setBlockState(pos.add(x+4, y+13, z+9), state, 2);
		world.setBlockState(pos.add(x+5, y+13, z+9), state, 2);
		world.setBlockState(pos.add(x+6, y+13, z+9), state, 2);
		world.setBlockState(pos.add(x+9, y+13, z+9), state, 2);
		world.setBlockState(pos.add(x+10, y+13, z+9), Blocks.AIR.getDefaultState(), 2);
		world.setBlockState(pos.add(x+11, y+13, z+9), Blocks.AIR.getDefaultState(), 2);
		world.setBlockState(pos.add(x+12, y+13, z+9), state, 2);
		world.setBlockState(pos.add(x+3, y+13, z+10), state, 2);
		world.setBlockState(pos.add(x+4, y+13, z+10), Blocks.AIR.getDefaultState(), 2);
		world.setBlockState(pos.add(x+5, y+13, z+10), Blocks.AIR.getDefaultState(), 2);
		world.setBlockState(pos.add(x+6, y+13, z+10), Blocks.AIR.getDefaultState(), 2);
		world.setBlockState(pos.add(x+7, y+13, z+10), state, 2);
		world.setBlockState(pos.add(x+9, y+13, z+10), state, 2);
		world.setBlockState(pos.add(x+10, y+13, z+10), Blocks.AIR.getDefaultState(), 2);
		world.setBlockState(pos.add(x+11, y+13, z+10), Blocks.AIR.getDefaultState(), 2);
		world.setBlockState(pos.add(x+12, y+13, z+10), state, 2);
		world.setBlockState(pos.add(x+3, y+13, z+11), state, 2);
		world.setBlockState(pos.add(x+4, y+13, z+11), Blocks.AIR.getDefaultState(), 2);
		world.setBlockState(pos.add(x+5, y+13, z+11), Blocks.AIR.getDefaultState(), 2);
		world.setBlockState(pos.add(x+6, y+13, z+11), Blocks.AIR.getDefaultState(), 2);
		world.setBlockState(pos.add(x+7, y+13, z+11), state, 2);
		world.setBlockState(pos.add(x+10, y+13, z+11), state, 2);
		world.setBlockState(pos.add(x+11, y+13, z+11), state, 2);
		world.setBlockState(pos.add(x+3, y+13, z+12), state, 2);
		world.setBlockState(pos.add(x+4, y+13, z+12), Blocks.AIR.getDefaultState(), 2);
		world.setBlockState(pos.add(x+5, y+13, z+12), Blocks.AIR.getDefaultState(), 2);
		world.setBlockState(pos.add(x+6, y+13, z+12), Blocks.AIR.getDefaultState(), 2);
		world.setBlockState(pos.add(x+7, y+13, z+12), state, 2);
		world.setBlockState(pos.add(x+4, y+13, z+13), state, 2);
		world.setBlockState(pos.add(x+5, y+13, z+13), state, 2);
		world.setBlockState(pos.add(x+6, y+13, z+13), state, 2);
		world.setBlockState(pos.add(x+5, y+14, z+3), state, 2);
		world.setBlockState(pos.add(x+6, y+14, z+3), state, 2);
		world.setBlockState(pos.add(x+4, y+14, z+4), state, 2);
		world.setBlockState(pos.add(x+5, y+14, z+4), Blocks.AIR.getDefaultState(), 2);
		world.setBlockState(pos.add(x+6, y+14, z+4), Blocks.AIR.getDefaultState(), 2);
		world.setBlockState(pos.add(x+7, y+14, z+4), state, 2);
		world.setBlockState(pos.add(x+4, y+14, z+5), state, 2);
		world.setBlockState(pos.add(x+5, y+14, z+5), Blocks.AIR.getDefaultState(), 2);
		world.setBlockState(pos.add(x+6, y+14, z+5), Blocks.AIR.getDefaultState(), 2);
		world.setBlockState(pos.add(x+7, y+14, z+5), state, 2);
		world.setBlockState(pos.add(x+5, y+14, z+6), state, 2);
		world.setBlockState(pos.add(x+6, y+14, z+6), state, 2);
		world.setBlockState(pos.add(x+10, y+14, z+8), state, 2);
		world.setBlockState(pos.add(x+11, y+14, z+8), state, 2);
		world.setBlockState(pos.add(x+4, y+14, z+9), state, 2);
		world.setBlockState(pos.add(x+5, y+14, z+9), state, 2);
		world.setBlockState(pos.add(x+6, y+14, z+9), state, 2);
		world.setBlockState(pos.add(x+9, y+14, z+9), state, 2);
		world.setBlockState(pos.add(x+10, y+14, z+9), Blocks.AIR.getDefaultState(), 2);
		world.setBlockState(pos.add(x+11, y+14, z+9), Blocks.AIR.getDefaultState(), 2);
		world.setBlockState(pos.add(x+12, y+14, z+9), state, 2);
		world.setBlockState(pos.add(x+3, y+14, z+10), state, 2);
		world.setBlockState(pos.add(x+4, y+14, z+10), Blocks.AIR.getDefaultState(), 2);
		world.setBlockState(pos.add(x+5, y+14, z+10), Blocks.AIR.getDefaultState(), 2);
		world.setBlockState(pos.add(x+6, y+14, z+10), Blocks.AIR.getDefaultState(), 2);
		world.setBlockState(pos.add(x+7, y+14, z+10), state, 2);
		world.setBlockState(pos.add(x+9, y+14, z+10), state, 2);
		world.setBlockState(pos.add(x+10, y+14, z+10), Blocks.AIR.getDefaultState(), 2);
		world.setBlockState(pos.add(x+11, y+14, z+10), Blocks.AIR.getDefaultState(), 2);
		world.setBlockState(pos.add(x+12, y+14, z+10), state, 2);
		world.setBlockState(pos.add(x+3, y+14, z+11), state, 2);
		world.setBlockState(pos.add(x+4, y+14, z+11), Blocks.AIR.getDefaultState(), 2);
		world.setBlockState(pos.add(x+5, y+14, z+11), Blocks.AIR.getDefaultState(), 2);
		world.setBlockState(pos.add(x+6, y+14, z+11), Blocks.AIR.getDefaultState(), 2);
		world.setBlockState(pos.add(x+7, y+14, z+11), state, 2);
		world.setBlockState(pos.add(x+10, y+14, z+11), state, 2);
		world.setBlockState(pos.add(x+11, y+14, z+11), state, 2);
		world.setBlockState(pos.add(x+3, y+14, z+12), state, 2);
		world.setBlockState(pos.add(x+4, y+14, z+12), Blocks.AIR.getDefaultState(), 2);
		world.setBlockState(pos.add(x+5, y+14, z+12), Blocks.AIR.getDefaultState(), 2);
		world.setBlockState(pos.add(x+6, y+14, z+12), Blocks.AIR.getDefaultState(), 2);
		world.setBlockState(pos.add(x+7, y+14, z+12), state, 2);
		world.setBlockState(pos.add(x+4, y+14, z+13), state, 2);
		world.setBlockState(pos.add(x+5, y+14, z+13), state, 2);
		world.setBlockState(pos.add(x+6, y+14, z+13), state, 2);
		world.setBlockState(pos.add(x+5, y+15, z+3), state, 2);
		world.setBlockState(pos.add(x+6, y+15, z+3), state, 2);
		world.setBlockState(pos.add(x+4, y+15, z+4), state, 2);
		world.setBlockState(pos.add(x+5, y+15, z+4), Blocks.AIR.getDefaultState(), 2);
		world.setBlockState(pos.add(x+6, y+15, z+4), Blocks.AIR.getDefaultState(), 2);
		world.setBlockState(pos.add(x+7, y+15, z+4), state, 2);
		world.setBlockState(pos.add(x+4, y+15, z+5), state, 2);
		world.setBlockState(pos.add(x+5, y+15, z+5), Blocks.AIR.getDefaultState(), 2);
		world.setBlockState(pos.add(x+6, y+15, z+5), Blocks.AIR.getDefaultState(), 2);
		world.setBlockState(pos.add(x+7, y+15, z+5), state, 2);
		world.setBlockState(pos.add(x+5, y+15, z+6), state, 2);
		world.setBlockState(pos.add(x+6, y+15, z+6), state, 2);
		world.setBlockState(pos.add(x+10, y+15, z+8), state, 2);
		world.setBlockState(pos.add(x+11, y+15, z+8), state, 2);
		world.setBlockState(pos.add(x+4, y+15, z+9), state, 2);
		world.setBlockState(pos.add(x+5, y+15, z+9), state, 2);
		world.setBlockState(pos.add(x+6, y+15, z+9), state, 2);
		world.setBlockState(pos.add(x+9, y+15, z+9), state, 2);
		world.setBlockState(pos.add(x+10, y+15, z+9), Blocks.AIR.getDefaultState(), 2);
		world.setBlockState(pos.add(x+11, y+15, z+9), Blocks.AIR.getDefaultState(), 2);
		world.setBlockState(pos.add(x+12, y+15, z+9), state, 2);
		world.setBlockState(pos.add(x+3, y+15, z+10), state, 2);
		world.setBlockState(pos.add(x+4, y+15, z+10), Blocks.AIR.getDefaultState(), 2);
		world.setBlockState(pos.add(x+5, y+15, z+10), Blocks.AIR.getDefaultState(), 2);
		world.setBlockState(pos.add(x+6, y+15, z+10), Blocks.AIR.getDefaultState(), 2);
		world.setBlockState(pos.add(x+7, y+15, z+10), state, 2);
		world.setBlockState(pos.add(x+9, y+15, z+10), state, 2);
		world.setBlockState(pos.add(x+10, y+15, z+10), Blocks.AIR.getDefaultState(), 2);
		world.setBlockState(pos.add(x+11, y+15, z+10), Blocks.AIR.getDefaultState(), 2);
		world.setBlockState(pos.add(x+12, y+15, z+10), state, 2);
		world.setBlockState(pos.add(x+3, y+15, z+11), state, 2);
		world.setBlockState(pos.add(x+4, y+15, z+11), Blocks.AIR.getDefaultState(), 2);
		world.setBlockState(pos.add(x+5, y+15, z+11), Blocks.AIR.getDefaultState(), 2);
		world.setBlockState(pos.add(x+6, y+15, z+11), Blocks.AIR.getDefaultState(), 2);
		world.setBlockState(pos.add(x+7, y+15, z+11), state, 2);
		world.setBlockState(pos.add(x+10, y+15, z+11), state, 2);
		world.setBlockState(pos.add(x+11, y+15, z+11), state, 2);
		world.setBlockState(pos.add(x+3, y+15, z+12), state, 2);
		world.setBlockState(pos.add(x+4, y+15, z+12), Blocks.AIR.getDefaultState(), 2);
		world.setBlockState(pos.add(x+5, y+15, z+12), Blocks.AIR.getDefaultState(), 2);
		world.setBlockState(pos.add(x+6, y+15, z+12), Blocks.AIR.getDefaultState(), 2);
		world.setBlockState(pos.add(x+7, y+15, z+12), state, 2);
		world.setBlockState(pos.add(x+4, y+15, z+13), state, 2);
		world.setBlockState(pos.add(x+5, y+15, z+13), state, 2);
		world.setBlockState(pos.add(x+6, y+15, z+13), state, 2);
		world.setBlockState(pos.add(x+5, y+16, z+3), state, 2);
		world.setBlockState(pos.add(x+6, y+16, z+3), state, 2);
		world.setBlockState(pos.add(x+4, y+16, z+4), state, 2);
		world.setBlockState(pos.add(x+5, y+16, z+4), Blocks.AIR.getDefaultState(), 2);
		world.setBlockState(pos.add(x+6, y+16, z+4), Blocks.AIR.getDefaultState(), 2);
		world.setBlockState(pos.add(x+7, y+16, z+4), state, 2);
		world.setBlockState(pos.add(x+4, y+16, z+5), state, 2);
		world.setBlockState(pos.add(x+5, y+16, z+5), Blocks.AIR.getDefaultState(), 2);
		world.setBlockState(pos.add(x+6, y+16, z+5), Blocks.AIR.getDefaultState(), 2);
		world.setBlockState(pos.add(x+7, y+16, z+5), state, 2);
		world.setBlockState(pos.add(x+5, y+16, z+6), state, 2);
		world.setBlockState(pos.add(x+6, y+16, z+6), state, 2);
		world.setBlockState(pos.add(x+10, y+16, z+8), state, 2);
		world.setBlockState(pos.add(x+11, y+16, z+8), state, 2);
		world.setBlockState(pos.add(x+4, y+16, z+9), state, 2);
		world.setBlockState(pos.add(x+5, y+16, z+9), state, 2);
		world.setBlockState(pos.add(x+6, y+16, z+9), state, 2);
		world.setBlockState(pos.add(x+9, y+16, z+9), state, 2);
		world.setBlockState(pos.add(x+10, y+16, z+9), Blocks.AIR.getDefaultState(), 2);
		world.setBlockState(pos.add(x+11, y+16, z+9), Blocks.AIR.getDefaultState(), 2);
		world.setBlockState(pos.add(x+12, y+16, z+9), state, 2);
		world.setBlockState(pos.add(x+3, y+16, z+10), state, 2);
		world.setBlockState(pos.add(x+4, y+16, z+10), Blocks.AIR.getDefaultState(), 2);
		world.setBlockState(pos.add(x+5, y+16, z+10), Blocks.AIR.getDefaultState(), 2);
		world.setBlockState(pos.add(x+6, y+16, z+10), Blocks.AIR.getDefaultState(), 2);
		world.setBlockState(pos.add(x+7, y+16, z+10), state, 2);
		world.setBlockState(pos.add(x+9, y+16, z+10), state, 2);
		world.setBlockState(pos.add(x+10, y+16, z+10), Blocks.AIR.getDefaultState(), 2);
		world.setBlockState(pos.add(x+11, y+16, z+10), Blocks.AIR.getDefaultState(), 2);
		world.setBlockState(pos.add(x+12, y+16, z+10), state, 2);
		world.setBlockState(pos.add(x+3, y+16, z+11), state, 2);
		world.setBlockState(pos.add(x+4, y+16, z+11), Blocks.AIR.getDefaultState(), 2);
		world.setBlockState(pos.add(x+5, y+16, z+11), Blocks.AIR.getDefaultState(), 2);
		world.setBlockState(pos.add(x+6, y+16, z+11), Blocks.AIR.getDefaultState(), 2);
		world.setBlockState(pos.add(x+7, y+16, z+11), state, 2);
		world.setBlockState(pos.add(x+10, y+16, z+11), state, 2);
		world.setBlockState(pos.add(x+11, y+16, z+11), state, 2);
		world.setBlockState(pos.add(x+3, y+16, z+12), state, 2);
		world.setBlockState(pos.add(x+4, y+16, z+12), Blocks.AIR.getDefaultState(), 2);
		world.setBlockState(pos.add(x+5, y+16, z+12), Blocks.AIR.getDefaultState(), 2);
		world.setBlockState(pos.add(x+6, y+16, z+12), Blocks.AIR.getDefaultState(), 2);
		world.setBlockState(pos.add(x+7, y+16, z+12), state, 2);
		world.setBlockState(pos.add(x+4, y+16, z+13), state, 2);
		world.setBlockState(pos.add(x+5, y+16, z+13), state, 2);
		world.setBlockState(pos.add(x+6, y+16, z+13), state, 2);
		world.setBlockState(pos.add(x+5, y+17, z+3), state, 2);
		world.setBlockState(pos.add(x+6, y+17, z+3), state, 2);
		world.setBlockState(pos.add(x+4, y+17, z+4), state, 2);
		world.setBlockState(pos.add(x+5, y+17, z+4), Blocks.AIR.getDefaultState(), 2);
		world.setBlockState(pos.add(x+6, y+17, z+4), Blocks.AIR.getDefaultState(), 2);
		world.setBlockState(pos.add(x+7, y+17, z+4), state, 2);
		world.setBlockState(pos.add(x+4, y+17, z+5), state, 2);
		world.setBlockState(pos.add(x+5, y+17, z+5), Blocks.AIR.getDefaultState(), 2);
		world.setBlockState(pos.add(x+6, y+17, z+5), Blocks.AIR.getDefaultState(), 2);
		world.setBlockState(pos.add(x+7, y+17, z+5), state, 2);
		world.setBlockState(pos.add(x+5, y+17, z+6), state, 2);
		world.setBlockState(pos.add(x+6, y+17, z+6), state, 2);
		world.setBlockState(pos.add(x+10, y+17, z+8), state, 2);
		world.setBlockState(pos.add(x+11, y+17, z+8), state, 2);
		world.setBlockState(pos.add(x+4, y+17, z+9), state, 2);
		world.setBlockState(pos.add(x+5, y+17, z+9), state, 2);
		world.setBlockState(pos.add(x+6, y+17, z+9), state, 2);
		world.setBlockState(pos.add(x+9, y+17, z+9), state, 2);
		world.setBlockState(pos.add(x+10, y+17, z+9), Blocks.AIR.getDefaultState(), 2);
		world.setBlockState(pos.add(x+11, y+17, z+9), Blocks.AIR.getDefaultState(), 2);
		world.setBlockState(pos.add(x+12, y+17, z+9), state, 2);
		world.setBlockState(pos.add(x+3, y+17, z+10), state, 2);
		world.setBlockState(pos.add(x+4, y+17, z+10), Blocks.AIR.getDefaultState(), 2);
		world.setBlockState(pos.add(x+5, y+17, z+10), Blocks.AIR.getDefaultState(), 2);
		world.setBlockState(pos.add(x+6, y+17, z+10), Blocks.AIR.getDefaultState(), 2);
		world.setBlockState(pos.add(x+7, y+17, z+10), state, 2);
		world.setBlockState(pos.add(x+9, y+17, z+10), state, 2);
		world.setBlockState(pos.add(x+10, y+17, z+10), Blocks.AIR.getDefaultState(), 2);
		world.setBlockState(pos.add(x+11, y+17, z+10), Blocks.AIR.getDefaultState(), 2);
		world.setBlockState(pos.add(x+12, y+17, z+10), state, 2);
		world.setBlockState(pos.add(x+3, y+17, z+11), state, 2);
		world.setBlockState(pos.add(x+4, y+17, z+11), Blocks.AIR.getDefaultState(), 2);
		world.setBlockState(pos.add(x+5, y+17, z+11), Blocks.AIR.getDefaultState(), 2);
		world.setBlockState(pos.add(x+6, y+17, z+11), Blocks.AIR.getDefaultState(), 2);
		world.setBlockState(pos.add(x+7, y+17, z+11), state, 2);
		world.setBlockState(pos.add(x+10, y+17, z+11), state, 2);
		world.setBlockState(pos.add(x+11, y+17, z+11), state, 2);
		world.setBlockState(pos.add(x+3, y+17, z+12), state, 2);
		world.setBlockState(pos.add(x+4, y+17, z+12), Blocks.AIR.getDefaultState(), 2);
		world.setBlockState(pos.add(x+5, y+17, z+12), Blocks.AIR.getDefaultState(), 2);
		world.setBlockState(pos.add(x+6, y+17, z+12), Blocks.AIR.getDefaultState(), 2);
		world.setBlockState(pos.add(x+7, y+17, z+12), state, 2);
		world.setBlockState(pos.add(x+4, y+17, z+13), state, 2);
		world.setBlockState(pos.add(x+5, y+17, z+13), state, 2);
		world.setBlockState(pos.add(x+6, y+17, z+13), state, 2);
		world.setBlockState(pos.add(x+5, y+18, z+3), state, 2);
		world.setBlockState(pos.add(x+6, y+18, z+3), state, 2);
		world.setBlockState(pos.add(x+4, y+18, z+4), state, 2);
		world.setBlockState(pos.add(x+5, y+18, z+4), Blocks.AIR.getDefaultState(), 2);
		world.setBlockState(pos.add(x+6, y+18, z+4), Blocks.AIR.getDefaultState(), 2);
		world.setBlockState(pos.add(x+7, y+18, z+4), state, 2);
		world.setBlockState(pos.add(x+4, y+18, z+5), state, 2);
		world.setBlockState(pos.add(x+5, y+18, z+5), Blocks.AIR.getDefaultState(), 2);
		world.setBlockState(pos.add(x+6, y+18, z+5), Blocks.AIR.getDefaultState(), 2);
		world.setBlockState(pos.add(x+7, y+18, z+5), state, 2);
		world.setBlockState(pos.add(x+5, y+18, z+6), state, 2);
		world.setBlockState(pos.add(x+6, y+18, z+6), state, 2);
		world.setBlockState(pos.add(x+10, y+18, z+8), state, 2);
		world.setBlockState(pos.add(x+11, y+18, z+8), state, 2);
		world.setBlockState(pos.add(x+4, y+18, z+9), state, 2);
		world.setBlockState(pos.add(x+5, y+18, z+9), state, 2);
		world.setBlockState(pos.add(x+6, y+18, z+9), state, 2);
		world.setBlockState(pos.add(x+9, y+18, z+9), state, 2);
		world.setBlockState(pos.add(x+10, y+18, z+9), Blocks.AIR.getDefaultState(), 2);
		world.setBlockState(pos.add(x+11, y+18, z+9), Blocks.AIR.getDefaultState(), 2);
		world.setBlockState(pos.add(x+12, y+18, z+9), state, 2);
		world.setBlockState(pos.add(x+3, y+18, z+10), state, 2);
		world.setBlockState(pos.add(x+4, y+18, z+10), Blocks.AIR.getDefaultState(), 2);
		world.setBlockState(pos.add(x+5, y+18, z+10), Blocks.AIR.getDefaultState(), 2);
		world.setBlockState(pos.add(x+6, y+18, z+10), Blocks.AIR.getDefaultState(), 2);
		world.setBlockState(pos.add(x+7, y+18, z+10), state, 2);
		world.setBlockState(pos.add(x+9, y+18, z+10), state, 2);
		world.setBlockState(pos.add(x+10, y+18, z+10), Blocks.AIR.getDefaultState(), 2);
		world.setBlockState(pos.add(x+11, y+18, z+10), Blocks.AIR.getDefaultState(), 2);
		world.setBlockState(pos.add(x+12, y+18, z+10), state, 2);
		world.setBlockState(pos.add(x+3, y+18, z+11), state, 2);
		world.setBlockState(pos.add(x+4, y+18, z+11), Blocks.AIR.getDefaultState(), 2);
		world.setBlockState(pos.add(x+5, y+18, z+11), Blocks.AIR.getDefaultState(), 2);
		world.setBlockState(pos.add(x+6, y+18, z+11), Blocks.AIR.getDefaultState(), 2);
		world.setBlockState(pos.add(x+7, y+18, z+11), state, 2);
		world.setBlockState(pos.add(x+10, y+18, z+11), state, 2);
		world.setBlockState(pos.add(x+11, y+18, z+11), state, 2);
		world.setBlockState(pos.add(x+3, y+18, z+12), state, 2);
		world.setBlockState(pos.add(x+4, y+18, z+12), Blocks.AIR.getDefaultState(), 2);
		world.setBlockState(pos.add(x+5, y+18, z+12), Blocks.AIR.getDefaultState(), 2);
		world.setBlockState(pos.add(x+6, y+18, z+12), Blocks.AIR.getDefaultState(), 2);
		world.setBlockState(pos.add(x+7, y+18, z+12), state, 2);
		world.setBlockState(pos.add(x+4, y+18, z+13), state, 2);
		world.setBlockState(pos.add(x+5, y+18, z+13), state, 2);
		world.setBlockState(pos.add(x+6, y+18, z+13), state, 2);
		world.setBlockState(pos.add(x+5, y+19, z+3), state, 2);
		world.setBlockState(pos.add(x+6, y+19, z+3), state, 2);
		world.setBlockState(pos.add(x+4, y+19, z+4), state, 2);
		world.setBlockState(pos.add(x+5, y+19, z+4), Blocks.AIR.getDefaultState(), 2);
		world.setBlockState(pos.add(x+6, y+19, z+4), Blocks.AIR.getDefaultState(), 2);
		world.setBlockState(pos.add(x+7, y+19, z+4), state, 2);
		world.setBlockState(pos.add(x+4, y+19, z+5), state, 2);
		world.setBlockState(pos.add(x+5, y+19, z+5), Blocks.AIR.getDefaultState(), 2);
		world.setBlockState(pos.add(x+6, y+19, z+5), Blocks.AIR.getDefaultState(), 2);
		world.setBlockState(pos.add(x+7, y+19, z+5), state, 2);
		world.setBlockState(pos.add(x+5, y+19, z+6), state, 2);
		world.setBlockState(pos.add(x+6, y+19, z+6), state, 2);
		world.setBlockState(pos.add(x+10, y+19, z+8), state, 2);
		world.setBlockState(pos.add(x+11, y+19, z+8), state, 2);
		world.setBlockState(pos.add(x+4, y+19, z+9), state, 2);
		world.setBlockState(pos.add(x+5, y+19, z+9), state, 2);
		world.setBlockState(pos.add(x+6, y+19, z+9), state, 2);
		world.setBlockState(pos.add(x+9, y+19, z+9), state, 2);
		world.setBlockState(pos.add(x+10, y+19, z+9), Blocks.AIR.getDefaultState(), 2);
		world.setBlockState(pos.add(x+11, y+19, z+9), Blocks.AIR.getDefaultState(), 2);
		world.setBlockState(pos.add(x+12, y+19, z+9), state, 2);
		world.setBlockState(pos.add(x+3, y+19, z+10), state, 2);
		world.setBlockState(pos.add(x+4, y+19, z+10), Blocks.AIR.getDefaultState(), 2);
		world.setBlockState(pos.add(x+5, y+19, z+10), Blocks.AIR.getDefaultState(), 2);
		world.setBlockState(pos.add(x+6, y+19, z+10), Blocks.AIR.getDefaultState(), 2);
		world.setBlockState(pos.add(x+7, y+19, z+10), state, 2);
		world.setBlockState(pos.add(x+9, y+19, z+10), state, 2);
		world.setBlockState(pos.add(x+10, y+19, z+10), Blocks.AIR.getDefaultState(), 2);
		world.setBlockState(pos.add(x+11, y+19, z+10), Blocks.AIR.getDefaultState(), 2);
		world.setBlockState(pos.add(x+12, y+19, z+10), state, 2);
		world.setBlockState(pos.add(x+3, y+19, z+11), state, 2);
		world.setBlockState(pos.add(x+4, y+19, z+11), Blocks.AIR.getDefaultState(), 2);
		world.setBlockState(pos.add(x+5, y+19, z+11), Blocks.AIR.getDefaultState(), 2);
		world.setBlockState(pos.add(x+6, y+19, z+11), Blocks.AIR.getDefaultState(), 2);
		world.setBlockState(pos.add(x+7, y+19, z+11), state, 2);
		world.setBlockState(pos.add(x+10, y+19, z+11), state, 2);
		world.setBlockState(pos.add(x+11, y+19, z+11), state, 2);
		world.setBlockState(pos.add(x+3, y+19, z+12), state, 2);
		world.setBlockState(pos.add(x+4, y+19, z+12), Blocks.AIR.getDefaultState(), 2);
		world.setBlockState(pos.add(x+5, y+19, z+12), Blocks.AIR.getDefaultState(), 2);
		world.setBlockState(pos.add(x+6, y+19, z+12), Blocks.AIR.getDefaultState(), 2);
		world.setBlockState(pos.add(x+7, y+19, z+12), state, 2);
		world.setBlockState(pos.add(x+4, y+19, z+13), state, 2);
		world.setBlockState(pos.add(x+5, y+19, z+13), state, 2);
		world.setBlockState(pos.add(x+6, y+19, z+13), state, 2);
		world.setBlockState(pos.add(x+5, y+20, z+3), state, 2);
		world.setBlockState(pos.add(x+6, y+20, z+3), state, 2);
		world.setBlockState(pos.add(x+4, y+20, z+4), state, 2);
		world.setBlockState(pos.add(x+5, y+20, z+4), Blocks.AIR.getDefaultState(), 2);
		world.setBlockState(pos.add(x+6, y+20, z+4), Blocks.AIR.getDefaultState(), 2);
		world.setBlockState(pos.add(x+7, y+20, z+4), state, 2);
		world.setBlockState(pos.add(x+4, y+20, z+5), state, 2);
		world.setBlockState(pos.add(x+5, y+20, z+5), Blocks.AIR.getDefaultState(), 2);
		world.setBlockState(pos.add(x+6, y+20, z+5), Blocks.AIR.getDefaultState(), 2);
		world.setBlockState(pos.add(x+7, y+20, z+5), state, 2);
		world.setBlockState(pos.add(x+5, y+20, z+6), state, 2);
		world.setBlockState(pos.add(x+6, y+20, z+6), state, 2);
		world.setBlockState(pos.add(x+10, y+20, z+8), state, 2);
		world.setBlockState(pos.add(x+11, y+20, z+8), state, 2);
		world.setBlockState(pos.add(x+4, y+20, z+9), state, 2);
		world.setBlockState(pos.add(x+5, y+20, z+9), state, 2);
		world.setBlockState(pos.add(x+6, y+20, z+9), state, 2);
		world.setBlockState(pos.add(x+9, y+20, z+9), state, 2);
		world.setBlockState(pos.add(x+10, y+20, z+9), Blocks.AIR.getDefaultState(), 2);
		world.setBlockState(pos.add(x+11, y+20, z+9), Blocks.AIR.getDefaultState(), 2);
		world.setBlockState(pos.add(x+12, y+20, z+9), state, 2);
		world.setBlockState(pos.add(x+3, y+20, z+10), state, 2);
		world.setBlockState(pos.add(x+4, y+20, z+10), Blocks.AIR.getDefaultState(), 2);
		world.setBlockState(pos.add(x+5, y+20, z+10), Blocks.AIR.getDefaultState(), 2);
		world.setBlockState(pos.add(x+6, y+20, z+10), Blocks.AIR.getDefaultState(), 2);
		world.setBlockState(pos.add(x+7, y+20, z+10), state, 2);
		world.setBlockState(pos.add(x+9, y+20, z+10), state, 2);
		world.setBlockState(pos.add(x+10, y+20, z+10), Blocks.AIR.getDefaultState(), 2);
		world.setBlockState(pos.add(x+11, y+20, z+10), Blocks.AIR.getDefaultState(), 2);
		world.setBlockState(pos.add(x+12, y+20, z+10), state, 2);
		world.setBlockState(pos.add(x+3, y+20, z+11), state, 2);
		world.setBlockState(pos.add(x+4, y+20, z+11), Blocks.AIR.getDefaultState(), 2);
		world.setBlockState(pos.add(x+5, y+20, z+11), Blocks.AIR.getDefaultState(), 2);
		world.setBlockState(pos.add(x+6, y+20, z+11), Blocks.AIR.getDefaultState(), 2);
		world.setBlockState(pos.add(x+7, y+20, z+11), state, 2);
		world.setBlockState(pos.add(x+10, y+20, z+11), state, 2);
		world.setBlockState(pos.add(x+11, y+20, z+11), state, 2);
		world.setBlockState(pos.add(x+3, y+20, z+12), state, 2);
		world.setBlockState(pos.add(x+4, y+20, z+12), Blocks.AIR.getDefaultState(), 2);
		world.setBlockState(pos.add(x+5, y+20, z+12), Blocks.AIR.getDefaultState(), 2);
		world.setBlockState(pos.add(x+6, y+20, z+12), Blocks.AIR.getDefaultState(), 2);
		world.setBlockState(pos.add(x+7, y+20, z+12), state, 2);
		world.setBlockState(pos.add(x+4, y+20, z+13), state, 2);
		world.setBlockState(pos.add(x+5, y+20, z+13), state, 2);
		world.setBlockState(pos.add(x+6, y+20, z+13), state, 2);
		world.setBlockState(pos.add(x+5, y+21, z+3), state, 2);
		world.setBlockState(pos.add(x+6, y+21, z+3), state, 2);
		world.setBlockState(pos.add(x+4, y+21, z+4), state, 2);
		world.setBlockState(pos.add(x+5, y+21, z+4), Blocks.AIR.getDefaultState(), 2);
		world.setBlockState(pos.add(x+6, y+21, z+4), Blocks.AIR.getDefaultState(), 2);
		world.setBlockState(pos.add(x+7, y+21, z+4), state, 2);
		world.setBlockState(pos.add(x+4, y+21, z+5), state, 2);
		world.setBlockState(pos.add(x+5, y+21, z+5), Blocks.AIR.getDefaultState(), 2);
		world.setBlockState(pos.add(x+6, y+21, z+5), Blocks.AIR.getDefaultState(), 2);
		world.setBlockState(pos.add(x+7, y+21, z+5), state, 2);
		world.setBlockState(pos.add(x+5, y+21, z+6), state, 2);
		world.setBlockState(pos.add(x+6, y+21, z+6), state, 2);
		world.setBlockState(pos.add(x+10, y+21, z+8), state, 2);
		world.setBlockState(pos.add(x+11, y+21, z+8), state, 2);
		world.setBlockState(pos.add(x+4, y+21, z+9), state, 2);
		world.setBlockState(pos.add(x+5, y+21, z+9), state, 2);
		world.setBlockState(pos.add(x+6, y+21, z+9), state, 2);
		world.setBlockState(pos.add(x+9, y+21, z+9), state, 2);
		world.setBlockState(pos.add(x+10, y+21, z+9), Blocks.AIR.getDefaultState(), 2);
		world.setBlockState(pos.add(x+11, y+21, z+9), Blocks.AIR.getDefaultState(), 2);
		world.setBlockState(pos.add(x+12, y+21, z+9), state, 2);
		world.setBlockState(pos.add(x+3, y+21, z+10), state, 2);
		world.setBlockState(pos.add(x+4, y+21, z+10), Blocks.AIR.getDefaultState(), 2);
		world.setBlockState(pos.add(x+5, y+21, z+10), Blocks.AIR.getDefaultState(), 2);
		world.setBlockState(pos.add(x+6, y+21, z+10), Blocks.AIR.getDefaultState(), 2);
		world.setBlockState(pos.add(x+7, y+21, z+10), state, 2);
		world.setBlockState(pos.add(x+9, y+21, z+10), state, 2);
		world.setBlockState(pos.add(x+10, y+21, z+10), Blocks.AIR.getDefaultState(), 2);
		world.setBlockState(pos.add(x+11, y+21, z+10), Blocks.AIR.getDefaultState(), 2);
		world.setBlockState(pos.add(x+12, y+21, z+10), state, 2);
		world.setBlockState(pos.add(x+3, y+21, z+11), state, 2);
		world.setBlockState(pos.add(x+4, y+21, z+11), Blocks.AIR.getDefaultState(), 2);
		world.setBlockState(pos.add(x+5, y+21, z+11), Blocks.AIR.getDefaultState(), 2);
		world.setBlockState(pos.add(x+6, y+21, z+11), Blocks.AIR.getDefaultState(), 2);
		world.setBlockState(pos.add(x+7, y+21, z+11), state, 2);
		world.setBlockState(pos.add(x+10, y+21, z+11), state, 2);
		world.setBlockState(pos.add(x+11, y+21, z+11), state, 2);
		world.setBlockState(pos.add(x+3, y+21, z+12), state, 2);
		world.setBlockState(pos.add(x+4, y+21, z+12), Blocks.AIR.getDefaultState(), 2);
		world.setBlockState(pos.add(x+5, y+21, z+12), Blocks.AIR.getDefaultState(), 2);
		world.setBlockState(pos.add(x+6, y+21, z+12), Blocks.AIR.getDefaultState(), 2);
		world.setBlockState(pos.add(x+7, y+21, z+12), state, 2);
		world.setBlockState(pos.add(x+4, y+21, z+13), state, 2);
		world.setBlockState(pos.add(x+5, y+21, z+13), state, 2);
		world.setBlockState(pos.add(x+6, y+21, z+13), state, 2);
		world.setBlockState(pos.add(x+5, y+22, z+3), state, 2);
		world.setBlockState(pos.add(x+6, y+22, z+3), state, 2);
		world.setBlockState(pos.add(x+4, y+22, z+4), state, 2);
		world.setBlockState(pos.add(x+5, y+22, z+4), Blocks.AIR.getDefaultState(), 2);
		world.setBlockState(pos.add(x+6, y+22, z+4), Blocks.AIR.getDefaultState(), 2);
		world.setBlockState(pos.add(x+7, y+22, z+4), state, 2);
		world.setBlockState(pos.add(x+4, y+22, z+5), state, 2);
		world.setBlockState(pos.add(x+5, y+22, z+5), Blocks.AIR.getDefaultState(), 2);
		world.setBlockState(pos.add(x+6, y+22, z+5), Blocks.AIR.getDefaultState(), 2);
		world.setBlockState(pos.add(x+7, y+22, z+5), state, 2);
		world.setBlockState(pos.add(x+5, y+22, z+6), state, 2);
		world.setBlockState(pos.add(x+6, y+22, z+6), state, 2);
		world.setBlockState(pos.add(x+10, y+22, z+8), state, 2);
		world.setBlockState(pos.add(x+11, y+22, z+8), state, 2);
		world.setBlockState(pos.add(x+4, y+22, z+9), state, 2);
		world.setBlockState(pos.add(x+5, y+22, z+9), state, 2);
		world.setBlockState(pos.add(x+6, y+22, z+9), state, 2);
		world.setBlockState(pos.add(x+9, y+22, z+9), state, 2);
		world.setBlockState(pos.add(x+10, y+22, z+9), Blocks.AIR.getDefaultState(), 2);
		world.setBlockState(pos.add(x+11, y+22, z+9), Blocks.AIR.getDefaultState(), 2);
		world.setBlockState(pos.add(x+12, y+22, z+9), state, 2);
		world.setBlockState(pos.add(x+3, y+22, z+10), state, 2);
		world.setBlockState(pos.add(x+4, y+22, z+10), Blocks.AIR.getDefaultState(), 2);
		world.setBlockState(pos.add(x+5, y+22, z+10), Blocks.AIR.getDefaultState(), 2);
		world.setBlockState(pos.add(x+6, y+22, z+10), Blocks.AIR.getDefaultState(), 2);
		world.setBlockState(pos.add(x+7, y+22, z+10), state, 2);
		world.setBlockState(pos.add(x+9, y+22, z+10), state, 2);
		world.setBlockState(pos.add(x+10, y+22, z+10), Blocks.AIR.getDefaultState(), 2);
		world.setBlockState(pos.add(x+11, y+22, z+10), Blocks.AIR.getDefaultState(), 2);
		world.setBlockState(pos.add(x+12, y+22, z+10), state, 2);
		world.setBlockState(pos.add(x+3, y+22, z+11), state, 2);
		world.setBlockState(pos.add(x+4, y+22, z+11), Blocks.AIR.getDefaultState(), 2);
		world.setBlockState(pos.add(x+5, y+22, z+11), Blocks.AIR.getDefaultState(), 2);
		world.setBlockState(pos.add(x+6, y+22, z+11), Blocks.AIR.getDefaultState(), 2);
		world.setBlockState(pos.add(x+7, y+22, z+11), state, 2);
		world.setBlockState(pos.add(x+10, y+22, z+11), state, 2);
		world.setBlockState(pos.add(x+11, y+22, z+11), state, 2);
		world.setBlockState(pos.add(x+3, y+22, z+12), state, 2);
		world.setBlockState(pos.add(x+4, y+22, z+12), Blocks.AIR.getDefaultState(), 2);
		world.setBlockState(pos.add(x+5, y+22, z+12), Blocks.AIR.getDefaultState(), 2);
		world.setBlockState(pos.add(x+6, y+22, z+12), Blocks.AIR.getDefaultState(), 2);
		world.setBlockState(pos.add(x+7, y+22, z+12), state, 2);
		world.setBlockState(pos.add(x+4, y+22, z+13), state, 2);
		world.setBlockState(pos.add(x+5, y+22, z+13), state, 2);
		world.setBlockState(pos.add(x+6, y+22, z+13), state, 2);
		world.setBlockState(pos.add(x+5, y+23, z+3), state, 2);
		world.setBlockState(pos.add(x+6, y+23, z+3), state, 2);
		world.setBlockState(pos.add(x+4, y+23, z+4), state, 2);
		world.setBlockState(pos.add(x+5, y+23, z+4), Blocks.AIR.getDefaultState(), 2);
		world.setBlockState(pos.add(x+6, y+23, z+4), Blocks.AIR.getDefaultState(), 2);
		world.setBlockState(pos.add(x+7, y+23, z+4), state, 2);
		world.setBlockState(pos.add(x+4, y+23, z+5), state, 2);
		world.setBlockState(pos.add(x+5, y+23, z+5), Blocks.AIR.getDefaultState(), 2);
		world.setBlockState(pos.add(x+6, y+23, z+5), Blocks.AIR.getDefaultState(), 2);
		world.setBlockState(pos.add(x+7, y+23, z+5), state, 2);
		world.setBlockState(pos.add(x+5, y+23, z+6), state, 2);
		world.setBlockState(pos.add(x+6, y+23, z+6), state, 2);
		world.setBlockState(pos.add(x+10, y+23, z+8), state, 2);
		world.setBlockState(pos.add(x+11, y+23, z+8), state, 2);
		world.setBlockState(pos.add(x+4, y+23, z+9), state, 2);
		world.setBlockState(pos.add(x+5, y+23, z+9), state, 2);
		world.setBlockState(pos.add(x+6, y+23, z+9), state, 2);
		world.setBlockState(pos.add(x+9, y+23, z+9), state, 2);
		world.setBlockState(pos.add(x+10, y+23, z+9), Blocks.AIR.getDefaultState(), 2);
		world.setBlockState(pos.add(x+11, y+23, z+9), Blocks.AIR.getDefaultState(), 2);
		world.setBlockState(pos.add(x+12, y+23, z+9), state, 2);
		world.setBlockState(pos.add(x+3, y+23, z+10), state, 2);
		world.setBlockState(pos.add(x+4, y+23, z+10), Blocks.AIR.getDefaultState(), 2);
		world.setBlockState(pos.add(x+5, y+23, z+10), Blocks.AIR.getDefaultState(), 2);
		world.setBlockState(pos.add(x+6, y+23, z+10), Blocks.AIR.getDefaultState(), 2);
		world.setBlockState(pos.add(x+7, y+23, z+10), state, 2);
		world.setBlockState(pos.add(x+9, y+23, z+10), state, 2);
		world.setBlockState(pos.add(x+10, y+23, z+10), Blocks.AIR.getDefaultState(), 2);
		world.setBlockState(pos.add(x+11, y+23, z+10), Blocks.AIR.getDefaultState(), 2);
		world.setBlockState(pos.add(x+12, y+23, z+10), state, 2);
		world.setBlockState(pos.add(x+3, y+23, z+11), state, 2);
		world.setBlockState(pos.add(x+4, y+23, z+11), Blocks.AIR.getDefaultState(), 2);
		world.setBlockState(pos.add(x+5, y+23, z+11), Blocks.AIR.getDefaultState(), 2);
		world.setBlockState(pos.add(x+6, y+23, z+11), Blocks.AIR.getDefaultState(), 2);
		world.setBlockState(pos.add(x+7, y+23, z+11), state, 2);
		world.setBlockState(pos.add(x+10, y+23, z+11), state, 2);
		world.setBlockState(pos.add(x+11, y+23, z+11), state, 2);
		world.setBlockState(pos.add(x+3, y+23, z+12), state, 2);
		world.setBlockState(pos.add(x+4, y+23, z+12), Blocks.AIR.getDefaultState(), 2);
		world.setBlockState(pos.add(x+5, y+23, z+12), Blocks.AIR.getDefaultState(), 2);
		world.setBlockState(pos.add(x+6, y+23, z+12), Blocks.AIR.getDefaultState(), 2);
		world.setBlockState(pos.add(x+7, y+23, z+12), state, 2);
		world.setBlockState(pos.add(x+4, y+23, z+13), state, 2);
		world.setBlockState(pos.add(x+5, y+23, z+13), state, 2);
		world.setBlockState(pos.add(x+6, y+23, z+13), state, 2);
		world.setBlockState(pos.add(x+5, y+24, z+3), state, 2);
		world.setBlockState(pos.add(x+6, y+24, z+3), state, 2);
		world.setBlockState(pos.add(x+4, y+24, z+4), state, 2);
		world.setBlockState(pos.add(x+5, y+24, z+4), Blocks.AIR.getDefaultState(), 2);
		world.setBlockState(pos.add(x+6, y+24, z+4), Blocks.AIR.getDefaultState(), 2);
		world.setBlockState(pos.add(x+7, y+24, z+4), state, 2);
		world.setBlockState(pos.add(x+4, y+24, z+5), state, 2);
		world.setBlockState(pos.add(x+5, y+24, z+5), Blocks.AIR.getDefaultState(), 2);
		world.setBlockState(pos.add(x+6, y+24, z+5), Blocks.AIR.getDefaultState(), 2);
		world.setBlockState(pos.add(x+7, y+24, z+5), state, 2);
		world.setBlockState(pos.add(x+5, y+24, z+6), state, 2);
		world.setBlockState(pos.add(x+6, y+24, z+6), state, 2);
		world.setBlockState(pos.add(x+10, y+24, z+8), state, 2);
		world.setBlockState(pos.add(x+11, y+24, z+8), state, 2);
		world.setBlockState(pos.add(x+4, y+24, z+9), state, 2);
		world.setBlockState(pos.add(x+5, y+24, z+9), state, 2);
		world.setBlockState(pos.add(x+6, y+24, z+9), state, 2);
		world.setBlockState(pos.add(x+9, y+24, z+9), state, 2);
		world.setBlockState(pos.add(x+10, y+24, z+9), Blocks.AIR.getDefaultState(), 2);
		world.setBlockState(pos.add(x+11, y+24, z+9), Blocks.AIR.getDefaultState(), 2);
		world.setBlockState(pos.add(x+12, y+24, z+9), state, 2);
		world.setBlockState(pos.add(x+3, y+24, z+10), state, 2);
		world.setBlockState(pos.add(x+4, y+24, z+10), Blocks.AIR.getDefaultState(), 2);
		world.setBlockState(pos.add(x+5, y+24, z+10), Blocks.AIR.getDefaultState(), 2);
		world.setBlockState(pos.add(x+6, y+24, z+10), Blocks.AIR.getDefaultState(), 2);
		world.setBlockState(pos.add(x+7, y+24, z+10), state, 2);
		world.setBlockState(pos.add(x+9, y+24, z+10), state, 2);
		world.setBlockState(pos.add(x+10, y+24, z+10), Blocks.AIR.getDefaultState(), 2);
		world.setBlockState(pos.add(x+11, y+24, z+10), Blocks.AIR.getDefaultState(), 2);
		world.setBlockState(pos.add(x+12, y+24, z+10), state, 2);
		world.setBlockState(pos.add(x+3, y+24, z+11), state, 2);
		world.setBlockState(pos.add(x+4, y+24, z+11), Blocks.AIR.getDefaultState(), 2);
		world.setBlockState(pos.add(x+5, y+24, z+11), Blocks.AIR.getDefaultState(), 2);
		world.setBlockState(pos.add(x+6, y+24, z+11), Blocks.AIR.getDefaultState(), 2);
		world.setBlockState(pos.add(x+7, y+24, z+11), state, 2);
		world.setBlockState(pos.add(x+10, y+24, z+11), state, 2);
		world.setBlockState(pos.add(x+11, y+24, z+11), state, 2);
		world.setBlockState(pos.add(x+3, y+24, z+12), state, 2);
		world.setBlockState(pos.add(x+4, y+24, z+12), Blocks.AIR.getDefaultState(), 2);
		world.setBlockState(pos.add(x+5, y+24, z+12), Blocks.AIR.getDefaultState(), 2);
		world.setBlockState(pos.add(x+6, y+24, z+12), Blocks.AIR.getDefaultState(), 2);
		world.setBlockState(pos.add(x+7, y+24, z+12), state, 2);
		world.setBlockState(pos.add(x+4, y+24, z+13), state, 2);
		world.setBlockState(pos.add(x+5, y+24, z+13), state, 2);
		world.setBlockState(pos.add(x+6, y+24, z+13), state, 2);
		world.setBlockState(pos.add(x+5, y+25, z+3), state, 2);
		world.setBlockState(pos.add(x+6, y+25, z+3), state, 2);
		world.setBlockState(pos.add(x+4, y+25, z+4), state, 2);
		world.setBlockState(pos.add(x+5, y+25, z+4), Blocks.AIR.getDefaultState(), 2);
		world.setBlockState(pos.add(x+6, y+25, z+4), Blocks.AIR.getDefaultState(), 2);
		world.setBlockState(pos.add(x+7, y+25, z+4), state, 2);
		world.setBlockState(pos.add(x+4, y+25, z+5), state, 2);
		world.setBlockState(pos.add(x+5, y+25, z+5), Blocks.AIR.getDefaultState(), 2);
		world.setBlockState(pos.add(x+6, y+25, z+5), Blocks.AIR.getDefaultState(), 2);
		world.setBlockState(pos.add(x+7, y+25, z+5), state, 2);
		world.setBlockState(pos.add(x+5, y+25, z+6), state, 2);
		world.setBlockState(pos.add(x+6, y+25, z+6), state, 2);
		world.setBlockState(pos.add(x+10, y+25, z+8), state, 2);
		world.setBlockState(pos.add(x+11, y+25, z+8), state, 2);
		world.setBlockState(pos.add(x+4, y+25, z+9), state, 2);
		world.setBlockState(pos.add(x+5, y+25, z+9), state, 2);
		world.setBlockState(pos.add(x+6, y+25, z+9), state, 2);
		world.setBlockState(pos.add(x+9, y+25, z+9), state, 2);
		world.setBlockState(pos.add(x+10, y+25, z+9), Blocks.AIR.getDefaultState(), 2);
		world.setBlockState(pos.add(x+11, y+25, z+9), Blocks.AIR.getDefaultState(), 2);
		world.setBlockState(pos.add(x+12, y+25, z+9), state, 2);
		world.setBlockState(pos.add(x+3, y+25, z+10), state, 2);
		world.setBlockState(pos.add(x+4, y+25, z+10), Blocks.AIR.getDefaultState(), 2);
		world.setBlockState(pos.add(x+5, y+25, z+10), Blocks.AIR.getDefaultState(), 2);
		world.setBlockState(pos.add(x+6, y+25, z+10), Blocks.AIR.getDefaultState(), 2);
		world.setBlockState(pos.add(x+7, y+25, z+10), state, 2);
		world.setBlockState(pos.add(x+9, y+25, z+10), state, 2);
