package ga.scmc.worldgen.structure;
import java.util.Random;

import net.minecraft.block.BlockPlanks;
import net.minecraft.block.BlockStainedGlass;
import net.minecraft.block.BlockStairs;
import net.minecraft.block.state.IBlockState;
import net.minecraft.init.Blocks;
import net.minecraft.item.EnumDyeColor;
import net.minecraft.util.EnumFacing;
import net.minecraft.util.math.BlockPos;
import net.minecraft.world.World;
import net.minecraft.world.chunk.IChunkGenerator;
import net.minecraft.world.chunk.IChunkProvider;
import net.minecraft.world.gen.feature.WorldGenerator;
import net.minecraftforge.fml.common.IWorldGenerator;

/** @author SoggyMustache's Structure Converter (http://soggymustache.net/tools.html) */
public class StructureTerranBarracksTemplate extends WorldGenerator implements IWorldGenerator{
	
    public StructureTerranBarracksTemplate() {
	}
    
	public StructureTerranBarracksTemplate(boolean b, int u, int i, int a, Boolean f){
         super(b);
	}
	
	@Override
	public boolean generate(World worldIn, Random r, BlockPos bp) {
		//Change k, i, or j to offset the structure
		int k = 0;
		int i = 0;
		int j = 0;
		worldIn.setBlockState(bp.add(i + 0, j + 0, k + 2), Blocks.STONE.getDefaultState());
		worldIn.setBlockState(bp.add(i + 0, j + 0, k + 22), Blocks.STONE.getDefaultState());
		worldIn.setBlockState(bp.add(i + 1, j + 0, k + 1), Blocks.STONE.getDefaultState());
		worldIn.setBlockState(bp.add(i + 1, j + 0, k + 2), Blocks.STONE.getDefaultState());
		worldIn.setBlockState(bp.add(i + 1, j + 0, k + 3), Blocks.STONE.getDefaultState());
		worldIn.setBlockState(bp.add(i + 1, j + 0, k + 21), Blocks.STONE.getDefaultState());
		worldIn.setBlockState(bp.add(i + 1, j + 0, k + 22), Blocks.STONE.getDefaultState());
		worldIn.setBlockState(bp.add(i + 1, j + 0, k + 23), Blocks.STONE.getDefaultState());
		worldIn.setBlockState(bp.add(i + 1, j + 1, k + 2), Blocks.STONE.getDefaultState());
		worldIn.setBlockState(bp.add(i + 1, j + 1, k + 22), Blocks.STONE.getDefaultState());
		worldIn.setBlockState(bp.add(i + 2, j + 0, k + 0), Blocks.STONE.getDefaultState());
		worldIn.setBlockState(bp.add(i + 2, j + 0, k + 1), Blocks.STONE.getDefaultState());
		worldIn.setBlockState(bp.add(i + 2, j + 0, k + 2), Blocks.STONE.getDefaultState());
		worldIn.setBlockState(bp.add(i + 2, j + 0, k + 3), Blocks.STONE.getDefaultState());
		worldIn.setBlockState(bp.add(i + 2, j + 0, k + 4), Blocks.STONE.getDefaultState());
		worldIn.setBlockState(bp.add(i + 2, j + 0, k + 20), Blocks.STONE.getDefaultState());
		worldIn.setBlockState(bp.add(i + 2, j + 0, k + 21), Blocks.STONE.getDefaultState());
		worldIn.setBlockState(bp.add(i + 2, j + 0, k + 22), Blocks.STONE.getDefaultState());
		worldIn.setBlockState(bp.add(i + 2, j + 0, k + 23), Blocks.STONE.getDefaultState());
		worldIn.setBlockState(bp.add(i + 2, j + 0, k + 24), Blocks.STONE.getDefaultState());
		worldIn.setBlockState(bp.add(i + 2, j + 1, k + 1), Blocks.STONE.getDefaultState());
		worldIn.setBlockState(bp.add(i + 2, j + 1, k + 2), Blocks.STONE.getDefaultState());
		worldIn.setBlockState(bp.add(i + 2, j + 1, k + 3), Blocks.STONE.getDefaultState());
		worldIn.setBlockState(bp.add(i + 2, j + 1, k + 21), Blocks.STONE.getDefaultState());
		worldIn.setBlockState(bp.add(i + 2, j + 1, k + 22), Blocks.STONE.getDefaultState());
		worldIn.setBlockState(bp.add(i + 2, j + 1, k + 23), Blocks.STONE.getDefaultState());
		worldIn.setBlockState(bp.add(i + 2, j + 2, k + 3), Blocks.STONE.getDefaultState());
		worldIn.setBlockState(bp.add(i + 2, j + 2, k + 21), Blocks.STONE.getDefaultState());
		worldIn.setBlockState(bp.add(i + 3, j + 0, k + 1), Blocks.STONE.getDefaultState());
		worldIn.setBlockState(bp.add(i + 3, j + 0, k + 2), Blocks.STONE.getDefaultState());
		worldIn.setBlockState(bp.add(i + 3, j + 0, k + 3), Blocks.STONE.getDefaultState());
		worldIn.setBlockState(bp.add(i + 3, j + 0, k + 21), Blocks.STONE.getDefaultState());
		worldIn.setBlockState(bp.add(i + 3, j + 0, k + 22), Blocks.STONE.getDefaultState());
		worldIn.setBlockState(bp.add(i + 3, j + 0, k + 23), Blocks.STONE.getDefaultState());
		worldIn.setBlockState(bp.add(i + 3, j + 1, k + 2), Blocks.STONE.getDefaultState());
		worldIn.setBlockState(bp.add(i + 3, j + 1, k + 3), Blocks.STONE.getDefaultState());
		worldIn.setBlockState(bp.add(i + 3, j + 1, k + 21), Blocks.STONE.getDefaultState());
		worldIn.setBlockState(bp.add(i + 3, j + 1, k + 22), Blocks.STONE.getDefaultState());
		worldIn.setBlockState(bp.add(i + 3, j + 2, k + 2), Blocks.STONE.getDefaultState());
		worldIn.setBlockState(bp.add(i + 3, j + 2, k + 3), Blocks.STONE.getDefaultState());
		worldIn.setBlockState(bp.add(i + 3, j + 2, k + 4), Blocks.STONE.getDefaultState());
		worldIn.setBlockState(bp.add(i + 3, j + 2, k + 20), Blocks.STONE.getDefaultState());
		worldIn.setBlockState(bp.add(i + 3, j + 2, k + 21), Blocks.STONE.getDefaultState());
		worldIn.setBlockState(bp.add(i + 3, j + 2, k + 22), Blocks.STONE.getDefaultState());
		worldIn.setBlockState(bp.add(i + 3, j + 3, k + 3), Blocks.STONE.getDefaultState());
		worldIn.setBlockState(bp.add(i + 3, j + 3, k + 4), Blocks.STONE.getDefaultState());
		worldIn.setBlockState(bp.add(i + 3, j + 3, k + 5), Blocks.STONE.getDefaultState());
		worldIn.setBlockState(bp.add(i + 3, j + 3, k + 6), Blocks.STONE.getDefaultState());
		worldIn.setBlockState(bp.add(i + 3, j + 3, k + 11), Blocks.COAL_BLOCK.getDefaultState());
		worldIn.setBlockState(bp.add(i + 3, j + 3, k + 12), Blocks.COAL_BLOCK.getDefaultState());
		worldIn.setBlockState(bp.add(i + 3, j + 3, k + 13), Blocks.COAL_BLOCK.getDefaultState());
		worldIn.setBlockState(bp.add(i + 3, j + 3, k + 18), Blocks.STONE.getDefaultState());
		worldIn.setBlockState(bp.add(i + 3, j + 3, k + 19), Blocks.STONE.getDefaultState());
		worldIn.setBlockState(bp.add(i + 3, j + 3, k + 20), Blocks.STONE.getDefaultState());
		worldIn.setBlockState(bp.add(i + 3, j + 3, k + 21), Blocks.STONE.getDefaultState());
		worldIn.setBlockState(bp.add(i + 3, j + 4, k + 3), Blocks.STONE.getDefaultState());
		worldIn.setBlockState(bp.add(i + 3, j + 4, k + 4), Blocks.STONE.getDefaultState());
		worldIn.setBlockState(bp.add(i + 3, j + 4, k + 5), Blocks.STONE.getDefaultState());
		worldIn.setBlockState(bp.add(i + 3, j + 4, k + 6), Blocks.STONE.getDefaultState());
		worldIn.setBlockState(bp.add(i + 3, j + 4, k + 10), Blocks.STONE.getDefaultState());
		worldIn.setBlockState(bp.add(i + 3, j + 4, k + 11), Blocks.COAL_BLOCK.getDefaultState());
		worldIn.setBlockState(bp.add(i + 3, j + 4, k + 12), Blocks.COAL_BLOCK.getDefaultState());
		worldIn.setBlockState(bp.add(i + 3, j + 4, k + 13), Blocks.COAL_BLOCK.getDefaultState());
		worldIn.setBlockState(bp.add(i + 3, j + 4, k + 14), Blocks.STONE.getDefaultState());
		worldIn.setBlockState(bp.add(i + 3, j + 4, k + 18), Blocks.STONE.getDefaultState());
		worldIn.setBlockState(bp.add(i + 3, j + 4, k + 19), Blocks.STONE.getDefaultState());
		worldIn.setBlockState(bp.add(i + 3, j + 4, k + 20), Blocks.STONE.getDefaultState());
		worldIn.setBlockState(bp.add(i + 3, j + 4, k + 21), Blocks.STONE.getDefaultState());
		worldIn.setBlockState(bp.add(i + 3, j + 5, k + 3), Blocks.STONE.getDefaultState());
		worldIn.setBlockState(bp.add(i + 3, j + 5, k + 4), Blocks.STONE.getDefaultState());
		worldIn.setBlockState(bp.add(i + 3, j + 5, k + 5), Blocks.STONE.getDefaultState());
		worldIn.setBlockState(bp.add(i + 3, j + 5, k + 6), Blocks.STONE.getDefaultState());
		worldIn.setBlockState(bp.add(i + 3, j + 5, k + 10), Blocks.STONE.getDefaultState());
		worldIn.setBlockState(bp.add(i + 3, j + 5, k + 11), Blocks.STONE.getDefaultState());
		worldIn.setBlockState(bp.add(i + 3, j + 5, k + 12), Blocks.STONE.getDefaultState());
		worldIn.setBlockState(bp.add(i + 3, j + 5, k + 13), Blocks.STONE.getDefaultState());
		worldIn.setBlockState(bp.add(i + 3, j + 5, k + 14), Blocks.STONE.getDefaultState());
		worldIn.setBlockState(bp.add(i + 3, j + 5, k + 18), Blocks.STONE.getDefaultState());
		worldIn.setBlockState(bp.add(i + 3, j + 5, k + 19), Blocks.STONE.getDefaultState());
		worldIn.setBlockState(bp.add(i + 3, j + 5, k + 20), Blocks.STONE.getDefaultState());
		worldIn.setBlockState(bp.add(i + 3, j + 5, k + 21), Blocks.STONE.getDefaultState());
		worldIn.setBlockState(bp.add(i + 3, j + 6, k + 3), (IBlockState)Blocks.STAINED_GLASS.getDefaultState().withProperty(BlockStainedGlass.COLOR, EnumDyeColor.YELLOW));
		worldIn.setBlockState(bp.add(i + 3, j + 6, k + 4), (IBlockState)Blocks.STAINED_GLASS.getDefaultState().withProperty(BlockStainedGlass.COLOR, EnumDyeColor.YELLOW));
		worldIn.setBlockState(bp.add(i + 3, j + 6, k + 5), (IBlockState)Blocks.STAINED_GLASS.getDefaultState().withProperty(BlockStainedGlass.COLOR, EnumDyeColor.YELLOW));
		worldIn.setBlockState(bp.add(i + 3, j + 6, k + 6), (IBlockState)Blocks.STAINED_GLASS.getDefaultState().withProperty(BlockStainedGlass.COLOR, EnumDyeColor.YELLOW));
		worldIn.setBlockState(bp.add(i + 3, j + 6, k + 10), (IBlockState)Blocks.STAINED_GLASS.getDefaultState().withProperty(BlockStainedGlass.COLOR, EnumDyeColor.YELLOW));
		worldIn.setBlockState(bp.add(i + 3, j + 6, k + 11), (IBlockState)Blocks.STAINED_GLASS.getDefaultState().withProperty(BlockStainedGlass.COLOR, EnumDyeColor.YELLOW));
		worldIn.setBlockState(bp.add(i + 3, j + 6, k + 12), (IBlockState)Blocks.STAINED_GLASS.getDefaultState().withProperty(BlockStainedGlass.COLOR, EnumDyeColor.YELLOW));
		worldIn.setBlockState(bp.add(i + 3, j + 6, k + 13), (IBlockState)Blocks.STAINED_GLASS.getDefaultState().withProperty(BlockStainedGlass.COLOR, EnumDyeColor.YELLOW));
		worldIn.setBlockState(bp.add(i + 3, j + 6, k + 14), (IBlockState)Blocks.STAINED_GLASS.getDefaultState().withProperty(BlockStainedGlass.COLOR, EnumDyeColor.YELLOW));
		worldIn.setBlockState(bp.add(i + 3, j + 6, k + 18), (IBlockState)Blocks.STAINED_GLASS.getDefaultState().withProperty(BlockStainedGlass.COLOR, EnumDyeColor.YELLOW));
		worldIn.setBlockState(bp.add(i + 3, j + 6, k + 19), (IBlockState)Blocks.STAINED_GLASS.getDefaultState().withProperty(BlockStainedGlass.COLOR, EnumDyeColor.YELLOW));
		worldIn.setBlockState(bp.add(i + 3, j + 6, k + 20), (IBlockState)Blocks.STAINED_GLASS.getDefaultState().withProperty(BlockStainedGlass.COLOR, EnumDyeColor.YELLOW));
		worldIn.setBlockState(bp.add(i + 3, j + 6, k + 21), (IBlockState)Blocks.STAINED_GLASS.getDefaultState().withProperty(BlockStainedGlass.COLOR, EnumDyeColor.YELLOW));
		worldIn.setBlockState(bp.add(i + 3, j + 7, k + 3), Blocks.LAPIS_BLOCK.getDefaultState());
		worldIn.setBlockState(bp.add(i + 3, j + 7, k + 4), Blocks.LAPIS_BLOCK.getDefaultState());
		worldIn.setBlockState(bp.add(i + 3, j + 7, k + 5), Blocks.LAPIS_BLOCK.getDefaultState());
		worldIn.setBlockState(bp.add(i + 3, j + 7, k + 6), Blocks.LAPIS_BLOCK.getDefaultState());
		worldIn.setBlockState(bp.add(i + 3, j + 7, k + 10), Blocks.STONE.getDefaultState());
		worldIn.setBlockState(bp.add(i + 3, j + 7, k + 11), Blocks.STONE.getDefaultState());
		worldIn.setBlockState(bp.add(i + 3, j + 7, k + 12), Blocks.STONE.getDefaultState());
		worldIn.setBlockState(bp.add(i + 3, j + 7, k + 13), Blocks.STONE.getDefaultState());
		worldIn.setBlockState(bp.add(i + 3, j + 7, k + 14), Blocks.STONE.getDefaultState());
		worldIn.setBlockState(bp.add(i + 3, j + 7, k + 18), Blocks.LAPIS_BLOCK.getDefaultState());
		worldIn.setBlockState(bp.add(i + 3, j + 7, k + 19), Blocks.LAPIS_BLOCK.getDefaultState());
		worldIn.setBlockState(bp.add(i + 3, j + 7, k + 20), Blocks.LAPIS_BLOCK.getDefaultState());
		worldIn.setBlockState(bp.add(i + 3, j + 7, k + 21), Blocks.LAPIS_BLOCK.getDefaultState());
		worldIn.setBlockState(bp.add(i + 3, j + 8, k + 3), Blocks.LAPIS_BLOCK.getDefaultState());
		worldIn.setBlockState(bp.add(i + 3, j + 8, k + 4), Blocks.COAL_BLOCK.getDefaultState());
		worldIn.setBlockState(bp.add(i + 3, j + 8, k + 5), Blocks.COAL_BLOCK.getDefaultState());
		worldIn.setBlockState(bp.add(i + 3, j + 8, k + 6), Blocks.LAPIS_BLOCK.getDefaultState());
		worldIn.setBlockState(bp.add(i + 3, j + 8, k + 10), Blocks.STONE.getDefaultState());
		worldIn.setBlockState(bp.add(i + 3, j + 8, k + 11), Blocks.STONE.getDefaultState());
		worldIn.setBlockState(bp.add(i + 3, j + 8, k + 12), Blocks.COAL_BLOCK.getDefaultState());
		worldIn.setBlockState(bp.add(i + 3, j + 8, k + 13), Blocks.STONE.getDefaultState());
		worldIn.setBlockState(bp.add(i + 3, j + 8, k + 14), Blocks.STONE.getDefaultState());
		worldIn.setBlockState(bp.add(i + 3, j + 8, k + 18), Blocks.LAPIS_BLOCK.getDefaultState());
		worldIn.setBlockState(bp.add(i + 3, j + 8, k + 19), Blocks.COAL_BLOCK.getDefaultState());
		worldIn.setBlockState(bp.add(i + 3, j + 8, k + 20), Blocks.COAL_BLOCK.getDefaultState());
		worldIn.setBlockState(bp.add(i + 3, j + 8, k + 21), Blocks.LAPIS_BLOCK.getDefaultState());
		worldIn.setBlockState(bp.add(i + 3, j + 9, k + 3), Blocks.LAPIS_BLOCK.getDefaultState());
		worldIn.setBlockState(bp.add(i + 3, j + 9, k + 4), Blocks.COAL_BLOCK.getDefaultState());
		worldIn.setBlockState(bp.add(i + 3, j + 9, k + 5), Blocks.COAL_BLOCK.getDefaultState());
		worldIn.setBlockState(bp.add(i + 3, j + 9, k + 6), Blocks.LAPIS_BLOCK.getDefaultState());
		worldIn.setBlockState(bp.add(i + 3, j + 9, k + 10), Blocks.STONE.getDefaultState());
		worldIn.setBlockState(bp.add(i + 3, j + 9, k + 11), Blocks.COAL_BLOCK.getDefaultState());
		worldIn.setBlockState(bp.add(i + 3, j + 9, k + 12), Blocks.COAL_BLOCK.getDefaultState());
		worldIn.setBlockState(bp.add(i + 3, j + 9, k + 13), Blocks.COAL_BLOCK.getDefaultState());
		worldIn.setBlockState(bp.add(i + 3, j + 9, k + 14), Blocks.STONE.getDefaultState());
		worldIn.setBlockState(bp.add(i + 3, j + 9, k + 18), Blocks.LAPIS_BLOCK.getDefaultState());
		worldIn.setBlockState(bp.add(i + 3, j + 9, k + 19), Blocks.COAL_BLOCK.getDefaultState());
		worldIn.setBlockState(bp.add(i + 3, j + 9, k + 20), Blocks.COAL_BLOCK.getDefaultState());
		worldIn.setBlockState(bp.add(i + 3, j + 9, k + 21), Blocks.LAPIS_BLOCK.getDefaultState());
		worldIn.setBlockState(bp.add(i + 3, j + 10, k + 4), Blocks.COAL_BLOCK.getDefaultState());
		worldIn.setBlockState(bp.add(i + 3, j + 10, k + 5), Blocks.COAL_BLOCK.getDefaultState());
		worldIn.setBlockState(bp.add(i + 3, j + 10, k + 6), Blocks.STONE.getDefaultState());
		worldIn.setBlockState(bp.add(i + 3, j + 10, k + 11), Blocks.COAL_BLOCK.getDefaultState());
		worldIn.setBlockState(bp.add(i + 3, j + 10, k + 12), Blocks.COAL_BLOCK.getDefaultState());
		worldIn.setBlockState(bp.add(i + 3, j + 10, k + 13), Blocks.COAL_BLOCK.getDefaultState());
		worldIn.setBlockState(bp.add(i + 3, j + 10, k + 18), Blocks.STONE.getDefaultState());
		worldIn.setBlockState(bp.add(i + 3, j + 10, k + 19), Blocks.COAL_BLOCK.getDefaultState());
		worldIn.setBlockState(bp.add(i + 3, j + 10, k + 20), Blocks.COAL_BLOCK.getDefaultState());
		worldIn.setBlockState(bp.add(i + 4, j + 0, k + 2), Blocks.STONE.getDefaultState());
		worldIn.setBlockState(bp.add(i + 4, j + 0, k + 22), Blocks.STONE.getDefaultState());
		worldIn.setBlockState(bp.add(i + 4, j + 2, k + 3), Blocks.STONE.getDefaultState());
		worldIn.setBlockState(bp.add(i + 4, j + 2, k + 4), Blocks.STONE.getDefaultState());
		worldIn.setBlockState(bp.add(i + 4, j + 2, k + 20), Blocks.STONE.getDefaultState());
		worldIn.setBlockState(bp.add(i + 4, j + 2, k + 21), Blocks.STONE.getDefaultState());
		worldIn.setBlockState(bp.add(i + 4, j + 3, k + 3), Blocks.STONE.getDefaultState());
		worldIn.setBlockState(bp.add(i + 4, j + 3, k + 4), Blocks.STONE.getDefaultState());
		worldIn.setBlockState(bp.add(i + 4, j + 3, k + 5), Blocks.STONE.getDefaultState());
		worldIn.setBlockState(bp.add(i + 4, j + 3, k + 6), Blocks.STONE.getDefaultState());
		worldIn.setBlockState(bp.add(i + 4, j + 3, k + 7), Blocks.STONE.getDefaultState());
		worldIn.setBlockState(bp.add(i + 4, j + 3, k + 8), Blocks.STONE.getDefaultState());
		worldIn.setBlockState(bp.add(i + 4, j + 3, k + 9), Blocks.STONE.getDefaultState());
		worldIn.setBlockState(bp.add(i + 4, j + 3, k + 10), Blocks.STONE.getDefaultState());
		worldIn.setBlockState(bp.add(i + 4, j + 3, k + 11), Blocks.STONE.getDefaultState());
		worldIn.setBlockState(bp.add(i + 4, j + 3, k + 12), Blocks.STONE.getDefaultState());
		worldIn.setBlockState(bp.add(i + 4, j + 3, k + 13), Blocks.STONE.getDefaultState());
		worldIn.setBlockState(bp.add(i + 4, j + 3, k + 14), Blocks.STONE.getDefaultState());
		worldIn.setBlockState(bp.add(i + 4, j + 3, k + 15), Blocks.STONE.getDefaultState());
		worldIn.setBlockState(bp.add(i + 4, j + 3, k + 16), Blocks.STONE.getDefaultState());
		worldIn.setBlockState(bp.add(i + 4, j + 3, k + 17), Blocks.STONE.getDefaultState());
		worldIn.setBlockState(bp.add(i + 4, j + 3, k + 18), Blocks.STONE.getDefaultState());
		worldIn.setBlockState(bp.add(i + 4, j + 3, k + 19), Blocks.STONE.getDefaultState());
		worldIn.setBlockState(bp.add(i + 4, j + 3, k + 20), Blocks.STONE.getDefaultState());
		worldIn.setBlockState(bp.add(i + 4, j + 3, k + 21), Blocks.STONE.getDefaultState());
		worldIn.setBlockState(bp.add(i + 4, j + 4, k + 3), Blocks.STONE.getDefaultState());
		worldIn.setBlockState(bp.add(i + 4, j + 4, k + 4), Blocks.STONE.getDefaultState());
		worldIn.setBlockState(bp.add(i + 4, j + 4, k + 5), Blocks.STONE.getDefaultState());
		worldIn.setBlockState(bp.add(i + 4, j + 4, k + 6), Blocks.STONE.getDefaultState());
		worldIn.setBlockState(bp.add(i + 4, j + 4, k + 7), Blocks.STONE.getDefaultState());
		worldIn.setBlockState(bp.add(i + 4, j + 4, k + 8), Blocks.STONE.getDefaultState());
		worldIn.setBlockState(bp.add(i + 4, j + 4, k + 9), Blocks.STONE.getDefaultState());
		worldIn.setBlockState(bp.add(i + 4, j + 4, k + 10), (IBlockState)Blocks.PLANKS.getDefaultState().withProperty(BlockPlanks.VARIANT, BlockPlanks.EnumType.OAK));
		worldIn.setBlockState(bp.add(i + 4, j + 4, k + 11), (IBlockState)Blocks.PLANKS.getDefaultState().withProperty(BlockPlanks.VARIANT, BlockPlanks.EnumType.OAK));
		worldIn.setBlockState(bp.add(i + 4, j + 4, k + 12), (IBlockState)Blocks.PLANKS.getDefaultState().withProperty(BlockPlanks.VARIANT, BlockPlanks.EnumType.OAK));
		worldIn.setBlockState(bp.add(i + 4, j + 4, k + 13), (IBlockState)Blocks.PLANKS.getDefaultState().withProperty(BlockPlanks.VARIANT, BlockPlanks.EnumType.OAK));
		worldIn.setBlockState(bp.add(i + 4, j + 4, k + 14), (IBlockState)Blocks.PLANKS.getDefaultState().withProperty(BlockPlanks.VARIANT, BlockPlanks.EnumType.OAK));
		worldIn.setBlockState(bp.add(i + 4, j + 4, k + 15), Blocks.STONE.getDefaultState());
		worldIn.setBlockState(bp.add(i + 4, j + 4, k + 16), Blocks.STONE.getDefaultState());
		worldIn.setBlockState(bp.add(i + 4, j + 4, k + 17), Blocks.STONE.getDefaultState());
		worldIn.setBlockState(bp.add(i + 4, j + 4, k + 18), Blocks.STONE.getDefaultState());
		worldIn.setBlockState(bp.add(i + 4, j + 4, k + 19), Blocks.STONE.getDefaultState());
		worldIn.setBlockState(bp.add(i + 4, j + 4, k + 20), Blocks.STONE.getDefaultState());
		worldIn.setBlockState(bp.add(i + 4, j + 4, k + 21), Blocks.STONE.getDefaultState());
		worldIn.setBlockState(bp.add(i + 4, j + 5, k + 3), Blocks.STONE.getDefaultState());
		worldIn.setBlockState(bp.add(i + 4, j + 5, k + 4), Blocks.STONE.getDefaultState());
		worldIn.setBlockState(bp.add(i + 4, j + 5, k + 5), Blocks.STONE.getDefaultState());
		worldIn.setBlockState(bp.add(i + 4, j + 5, k + 6), Blocks.STONE.getDefaultState());
		worldIn.setBlockState(bp.add(i + 4, j + 5, k + 7), Blocks.STONE.getDefaultState());
		worldIn.setBlockState(bp.add(i + 4, j + 5, k + 8), Blocks.STONE.getDefaultState());
		worldIn.setBlockState(bp.add(i + 4, j + 5, k + 9), Blocks.STONE.getDefaultState());
		worldIn.setBlockState(bp.add(i + 4, j + 5, k + 15), Blocks.STONE.getDefaultState());
		worldIn.setBlockState(bp.add(i + 4, j + 5, k + 16), Blocks.STONE.getDefaultState());
		worldIn.setBlockState(bp.add(i + 4, j + 5, k + 17), Blocks.STONE.getDefaultState());
		worldIn.setBlockState(bp.add(i + 4, j + 5, k + 18), Blocks.STONE.getDefaultState());
		worldIn.setBlockState(bp.add(i + 4, j + 5, k + 19), Blocks.STONE.getDefaultState());
		worldIn.setBlockState(bp.add(i + 4, j + 5, k + 20), Blocks.STONE.getDefaultState());
		worldIn.setBlockState(bp.add(i + 4, j + 5, k + 21), Blocks.STONE.getDefaultState());
		worldIn.setBlockState(bp.add(i + 4, j + 6, k + 3), (IBlockState)Blocks.STAINED_GLASS.getDefaultState().withProperty(BlockStainedGlass.COLOR, EnumDyeColor.YELLOW));
		worldIn.setBlockState(bp.add(i + 4, j + 6, k + 7), Blocks.STONE.getDefaultState());
		worldIn.setBlockState(bp.add(i + 4, j + 6, k + 8), Blocks.STONE.getDefaultState());
		worldIn.setBlockState(bp.add(i + 4, j + 6, k + 9), (IBlockState)Blocks.STAINED_GLASS.getDefaultState().withProperty(BlockStainedGlass.COLOR, EnumDyeColor.YELLOW));
		worldIn.setBlockState(bp.add(i + 4, j + 6, k + 15), (IBlockState)Blocks.STAINED_GLASS.getDefaultState().withProperty(BlockStainedGlass.COLOR, EnumDyeColor.YELLOW));
		worldIn.setBlockState(bp.add(i + 4, j + 6, k + 16), Blocks.STONE.getDefaultState());
		worldIn.setBlockState(bp.add(i + 4, j + 6, k + 17), Blocks.STONE.getDefaultState());
		worldIn.setBlockState(bp.add(i + 4, j + 6, k + 21), (IBlockState)Blocks.STAINED_GLASS.getDefaultState().withProperty(BlockStainedGlass.COLOR, EnumDyeColor.YELLOW));
		worldIn.setBlockState(bp.add(i + 4, j + 7, k + 3), Blocks.LAPIS_BLOCK.getDefaultState());
		worldIn.setBlockState(bp.add(i + 4, j + 7, k + 4), Blocks.STONE.getDefaultState());
		worldIn.setBlockState(bp.add(i + 4, j + 7, k + 5), Blocks.STONE.getDefaultState());
		worldIn.setBlockState(bp.add(i + 4, j + 7, k + 6), Blocks.STONE.getDefaultState());
		worldIn.setBlockState(bp.add(i + 4, j + 7, k + 7), Blocks.LAPIS_BLOCK.getDefaultState());
		worldIn.setBlockState(bp.add(i + 4, j + 7, k + 8), Blocks.STONE.getDefaultState());
		worldIn.setBlockState(bp.add(i + 4, j + 7, k + 9), Blocks.STONE.getDefaultState());
		worldIn.setBlockState(bp.add(i + 4, j + 7, k + 15), Blocks.STONE.getDefaultState());
		worldIn.setBlockState(bp.add(i + 4, j + 7, k + 16), Blocks.STONE.getDefaultState());
		worldIn.setBlockState(bp.add(i + 4, j + 7, k + 17), Blocks.LAPIS_BLOCK.getDefaultState());
		worldIn.setBlockState(bp.add(i + 4, j + 7, k + 18), Blocks.STONE.getDefaultState());
		worldIn.setBlockState(bp.add(i + 4, j + 7, k + 19), Blocks.STONE.getDefaultState());
		worldIn.setBlockState(bp.add(i + 4, j + 7, k + 20), Blocks.STONE.getDefaultState());
		worldIn.setBlockState(bp.add(i + 4, j + 7, k + 21), Blocks.LAPIS_BLOCK.getDefaultState());
		worldIn.setBlockState(bp.add(i + 4, j + 8, k + 3), Blocks.LAPIS_BLOCK.getDefaultState());
		worldIn.setBlockState(bp.add(i + 4, j + 8, k + 4), Blocks.STONE.getDefaultState());
		worldIn.setBlockState(bp.add(i + 4, j + 8, k + 5), Blocks.STONE.getDefaultState());
		worldIn.setBlockState(bp.add(i + 4, j + 8, k + 6), Blocks.STONE.getDefaultState());
		worldIn.setBlockState(bp.add(i + 4, j + 8, k + 7), Blocks.LAPIS_BLOCK.getDefaultState());
		worldIn.setBlockState(bp.add(i + 4, j + 8, k + 8), Blocks.STONE.getDefaultState());
		worldIn.setBlockState(bp.add(i + 4, j + 8, k + 9), Blocks.STONE.getDefaultState());
		worldIn.setBlockState(bp.add(i + 4, j + 8, k + 10), Blocks.STONE.getDefaultState());
		worldIn.setBlockState(bp.add(i + 4, j + 8, k + 11), Blocks.STONE.getDefaultState());
		worldIn.setBlockState(bp.add(i + 4, j + 8, k + 12), Blocks.STONE.getDefaultState());
		worldIn.setBlockState(bp.add(i + 4, j + 8, k + 13), Blocks.STONE.getDefaultState());
		worldIn.setBlockState(bp.add(i + 4, j + 8, k + 14), Blocks.STONE.getDefaultState());
		worldIn.setBlockState(bp.add(i + 4, j + 8, k + 15), Blocks.STONE.getDefaultState());
		worldIn.setBlockState(bp.add(i + 4, j + 8, k + 16), Blocks.STONE.getDefaultState());
		worldIn.setBlockState(bp.add(i + 4, j + 8, k + 17), Blocks.LAPIS_BLOCK.getDefaultState());
		worldIn.setBlockState(bp.add(i + 4, j + 8, k + 18), Blocks.STONE.getDefaultState());
		worldIn.setBlockState(bp.add(i + 4, j + 8, k + 19), Blocks.STONE.getDefaultState());
		worldIn.setBlockState(bp.add(i + 4, j + 8, k + 20), Blocks.STONE.getDefaultState());
		worldIn.setBlockState(bp.add(i + 4, j + 8, k + 21), Blocks.LAPIS_BLOCK.getDefaultState());
		worldIn.setBlockState(bp.add(i + 4, j + 9, k + 3), Blocks.LAPIS_BLOCK.getDefaultState());
		worldIn.setBlockState(bp.add(i + 4, j + 9, k + 4), Blocks.STONE.getDefaultState());
		worldIn.setBlockState(bp.add(i + 4, j + 9, k + 5), Blocks.STONE.getDefaultState());
		worldIn.setBlockState(bp.add(i + 4, j + 9, k + 6), Blocks.STONE.getDefaultState());
		worldIn.setBlockState(bp.add(i + 4, j + 9, k + 7), Blocks.LAPIS_BLOCK.getDefaultState());
		worldIn.setBlockState(bp.add(i + 4, j + 9, k + 8), Blocks.STONE.getDefaultState());
		worldIn.setBlockState(bp.add(i + 4, j + 9, k + 9), Blocks.STONE.getDefaultState());
		worldIn.setBlockState(bp.add(i + 4, j + 9, k + 10), Blocks.STONE.getDefaultState());
		worldIn.setBlockState(bp.add(i + 4, j + 9, k + 11), Blocks.STONE.getDefaultState());
		worldIn.setBlockState(bp.add(i + 4, j + 9, k + 12), Blocks.STONE.getDefaultState());
		worldIn.setBlockState(bp.add(i + 4, j + 9, k + 13), Blocks.STONE.getDefaultState());
		worldIn.setBlockState(bp.add(i + 4, j + 9, k + 14), Blocks.STONE.getDefaultState());
		worldIn.setBlockState(bp.add(i + 4, j + 9, k + 15), Blocks.STONE.getDefaultState());
		worldIn.setBlockState(bp.add(i + 4, j + 9, k + 16), Blocks.STONE.getDefaultState());
		worldIn.setBlockState(bp.add(i + 4, j + 9, k + 17), Blocks.LAPIS_BLOCK.getDefaultState());
		worldIn.setBlockState(bp.add(i + 4, j + 9, k + 18), Blocks.STONE.getDefaultState());
		worldIn.setBlockState(bp.add(i + 4, j + 9, k + 19), Blocks.STONE.getDefaultState());
		worldIn.setBlockState(bp.add(i + 4, j + 9, k + 20), Blocks.STONE.getDefaultState());
		worldIn.setBlockState(bp.add(i + 4, j + 9, k + 21), Blocks.LAPIS_BLOCK.getDefaultState());
		worldIn.setBlockState(bp.add(i + 4, j + 10, k + 3), Blocks.LAPIS_BLOCK.getDefaultState());
		worldIn.setBlockState(bp.add(i + 4, j + 10, k + 4), Blocks.COAL_BLOCK.getDefaultState());
		worldIn.setBlockState(bp.add(i + 4, j + 10, k + 5), Blocks.COAL_BLOCK.getDefaultState());
		worldIn.setBlockState(bp.add(i + 4, j + 10, k + 6), Blocks.STONE.getDefaultState());
		worldIn.setBlockState(bp.add(i + 4, j + 10, k + 7), Blocks.STONE.getDefaultState());
		worldIn.setBlockState(bp.add(i + 4, j + 10, k + 9), Blocks.STONE.getDefaultState());
		worldIn.setBlockState(bp.add(i + 4, j + 10, k + 10), Blocks.STONE.getDefaultState());
		worldIn.setBlockState(bp.add(i + 4, j + 10, k + 11), Blocks.COAL_BLOCK.getDefaultState());
		worldIn.setBlockState(bp.add(i + 4, j + 10, k + 12), Blocks.COAL_BLOCK.getDefaultState());
		worldIn.setBlockState(bp.add(i + 4, j + 10, k + 13), Blocks.COAL_BLOCK.getDefaultState());
		worldIn.setBlockState(bp.add(i + 4, j + 10, k + 14), Blocks.STONE.getDefaultState());
		worldIn.setBlockState(bp.add(i + 4, j + 10, k + 15), Blocks.STONE.getDefaultState());
		worldIn.setBlockState(bp.add(i + 4, j + 10, k + 17), Blocks.STONE.getDefaultState());
		worldIn.setBlockState(bp.add(i + 4, j + 10, k + 18), Blocks.STONE.getDefaultState());
		worldIn.setBlockState(bp.add(i + 4, j + 10, k + 19), Blocks.COAL_BLOCK.getDefaultState());
		worldIn.setBlockState(bp.add(i + 4, j + 10, k + 20), Blocks.COAL_BLOCK.getDefaultState());
		worldIn.setBlockState(bp.add(i + 4, j + 10, k + 21), Blocks.LAPIS_BLOCK.getDefaultState());
		worldIn.setBlockState(bp.add(i + 4, j + 11, k + 11), Blocks.STONE.getDefaultState());
		worldIn.setBlockState(bp.add(i + 4, j + 11, k + 12), Blocks.STONE.getDefaultState());
		worldIn.setBlockState(bp.add(i + 4, j + 11, k + 13), Blocks.STONE.getDefaultState());
		worldIn.setBlockState(bp.add(i + 5, j + 3, k + 3), Blocks.STONE.getDefaultState());
		worldIn.setBlockState(bp.add(i + 5, j + 3, k + 4), Blocks.STONE.getDefaultState());
		worldIn.setBlockState(bp.add(i + 5, j + 3, k + 5), Blocks.STONE.getDefaultState());
		worldIn.setBlockState(bp.add(i + 5, j + 3, k + 6), Blocks.STONE.getDefaultState());
		worldIn.setBlockState(bp.add(i + 5, j + 3, k + 7), Blocks.STONE.getDefaultState());
		worldIn.setBlockState(bp.add(i + 5, j + 3, k + 8), Blocks.STONE.getDefaultState());
		worldIn.setBlockState(bp.add(i + 5, j + 3, k + 9), Blocks.STONE.getDefaultState());
		worldIn.setBlockState(bp.add(i + 5, j + 3, k + 10), Blocks.STONE.getDefaultState());
		worldIn.setBlockState(bp.add(i + 5, j + 3, k + 11), Blocks.STONE.getDefaultState());
		worldIn.setBlockState(bp.add(i + 5, j + 3, k + 12), Blocks.STONE.getDefaultState());
		worldIn.setBlockState(bp.add(i + 5, j + 3, k + 13), Blocks.STONE.getDefaultState());
		worldIn.setBlockState(bp.add(i + 5, j + 3, k + 14), Blocks.STONE.getDefaultState());
		worldIn.setBlockState(bp.add(i + 5, j + 3, k + 15), Blocks.STONE.getDefaultState());
		worldIn.setBlockState(bp.add(i + 5, j + 3, k + 16), Blocks.STONE.getDefaultState());
		worldIn.setBlockState(bp.add(i + 5, j + 3, k + 17), Blocks.STONE.getDefaultState());
		worldIn.setBlockState(bp.add(i + 5, j + 3, k + 18), Blocks.STONE.getDefaultState());
		worldIn.setBlockState(bp.add(i + 5, j + 3, k + 19), Blocks.STONE.getDefaultState());
		worldIn.setBlockState(bp.add(i + 5, j + 3, k + 20), Blocks.STONE.getDefaultState());
		worldIn.setBlockState(bp.add(i + 5, j + 3, k + 21), Blocks.STONE.getDefaultState());
		worldIn.setBlockState(bp.add(i + 5, j + 4, k + 3), Blocks.STONE.getDefaultState());
		worldIn.setBlockState(bp.add(i + 5, j + 4, k + 4), Blocks.STONE.getDefaultState());
		worldIn.setBlockState(bp.add(i + 5, j + 4, k + 5), (IBlockState)Blocks.PLANKS.getDefaultState().withProperty(BlockPlanks.VARIANT, BlockPlanks.EnumType.OAK));
		worldIn.setBlockState(bp.add(i + 5, j + 4, k + 6), (IBlockState)Blocks.PLANKS.getDefaultState().withProperty(BlockPlanks.VARIANT, BlockPlanks.EnumType.OAK));
		worldIn.setBlockState(bp.add(i + 5, j + 4, k + 7), Blocks.STONE.getDefaultState());
		worldIn.setBlockState(bp.add(i + 5, j + 4, k + 8), (IBlockState)Blocks.PLANKS.getDefaultState().withProperty(BlockPlanks.VARIANT, BlockPlanks.EnumType.OAK));
		worldIn.setBlockState(bp.add(i + 5, j + 4, k + 9), (IBlockState)Blocks.PLANKS.getDefaultState().withProperty(BlockPlanks.VARIANT, BlockPlanks.EnumType.OAK));
		worldIn.setBlockState(bp.add(i + 5, j + 4, k + 10), (IBlockState)Blocks.PLANKS.getDefaultState().withProperty(BlockPlanks.VARIANT, BlockPlanks.EnumType.OAK));
		worldIn.setBlockState(bp.add(i + 5, j + 4, k + 11), (IBlockState)Blocks.PLANKS.getDefaultState().withProperty(BlockPlanks.VARIANT, BlockPlanks.EnumType.OAK));
		worldIn.setBlockState(bp.add(i + 5, j + 4, k + 12), (IBlockState)Blocks.PLANKS.getDefaultState().withProperty(BlockPlanks.VARIANT, BlockPlanks.EnumType.OAK));
		worldIn.setBlockState(bp.add(i + 5, j + 4, k + 13), (IBlockState)Blocks.PLANKS.getDefaultState().withProperty(BlockPlanks.VARIANT, BlockPlanks.EnumType.OAK));
		worldIn.setBlockState(bp.add(i + 5, j + 4, k + 14), (IBlockState)Blocks.PLANKS.getDefaultState().withProperty(BlockPlanks.VARIANT, BlockPlanks.EnumType.OAK));
		worldIn.setBlockState(bp.add(i + 5, j + 4, k + 15), (IBlockState)Blocks.PLANKS.getDefaultState().withProperty(BlockPlanks.VARIANT, BlockPlanks.EnumType.OAK));
		worldIn.setBlockState(bp.add(i + 5, j + 4, k + 16), (IBlockState)Blocks.PLANKS.getDefaultState().withProperty(BlockPlanks.VARIANT, BlockPlanks.EnumType.OAK));
		worldIn.setBlockState(bp.add(i + 5, j + 4, k + 17), Blocks.STONE.getDefaultState());
		worldIn.setBlockState(bp.add(i + 5, j + 4, k + 18), (IBlockState)Blocks.PLANKS.getDefaultState().withProperty(BlockPlanks.VARIANT, BlockPlanks.EnumType.OAK));
		worldIn.setBlockState(bp.add(i + 5, j + 4, k + 19), (IBlockState)Blocks.PLANKS.getDefaultState().withProperty(BlockPlanks.VARIANT, BlockPlanks.EnumType.OAK));
		worldIn.setBlockState(bp.add(i + 5, j + 4, k + 20), Blocks.STONE.getDefaultState());
		worldIn.setBlockState(bp.add(i + 5, j + 4, k + 21), Blocks.STONE.getDefaultState());
		worldIn.setBlockState(bp.add(i + 5, j + 5, k + 3), Blocks.STONE.getDefaultState());
		worldIn.setBlockState(bp.add(i + 5, j + 5, k + 4), Blocks.STONE.getDefaultState());
		worldIn.setBlockState(bp.add(i + 5, j + 5, k + 7), Blocks.STONE.getDefaultState());
		worldIn.setBlockState(bp.add(i + 5, j + 5, k + 17), Blocks.STONE.getDefaultState());
		worldIn.setBlockState(bp.add(i + 5, j + 5, k + 20), Blocks.STONE.getDefaultState());
		worldIn.setBlockState(bp.add(i + 5, j + 5, k + 21), Blocks.STONE.getDefaultState());
		worldIn.setBlockState(bp.add(i + 5, j + 6, k + 3), (IBlockState)Blocks.STAINED_GLASS.getDefaultState().withProperty(BlockStainedGlass.COLOR, EnumDyeColor.YELLOW));
		worldIn.setBlockState(bp.add(i + 5, j + 6, k + 7), Blocks.STONE.getDefaultState());
		worldIn.setBlockState(bp.add(i + 5, j + 6, k + 17), Blocks.STONE.getDefaultState());
		worldIn.setBlockState(bp.add(i + 5, j + 6, k + 21), (IBlockState)Blocks.STAINED_GLASS.getDefaultState().withProperty(BlockStainedGlass.COLOR, EnumDyeColor.YELLOW));
		worldIn.setBlockState(bp.add(i + 5, j + 7, k + 3), Blocks.LAPIS_BLOCK.getDefaultState());
		worldIn.setBlockState(bp.add(i + 5, j + 7, k + 4), Blocks.STONE.getDefaultState());
		worldIn.setBlockState(bp.add(i + 5, j + 7, k + 7), Blocks.STONE.getDefaultState());
		worldIn.setBlockState(bp.add(i + 5, j + 7, k + 17), Blocks.STONE.getDefaultState());
		worldIn.setBlockState(bp.add(i + 5, j + 7, k + 20), Blocks.STONE.getDefaultState());
		worldIn.setBlockState(bp.add(i + 5, j + 7, k + 21), Blocks.LAPIS_BLOCK.getDefaultState());
		worldIn.setBlockState(bp.add(i + 5, j + 8, k + 3), Blocks.LAPIS_BLOCK.getDefaultState());
		worldIn.setBlockState(bp.add(i + 5, j + 8, k + 4), Blocks.STONE.getDefaultState());
		worldIn.setBlockState(bp.add(i + 5, j + 8, k + 7), Blocks.STONE.getDefaultState());
		worldIn.setBlockState(bp.add(i + 5, j + 8, k + 17), Blocks.STONE.getDefaultState());
		worldIn.setBlockState(bp.add(i + 5, j + 8, k + 20), Blocks.STONE.getDefaultState());
		worldIn.setBlockState(bp.add(i + 5, j + 8, k + 21), Blocks.LAPIS_BLOCK.getDefaultState());
		worldIn.setBlockState(bp.add(i + 5, j + 9, k + 3), Blocks.LAPIS_BLOCK.getDefaultState());
		worldIn.setBlockState(bp.add(i + 5, j + 9, k + 4), Blocks.STONE.getDefaultState());
		worldIn.setBlockState(bp.add(i + 5, j + 9, k + 7), Blocks.STONE.getDefaultState());
		worldIn.setBlockState(bp.add(i + 5, j + 9, k + 8), Blocks.STONE.getDefaultState());
		worldIn.setBlockState(bp.add(i + 5, j + 9, k + 9), Blocks.STONE.getDefaultState());
		worldIn.setBlockState(bp.add(i + 5, j + 9, k + 15), Blocks.SEA_LANTERN.getDefaultState());
		worldIn.setBlockState(bp.add(i + 5, j + 9, k + 16), Blocks.STONE.getDefaultState());
		worldIn.setBlockState(bp.add(i + 5, j + 9, k + 17), Blocks.SEA_LANTERN.getDefaultState());
		worldIn.setBlockState(bp.add(i + 5, j + 9, k + 20), Blocks.STONE.getDefaultState());
		worldIn.setBlockState(bp.add(i + 5, j + 9, k + 21), Blocks.LAPIS_BLOCK.getDefaultState());
		worldIn.setBlockState(bp.add(i + 5, j + 10, k + 3), Blocks.LAPIS_BLOCK.getDefaultState());
		worldIn.setBlockState(bp.add(i + 5, j + 10, k + 4), Blocks.LAPIS_BLOCK.getDefaultState());
		worldIn.setBlockState(bp.add(i + 5, j + 10, k + 5), Blocks.STONE.getDefaultState());
		worldIn.setBlockState(bp.add(i + 5, j + 10, k + 6), Blocks.STONE.getDefaultState());
		worldIn.setBlockState(bp.add(i + 5, j + 10, k + 7), Blocks.STONE.getDefaultState());
		worldIn.setBlockState(bp.add(i + 5, j + 10, k + 9), Blocks.STONE.getDefaultState());
		worldIn.setBlockState(bp.add(i + 5, j + 10, k + 10), Blocks.STONE.getDefaultState());
		worldIn.setBlockState(bp.add(i + 5, j + 10, k + 11), Blocks.STONE.getDefaultState());
		worldIn.setBlockState(bp.add(i + 5, j + 10, k + 12), Blocks.STONE.getDefaultState());
		worldIn.setBlockState(bp.add(i + 5, j + 10, k + 13), Blocks.STONE.getDefaultState());
		worldIn.setBlockState(bp.add(i + 5, j + 10, k + 14), Blocks.STONE.getDefaultState());
		worldIn.setBlockState(bp.add(i + 5, j + 10, k + 15), Blocks.STONE.getDefaultState());
		worldIn.setBlockState(bp.add(i + 5, j + 10, k + 17), Blocks.STONE.getDefaultState());
		worldIn.setBlockState(bp.add(i + 5, j + 10, k + 18), Blocks.STONE.getDefaultState());
		worldIn.setBlockState(bp.add(i + 5, j + 10, k + 19), Blocks.STONE.getDefaultState());
		worldIn.setBlockState(bp.add(i + 5, j + 10, k + 20), Blocks.LAPIS_BLOCK.getDefaultState());
		worldIn.setBlockState(bp.add(i + 5, j + 10, k + 21), Blocks.LAPIS_BLOCK.getDefaultState());
		worldIn.setBlockState(bp.add(i + 5, j + 11, k + 10), Blocks.STONE.getDefaultState());
		worldIn.setBlockState(bp.add(i + 5, j + 11, k + 11), Blocks.STONE.getDefaultState());
		worldIn.setBlockState(bp.add(i + 5, j + 11, k + 12), Blocks.STONE.getDefaultState());
		worldIn.setBlockState(bp.add(i + 5, j + 11, k + 13), Blocks.STONE.getDefaultState());
		worldIn.setBlockState(bp.add(i + 5, j + 11, k + 14), Blocks.STONE.getDefaultState());
		worldIn.setBlockState(bp.add(i + 5, j + 12, k + 11), Blocks.STONE.getDefaultState());
		worldIn.setBlockState(bp.add(i + 5, j + 12, k + 12), Blocks.STONE.getDefaultState());
		worldIn.setBlockState(bp.add(i + 5, j + 12, k + 13), Blocks.STONE.getDefaultState());
		worldIn.setBlockState(bp.add(i + 6, j + 3, k + 3), Blocks.STONE.getDefaultState());
		worldIn.setBlockState(bp.add(i + 6, j + 3, k + 4), Blocks.STONE.getDefaultState());
		worldIn.setBlockState(bp.add(i + 6, j + 3, k + 5), Blocks.STONE.getDefaultState());
		worldIn.setBlockState(bp.add(i + 6, j + 3, k + 6), Blocks.STONE.getDefaultState());
		worldIn.setBlockState(bp.add(i + 6, j + 3, k + 7), Blocks.STONE.getDefaultState());
		worldIn.setBlockState(bp.add(i + 6, j + 3, k + 8), Blocks.STONE.getDefaultState());
		worldIn.setBlockState(bp.add(i + 6, j + 3, k + 9), Blocks.STONE.getDefaultState());
		worldIn.setBlockState(bp.add(i + 6, j + 3, k + 10), Blocks.STONE.getDefaultState());
		worldIn.setBlockState(bp.add(i + 6, j + 3, k + 11), Blocks.STONE.getDefaultState());
		worldIn.setBlockState(bp.add(i + 6, j + 3, k + 12), Blocks.STONE.getDefaultState());
		worldIn.setBlockState(bp.add(i + 6, j + 3, k + 13), Blocks.STONE.getDefaultState());
		worldIn.setBlockState(bp.add(i + 6, j + 3, k + 14), Blocks.STONE.getDefaultState());
		worldIn.setBlockState(bp.add(i + 6, j + 3, k + 15), Blocks.STONE.getDefaultState());
		worldIn.setBlockState(bp.add(i + 6, j + 3, k + 16), Blocks.STONE.getDefaultState());
		worldIn.setBlockState(bp.add(i + 6, j + 3, k + 17), Blocks.STONE.getDefaultState());
		worldIn.setBlockState(bp.add(i + 6, j + 3, k + 18), Blocks.STONE.getDefaultState());
		worldIn.setBlockState(bp.add(i + 6, j + 3, k + 19), Blocks.STONE.getDefaultState());
		worldIn.setBlockState(bp.add(i + 6, j + 3, k + 20), Blocks.STONE.getDefaultState());
		worldIn.setBlockState(bp.add(i + 6, j + 3, k + 21), Blocks.STONE.getDefaultState());
		worldIn.setBlockState(bp.add(i + 6, j + 4, k + 3), Blocks.STONE.getDefaultState());
		worldIn.setBlockState(bp.add(i + 6, j + 4, k + 4), Blocks.STONE.getDefaultState());
		worldIn.setBlockState(bp.add(i + 6, j + 4, k + 5), (IBlockState)Blocks.PLANKS.getDefaultState().withProperty(BlockPlanks.VARIANT, BlockPlanks.EnumType.OAK));
		worldIn.setBlockState(bp.add(i + 6, j + 4, k + 6), (IBlockState)Blocks.PLANKS.getDefaultState().withProperty(BlockPlanks.VARIANT, BlockPlanks.EnumType.OAK));
		worldIn.setBlockState(bp.add(i + 6, j + 4, k + 7), (IBlockState)Blocks.PLANKS.getDefaultState().withProperty(BlockPlanks.VARIANT, BlockPlanks.EnumType.OAK));
		worldIn.setBlockState(bp.add(i + 6, j + 4, k + 8), (IBlockState)Blocks.PLANKS.getDefaultState().withProperty(BlockPlanks.VARIANT, BlockPlanks.EnumType.OAK));
		worldIn.setBlockState(bp.add(i + 6, j + 4, k + 9), (IBlockState)Blocks.PLANKS.getDefaultState().withProperty(BlockPlanks.VARIANT, BlockPlanks.EnumType.OAK));
		worldIn.setBlockState(bp.add(i + 6, j + 4, k + 10), Blocks.STONE.getDefaultState());
		worldIn.setBlockState(bp.add(i + 6, j + 4, k + 11), Blocks.STONE.getDefaultState());
		worldIn.setBlockState(bp.add(i + 6, j + 4, k + 12), Blocks.STONE.getDefaultState());
		worldIn.setBlockState(bp.add(i + 6, j + 4, k + 13), Blocks.STONE.getDefaultState());
		worldIn.setBlockState(bp.add(i + 6, j + 4, k + 14), Blocks.STONE.getDefaultState());
		worldIn.setBlockState(bp.add(i + 6, j + 4, k + 15), (IBlockState)Blocks.PLANKS.getDefaultState().withProperty(BlockPlanks.VARIANT, BlockPlanks.EnumType.OAK));
		worldIn.setBlockState(bp.add(i + 6, j + 4, k + 16), (IBlockState)Blocks.PLANKS.getDefaultState().withProperty(BlockPlanks.VARIANT, BlockPlanks.EnumType.OAK));
		worldIn.setBlockState(bp.add(i + 6, j + 4, k + 17), (IBlockState)Blocks.PLANKS.getDefaultState().withProperty(BlockPlanks.VARIANT, BlockPlanks.EnumType.OAK));
		worldIn.setBlockState(bp.add(i + 6, j + 4, k + 18), (IBlockState)Blocks.PLANKS.getDefaultState().withProperty(BlockPlanks.VARIANT, BlockPlanks.EnumType.OAK));
		worldIn.setBlockState(bp.add(i + 6, j + 4, k + 19), (IBlockState)Blocks.PLANKS.getDefaultState().withProperty(BlockPlanks.VARIANT, BlockPlanks.EnumType.OAK));
		worldIn.setBlockState(bp.add(i + 6, j + 4, k + 20), Blocks.STONE.getDefaultState());
		worldIn.setBlockState(bp.add(i + 6, j + 4, k + 21), Blocks.STONE.getDefaultState());
		worldIn.setBlockState(bp.add(i + 6, j + 5, k + 3), Blocks.STONE.getDefaultState());
		worldIn.setBlockState(bp.add(i + 6, j + 5, k + 4), Blocks.STONE.getDefaultState());
		worldIn.setBlockState(bp.add(i + 6, j + 5, k + 20), Blocks.STONE.getDefaultState());
		worldIn.setBlockState(bp.add(i + 6, j + 5, k + 21), Blocks.STONE.getDefaultState());
		worldIn.setBlockState(bp.add(i + 6, j + 6, k + 3), Blocks.STONE.getDefaultState());
		worldIn.setBlockState(bp.add(i + 6, j + 6, k + 21), Blocks.STONE.getDefaultState());
		worldIn.setBlockState(bp.add(i + 6, j + 7, k + 3), Blocks.LAPIS_BLOCK.getDefaultState());
		worldIn.setBlockState(bp.add(i + 6, j + 7, k + 4), Blocks.STONE.getDefaultState());
		worldIn.setBlockState(bp.add(i + 6, j + 7, k + 20), Blocks.STONE.getDefaultState());
		worldIn.setBlockState(bp.add(i + 6, j + 7, k + 21), Blocks.LAPIS_BLOCK.getDefaultState());
		worldIn.setBlockState(bp.add(i + 6, j + 8, k + 3), Blocks.LAPIS_BLOCK.getDefaultState());
		worldIn.setBlockState(bp.add(i + 6, j + 8, k + 4), Blocks.STONE.getDefaultState());
		worldIn.setBlockState(bp.add(i + 6, j + 8, k + 20), Blocks.STONE.getDefaultState());
		worldIn.setBlockState(bp.add(i + 6, j + 8, k + 21), Blocks.LAPIS_BLOCK.getDefaultState());
		worldIn.setBlockState(bp.add(i + 6, j + 9, k + 3), Blocks.LAPIS_BLOCK.getDefaultState());
		worldIn.setBlockState(bp.add(i + 6, j + 9, k + 4), Blocks.STONE.getDefaultState());
		worldIn.setBlockState(bp.add(i + 6, j + 9, k + 7), Blocks.SEA_LANTERN.getDefaultState());
		worldIn.setBlockState(bp.add(i + 6, j + 9, k + 8), Blocks.STONE.getDefaultState());
		worldIn.setBlockState(bp.add(i + 6, j + 9, k + 9), Blocks.SEA_LANTERN.getDefaultState());
		worldIn.setBlockState(bp.add(i + 6, j + 9, k + 15), Blocks.SEA_LANTERN.getDefaultState());
		worldIn.setBlockState(bp.add(i + 6, j + 9, k + 16), Blocks.STONE.getDefaultState());
		worldIn.setBlockState(bp.add(i + 6, j + 9, k + 17), Blocks.SEA_LANTERN.getDefaultState());
		worldIn.setBlockState(bp.add(i + 6, j + 9, k + 20), Blocks.STONE.getDefaultState());
		worldIn.setBlockState(bp.add(i + 6, j + 9, k + 21), Blocks.LAPIS_BLOCK.getDefaultState());
		worldIn.setBlockState(bp.add(i + 6, j + 10, k + 3), Blocks.LAPIS_BLOCK.getDefaultState());
		worldIn.setBlockState(bp.add(i + 6, j + 10, k + 4), Blocks.LAPIS_BLOCK.getDefaultState());
		worldIn.setBlockState(bp.add(i + 6, j + 10, k + 5), Blocks.STONE.getDefaultState());
		worldIn.setBlockState(bp.add(i + 6, j + 10, k + 6), Blocks.STONE.getDefaultState());
		worldIn.setBlockState(bp.add(i + 6, j + 10, k + 7), Blocks.STONE.getDefaultState());
		worldIn.setBlockState(bp.add(i + 6, j + 10, k + 9), Blocks.STONE.getDefaultState());
		worldIn.setBlockState(bp.add(i + 6, j + 10, k + 10), Blocks.STONE.getDefaultState());
		worldIn.setBlockState(bp.add(i + 6, j + 10, k + 11), Blocks.STONE.getDefaultState());
		worldIn.setBlockState(bp.add(i + 6, j + 10, k + 12), Blocks.STONE.getDefaultState());
		worldIn.setBlockState(bp.add(i + 6, j + 10, k + 13), Blocks.STONE.getDefaultState());
		worldIn.setBlockState(bp.add(i + 6, j + 10, k + 14), Blocks.STONE.getDefaultState());
		worldIn.setBlockState(bp.add(i + 6, j + 10, k + 15), Blocks.STONE.getDefaultState());
		worldIn.setBlockState(bp.add(i + 6, j + 10, k + 17), Blocks.STONE.getDefaultState());
		worldIn.setBlockState(bp.add(i + 6, j + 10, k + 18), Blocks.STONE.getDefaultState());
		worldIn.setBlockState(bp.add(i + 6, j + 10, k + 19), Blocks.STONE.getDefaultState());
		worldIn.setBlockState(bp.add(i + 6, j + 10, k + 20), Blocks.LAPIS_BLOCK.getDefaultState());
		worldIn.setBlockState(bp.add(i + 6, j + 10, k + 21), Blocks.LAPIS_BLOCK.getDefaultState());
		worldIn.setBlockState(bp.add(i + 6, j + 11, k + 10), Blocks.STONE.getDefaultState());
		worldIn.setBlockState(bp.add(i + 6, j + 11, k + 11), Blocks.STONE.getDefaultState());
		worldIn.setBlockState(bp.add(i + 6, j + 11, k + 12), Blocks.STONE.getDefaultState());
		worldIn.setBlockState(bp.add(i + 6, j + 11, k + 13), Blocks.STONE.getDefaultState());
		worldIn.setBlockState(bp.add(i + 6, j + 11, k + 14), Blocks.STONE.getDefaultState());
		worldIn.setBlockState(bp.add(i + 6, j + 12, k + 11), Blocks.STONE.getDefaultState());
		worldIn.setBlockState(bp.add(i + 6, j + 12, k + 12), Blocks.STONE.getDefaultState());
		worldIn.setBlockState(bp.add(i + 6, j + 12, k + 13), Blocks.STONE.getDefaultState());
		worldIn.setBlockState(bp.add(i + 7, j + 3, k + 3), Blocks.STONE.getDefaultState());
		worldIn.setBlockState(bp.add(i + 7, j + 3, k + 4), Blocks.STONE.getDefaultState());
		worldIn.setBlockState(bp.add(i + 7, j + 3, k + 5), Blocks.STONE.getDefaultState());
		worldIn.setBlockState(bp.add(i + 7, j + 3, k + 6), Blocks.STONE.getDefaultState());
		worldIn.setBlockState(bp.add(i + 7, j + 3, k + 7), Blocks.STONE.getDefaultState());
		worldIn.setBlockState(bp.add(i + 7, j + 3, k + 8), Blocks.STONE.getDefaultState());
		worldIn.setBlockState(bp.add(i + 7, j + 3, k + 9), Blocks.STONE.getDefaultState());
		worldIn.setBlockState(bp.add(i + 7, j + 3, k + 10), Blocks.STONE.getDefaultState());
		worldIn.setBlockState(bp.add(i + 7, j + 3, k + 14), Blocks.STONE.getDefaultState());
		worldIn.setBlockState(bp.add(i + 7, j + 3, k + 15), Blocks.STONE.getDefaultState());
		worldIn.setBlockState(bp.add(i + 7, j + 3, k + 16), Blocks.STONE.getDefaultState());
		worldIn.setBlockState(bp.add(i + 7, j + 3, k + 17), Blocks.STONE.getDefaultState());
		worldIn.setBlockState(bp.add(i + 7, j + 3, k + 18), Blocks.STONE.getDefaultState());
		worldIn.setBlockState(bp.add(i + 7, j + 3, k + 19), Blocks.STONE.getDefaultState());
		worldIn.setBlockState(bp.add(i + 7, j + 3, k + 20), Blocks.STONE.getDefaultState());
		worldIn.setBlockState(bp.add(i + 7, j + 3, k + 21), Blocks.STONE.getDefaultState());
		worldIn.setBlockState(bp.add(i + 7, j + 4, k + 3), Blocks.STONE.getDefaultState());
		worldIn.setBlockState(bp.add(i + 7, j + 4, k + 4), Blocks.STONE.getDefaultState());
		worldIn.setBlockState(bp.add(i + 7, j + 4, k + 5), (IBlockState)Blocks.PLANKS.getDefaultState().withProperty(BlockPlanks.VARIANT, BlockPlanks.EnumType.OAK));
		worldIn.setBlockState(bp.add(i + 7, j + 4, k + 6), (IBlockState)Blocks.PLANKS.getDefaultState().withProperty(BlockPlanks.VARIANT, BlockPlanks.EnumType.OAK));
		worldIn.setBlockState(bp.add(i + 7, j + 4, k + 7), (IBlockState)Blocks.PLANKS.getDefaultState().withProperty(BlockPlanks.VARIANT, BlockPlanks.EnumType.OAK));
		worldIn.setBlockState(bp.add(i + 7, j + 4, k + 8), (IBlockState)Blocks.PLANKS.getDefaultState().withProperty(BlockPlanks.VARIANT, BlockPlanks.EnumType.OAK));
		worldIn.setBlockState(bp.add(i + 7, j + 4, k + 9), (IBlockState)Blocks.PLANKS.getDefaultState().withProperty(BlockPlanks.VARIANT, BlockPlanks.EnumType.OAK));
		worldIn.setBlockState(bp.add(i + 7, j + 4, k + 10), Blocks.STONE.getDefaultState());
		worldIn.setBlockState(bp.add(i + 7, j + 4, k + 14), Blocks.STONE.getDefaultState());
		worldIn.setBlockState(bp.add(i + 7, j + 4, k + 15), (IBlockState)Blocks.PLANKS.getDefaultState().withProperty(BlockPlanks.VARIANT, BlockPlanks.EnumType.OAK));
		worldIn.setBlockState(bp.add(i + 7, j + 4, k + 16), (IBlockState)Blocks.PLANKS.getDefaultState().withProperty(BlockPlanks.VARIANT, BlockPlanks.EnumType.OAK));
		worldIn.setBlockState(bp.add(i + 7, j + 4, k + 17), (IBlockState)Blocks.PLANKS.getDefaultState().withProperty(BlockPlanks.VARIANT, BlockPlanks.EnumType.OAK));
		worldIn.setBlockState(bp.add(i + 7, j + 4, k + 18), (IBlockState)Blocks.PLANKS.getDefaultState().withProperty(BlockPlanks.VARIANT, BlockPlanks.EnumType.OAK));
		worldIn.setBlockState(bp.add(i + 7, j + 4, k + 19), (IBlockState)Blocks.PLANKS.getDefaultState().withProperty(BlockPlanks.VARIANT, BlockPlanks.EnumType.OAK));
		worldIn.setBlockState(bp.add(i + 7, j + 4, k + 20), Blocks.STONE.getDefaultState());
		worldIn.setBlockState(bp.add(i + 7, j + 4, k + 21), Blocks.STONE.getDefaultState());
		worldIn.setBlockState(bp.add(i + 7, j + 5, k + 3), Blocks.STONE.getDefaultState());
		worldIn.setBlockState(bp.add(i + 7, j + 5, k + 4), Blocks.STONE.getDefaultState());
		worldIn.setBlockState(bp.add(i + 7, j + 5, k + 20), Blocks.STONE.getDefaultState());
		worldIn.setBlockState(bp.add(i + 7, j + 5, k + 21), Blocks.STONE.getDefaultState());
		worldIn.setBlockState(bp.add(i + 7, j + 6, k + 3), Blocks.STONE.getDefaultState());
		worldIn.setBlockState(bp.add(i + 7, j + 6, k + 4), Blocks.STONE.getDefaultState());
		worldIn.setBlockState(bp.add(i + 7, j + 6, k + 20), Blocks.STONE.getDefaultState());
		worldIn.setBlockState(bp.add(i + 7, j + 6, k + 21), Blocks.STONE.getDefaultState());
		worldIn.setBlockState(bp.add(i + 7, j + 7, k + 3), Blocks.LAPIS_BLOCK.getDefaultState());
		worldIn.setBlockState(bp.add(i + 7, j + 7, k + 4), Blocks.STONE.getDefaultState());
		worldIn.setBlockState(bp.add(i + 7, j + 7, k + 20), Blocks.STONE.getDefaultState());
		worldIn.setBlockState(bp.add(i + 7, j + 7, k + 21), Blocks.LAPIS_BLOCK.getDefaultState());
		worldIn.setBlockState(bp.add(i + 7, j + 8, k + 3), Blocks.LAPIS_BLOCK.getDefaultState());
		worldIn.setBlockState(bp.add(i + 7, j + 8, k + 4), Blocks.STONE.getDefaultState());
		worldIn.setBlockState(bp.add(i + 7, j + 8, k + 20), Blocks.STONE.getDefaultState());
		worldIn.setBlockState(bp.add(i + 7, j + 8, k + 21), Blocks.LAPIS_BLOCK.getDefaultState());
		worldIn.setBlockState(bp.add(i + 7, j + 9, k + 3), Blocks.LAPIS_BLOCK.getDefaultState());
		worldIn.setBlockState(bp.add(i + 7, j + 9, k + 4), Blocks.STONE.getDefaultState());
		worldIn.setBlockState(bp.add(i + 7, j + 9, k + 7), Blocks.SEA_LANTERN.getDefaultState());
		worldIn.setBlockState(bp.add(i + 7, j + 9, k + 8), Blocks.STONE.getDefaultState());
		worldIn.setBlockState(bp.add(i + 7, j + 9, k + 9), Blocks.SEA_LANTERN.getDefaultState());
		worldIn.setBlockState(bp.add(i + 7, j + 9, k + 15), Blocks.SEA_LANTERN.getDefaultState());
		worldIn.setBlockState(bp.add(i + 7, j + 9, k + 16), Blocks.STONE.getDefaultState());
		worldIn.setBlockState(bp.add(i + 7, j + 9, k + 17), Blocks.SEA_LANTERN.getDefaultState());
		worldIn.setBlockState(bp.add(i + 7, j + 9, k + 20), Blocks.STONE.getDefaultState());
		worldIn.setBlockState(bp.add(i + 7, j + 9, k + 21), Blocks.LAPIS_BLOCK.getDefaultState());
		worldIn.setBlockState(bp.add(i + 7, j + 10, k + 3), Blocks.LAPIS_BLOCK.getDefaultState());
		worldIn.setBlockState(bp.add(i + 7, j + 10, k + 4), Blocks.LAPIS_BLOCK.getDefaultState());
		worldIn.setBlockState(bp.add(i + 7, j + 10, k + 5), Blocks.STONE.getDefaultState());
		worldIn.setBlockState(bp.add(i + 7, j + 10, k + 6), Blocks.STONE.getDefaultState());
		worldIn.setBlockState(bp.add(i + 7, j + 10, k + 7), Blocks.STONE.getDefaultState());
		worldIn.setBlockState(bp.add(i + 7, j + 10, k + 9), Blocks.STONE.getDefaultState());
		worldIn.setBlockState(bp.add(i + 7, j + 10, k + 10), Blocks.STONE.getDefaultState());
		worldIn.setBlockState(bp.add(i + 7, j + 10, k + 11), Blocks.STONE.getDefaultState());
		worldIn.setBlockState(bp.add(i + 7, j + 10, k + 12), Blocks.STONE.getDefaultState());
		worldIn.setBlockState(bp.add(i + 7, j + 10, k + 13), Blocks.STONE.getDefaultState());
		worldIn.setBlockState(bp.add(i + 7, j + 10, k + 14), Blocks.STONE.getDefaultState());
		worldIn.setBlockState(bp.add(i + 7, j + 10, k + 15), Blocks.STONE.getDefaultState());
		worldIn.setBlockState(bp.add(i + 7, j + 10, k + 17), Blocks.STONE.getDefaultState());
		worldIn.setBlockState(bp.add(i + 7, j + 10, k + 18), Blocks.STONE.getDefaultState());
		worldIn.setBlockState(bp.add(i + 7, j + 10, k + 19), Blocks.STONE.getDefaultState());
		worldIn.setBlockState(bp.add(i + 7, j + 10, k + 20), Blocks.LAPIS_BLOCK.getDefaultState());
		worldIn.setBlockState(bp.add(i + 7, j + 10, k + 21), Blocks.LAPIS_BLOCK.getDefaultState());
		worldIn.setBlockState(bp.add(i + 7, j + 11, k + 10), Blocks.STONE.getDefaultState());
		worldIn.setBlockState(bp.add(i + 7, j + 11, k + 11), Blocks.STONE.getDefaultState());
		worldIn.setBlockState(bp.add(i + 7, j + 11, k + 12), Blocks.STONE.getDefaultState());
		worldIn.setBlockState(bp.add(i + 7, j + 11, k + 13), Blocks.STONE.getDefaultState());
		worldIn.setBlockState(bp.add(i + 7, j + 11, k + 14), Blocks.STONE.getDefaultState());
		worldIn.setBlockState(bp.add(i + 7, j + 12, k + 11), Blocks.STONE.getDefaultState());
		worldIn.setBlockState(bp.add(i + 7, j + 12, k + 12), Blocks.STONE.getDefaultState());
		worldIn.setBlockState(bp.add(i + 7, j + 12, k + 13), Blocks.STONE.getDefaultState());
		worldIn.setBlockState(bp.add(i + 8, j + 0, k + 11), (IBlockState)Blocks.STONE_BRICK_STAIRS.getDefaultState().withProperty(BlockStairs.FACING, EnumFacing.EAST));
		worldIn.setBlockState(bp.add(i + 8, j + 0, k + 12), (IBlockState)Blocks.STONE_BRICK_STAIRS.getDefaultState().withProperty(BlockStairs.FACING, EnumFacing.EAST));
		worldIn.setBlockState(bp.add(i + 8, j + 0, k + 13), (IBlockState)Blocks.STONE_BRICK_STAIRS.getDefaultState().withProperty(BlockStairs.FACING, EnumFacing.EAST));
		worldIn.setBlockState(bp.add(i + 8, j + 3, k + 3), Blocks.STONE.getDefaultState());
		worldIn.setBlockState(bp.add(i + 8, j + 3, k + 4), Blocks.STONE.getDefaultState());
		worldIn.setBlockState(bp.add(i + 8, j + 3, k + 5), Blocks.STONE.getDefaultState());
		worldIn.setBlockState(bp.add(i + 8, j + 3, k + 6), Blocks.STONE.getDefaultState());
		worldIn.setBlockState(bp.add(i + 8, j + 3, k + 7), Blocks.STONE.getDefaultState());
		worldIn.setBlockState(bp.add(i + 8, j + 3, k + 8), Blocks.STONE.getDefaultState());
		worldIn.setBlockState(bp.add(i + 8, j + 3, k + 9), Blocks.STONE.getDefaultState());
		worldIn.setBlockState(bp.add(i + 8, j + 3, k + 10), Blocks.STONE.getDefaultState());
		worldIn.setBlockState(bp.add(i + 8, j + 3, k + 14), Blocks.STONE.getDefaultState());
		worldIn.setBlockState(bp.add(i + 8, j + 3, k + 15), Blocks.STONE.getDefaultState());
		worldIn.setBlockState(bp.add(i + 8, j + 3, k + 16), Blocks.STONE.getDefaultState());
		worldIn.setBlockState(bp.add(i + 8, j + 3, k + 17), Blocks.STONE.getDefaultState());
		worldIn.setBlockState(bp.add(i + 8, j + 3, k + 18), Blocks.STONE.getDefaultState());
		worldIn.setBlockState(bp.add(i + 8, j + 3, k + 19), Blocks.STONE.getDefaultState());
		worldIn.setBlockState(bp.add(i + 8, j + 3, k + 20), Blocks.STONE.getDefaultState());
		worldIn.setBlockState(bp.add(i + 8, j + 3, k + 21), Blocks.STONE.getDefaultState());
		worldIn.setBlockState(bp.add(i + 8, j + 4, k + 3), Blocks.STONE.getDefaultState());
		worldIn.setBlockState(bp.add(i + 8, j + 4, k + 4), Blocks.STONE.getDefaultState());
		worldIn.setBlockState(bp.add(i + 8, j + 4, k + 5), (IBlockState)Blocks.PLANKS.getDefaultState().withProperty(BlockPlanks.VARIANT, BlockPlanks.EnumType.OAK));
		worldIn.setBlockState(bp.add(i + 8, j + 4, k + 6), (IBlockState)Blocks.PLANKS.getDefaultState().withProperty(BlockPlanks.VARIANT, BlockPlanks.EnumType.OAK));
		worldIn.setBlockState(bp.add(i + 8, j + 4, k + 7), (IBlockState)Blocks.PLANKS.getDefaultState().withProperty(BlockPlanks.VARIANT, BlockPlanks.EnumType.OAK));
		worldIn.setBlockState(bp.add(i + 8, j + 4, k + 8), (IBlockState)Blocks.PLANKS.getDefaultState().withProperty(BlockPlanks.VARIANT, BlockPlanks.EnumType.OAK));
		worldIn.setBlockState(bp.add(i + 8, j + 4, k + 9), (IBlockState)Blocks.PLANKS.getDefaultState().withProperty(BlockPlanks.VARIANT, BlockPlanks.EnumType.OAK));
		worldIn.setBlockState(bp.add(i + 8, j + 4, k + 10), Blocks.STONE.getDefaultState());
		worldIn.setBlockState(bp.add(i + 8, j + 4, k + 14), Blocks.STONE.getDefaultState());
		worldIn.setBlockState(bp.add(i + 8, j + 4, k + 15), (IBlockState)Blocks.PLANKS.getDefaultState().withProperty(BlockPlanks.VARIANT, BlockPlanks.EnumType.OAK));
		worldIn.setBlockState(bp.add(i + 8, j + 4, k + 16), (IBlockState)Blocks.PLANKS.getDefaultState().withProperty(BlockPlanks.VARIANT, BlockPlanks.EnumType.OAK));
		worldIn.setBlockState(bp.add(i + 8, j + 4, k + 17), (IBlockState)Blocks.PLANKS.getDefaultState().withProperty(BlockPlanks.VARIANT, BlockPlanks.EnumType.OAK));
		worldIn.setBlockState(bp.add(i + 8, j + 4, k + 18), (IBlockState)Blocks.PLANKS.getDefaultState().withProperty(BlockPlanks.VARIANT, BlockPlanks.EnumType.OAK));
		worldIn.setBlockState(bp.add(i + 8, j + 4, k + 19), (IBlockState)Blocks.PLANKS.getDefaultState().withProperty(BlockPlanks.VARIANT, BlockPlanks.EnumType.OAK));
		worldIn.setBlockState(bp.add(i + 8, j + 4, k + 20), Blocks.STONE.getDefaultState());
		worldIn.setBlockState(bp.add(i + 8, j + 4, k + 21), Blocks.STONE.getDefaultState());
		worldIn.setBlockState(bp.add(i + 8, j + 5, k + 3), Blocks.STONE.getDefaultState());
		worldIn.setBlockState(bp.add(i + 8, j + 5, k + 4), Blocks.STONE.getDefaultState());
		worldIn.setBlockState(bp.add(i + 8, j + 5, k + 20), Blocks.STONE.getDefaultState());
		worldIn.setBlockState(bp.add(i + 8, j + 5, k + 21), Blocks.STONE.getDefaultState());
		worldIn.setBlockState(bp.add(i + 8, j + 6, k + 3), Blocks.STONE.getDefaultState());
		worldIn.setBlockState(bp.add(i + 8, j + 6, k + 4), Blocks.STONE.getDefaultState());
		worldIn.setBlockState(bp.add(i + 8, j + 6, k + 20), Blocks.STONE.getDefaultState());
		worldIn.setBlockState(bp.add(i + 8, j + 6, k + 21), Blocks.STONE.getDefaultState());
		worldIn.setBlockState(bp.add(i + 8, j + 7, k + 3), Blocks.LAPIS_BLOCK.getDefaultState());
		worldIn.setBlockState(bp.add(i + 8, j + 7, k + 4), Blocks.STONE.getDefaultState());
		worldIn.setBlockState(bp.add(i + 8, j + 7, k + 20), Blocks.STONE.getDefaultState());
		worldIn.setBlockState(bp.add(i + 8, j + 7, k + 21), Blocks.LAPIS_BLOCK.getDefaultState());
		worldIn.setBlockState(bp.add(i + 8, j + 8, k + 3), Blocks.LAPIS_BLOCK.getDefaultState());
		worldIn.setBlockState(bp.add(i + 8, j + 8, k + 4), Blocks.STONE.getDefaultState());
		worldIn.setBlockState(bp.add(i + 8, j + 8, k + 20), Blocks.STONE.getDefaultState());
		worldIn.setBlockState(bp.add(i + 8, j + 8, k + 21), Blocks.LAPIS_BLOCK.getDefaultState());
		worldIn.setBlockState(bp.add(i + 8, j + 9, k + 3), Blocks.LAPIS_BLOCK.getDefaultState());
		worldIn.setBlockState(bp.add(i + 8, j + 9, k + 4), Blocks.STONE.getDefaultState());
		worldIn.setBlockState(bp.add(i + 8, j + 9, k + 7), Blocks.SEA_LANTERN.getDefaultState());
		worldIn.setBlockState(bp.add(i + 8, j + 9, k + 8), Blocks.STONE.getDefaultState());
		worldIn.setBlockState(bp.add(i + 8, j + 9, k + 9), Blocks.SEA_LANTERN.getDefaultState());
		worldIn.setBlockState(bp.add(i + 8, j + 9, k + 15), Blocks.SEA_LANTERN.getDefaultState());
		worldIn.setBlockState(bp.add(i + 8, j + 9, k + 16), Blocks.STONE.getDefaultState());
		worldIn.setBlockState(bp.add(i + 8, j + 9, k + 17), Blocks.SEA_LANTERN.getDefaultState());
		worldIn.setBlockState(bp.add(i + 8, j + 9, k + 20), Blocks.STONE.getDefaultState());
		worldIn.setBlockState(bp.add(i + 8, j + 9, k + 21), Blocks.LAPIS_BLOCK.getDefaultState());
		worldIn.setBlockState(bp.add(i + 8, j + 10, k + 3), Blocks.LAPIS_BLOCK.getDefaultState());
		worldIn.setBlockState(bp.add(i + 8, j + 10, k + 4), Blocks.LAPIS_BLOCK.getDefaultState());
		worldIn.setBlockState(bp.add(i + 8, j + 10, k + 5), Blocks.STONE.getDefaultState());
		worldIn.setBlockState(bp.add(i + 8, j + 10, k + 6), Blocks.STONE.getDefaultState());
		worldIn.setBlockState(bp.add(i + 8, j + 10, k + 7), Blocks.STONE.getDefaultState());
		worldIn.setBlockState(bp.add(i + 8, j + 10, k + 9), Blocks.STONE.getDefaultState());
		worldIn.setBlockState(bp.add(i + 8, j + 10, k + 10), Blocks.STONE.getDefaultState());
		worldIn.setBlockState(bp.add(i + 8, j + 10, k + 11), Blocks.STONE.getDefaultState());
		worldIn.setBlockState(bp.add(i + 8, j + 10, k + 12), Blocks.STONE.getDefaultState());
		worldIn.setBlockState(bp.add(i + 8, j + 10, k + 13), Blocks.STONE.getDefaultState());
		worldIn.setBlockState(bp.add(i + 8, j + 10, k + 14), Blocks.STONE.getDefaultState());
		worldIn.setBlockState(bp.add(i + 8, j + 10, k + 15), Blocks.STONE.getDefaultState());
		worldIn.setBlockState(bp.add(i + 8, j + 10, k + 17), Blocks.STONE.getDefaultState());
		worldIn.setBlockState(bp.add(i + 8, j + 10, k + 18), Blocks.STONE.getDefaultState());
		worldIn.setBlockState(bp.add(i + 8, j + 10, k + 19), Blocks.STONE.getDefaultState());
		worldIn.setBlockState(bp.add(i + 8, j + 10, k + 20), Blocks.LAPIS_BLOCK.getDefaultState());
		worldIn.setBlockState(bp.add(i + 8, j + 10, k + 21), Blocks.LAPIS_BLOCK.getDefaultState());
		worldIn.setBlockState(bp.add(i + 8, j + 11, k + 10), Blocks.STONE.getDefaultState());
		worldIn.setBlockState(bp.add(i + 8, j + 11, k + 11), Blocks.STONE.getDefaultState());
		worldIn.setBlockState(bp.add(i + 8, j + 11, k + 12), Blocks.STONE.getDefaultState());
		worldIn.setBlockState(bp.add(i + 8, j + 11, k + 13), Blocks.STONE.getDefaultState());
		worldIn.setBlockState(bp.add(i + 8, j + 11, k + 14), Blocks.STONE.getDefaultState());
		worldIn.setBlockState(bp.add(i + 8, j + 12, k + 11), Blocks.STONE.getDefaultState());
		worldIn.setBlockState(bp.add(i + 8, j + 12, k + 12), Blocks.STONE.getDefaultState());
		worldIn.setBlockState(bp.add(i + 8, j + 12, k + 13), Blocks.STONE.getDefaultState());
		worldIn.setBlockState(bp.add(i + 9, j + 1, k + 11), (IBlockState)Blocks.STONE_BRICK_STAIRS.getDefaultState().withProperty(BlockStairs.FACING, EnumFacing.EAST));
		worldIn.setBlockState(bp.add(i + 9, j + 1, k + 12), (IBlockState)Blocks.STONE_BRICK_STAIRS.getDefaultState().withProperty(BlockStairs.FACING, EnumFacing.EAST));
		worldIn.setBlockState(bp.add(i + 9, j + 1, k + 13), (IBlockState)Blocks.STONE_BRICK_STAIRS.getDefaultState().withProperty(BlockStairs.FACING, EnumFacing.EAST));
		worldIn.setBlockState(bp.add(i + 9, j + 3, k + 3), Blocks.STONE.getDefaultState());
		worldIn.setBlockState(bp.add(i + 9, j + 3, k + 4), Blocks.STONE.getDefaultState());
		worldIn.setBlockState(bp.add(i + 9, j + 3, k + 5), Blocks.STONE.getDefaultState());
		worldIn.setBlockState(bp.add(i + 9, j + 3, k + 6), Blocks.STONE.getDefaultState());
		worldIn.setBlockState(bp.add(i + 9, j + 3, k + 7), Blocks.STONE.getDefaultState());
		worldIn.setBlockState(bp.add(i + 9, j + 3, k + 8), Blocks.STONE.getDefaultState());
		worldIn.setBlockState(bp.add(i + 9, j + 3, k + 9), Blocks.STONE.getDefaultState());
		worldIn.setBlockState(bp.add(i + 9, j + 3, k + 10), Blocks.STONE.getDefaultState());
		worldIn.setBlockState(bp.add(i + 9, j + 3, k + 14), Blocks.STONE.getDefaultState());
		worldIn.setBlockState(bp.add(i + 9, j + 3, k + 15), Blocks.STONE.getDefaultState());
		worldIn.setBlockState(bp.add(i + 9, j + 3, k + 16), Blocks.STONE.getDefaultState());
		worldIn.setBlockState(bp.add(i + 9, j + 3, k + 17), Blocks.STONE.getDefaultState());
		worldIn.setBlockState(bp.add(i + 9, j + 3, k + 18), Blocks.STONE.getDefaultState());
		worldIn.setBlockState(bp.add(i + 9, j + 3, k + 19), Blocks.STONE.getDefaultState());
		worldIn.setBlockState(bp.add(i + 9, j + 3, k + 20), Blocks.STONE.getDefaultState());
		worldIn.setBlockState(bp.add(i + 9, j + 3, k + 21), Blocks.STONE.getDefaultState());
		worldIn.setBlockState(bp.add(i + 9, j + 4, k + 3), Blocks.STONE.getDefaultState());
		worldIn.setBlockState(bp.add(i + 9, j + 4, k + 4), Blocks.STONE.getDefaultState());
		worldIn.setBlockState(bp.add(i + 9, j + 4, k + 5), (IBlockState)Blocks.PLANKS.getDefaultState().withProperty(BlockPlanks.VARIANT, BlockPlanks.EnumType.OAK));
		worldIn.setBlockState(bp.add(i + 9, j + 4, k + 6), (IBlockState)Blocks.PLANKS.getDefaultState().withProperty(BlockPlanks.VARIANT, BlockPlanks.EnumType.OAK));
		worldIn.setBlockState(bp.add(i + 9, j + 4, k + 7), (IBlockState)Blocks.PLANKS.getDefaultState().withProperty(BlockPlanks.VARIANT, BlockPlanks.EnumType.OAK));
		worldIn.setBlockState(bp.add(i + 9, j + 4, k + 8), (IBlockState)Blocks.PLANKS.getDefaultState().withProperty(BlockPlanks.VARIANT, BlockPlanks.EnumType.OAK));
		worldIn.setBlockState(bp.add(i + 9, j + 4, k + 9), (IBlockState)Blocks.PLANKS.getDefaultState().withProperty(BlockPlanks.VARIANT, BlockPlanks.EnumType.OAK));
		worldIn.setBlockState(bp.add(i + 9, j + 4, k + 10), Blocks.STONE.getDefaultState());
		worldIn.setBlockState(bp.add(i + 9, j + 4, k + 14), Blocks.STONE.getDefaultState());
		worldIn.setBlockState(bp.add(i + 9, j + 4, k + 15), (IBlockState)Blocks.PLANKS.getDefaultState().withProperty(BlockPlanks.VARIANT, BlockPlanks.EnumType.OAK));
		worldIn.setBlockState(bp.add(i + 9, j + 4, k + 16), (IBlockState)Blocks.PLANKS.getDefaultState().withProperty(BlockPlanks.VARIANT, BlockPlanks.EnumType.OAK));
		worldIn.setBlockState(bp.add(i + 9, j + 4, k + 17), (IBlockState)Blocks.PLANKS.getDefaultState().withProperty(BlockPlanks.VARIANT, BlockPlanks.EnumType.OAK));
		worldIn.setBlockState(bp.add(i + 9, j + 4, k + 18), (IBlockState)Blocks.PLANKS.getDefaultState().withProperty(BlockPlanks.VARIANT, BlockPlanks.EnumType.OAK));
		worldIn.setBlockState(bp.add(i + 9, j + 4, k + 19), (IBlockState)Blocks.PLANKS.getDefaultState().withProperty(BlockPlanks.VARIANT, BlockPlanks.EnumType.OAK));
		worldIn.setBlockState(bp.add(i + 9, j + 4, k + 20), Blocks.STONE.getDefaultState());
		worldIn.setBlockState(bp.add(i + 9, j + 4, k + 21), Blocks.STONE.getDefaultState());
		worldIn.setBlockState(bp.add(i + 9, j + 5, k + 3), Blocks.STONE.getDefaultState());
		worldIn.setBlockState(bp.add(i + 9, j + 5, k + 4), Blocks.STONE.getDefaultState());
		worldIn.setBlockState(bp.add(i + 9, j + 5, k + 5), Blocks.BED.getDefaultState());
		worldIn.setBlockState(bp.add(i + 9, j + 5, k + 6), Blocks.BED.getDefaultState());
		worldIn.setBlockState(bp.add(i + 9, j + 5, k + 18), Blocks.BED.getDefaultState());
		worldIn.setBlockState(bp.add(i + 9, j + 5, k + 19), Blocks.BED.getDefaultState());
		worldIn.setBlockState(bp.add(i + 9, j + 5, k + 20), Blocks.STONE.getDefaultState());
		worldIn.setBlockState(bp.add(i + 9, j + 5, k + 21), Blocks.STONE.getDefaultState());
		worldIn.setBlockState(bp.add(i + 9, j + 6, k + 3), Blocks.STONE.getDefaultState());
		worldIn.setBlockState(bp.add(i + 9, j + 6, k + 4), Blocks.STONE.getDefaultState());
		worldIn.setBlockState(bp.add(i + 9, j + 6, k + 20), Blocks.STONE.getDefaultState());
		worldIn.setBlockState(bp.add(i + 9, j + 6, k + 21), Blocks.STONE.getDefaultState());
		worldIn.setBlockState(bp.add(i + 9, j + 7, k + 3), Blocks.LAPIS_BLOCK.getDefaultState());
		worldIn.setBlockState(bp.add(i + 9, j + 7, k + 4), Blocks.STONE.getDefaultState());
		worldIn.setBlockState(bp.add(i + 9, j + 7, k + 20), Blocks.STONE.getDefaultState());
		worldIn.setBlockState(bp.add(i + 9, j + 7, k + 21), Blocks.LAPIS_BLOCK.getDefaultState());
		worldIn.setBlockState(bp.add(i + 9, j + 8, k + 3), Blocks.LAPIS_BLOCK.getDefaultState());
		worldIn.setBlockState(bp.add(i + 9, j + 8, k + 4), Blocks.STONE.getDefaultState());
		worldIn.setBlockState(bp.add(i + 9, j + 8, k + 20), Blocks.STONE.getDefaultState());
		worldIn.setBlockState(bp.add(i + 9, j + 8, k + 21), Blocks.LAPIS_BLOCK.getDefaultState());
		worldIn.setBlockState(bp.add(i + 9, j + 9, k + 3), Blocks.LAPIS_BLOCK.getDefaultState());
		worldIn.setBlockState(bp.add(i + 9, j + 9, k + 4), Blocks.STONE.getDefaultState());
		worldIn.setBlockState(bp.add(i + 9, j + 9, k + 7), Blocks.SEA_LANTERN.getDefaultState());
		worldIn.setBlockState(bp.add(i + 9, j + 9, k + 8), Blocks.STONE.getDefaultState());
		worldIn.setBlockState(bp.add(i + 9, j + 9, k + 9), Blocks.SEA_LANTERN.getDefaultState());
		worldIn.setBlockState(bp.add(i + 9, j + 9, k + 15), Blocks.SEA_LANTERN.getDefaultState());
		worldIn.setBlockState(bp.add(i + 9, j + 9, k + 16), Blocks.STONE.getDefaultState());
		worldIn.setBlockState(bp.add(i + 9, j + 9, k + 17), Blocks.SEA_LANTERN.getDefaultState());
		worldIn.setBlockState(bp.add(i + 9, j + 9, k + 20), Blocks.STONE.getDefaultState());
		worldIn.setBlockState(bp.add(i + 9, j + 9, k + 21), Blocks.LAPIS_BLOCK.getDefaultState());
		worldIn.setBlockState(bp.add(i + 9, j + 10, k + 3), Blocks.LAPIS_BLOCK.getDefaultState());
		worldIn.setBlockState(bp.add(i + 9, j + 10, k + 4), Blocks.LAPIS_BLOCK.getDefaultState());
		worldIn.setBlockState(bp.add(i + 9, j + 10, k + 5), Blocks.STONE.getDefaultState());
		worldIn.setBlockState(bp.add(i + 9, j + 10, k + 6), Blocks.STONE.getDefaultState());
		worldIn.setBlockState(bp.add(i + 9, j + 10, k + 7), Blocks.STONE.getDefaultState());
		worldIn.setBlockState(bp.add(i + 9, j + 10, k + 9), Blocks.STONE.getDefaultState());
		worldIn.setBlockState(bp.add(i + 9, j + 10, k + 10), Blocks.STONE.getDefaultState());
		worldIn.setBlockState(bp.add(i + 9, j + 10, k + 11), Blocks.STONE.getDefaultState());
		worldIn.setBlockState(bp.add(i + 9, j + 10, k + 12), Blocks.STONE.getDefaultState());
		worldIn.setBlockState(bp.add(i + 9, j + 10, k + 13), Blocks.STONE.getDefaultState());
		worldIn.setBlockState(bp.add(i + 9, j + 10, k + 14), Blocks.STONE.getDefaultState());
		worldIn.setBlockState(bp.add(i + 9, j + 10, k + 15), Blocks.STONE.getDefaultState());
		worldIn.setBlockState(bp.add(i + 9, j + 10, k + 17), Blocks.STONE.getDefaultState());
		worldIn.setBlockState(bp.add(i + 9, j + 10, k + 18), Blocks.STONE.getDefaultState());
		worldIn.setBlockState(bp.add(i + 9, j + 10, k + 19), Blocks.STONE.getDefaultState());
		worldIn.setBlockState(bp.add(i + 9, j + 10, k + 20), Blocks.LAPIS_BLOCK.getDefaultState());
		worldIn.setBlockState(bp.add(i + 9, j + 10, k + 21), Blocks.LAPIS_BLOCK.getDefaultState());
		worldIn.setBlockState(bp.add(i + 9, j + 11, k + 10), Blocks.STONE.getDefaultState());
		worldIn.setBlockState(bp.add(i + 9, j + 11, k + 11), Blocks.STONE.getDefaultState());
		worldIn.setBlockState(bp.add(i + 9, j + 11, k + 12), Blocks.STONE.getDefaultState());
		worldIn.setBlockState(bp.add(i + 9, j + 11, k + 13), Blocks.STONE.getDefaultState());
		worldIn.setBlockState(bp.add(i + 9, j + 11, k + 14), Blocks.STONE.getDefaultState());
		worldIn.setBlockState(bp.add(i + 9, j + 12, k + 11), Blocks.STONE.getDefaultState());
		worldIn.setBlockState(bp.add(i + 9, j + 12, k + 12), Blocks.STONE.getDefaultState());
		worldIn.setBlockState(bp.add(i + 9, j + 12, k + 13), Blocks.STONE.getDefaultState());
		worldIn.setBlockState(bp.add(i + 10, j + 2, k + 11), (IBlockState)Blocks.STONE_BRICK_STAIRS.getDefaultState().withProperty(BlockStairs.FACING, EnumFacing.EAST));
		worldIn.setBlockState(bp.add(i + 10, j + 2, k + 12), (IBlockState)Blocks.STONE_BRICK_STAIRS.getDefaultState().withProperty(BlockStairs.FACING, EnumFacing.EAST));
		worldIn.setBlockState(bp.add(i + 10, j + 2, k + 13), (IBlockState)Blocks.STONE_BRICK_STAIRS.getDefaultState().withProperty(BlockStairs.FACING, EnumFacing.EAST));
		worldIn.setBlockState(bp.add(i + 10, j + 3, k + 3), Blocks.STONE.getDefaultState());
		worldIn.setBlockState(bp.add(i + 10, j + 3, k + 4), Blocks.STONE.getDefaultState());
		worldIn.setBlockState(bp.add(i + 10, j + 3, k + 5), Blocks.STONE.getDefaultState());
		worldIn.setBlockState(bp.add(i + 10, j + 3, k + 6), Blocks.STONE.getDefaultState());
		worldIn.setBlockState(bp.add(i + 10, j + 3, k + 7), Blocks.STONE.getDefaultState());
		worldIn.setBlockState(bp.add(i + 10, j + 3, k + 8), Blocks.STONE.getDefaultState());
		worldIn.setBlockState(bp.add(i + 10, j + 3, k + 9), Blocks.STONE.getDefaultState());
		worldIn.setBlockState(bp.add(i + 10, j + 3, k + 10), Blocks.STONE.getDefaultState());
		worldIn.setBlockState(bp.add(i + 10, j + 3, k + 14), Blocks.STONE.getDefaultState());
		worldIn.setBlockState(bp.add(i + 10, j + 3, k + 15), Blocks.STONE.getDefaultState());
		worldIn.setBlockState(bp.add(i + 10, j + 3, k + 16), Blocks.STONE.getDefaultState());
		worldIn.setBlockState(bp.add(i + 10, j + 3, k + 17), Blocks.STONE.getDefaultState());
		worldIn.setBlockState(bp.add(i + 10, j + 3, k + 18), Blocks.STONE.getDefaultState());
		worldIn.setBlockState(bp.add(i + 10, j + 3, k + 19), Blocks.STONE.getDefaultState());
		worldIn.setBlockState(bp.add(i + 10, j + 3, k + 20), Blocks.STONE.getDefaultState());
		worldIn.setBlockState(bp.add(i + 10, j + 3, k + 21), Blocks.STONE.getDefaultState());
		worldIn.setBlockState(bp.add(i + 10, j + 4, k + 3), Blocks.STONE.getDefaultState());
		worldIn.setBlockState(bp.add(i + 10, j + 4, k + 4), Blocks.STONE.getDefaultState());
		worldIn.setBlockState(bp.add(i + 10, j + 4, k + 5), (IBlockState)Blocks.PLANKS.getDefaultState().withProperty(BlockPlanks.VARIANT, BlockPlanks.EnumType.OAK));
		worldIn.setBlockState(bp.add(i + 10, j + 4, k + 6), (IBlockState)Blocks.PLANKS.getDefaultState().withProperty(BlockPlanks.VARIANT, BlockPlanks.EnumType.OAK));
		worldIn.setBlockState(bp.add(i + 10, j + 4, k + 7), (IBlockState)Blocks.PLANKS.getDefaultState().withProperty(BlockPlanks.VARIANT, BlockPlanks.EnumType.OAK));
		worldIn.setBlockState(bp.add(i + 10, j + 4, k + 8), (IBlockState)Blocks.PLANKS.getDefaultState().withProperty(BlockPlanks.VARIANT, BlockPlanks.EnumType.OAK));
		worldIn.setBlockState(bp.add(i + 10, j + 4, k + 9), (IBlockState)Blocks.PLANKS.getDefaultState().withProperty(BlockPlanks.VARIANT, BlockPlanks.EnumType.OAK));
		worldIn.setBlockState(bp.add(i + 10, j + 4, k + 10), Blocks.STONE.getDefaultState());
		worldIn.setBlockState(bp.add(i + 10, j + 4, k + 14), Blocks.STONE.getDefaultState());
		worldIn.setBlockState(bp.add(i + 10, j + 4, k + 15), (IBlockState)Blocks.PLANKS.getDefaultState().withProperty(BlockPlanks.VARIANT, BlockPlanks.EnumType.OAK));
		worldIn.setBlockState(bp.add(i + 10, j + 4, k + 16), (IBlockState)Blocks.PLANKS.getDefaultState().withProperty(BlockPlanks.VARIANT, BlockPlanks.EnumType.OAK));
		worldIn.setBlockState(bp.add(i + 10, j + 4, k + 17), (IBlockState)Blocks.PLANKS.getDefaultState().withProperty(BlockPlanks.VARIANT, BlockPlanks.EnumType.OAK));
		worldIn.setBlockState(bp.add(i + 10, j + 4, k + 18), (IBlockState)Blocks.PLANKS.getDefaultState().withProperty(BlockPlanks.VARIANT, BlockPlanks.EnumType.OAK));
		worldIn.setBlockState(bp.add(i + 10, j + 4, k + 19), (IBlockState)Blocks.PLANKS.getDefaultState().withProperty(BlockPlanks.VARIANT, BlockPlanks.EnumType.OAK));
		worldIn.setBlockState(bp.add(i + 10, j + 4, k + 20), Blocks.STONE.getDefaultState());
		worldIn.setBlockState(bp.add(i + 10, j + 4, k + 21), Blocks.STONE.getDefaultState());
		worldIn.setBlockState(bp.add(i + 10, j + 5, k + 3), Blocks.STONE.getDefaultState());
		worldIn.setBlockState(bp.add(i + 10, j + 5, k + 4), Blocks.STONE.getDefaultState());
		worldIn.setBlockState(bp.add(i + 10, j + 5, k + 20), Blocks.STONE.getDefaultState());
		worldIn.setBlockState(bp.add(i + 10, j + 5, k + 21), Blocks.STONE.getDefaultState());
		worldIn.setBlockState(bp.add(i + 10, j + 6, k + 3), Blocks.STONE.getDefaultState());
		worldIn.setBlockState(bp.add(i + 10, j + 6, k + 4), Blocks.STONE.getDefaultState());
		worldIn.setBlockState(bp.add(i + 10, j + 6, k + 20), Blocks.STONE.getDefaultState());
		worldIn.setBlockState(bp.add(i + 10, j + 6, k + 21), Blocks.STONE.getDefaultState());
		worldIn.setBlockState(bp.add(i + 10, j + 7, k + 3), Blocks.LAPIS_BLOCK.getDefaultState());
		worldIn.setBlockState(bp.add(i + 10, j + 7, k + 4), Blocks.STONE.getDefaultState());
		worldIn.setBlockState(bp.add(i + 10, j + 7, k + 20), Blocks.STONE.getDefaultState());
		worldIn.setBlockState(bp.add(i + 10, j + 7, k + 21), Blocks.LAPIS_BLOCK.getDefaultState());
		worldIn.setBlockState(bp.add(i + 10, j + 8, k + 3), Blocks.LAPIS_BLOCK.getDefaultState());
		worldIn.setBlockState(bp.add(i + 10, j + 8, k + 4), Blocks.STONE.getDefaultState());
		worldIn.setBlockState(bp.add(i + 10, j + 8, k + 20), Blocks.STONE.getDefaultState());
		worldIn.setBlockState(bp.add(i + 10, j + 8, k + 21), Blocks.LAPIS_BLOCK.getDefaultState());
		worldIn.setBlockState(bp.add(i + 10, j + 9, k + 3), Blocks.LAPIS_BLOCK.getDefaultState());
		worldIn.setBlockState(bp.add(i + 10, j + 9, k + 4), Blocks.STONE.getDefaultState());
		worldIn.setBlockState(bp.add(i + 10, j + 9, k + 7), Blocks.SEA_LANTERN.getDefaultState());
		worldIn.setBlockState(bp.add(i + 10, j + 9, k + 8), Blocks.STONE.getDefaultState());
		worldIn.setBlockState(bp.add(i + 10, j + 9, k + 9), Blocks.SEA_LANTERN.getDefaultState());
		worldIn.setBlockState(bp.add(i + 10, j + 9, k + 15), Blocks.SEA_LANTERN.getDefaultState());
		worldIn.setBlockState(bp.add(i + 10, j + 9, k + 16), Blocks.STONE.getDefaultState());
		worldIn.setBlockState(bp.add(i + 10, j + 9, k + 17), Blocks.SEA_LANTERN.getDefaultState());
		worldIn.setBlockState(bp.add(i + 10, j + 9, k + 20), Blocks.STONE.getDefaultState());
		worldIn.setBlockState(bp.add(i + 10, j + 9, k + 21), Blocks.LAPIS_BLOCK.getDefaultState());
		worldIn.setBlockState(bp.add(i + 10, j + 10, k + 3), Blocks.LAPIS_BLOCK.getDefaultState());
		worldIn.setBlockState(bp.add(i + 10, j + 10, k + 4), Blocks.LAPIS_BLOCK.getDefaultState());
		worldIn.setBlockState(bp.add(i + 10, j + 10, k + 5), Blocks.STONE.getDefaultState());
		worldIn.setBlockState(bp.add(i + 10, j + 10, k + 6), Blocks.STONE.getDefaultState());
		worldIn.setBlockState(bp.add(i + 10, j + 10, k + 7), Blocks.STONE.getDefaultState());
		worldIn.setBlockState(bp.add(i + 10, j + 10, k + 9), Blocks.STONE.getDefaultState());
		worldIn.setBlockState(bp.add(i + 10, j + 10, k + 10), Blocks.STONE.getDefaultState());
		worldIn.setBlockState(bp.add(i + 10, j + 10, k + 11), Blocks.STONE.getDefaultState());
		worldIn.setBlockState(bp.add(i + 10, j + 10, k + 12), Blocks.STONE.getDefaultState());
		worldIn.setBlockState(bp.add(i + 10, j + 10, k + 13), Blocks.STONE.getDefaultState());
		worldIn.setBlockState(bp.add(i + 10, j + 10, k + 14), Blocks.STONE.getDefaultState());
		worldIn.setBlockState(bp.add(i + 10, j + 10, k + 15), Blocks.STONE.getDefaultState());
		worldIn.setBlockState(bp.add(i + 10, j + 10, k + 17), Blocks.STONE.getDefaultState());
		worldIn.setBlockState(bp.add(i + 10, j + 10, k + 18), Blocks.STONE.getDefaultState());
		worldIn.setBlockState(bp.add(i + 10, j + 10, k + 19), Blocks.STONE.getDefaultState());
		worldIn.setBlockState(bp.add(i + 10, j + 10, k + 20), Blocks.LAPIS_BLOCK.getDefaultState());
		worldIn.setBlockState(bp.add(i + 10, j + 10, k + 21), Blocks.LAPIS_BLOCK.getDefaultState());
		worldIn.setBlockState(bp.add(i + 10, j + 11, k + 11), Blocks.STONE.getDefaultState());
		worldIn.setBlockState(bp.add(i + 10, j + 11, k + 12), Blocks.STONE.getDefaultState());
		worldIn.setBlockState(bp.add(i + 10, j + 11, k + 13), Blocks.STONE.getDefaultState());
		worldIn.setBlockState(bp.add(i + 11, j + 3, k + 3), Blocks.STONE.getDefaultState());
		worldIn.setBlockState(bp.add(i + 11, j + 3, k + 4), Blocks.STONE.getDefaultState());
		worldIn.setBlockState(bp.add(i + 11, j + 3, k + 5), Blocks.STONE.getDefaultState());
		worldIn.setBlockState(bp.add(i + 11, j + 3, k + 6), Blocks.STONE.getDefaultState());
		worldIn.setBlockState(bp.add(i + 11, j + 3, k + 7), Blocks.STONE.getDefaultState());
		worldIn.setBlockState(bp.add(i + 11, j + 3, k + 8), Blocks.STONE.getDefaultState());
		worldIn.setBlockState(bp.add(i + 11, j + 3, k + 9), Blocks.STONE.getDefaultState());
		worldIn.setBlockState(bp.add(i + 11, j + 3, k + 10), Blocks.STONE.getDefaultState());
		worldIn.setBlockState(bp.add(i + 11, j + 3, k + 11), (IBlockState)Blocks.STONE_BRICK_STAIRS.getDefaultState().withProperty(BlockStairs.FACING, EnumFacing.EAST));
		worldIn.setBlockState(bp.add(i + 11, j + 3, k + 12), (IBlockState)Blocks.STONE_BRICK_STAIRS.getDefaultState().withProperty(BlockStairs.FACING, EnumFacing.EAST));
		worldIn.setBlockState(bp.add(i + 11, j + 3, k + 13), (IBlockState)Blocks.STONE_BRICK_STAIRS.getDefaultState().withProperty(BlockStairs.FACING, EnumFacing.EAST));
		worldIn.setBlockState(bp.add(i + 11, j + 3, k + 14), Blocks.STONE.getDefaultState());
		worldIn.setBlockState(bp.add(i + 11, j + 3, k + 15), Blocks.STONE.getDefaultState());
		worldIn.setBlockState(bp.add(i + 11, j + 3, k + 16), Blocks.STONE.getDefaultState());
		worldIn.setBlockState(bp.add(i + 11, j + 3, k + 17), Blocks.STONE.getDefaultState());
		worldIn.setBlockState(bp.add(i + 11, j + 3, k + 18), Blocks.STONE.getDefaultState());
		worldIn.setBlockState(bp.add(i + 11, j + 3, k + 19), Blocks.STONE.getDefaultState());
		worldIn.setBlockState(bp.add(i + 11, j + 3, k + 20), Blocks.STONE.getDefaultState());
		worldIn.setBlockState(bp.add(i + 11, j + 3, k + 21), Blocks.STONE.getDefaultState());
		worldIn.setBlockState(bp.add(i + 11, j + 4, k + 3), Blocks.STONE.getDefaultState());
		worldIn.setBlockState(bp.add(i + 11, j + 4, k + 4), Blocks.STONE.getDefaultState());
		worldIn.setBlockState(bp.add(i + 11, j + 4, k + 5), (IBlockState)Blocks.PLANKS.getDefaultState().withProperty(BlockPlanks.VARIANT, BlockPlanks.EnumType.OAK));
		worldIn.setBlockState(bp.add(i + 11, j + 4, k + 6), (IBlockState)Blocks.PLANKS.getDefaultState().withProperty(BlockPlanks.VARIANT, BlockPlanks.EnumType.OAK));
		worldIn.setBlockState(bp.add(i + 11, j + 4, k + 7), (IBlockState)Blocks.PLANKS.getDefaultState().withProperty(BlockPlanks.VARIANT, BlockPlanks.EnumType.OAK));
		worldIn.setBlockState(bp.add(i + 11, j + 4, k + 8), (IBlockState)Blocks.PLANKS.getDefaultState().withProperty(BlockPlanks.VARIANT, BlockPlanks.EnumType.OAK));
		worldIn.setBlockState(bp.add(i + 11, j + 4, k + 9), (IBlockState)Blocks.PLANKS.getDefaultState().withProperty(BlockPlanks.VARIANT, BlockPlanks.EnumType.OAK));
		worldIn.setBlockState(bp.add(i + 11, j + 4, k + 10), Blocks.STONE.getDefaultState());
		worldIn.setBlockState(bp.add(i + 11, j + 4, k + 14), Blocks.STONE.getDefaultState());
		worldIn.setBlockState(bp.add(i + 11, j + 4, k + 15), (IBlockState)Blocks.PLANKS.getDefaultState().withProperty(BlockPlanks.VARIANT, BlockPlanks.EnumType.OAK));
		worldIn.setBlockState(bp.add(i + 11, j + 4, k + 16), (IBlockState)Blocks.PLANKS.getDefaultState().withProperty(BlockPlanks.VARIANT, BlockPlanks.EnumType.OAK));
		worldIn.setBlockState(bp.add(i + 11, j + 4, k + 17), (IBlockState)Blocks.PLANKS.getDefaultState().withProperty(BlockPlanks.VARIANT, BlockPlanks.EnumType.OAK));
		worldIn.setBlockState(bp.add(i + 11, j + 4, k + 18), (IBlockState)Blocks.PLANKS.getDefaultState().withProperty(BlockPlanks.VARIANT, BlockPlanks.EnumType.OAK));
		worldIn.setBlockState(bp.add(i + 11, j + 4, k + 19), (IBlockState)Blocks.PLANKS.getDefaultState().withProperty(BlockPlanks.VARIANT, BlockPlanks.EnumType.OAK));
		worldIn.setBlockState(bp.add(i + 11, j + 4, k + 20), Blocks.STONE.getDefaultState());
		worldIn.setBlockState(bp.add(i + 11, j + 4, k + 21), Blocks.STONE.getDefaultState());
		worldIn.setBlockState(bp.add(i + 11, j + 5, k + 3), Blocks.STONE.getDefaultState());
		worldIn.setBlockState(bp.add(i + 11, j + 5, k + 4), Blocks.STONE.getDefaultState());
		worldIn.setBlockState(bp.add(i + 11, j + 5, k + 5), Blocks.BED.getDefaultState());
		worldIn.setBlockState(bp.add(i + 11, j + 5, k + 6), Blocks.BED.getDefaultState());
		worldIn.setBlockState(bp.add(i + 11, j + 5, k + 18), Blocks.BED.getDefaultState());
		worldIn.setBlockState(bp.add(i + 11, j + 5, k + 19), Blocks.BED.getDefaultState());
		worldIn.setBlockState(bp.add(i + 11, j + 5, k + 20), Blocks.STONE.getDefaultState());
		worldIn.setBlockState(bp.add(i + 11, j + 5, k + 21), Blocks.STONE.getDefaultState());
		worldIn.setBlockState(bp.add(i + 11, j + 6, k + 3), Blocks.STONE.getDefaultState());
		worldIn.setBlockState(bp.add(i + 11, j + 6, k + 4), Blocks.STONE.getDefaultState());
		worldIn.setBlockState(bp.add(i + 11, j + 6, k + 20), Blocks.STONE.getDefaultState());
		worldIn.setBlockState(bp.add(i + 11, j + 6, k + 21), Blocks.STONE.getDefaultState());
		worldIn.setBlockState(bp.add(i + 11, j + 7, k + 3), Blocks.LAPIS_BLOCK.getDefaultState());
		worldIn.setBlockState(bp.add(i + 11, j + 7, k + 4), Blocks.STONE.getDefaultState());
		worldIn.setBlockState(bp.add(i + 11, j + 7, k + 20), Blocks.STONE.getDefaultState());
		worldIn.setBlockState(bp.add(i + 11, j + 7, k + 21), Blocks.LAPIS_BLOCK.getDefaultState());
		worldIn.setBlockState(bp.add(i + 11, j + 8, k + 3), Blocks.LAPIS_BLOCK.getDefaultState());
		worldIn.setBlockState(bp.add(i + 11, j + 8, k + 4), Blocks.STONE.getDefaultState());
		worldIn.setBlockState(bp.add(i + 11, j + 8, k + 20), Blocks.STONE.getDefaultState());
		worldIn.setBlockState(bp.add(i + 11, j + 8, k + 21), Blocks.LAPIS_BLOCK.getDefaultState());
		worldIn.setBlockState(bp.add(i + 11, j + 9, k + 3), Blocks.LAPIS_BLOCK.getDefaultState());
		worldIn.setBlockState(bp.add(i + 11, j + 9, k + 4), Blocks.STONE.getDefaultState());
		worldIn.setBlockState(bp.add(i + 11, j + 9, k + 7), Blocks.SEA_LANTERN.getDefaultState());
		worldIn.setBlockState(bp.add(i + 11, j + 9, k + 8), Blocks.STONE.getDefaultState());
		worldIn.setBlockState(bp.add(i + 11, j + 9, k + 9), Blocks.SEA_LANTERN.getDefaultState());
		worldIn.setBlockState(bp.add(i + 11, j + 9, k + 15), Blocks.SEA_LANTERN.getDefaultState());
		worldIn.setBlockState(bp.add(i + 11, j + 9, k + 16), Blocks.STONE.getDefaultState());
		worldIn.setBlockState(bp.add(i + 11, j + 9, k + 17), Blocks.SEA_LANTERN.getDefaultState());
		worldIn.setBlockState(bp.add(i + 11, j + 9, k + 20), Blocks.STONE.getDefaultState());
		worldIn.setBlockState(bp.add(i + 11, j + 9, k + 21), Blocks.LAPIS_BLOCK.getDefaultState());
		worldIn.setBlockState(bp.add(i + 11, j + 10, k + 3), Blocks.LAPIS_BLOCK.getDefaultState());
		worldIn.setBlockState(bp.add(i + 11, j + 10, k + 4), Blocks.LAPIS_BLOCK.getDefaultState());
		worldIn.setBlockState(bp.add(i + 11, j + 10, k + 5), Blocks.STONE.getDefaultState());
		worldIn.setBlockState(bp.add(i + 11, j + 10, k + 6), Blocks.STONE.getDefaultState());
		worldIn.setBlockState(bp.add(i + 11, j + 10, k + 7), Blocks.STONE.getDefaultState());
		worldIn.setBlockState(bp.add(i + 11, j + 10, k + 9), Blocks.STONE.getDefaultState());
		worldIn.setBlockState(bp.add(i + 11, j + 10, k + 10), Blocks.STONE.getDefaultState());
		worldIn.setBlockState(bp.add(i + 11, j + 10, k + 11), Blocks.STONE.getDefaultState());
		worldIn.setBlockState(bp.add(i + 11, j + 10, k + 12), Blocks.STONE.getDefaultState());
		worldIn.setBlockState(bp.add(i + 11, j + 10, k + 13), Blocks.STONE.getDefaultState());
		worldIn.setBlockState(bp.add(i + 11, j + 10, k + 14), Blocks.STONE.getDefaultState());
		worldIn.setBlockState(bp.add(i + 11, j + 10, k + 15), Blocks.STONE.getDefaultState());
		worldIn.setBlockState(bp.add(i + 11, j + 10, k + 17), Blocks.STONE.getDefaultState());
		worldIn.setBlockState(bp.add(i + 11, j + 10, k + 18), Blocks.STONE.getDefaultState());
		worldIn.setBlockState(bp.add(i + 11, j + 10, k + 19), Blocks.STONE.getDefaultState());
		worldIn.setBlockState(bp.add(i + 11, j + 10, k + 20), Blocks.LAPIS_BLOCK.getDefaultState());
		worldIn.setBlockState(bp.add(i + 11, j + 10, k + 21), Blocks.LAPIS_BLOCK.getDefaultState());
		worldIn.setBlockState(bp.add(i + 11, j + 11, k + 11), Blocks.STONE.getDefaultState());
		worldIn.setBlockState(bp.add(i + 11, j + 11, k + 12), Blocks.STONE.getDefaultState());
		worldIn.setBlockState(bp.add(i + 11, j + 11, k + 13), Blocks.STONE.getDefaultState());
		worldIn.setBlockState(bp.add(i + 12, j + 3, k + 3), Blocks.STONE.getDefaultState());
		worldIn.setBlockState(bp.add(i + 12, j + 3, k + 4), Blocks.STONE.getDefaultState());
		worldIn.setBlockState(bp.add(i + 12, j + 3, k + 5), Blocks.STONE.getDefaultState());
		worldIn.setBlockState(bp.add(i + 12, j + 3, k + 6), Blocks.STONE.getDefaultState());
		worldIn.setBlockState(bp.add(i + 12, j + 3, k + 7), Blocks.STONE.getDefaultState());
		worldIn.setBlockState(bp.add(i + 12, j + 3, k + 8), Blocks.STONE.getDefaultState());
		worldIn.setBlockState(bp.add(i + 12, j + 3, k + 9), Blocks.STONE.getDefaultState());
		worldIn.setBlockState(bp.add(i + 12, j + 3, k + 10), Blocks.STONE.getDefaultState());
		worldIn.setBlockState(bp.add(i + 12, j + 3, k + 11), Blocks.STONE.getDefaultState());
		worldIn.setBlockState(bp.add(i + 12, j + 3, k + 12), Blocks.STONE.getDefaultState());
		worldIn.setBlockState(bp.add(i + 12, j + 3, k + 13), Blocks.STONE.getDefaultState());
		worldIn.setBlockState(bp.add(i + 12, j + 3, k + 14), Blocks.STONE.getDefaultState());
		worldIn.setBlockState(bp.add(i + 12, j + 3, k + 15), Blocks.STONE.getDefaultState());
		worldIn.setBlockState(bp.add(i + 12, j + 3, k + 16), Blocks.STONE.getDefaultState());
		worldIn.setBlockState(bp.add(i + 12, j + 3, k + 17), Blocks.STONE.getDefaultState());
		worldIn.setBlockState(bp.add(i + 12, j + 3, k + 18), Blocks.STONE.getDefaultState());
		worldIn.setBlockState(bp.add(i + 12, j + 3, k + 19), Blocks.STONE.getDefaultState());
		worldIn.setBlockState(bp.add(i + 12, j + 3, k + 20), Blocks.STONE.getDefaultState());
		worldIn.setBlockState(bp.add(i + 12, j + 3, k + 21), Blocks.STONE.getDefaultState());
		worldIn.setBlockState(bp.add(i + 12, j + 4, k + 3), Blocks.STONE.getDefaultState());
		worldIn.setBlockState(bp.add(i + 12, j + 4, k + 4), Blocks.STONE.getDefaultState());
		worldIn.setBlockState(bp.add(i + 12, j + 4, k + 5), (IBlockState)Blocks.PLANKS.getDefaultState().withProperty(BlockPlanks.VARIANT, BlockPlanks.EnumType.OAK));
		worldIn.setBlockState(bp.add(i + 12, j + 4, k + 6), (IBlockState)Blocks.PLANKS.getDefaultState().withProperty(BlockPlanks.VARIANT, BlockPlanks.EnumType.OAK));
		worldIn.setBlockState(bp.add(i + 12, j + 4, k + 7), (IBlockState)Blocks.PLANKS.getDefaultState().withProperty(BlockPlanks.VARIANT, BlockPlanks.EnumType.OAK));
		worldIn.setBlockState(bp.add(i + 12, j + 4, k + 8), (IBlockState)Blocks.PLANKS.getDefaultState().withProperty(BlockPlanks.VARIANT, BlockPlanks.EnumType.OAK));
		worldIn.setBlockState(bp.add(i + 12, j + 4, k + 9), (IBlockState)Blocks.PLANKS.getDefaultState().withProperty(BlockPlanks.VARIANT, BlockPlanks.EnumType.OAK));
		worldIn.setBlockState(bp.add(i + 12, j + 4, k + 10), Blocks.STONE.getDefaultState());
		worldIn.setBlockState(bp.add(i + 12, j + 4, k + 11), (IBlockState)Blocks.STONE_BRICK_STAIRS.getDefaultState().withProperty(BlockStairs.FACING, EnumFacing.EAST));
		worldIn.setBlockState(bp.add(i + 12, j + 4, k + 12), (IBlockState)Blocks.STONE_BRICK_STAIRS.getDefaultState().withProperty(BlockStairs.FACING, EnumFacing.EAST));
		worldIn.setBlockState(bp.add(i + 12, j + 4, k + 13), (IBlockState)Blocks.STONE_BRICK_STAIRS.getDefaultState().withProperty(BlockStairs.FACING, EnumFacing.EAST));
		worldIn.setBlockState(bp.add(i + 12, j + 4, k + 14), Blocks.STONE.getDefaultState());
		worldIn.setBlockState(bp.add(i + 12, j + 4, k + 15), (IBlockState)Blocks.PLANKS.getDefaultState().withProperty(BlockPlanks.VARIANT, BlockPlanks.EnumType.OAK));
		worldIn.setBlockState(bp.add(i + 12, j + 4, k + 16), (IBlockState)Blocks.PLANKS.getDefaultState().withProperty(BlockPlanks.VARIANT, BlockPlanks.EnumType.OAK));
		worldIn.setBlockState(bp.add(i + 12, j + 4, k + 17), (IBlockState)Blocks.PLANKS.getDefaultState().withProperty(BlockPlanks.VARIANT, BlockPlanks.EnumType.OAK));
		worldIn.setBlockState(bp.add(i + 12, j + 4, k + 18), (IBlockState)Blocks.PLANKS.getDefaultState().withProperty(BlockPlanks.VARIANT, BlockPlanks.EnumType.OAK));
		worldIn.setBlockState(bp.add(i + 12, j + 4, k + 19), (IBlockState)Blocks.PLANKS.getDefaultState().withProperty(BlockPlanks.VARIANT, BlockPlanks.EnumType.OAK));
		worldIn.setBlockState(bp.add(i + 12, j + 4, k + 20), Blocks.STONE.getDefaultState());
		worldIn.setBlockState(bp.add(i + 12, j + 4, k + 21), Blocks.STONE.getDefaultState());
		worldIn.setBlockState(bp.add(i + 12, j + 5, k + 3), Blocks.STONE.getDefaultState());
		worldIn.setBlockState(bp.add(i + 12, j + 5, k + 4), Blocks.STONE.getDefaultState());
		worldIn.setBlockState(bp.add(i + 12, j + 5, k + 20), Blocks.STONE.getDefaultState());
		worldIn.setBlockState(bp.add(i + 12, j + 5, k + 21), Blocks.STONE.getDefaultState());
		worldIn.setBlockState(bp.add(i + 12, j + 6, k + 3), Blocks.STONE.getDefaultState());
		worldIn.setBlockState(bp.add(i + 12, j + 6, k + 4), Blocks.STONE.getDefaultState());
		worldIn.setBlockState(bp.add(i + 12, j + 6, k + 20), Blocks.STONE.getDefaultState());
		worldIn.setBlockState(bp.add(i + 12, j + 6, k + 21), Blocks.STONE.getDefaultState());
		worldIn.setBlockState(bp.add(i + 12, j + 7, k + 3), Blocks.LAPIS_BLOCK.getDefaultState());
		worldIn.setBlockState(bp.add(i + 12, j + 7, k + 4), Blocks.STONE.getDefaultState());
		worldIn.setBlockState(bp.add(i + 12, j + 7, k + 20), Blocks.STONE.getDefaultState());
		worldIn.setBlockState(bp.add(i + 12, j + 7, k + 21), Blocks.LAPIS_BLOCK.getDefaultState());
		worldIn.setBlockState(bp.add(i + 12, j + 8, k + 3), Blocks.LAPIS_BLOCK.getDefaultState());
		worldIn.setBlockState(bp.add(i + 12, j + 8, k + 4), Blocks.STONE.getDefaultState());
		worldIn.setBlockState(bp.add(i + 12, j + 8, k + 20), Blocks.STONE.getDefaultState());
		worldIn.setBlockState(bp.add(i + 12, j + 8, k + 21), Blocks.LAPIS_BLOCK.getDefaultState());
		worldIn.setBlockState(bp.add(i + 12, j + 9, k + 3), Blocks.LAPIS_BLOCK.getDefaultState());
		worldIn.setBlockState(bp.add(i + 12, j + 9, k + 4), Blocks.STONE.getDefaultState());
		worldIn.setBlockState(bp.add(i + 12, j + 9, k + 7), Blocks.SEA_LANTERN.getDefaultState());
		worldIn.setBlockState(bp.add(i + 12, j + 9, k + 8), Blocks.STONE.getDefaultState());
		worldIn.setBlockState(bp.add(i + 12, j + 9, k + 9), Blocks.SEA_LANTERN.getDefaultState());
		worldIn.setBlockState(bp.add(i + 12, j + 9, k + 15), Blocks.SEA_LANTERN.getDefaultState());
		worldIn.setBlockState(bp.add(i + 12, j + 9, k + 16), Blocks.STONE.getDefaultState());
		worldIn.setBlockState(bp.add(i + 12, j + 9, k + 17), Blocks.SEA_LANTERN.getDefaultState());
		worldIn.setBlockState(bp.add(i + 12, j + 9, k + 20), Blocks.STONE.getDefaultState());
		worldIn.setBlockState(bp.add(i + 12, j + 9, k + 21), Blocks.LAPIS_BLOCK.getDefaultState());
		worldIn.setBlockState(bp.add(i + 12, j + 10, k + 3), Blocks.LAPIS_BLOCK.getDefaultState());
		worldIn.setBlockState(bp.add(i + 12, j + 10, k + 4), Blocks.LAPIS_BLOCK.getDefaultState());
		worldIn.setBlockState(bp.add(i + 12, j + 10, k + 5), Blocks.STONE.getDefaultState());
		worldIn.setBlockState(bp.add(i + 12, j + 10, k + 6), Blocks.STONE.getDefaultState());
		worldIn.setBlockState(bp.add(i + 12, j + 10, k + 7), Blocks.STONE.getDefaultState());
		worldIn.setBlockState(bp.add(i + 12, j + 10, k + 9), Blocks.STONE.getDefaultState());
		worldIn.setBlockState(bp.add(i + 12, j + 10, k + 10), Blocks.STONE.getDefaultState());
		worldIn.setBlockState(bp.add(i + 12, j + 10, k + 11), Blocks.STONE.getDefaultState());
		worldIn.setBlockState(bp.add(i + 12, j + 10, k + 12), Blocks.STONE.getDefaultState());
		worldIn.setBlockState(bp.add(i + 12, j + 10, k + 13), Blocks.STONE.getDefaultState());
		worldIn.setBlockState(bp.add(i + 12, j + 10, k + 14), Blocks.STONE.getDefaultState());
		worldIn.setBlockState(bp.add(i + 12, j + 10, k + 15), Blocks.STONE.getDefaultState());
		worldIn.setBlockState(bp.add(i + 12, j + 10, k + 17), Blocks.STONE.getDefaultState());
		worldIn.setBlockState(bp.add(i + 12, j + 10, k + 18), Blocks.STONE.getDefaultState());
		worldIn.setBlockState(bp.add(i + 12, j + 10, k + 19), Blocks.STONE.getDefaultState());
		worldIn.setBlockState(bp.add(i + 12, j + 10, k + 20), Blocks.LAPIS_BLOCK.getDefaultState());
		worldIn.setBlockState(bp.add(i + 12, j + 10, k + 21), Blocks.LAPIS_BLOCK.getDefaultState());
		worldIn.setBlockState(bp.add(i + 13, j + 3, k + 3), Blocks.STONE.getDefaultState());
		worldIn.setBlockState(bp.add(i + 13, j + 3, k + 4), Blocks.STONE.getDefaultState());
		worldIn.setBlockState(bp.add(i + 13, j + 3, k + 5), Blocks.STONE.getDefaultState());
		worldIn.setBlockState(bp.add(i + 13, j + 3, k + 6), Blocks.STONE.getDefaultState());
		worldIn.setBlockState(bp.add(i + 13, j + 3, k + 7), Blocks.STONE.getDefaultState());
		worldIn.setBlockState(bp.add(i + 13, j + 3, k + 8), Blocks.STONE.getDefaultState());
		worldIn.setBlockState(bp.add(i + 13, j + 3, k + 9), Blocks.STONE.getDefaultState());
		worldIn.setBlockState(bp.add(i + 13, j + 3, k + 10), Blocks.STONE.getDefaultState());
		worldIn.setBlockState(bp.add(i + 13, j + 3, k + 11), Blocks.STONE.getDefaultState());
		worldIn.setBlockState(bp.add(i + 13, j + 3, k + 12), Blocks.STONE.getDefaultState());
		worldIn.setBlockState(bp.add(i + 13, j + 3, k + 13), Blocks.STONE.getDefaultState());
		worldIn.setBlockState(bp.add(i + 13, j + 3, k + 14), Blocks.STONE.getDefaultState());
		worldIn.setBlockState(bp.add(i + 13, j + 3, k + 15), Blocks.STONE.getDefaultState());
		worldIn.setBlockState(bp.add(i + 13, j + 3, k + 16), Blocks.STONE.getDefaultState());
		worldIn.setBlockState(bp.add(i + 13, j + 3, k + 17), Blocks.STONE.getDefaultState());
		worldIn.setBlockState(bp.add(i + 13, j + 3, k + 18), Blocks.STONE.getDefaultState());
		worldIn.setBlockState(bp.add(i + 13, j + 3, k + 19), Blocks.STONE.getDefaultState());
		worldIn.setBlockState(bp.add(i + 13, j + 3, k + 20), Blocks.STONE.getDefaultState());
		worldIn.setBlockState(bp.add(i + 13, j + 3, k + 21), Blocks.STONE.getDefaultState());
		worldIn.setBlockState(bp.add(i + 13, j + 4, k + 3), Blocks.STONE.getDefaultState());
		worldIn.setBlockState(bp.add(i + 13, j + 4, k + 4), Blocks.STONE.getDefaultState());
		worldIn.setBlockState(bp.add(i + 13, j + 4, k + 5), Blocks.STONE.getDefaultState());
		worldIn.setBlockState(bp.add(i + 13, j + 4, k + 6), (IBlockState)Blocks.PLANKS.getDefaultState().withProperty(BlockPlanks.VARIANT, BlockPlanks.EnumType.OAK));
		worldIn.setBlockState(bp.add(i + 13, j + 4, k + 7), (IBlockState)Blocks.PLANKS.getDefaultState().withProperty(BlockPlanks.VARIANT, BlockPlanks.EnumType.OAK));
		worldIn.setBlockState(bp.add(i + 13, j + 4, k + 8), (IBlockState)Blocks.PLANKS.getDefaultState().withProperty(BlockPlanks.VARIANT, BlockPlanks.EnumType.OAK));
		worldIn.setBlockState(bp.add(i + 13, j + 4, k + 9), (IBlockState)Blocks.PLANKS.getDefaultState().withProperty(BlockPlanks.VARIANT, BlockPlanks.EnumType.OAK));
		worldIn.setBlockState(bp.add(i + 13, j + 4, k + 10), (IBlockState)Blocks.PLANKS.getDefaultState().withProperty(BlockPlanks.VARIANT, BlockPlanks.EnumType.OAK));
		worldIn.setBlockState(bp.add(i + 13, j + 4, k + 11), (IBlockState)Blocks.PLANKS.getDefaultState().withProperty(BlockPlanks.VARIANT, BlockPlanks.EnumType.OAK));
		worldIn.setBlockState(bp.add(i + 13, j + 4, k + 12), (IBlockState)Blocks.PLANKS.getDefaultState().withProperty(BlockPlanks.VARIANT, BlockPlanks.EnumType.OAK));
		worldIn.setBlockState(bp.add(i + 13, j + 4, k + 13), (IBlockState)Blocks.PLANKS.getDefaultState().withProperty(BlockPlanks.VARIANT, BlockPlanks.EnumType.OAK));
		worldIn.setBlockState(bp.add(i + 13, j + 4, k + 14), (IBlockState)Blocks.PLANKS.getDefaultState().withProperty(BlockPlanks.VARIANT, BlockPlanks.EnumType.OAK));
		worldIn.setBlockState(bp.add(i + 13, j + 4, k + 15), (IBlockState)Blocks.PLANKS.getDefaultState().withProperty(BlockPlanks.VARIANT, BlockPlanks.EnumType.OAK));
		worldIn.setBlockState(bp.add(i + 13, j + 4, k + 16), (IBlockState)Blocks.PLANKS.getDefaultState().withProperty(BlockPlanks.VARIANT, BlockPlanks.EnumType.OAK));
		worldIn.setBlockState(bp.add(i + 13, j + 4, k + 17), (IBlockState)Blocks.PLANKS.getDefaultState().withProperty(BlockPlanks.VARIANT, BlockPlanks.EnumType.OAK));
		worldIn.setBlockState(bp.add(i + 13, j + 4, k + 18), (IBlockState)Blocks.PLANKS.getDefaultState().withProperty(BlockPlanks.VARIANT, BlockPlanks.EnumType.OAK));
		worldIn.setBlockState(bp.add(i + 13, j + 4, k + 19), Blocks.STONE.getDefaultState());
		worldIn.setBlockState(bp.add(i + 13, j + 4, k + 20), Blocks.STONE.getDefaultState());
		worldIn.setBlockState(bp.add(i + 13, j + 4, k + 21), Blocks.STONE.getDefaultState());
		worldIn.setBlockState(bp.add(i + 13, j + 5, k + 3), Blocks.STONE.getDefaultState());
